Workbook

Sheet الإعدادات
A1: لوحة الإعدادات — شيت مراجعة المشتريات والمبيعات
A3: السنة | B3: 2026 | C3: أدخل السنة الميلادية (مثال: 2026)
A4: الشهر (1 - 12) | B4: 8 | C4: اختر رقم الشهر من القائمة المنسدلة
A5: اسم الشهر (تلقائي) | B5: =CHOOSE(B4,"يناير","فبراير","مارس","أبريل","مايو","يونيو","يوليو","أغسطس","سبتمبر","أكتوبر","نوفمبر","ديسمبر") | C5: يُحسب تلقائياً
A6: عدد أيام الشهر (تلقائي) | B6: =DAY(EOMONTH(DATE(B3,B4,1),0)) | C6: يُحسب تلقائياً — يتغير حسب الشهر والسنة (يشمل السنوات الكبيسة)
A7: تاريخ بداية الشهر (تلقائي) | B7: =DATE(B3,B4,1) | C7: يُحسب تلقائياً
A8: نسبة ضريبة القيمة المضافة | B8: 0.15 | C8: عدّلها هنا إذا تغيّرت النسبة — تنعكس على كل الأوراق
A10: طريقة الاستخدام ودليل الألوان
A11: خلايا صفراء / كريمية | B11: خلايا إدخال — اكتب فيها فقط. باقي الخلايا معادلات تلقائية لا تُعدَّل.
A12: جدول المبيعات (أخضر) | B12: أدخل كود الصنف، الكمية المباعة، وسعر البيع. الاسم والإجماليات والضريبة تُحسب تلقائياً.
A13: جدول المشتريات (أزرق) | B13: مرتبط بالمبيعات: القائمة المنسدلة في كود الشراء تعرض أصناف مبيعات اليوم فقط، ويمكن إدخال أكثر من فاتورة لنفس الصنف. إذا حذفت الصنف من المبيعات يُشطب سطر الشراء تلقائياً ويُستبعد من كل الحسابات والإجماليات.
A14: تحليل الربحية (ذهبي) | B14: يُحسب تلقائياً لكل صنف مبيع: إجمالي الكمية المشتراة، عدد فواتير الشراء، التكلفة، صافي الربح، وهامش الربح.
A15: تغيير الشهر | B15: غيّر السنة أو الشهر أعلاه فتتحدّث تواريخ كل الأيام تلقائياً، والأيام الزائدة عن الشهر (29/30/31) تظهر عليها علامة "خارج نطاق الشهر" وتُستبعد من الملخص.
A16: حالة الفاتورة (تلقائي) | B16: لكل سطر شراء: إذا كُتب سعر الشراء تظهر "✓ تم استلام الفاتورة" بالأخضر، وإذا كان السعر فارغاً تظهر "✗ لم تصل من المورد" بالأحمر.
A17: تنبيهات تلقائية | B17: الربح السالب بالأحمر — الكود غير المعرّف بالأحمر — وعمود "حالة فواتير الصنف" يبيّن كم فاتورة اكتملت من إجمالي فواتير الصنف.
A18: ملخص الشهر | B18: ورقة تجمع نتائج كل الأيام تلقائياً مع مؤشرات الأداء وأفضل وأسوأ يوم.

Sheet ملخص الشهر
A1: =CONCATENATE("ملخص شهر ",الإعدادات!B5," ",الإعدادات!B3)
B3: إجمالي المبيعات (قبل الضريبة) | D3: إجمالي المشتريات (قبل الضريبة) | F3: صافي الربح | H3: هامش الربح العام
B4: =SUM(C8:C38) | D4: =SUM(D8:D38) | F4: =SUM(E8:E38) | H4: =IF(N(B4)=0,"",F4/B4)
B5: أفضل يوم (أعلى ربح): | C5: =IFERROR("يوم "&INDEX(A8:A38,MATCH(MAX(E8:E38),E8:E38,0)),"") | E5: أضعف يوم (أدنى ربح): | F5: =IFERROR("يوم "&INDEX(A8:A38,MATCH(MIN(E8:E38),E8:E38,0)),"")
A7: اليوم | B7: التاريخ | C7: المبيعات (قبل الضريبة) | D7: المشتريات (قبل الضريبة) | E7: صافي الربح | F7: هامش الربح % | G7: ضريبة المبيعات | H7: ضريبة المشتريات
A8: 1 | B8: =IF($A8<=الإعدادات!$B$6,DATE(الإعدادات!$B$3,الإعدادات!$B$4,$A8),"") | C8: =IF($A8<=الإعدادات!$B$6,N(INDIRECT("'يوم "&$A8&"'!E155")),"") | D8: =IF($A8<=الإعدادات!$B$6,N(INDIRECT("'يوم "&$A8&"'!O155")),"") | E8: =IF($A8<=الإعدادات!$B$6,N(INDIRECT("'يوم "&$A8&"'!V155")),"") | F8: =IF(N(C8)=0,"",E8/C8) | G8: =IF($A8<=الإعدادات!$B$6,N(INDIRECT("'يوم "&$A8&"'!F155")),"") | H8: =IF($A8<=الإعدادات!$B$6,N(INDIRECT("'يوم "&$A8&"'!P155")),"")
A9: 2 | B9: =IF($A9<=الإعدادات!$B$6,DATE(الإعدادات!$B$3,الإعدادات!$B$4,$A9),"") | C9: =IF($A9<=الإعدادات!$B$6,N(INDIRECT("'يوم "&$A9&"'!E155")),"") | D9: =IF($A9<=الإعدادات!$B$6,N(INDIRECT("'يوم "&$A9&"'!O155")),"") | E9: =IF($A9<=الإعدادات!$B$6,N(INDIRECT("'يوم "&$A9&"'!V155")),"") | F9: =IF(N(C9)=0,"",E9/C9) | G9: =IF($A9<=الإعدادات!$B$6,N(INDIRECT("'يوم "&$A9&"'!F155")),"") | H9: =IF($A9<=الإعدادات!$B$6,N(INDIRECT("'يوم "&$A9&"'!P155")),"")
A10: 3 | B10: =IF($A10<=الإعدادات!$B$6,DATE(الإعدادات!$B$3,الإعدادات!$B$4,$A10),"") | C10: =IF($A10<=الإعدادات!$B$6,N(INDIRECT("'يوم "&$A10&"'!E155")),"") | D10: =IF($A10<=الإعدادات!$B$6,N(INDIRECT("'يوم "&$A10&"'!O155")),"") | E10: =IF($A10<=الإعدادات!$B$6,N(INDIRECT("'يوم "&$A10&"'!V155")),"") | F10: =IF(N(C10)=0,"",E10/C10) | G10: =IF($A10<=الإعدادات!$B$6,N(INDIRECT("'يوم "&$A10&"'!F155")),"") | H10: =IF($A10<=الإعدادات!$B$6,N(INDIRECT("'يوم "&$A10&"'!P155")),"")
A11: 4 | B11: =IF($A11<=الإعدادات!$B$6,DATE(الإعدادات!$B$3,الإعدادات!$B$4,$A11),"") | C11: =IF($A11<=الإعدادات!$B$6,N(INDIRECT("'يوم "&$A11&"'!E155")),"") | D11: =IF($A11<=الإعدادات!$B$6,N(INDIRECT("'يوم "&$A11&"'!O155")),"") | E11: =IF($A11<=الإعدادات!$B$6,N(INDIRECT("'يوم "&$A11&"'!V155")),"") | F11: =IF(N(C11)=0,"",E11/C11) | G11: =IF($A11<=الإعدادات!$B$6,N(INDIRECT("'يوم "&$A11&"'!F155")),"") | H11: =IF($A11<=الإعدادات!$B$6,N(INDIRECT("'يوم "&$A11&"'!P155")),"")
A12: 5 | B12: =IF($A12<=الإعدادات!$B$6,DATE(الإعدادات!$B$3,الإعدادات!$B$4,$A12),"") | C12: =IF($A12<=الإعدادات!$B$6,N(INDIRECT("'يوم "&$A12&"'!E155")),"") | D12: =IF($A12<=الإعدادات!$B$6,N(INDIRECT("'يوم "&$A12&"'!O155")),"") | E12: =IF($A12<=الإعدادات!$B$6,N(INDIRECT("'يوم "&$A12&"'!V155")),"") | F12: =IF(N(C12)=0,"",E12/C12) | G12: =IF($A12<=الإعدادات!$B$6,N(INDIRECT("'يوم "&$A12&"'!F155")),"") | H12: =IF($A12<=الإعدادات!$B$6,N(INDIRECT("'يوم "&$A12&"'!P155")),"")
A13: 6 | B13: =IF($A13<=الإعدادات!$B$6,DATE(الإعدادات!$B$3,الإعدادات!$B$4,$A13),"") | C13: =IF($A13<=الإعدادات!$B$6,N(INDIRECT("'يوم "&$A13&"'!E155")),"") | D13: =IF($A13<=الإعدادات!$B$6,N(INDIRECT("'يوم "&$A13&"'!O155")),"") | E13: =IF($A13<=الإعدادات!$B$6,N(INDIRECT("'يوم "&$A13&"'!V155")),"") | F13: =IF(N(C13)=0,"",E13/C13) | G13: =IF($A13<=الإعدادات!$B$6,N(INDIRECT("'يوم "&$A13&"'!F155")),"") | H13: =IF($A13<=الإعدادات!$B$6,N(INDIRECT("'يوم "&$A13&"'!P155")),"")
A14: 7 | B14: =IF($A14<=الإعدادات!$B$6,DATE(الإعدادات!$B$3,الإعدادات!$B$4,$A14),"") | C14: =IF($A14<=الإعدادات!$B$6,N(INDIRECT("'يوم "&$A14&"'!E155")),"") | D14: =IF($A14<=الإعدادات!$B$6,N(INDIRECT("'يوم "&$A14&"'!O155")),"") | E14: =IF($A14<=الإعدادات!$B$6,N(INDIRECT("'يوم "&$A14&"'!V155")),"") | F14: =IF(N(C14)=0,"",E14/C14) | G14: =IF($A14<=الإعدادات!$B$6,N(INDIRECT("'يوم "&$A14&"'!F155")),"") | H14: =IF($A14<=الإعدادات!$B$6,N(INDIRECT("'يوم "&$A14&"'!P155")),"")
A15: 8 | B15: =IF($A15<=الإعدادات!$B$6,DATE(الإعدادات!$B$3,الإعدادات!$B$4,$A15),"") | C15: =IF($A15<=الإعدادات!$B$6,N(INDIRECT("'يوم "&$A15&"'!E155")),"") | D15: =IF($A15<=الإعدادات!$B$6,N(INDIRECT("'يوم "&$A15&"'!O155")),"") | E15: =IF($A15<=الإعدادات!$B$6,N(INDIRECT("'يوم "&$A15&"'!V155")),"") | F15: =IF(N(C15)=0,"",E15/C15) | G15: =IF($A15<=الإعدادات!$B$6,N(INDIRECT("'يوم "&$A15&"'!F155")),"") | H15: =IF($A15<=الإعدادات!$B$6,N(INDIRECT("'يوم "&$A15&"'!P155")),"")
A16: 9 | B16: =IF($A16<=الإعدادات!$B$6,DATE(الإعدادات!$B$3,الإعدادات!$B$4,$A16),"") | C16: =IF($A16<=الإعدادات!$B$6,N(INDIRECT("'يوم "&$A16&"'!E155")),"") | D16: =IF($A16<=الإعدادات!$B$6,N(INDIRECT("'يوم "&$A16&"'!O155")),"") | E16: =IF($A16<=الإعدادات!$B$6,N(INDIRECT("'يوم "&$A16&"'!V155")),"") | F16: =IF(N(C16)=0,"",E16/C16) | G16: =IF($A16<=الإعدادات!$B$6,N(INDIRECT("'يوم "&$A16&"'!F155")),"") | H16: =IF($A16<=الإعدادات!$B$6,N(INDIRECT("'يوم "&$A16&"'!P155")),"")
A17: 10 | B17: =IF($A17<=الإعدادات!$B$6,DATE(الإعدادات!$B$3,الإعدادات!$B$4,$A17),"") | C17: =IF($A17<=الإعدادات!$B$6,N(INDIRECT("'يوم "&$A17&"'!E155")),"") | D17: =IF($A17<=الإعدادات!$B$6,N(INDIRECT("'يوم "&$A17&"'!O155")),"") | E17: =IF($A17<=الإعدادات!$B$6,N(INDIRECT("'يوم "&$A17&"'!V155")),"") | F17: =IF(N(C17)=0,"",E17/C17) | G17: =IF($A17<=الإعدادات!$B$6,N(INDIRECT("'يوم "&$A17&"'!F155")),"") | H17: =IF($A17<=الإعدادات!$B$6,N(INDIRECT("'يوم "&$A17&"'!P155")),"")
A18: 11 | B18: =IF($A18<=الإعدادات!$B$6,DATE(الإعدادات!$B$3,الإعدادات!$B$4,$A18),"") | C18: =IF($A18<=الإعدادات!$B$6,N(INDIRECT("'يوم "&$A18&"'!E155")),"") | D18: =IF($A18<=الإعدادات!$B$6,N(INDIRECT("'يوم "&$A18&"'!O155")),"") | E18: =IF($A18<=الإعدادات!$B$6,N(INDIRECT("'يوم "&$A18&"'!V155")),"") | F18: =IF(N(C18)=0,"",E18/C18) | G18: =IF($A18<=الإعدادات!$B$6,N(INDIRECT("'يوم "&$A18&"'!F155")),"") | H18: =IF($A18<=الإعدادات!$B$6,N(INDIRECT("'يوم "&$A18&"'!P155")),"")
A19: 12 | B19: =IF($A19<=الإعدادات!$B$6,DATE(الإعدادات!$B$3,الإعدادات!$B$4,$A19),"") | C19: =IF($A19<=الإعدادات!$B$6,N(INDIRECT("'يوم "&$A19&"'!E155")),"") | D19: =IF($A19<=الإعدادات!$B$6,N(INDIRECT("'يوم "&$A19&"'!O155")),"") | E19: =IF($A19<=الإعدادات!$B$6,N(INDIRECT("'يوم "&$A19&"'!V155")),"") | F19: =IF(N(C19)=0,"",E19/C19) | G19: =IF($A19<=الإعدادات!$B$6,N(INDIRECT("'يوم "&$A19&"'!F155")),"") | H19: =IF($A19<=الإعدادات!$B$6,N(INDIRECT("'يوم "&$A19&"'!P155")),"")
... A38: 31 | B38: =IF($A38<=الإعدادات!$B$6,DATE(الإعدادات!$B$3,الإعدادات!$B$4,$A38),"") | C38: =IF($A38<=الإعدادات!$B$6,N(INDIRECT("'يوم "&$A38&"'!E155")),"") | D38: =IF($A38<=الإعدادات!$B$6,N(INDIRECT("'يوم "&$A38&"'!O155")),"") | E38: =IF($A38<=الإعدادات!$B$6,N(INDIRECT("'يوم "&$A38&"'!V155")),"") | F38: =IF(N(C38)=0,"",E38/C38) | G38: =IF($A38<=الإعدادات!$B$6,N(INDIRECT("'يوم "&$A38&"'!F155")),"") | H38: =IF($A38<=الإعدادات!$B$6,N(INDIRECT("'يوم "&$A38&"'!P155")),"")
A39: إجمالي الشهر | C39: =SUM(C8:C38) | D39: =SUM(D8:D38) | E39: =SUM(E8:E38) | F39: =IF(N(C39)=0,"",E39/C39) | G39: =SUM(G8:G38) | H39: =SUM(H8:H38)
A42: مؤشرات إضافية — مركز ضريبة القيمة المضافة والأداء اليومي
B43: صافي ض.ق.م المستحقة للسداد (مبيعات − مشتريات) | D43: ض.ق.م المبيعات (محصّلة) | F43: ض.ق.م المشتريات (قابلة للخصم) | H43: إجمالي المبيعات شامل الضريبة
B44: =G39-H39 | D44: =G39 | F44: =H39 | H44: =B4+G39
B46: عدد أيام العمل الفعّالة | D46: متوسط المبيعات اليومي | F46: متوسط صافي الربح اليومي | H46: أعلى مبيعات في يوم واحد
B47: =COUNTIF(C8:C38,">0") | D47: =IF(N($B$47)=0,"",B4/$B$47) | F47: =IF(N($B$47)=0,"",F4/$B$47) | H47: =MAX(C8:C38)

Sheet قائمة الأصناف
A1: دليل وأكواد الأصناف المعتمد
A2: كود الصنف | B2: اسم الصنف
A3: 048271 | B3: مانجو تيمور | C3: =IF(TRIM(A3)="","",IF(ISNUMBER(VALUE(TRIM(A3))),TEXT(VALUE(TRIM(A3)),"0"),TRIM(A3)))
A4: 048568 | B4: مانجو يمنى | C4: =IF(TRIM(A4)="","",IF(ISNUMBER(VALUE(TRIM(A4))),TEXT(VALUE(TRIM(A4)),"0"),TRIM(A4)))
A5: 048593 | B5: مانجو تومي | C5: =IF(TRIM(A5)="","",IF(ISNUMBER(VALUE(TRIM(A5))),TEXT(VALUE(TRIM(A5)),"0"),TRIM(A5)))
A6: 047906 | B6: برتقال أبو صره | C6: =IF(TRIM(A6)="","",IF(ISNUMBER(VALUE(TRIM(A6))),TEXT(VALUE(TRIM(A6)),"0"),TRIM(A6)))
A7: 049494 | B7: برتقال عصير | C7: =IF(TRIM(A7)="","",IF(ISNUMBER(VALUE(TRIM(A7))),TEXT(VALUE(TRIM(A7)),"0"),TRIM(A7)))
A8: 000009 | B8: خوخ | C8: =IF(TRIM(A8)="","",IF(ISNUMBER(VALUE(TRIM(A8))),TEXT(VALUE(TRIM(A8)),"0"),TRIM(A8)))
A9: 048432 | B9: كلمنتينا | C9: =IF(TRIM(A9)="","",IF(ISNUMBER(VALUE(TRIM(A9))),TEXT(VALUE(TRIM(A9)),"0"),TRIM(A9)))
A10: 049500 | B10: تفاح جالا | C10: =IF(TRIM(A10)="","",IF(ISNUMBER(VALUE(TRIM(A10))),TEXT(VALUE(TRIM(A10)),"0"),TRIM(A10)))
A11: 055071 | B11: عنب احمر | C11: =IF(TRIM(A11)="","",IF(ISNUMBER(VALUE(TRIM(A11))),TEXT(VALUE(TRIM(A11)),"0"),TRIM(A11)))
A12: 000010 | B12: مشمش | C12: =IF(TRIM(A12)="","",IF(ISNUMBER(VALUE(TRIM(A12))),TEXT(VALUE(TRIM(A12)),"0"),TRIM(A12)))
A13: 048623 | B13: شمام | C13: =IF(TRIM(A13)="","",IF(ISNUMBER(VALUE(TRIM(A13))),TEXT(VALUE(TRIM(A13)),"0"),TRIM(A13)))
A14: 048024 | B14: ليمون | C14: =IF(TRIM(A14)="","",IF(ISNUMBER(VALUE(TRIM(A14))),TEXT(VALUE(TRIM(A14)),"0"),TRIM(A14)))
... A495: 074355 | B495: شمام حلو اردني | C495: =IF(TRIM(A495)="","",IF(ISNUMBER(VALUE(TRIM(A495))),TEXT(VALUE(TRIM(A495)),"0"),TRIM(A495)))
C496: =IF(TRIM(A496)="","",IF(ISNUMBER(VALUE(TRIM(A496))),TEXT(VALUE(TRIM(A496)),"0"),TRIM(A496)))
C497: =IF(TRIM(A497)="","",IF(ISNUMBER(VALUE(TRIM(A497))),TEXT(VALUE(TRIM(A497)),"0"),TRIM(A497)))
C498: =IF(TRIM(A498)="","",IF(ISNUMBER(VALUE(TRIM(A498))),TEXT(VALUE(TRIM(A498)),"0"),TRIM(A498)))
C499: =IF(TRIM(A499)="","",IF(ISNUMBER(VALUE(TRIM(A499))),TEXT(VALUE(TRIM(A499)),"0"),TRIM(A499)))
C500: =IF(TRIM(A500)="","",IF(ISNUMBER(VALUE(TRIM(A500))),TEXT(VALUE(TRIM(A500)),"0"),TRIM(A500)))
C501: =IF(TRIM(A501)="","",IF(ISNUMBER(VALUE(TRIM(A501))),TEXT(VALUE(TRIM(A501)),"0"),TRIM(A501)))
C502: =IF(TRIM(A502)="","",IF(ISNUMBER(VALUE(TRIM(A502))),TEXT(VALUE(TRIM(A502)),"0"),TRIM(A502)))
C503: =IF(TRIM(A503)="","",IF(ISNUMBER(VALUE(TRIM(A503))),TEXT(VALUE(TRIM(A503)),"0"),TRIM(A503)))
C504: =IF(TRIM(A504)="","",IF(ISNUMBER(VALUE(TRIM(A504))),TEXT(VALUE(TRIM(A504)),"0"),TRIM(A504)))
C505: =IF(TRIM(A505)="","",IF(ISNUMBER(VALUE(TRIM(A505))),TEXT(VALUE(TRIM(A505)),"0"),TRIM(A505)))
C506: =IF(TRIM(A506)="","",IF(ISNUMBER(VALUE(TRIM(A506))),TEXT(VALUE(TRIM(A506)),"0"),TRIM(A506)))
C507: =IF(TRIM(A507)="","",IF(ISNUMBER(VALUE(TRIM(A507))),TEXT(VALUE(TRIM(A507)),"0"),TRIM(A507)))
... C1000: =IF(TRIM(A1000)="","",IF(ISNUMBER(VALUE(TRIM(A1000))),TEXT(VALUE(TRIM(A1000)),"0"),TRIM(A1000)))

Sheet يوم 1
A1: رقم اليوم: | B1: 1 | C1: التاريخ: | D1: =IF($B$1<=الإعدادات!$B$6,DATE(الإعدادات!$B$3,الإعدادات!$B$4,$B$1),"") | E1: اليوم: | F1: =IF($D$1="","",CHOOSE(WEEKDAY($D$1),"الأحد","الاثنين","الثلاثاء","الأربعاء","الخميس","الجمعة","السبت")) | H1: =IF($B$1<=الإعدادات!$B$6,"✓ يوم فعّال ضمن شهر "&الإعدادات!$B$5,"✗ خارج نطاق الشهر المحدد — لا تُدخل بيانات هنا")
A3: جدول المبيعات اليومية | H3: جدول المشتريات وفواتير الموردين (سطر لكل فاتورة — يسمح بأكثر من فاتورة لنفس الصنف) | R3: تحليل الربحية لكل صنف مبيع (تلقائي)
A4: كود الصنف | B4: اسم الصنف (تلقائي) | C4: الكمية المباعة | D4: سعر البيع | E4: الإجمالي قبل الضريبة | F4: الضريبة | G4: الإجمالي شامل الضريبة | H4: كود الصنف | I4: اسم الصنف (تلقائي) | J4: حالة الفاتورة | K4: اسم المورد | L4: رقم الفاتورة | M4: الكمية المشتراة | N4: سعر الشراء | O4: الإجمالي قبل الضريبة | P4: الضريبة | Q4: الإجمالي شامل الضريبة | R4: إجمالي الكمية المشتراة | S4: عدد فواتير الشراء | T4: إجمالي تكلفة الشراء | U4: متوسط سعر الشراء | V4: صافي الربح (قبل الضريبة) | W4: هامش الربح % | X4: حالة فواتير الصنف (إجمالي)
A5: 048643 | B5: =IF(Y5="","",IFERROR(INDEX('قائمة الأصناف'!$B$3:$B$1000,MATCH(Y5,'قائمة الأصناف'!$C$3:$C$1000,0)),"⚠ كود غير معرف")) | C5: 3160 | D5: 5.75 | E5: =IF(OR(C5="",D5=""),"",C5*D5) | F5: =IF(E5="","",E5*الإعدادات!$B$8) | G5: =IF(E5="","",E5+F5) | H5: 048643 | I5: =IF(Z5="","",IF(COUNTIF($Y$5:$Y$154,Z5)=0,"⚠ الصنف غير موجود في المبيعات",IFERROR(INDEX('قائمة الأصناف'!$B$3:$B$1000,MATCH(Z5,'قائمة الأصناف'!$C$3:$C$1000,0)),"⚠ كود غير معرف"))) | J5: =IF(AND(Z5="",TRIM(K5)="",M5="",N5=""),"",IF(AND(Z5<>"",COUNTIF($Y$5:$Y$154,Z5)=0),"✗ حُذف من المبيعات — مستبعد من الحساب",IF(N5="","✗ لم تصل من المورد","✓ تم استلام الفاتورة"))) | O5: =IF(OR(M5="",N5=""),"",IF(COUNTIF($Y$5:$Y$154,Z5)=0,"",M5*N5)) | P5: =IF(O5="","",O5*الإعدادات!$B$8) | Q5: =IF(O5="","",O5+P5) | R5: =IF(Y5="","",SUMIFS($M$5:$M$154,$Z$5:$Z$154,Y5)) | S5: =IF(Y5="","",COUNTIFS($Z$5:$Z$154,Y5)) | T5: =IF(Y5="","",SUMIFS($O$5:$O$154,$Z$5:$Z$154,Y5)) | U5: =IF(Y5="","",IF(N(R5)=0,"",T5/R5)) | V5: =IF(Y5="","",N(E5)-T5) | W5: =IF(Y5="","",IF(N(E5)=0,"",V5/E5)) | X5: =IF(Y5="","",IF(S5=0,"⏳ لا توجد فواتير شراء",IF(COUNTIFS($Z$5:$Z$154,Y5,$N$5:$N$154,">0")=S5,"✓ اكتملت جميع الفواتير ("&S5&")","⚠ وصل "&COUNTIFS($Z$5:$Z$154,Y5,$N$5:$N$154,">0")&" من "&S5&" فواتير"))) | Y5: =IF(TRIM(A5)="","",IF(ISNUMBER(VALUE(TRIM(A5))),TEXT(VALUE(TRIM(A5)),"0"),TRIM(A5))) | Z5: =IF(TRIM(H5)="","",IF(ISNUMBER(VALUE(TRIM(H5))),TEXT(VALUE(TRIM(H5)),"0"),TRIM(H5)))
A6: 047884 | B6: =IF(Y6="","",IFERROR(INDEX('قائمة الأصناف'!$B$3:$B$1000,MATCH(Y6,'قائمة الأصناف'!$C$3:$C$1000,0)),"⚠ كود غير معرف")) | C6: 2184 | D6: 7 | E6: =IF(OR(C6="",D6=""),"",C6*D6) | F6: =IF(E6="","",E6*الإعدادات!$B$8) | G6: =IF(E6="","",E6+F6) | H6: 047884 | I6: =IF(Z6="","",IF(COUNTIF($Y$5:$Y$154,Z6)=0,"⚠ الصنف غير موجود في المبيعات",IFERROR(INDEX('قائمة الأصناف'!$B$3:$B$1000,MATCH(Z6,'قائمة الأصناف'!$C$3:$C$1000,0)),"⚠ كود غير معرف"))) | J6: =IF(AND(Z6="",TRIM(K6)="",M6="",N6=""),"",IF(AND(Z6<>"",COUNTIF($Y$5:$Y$154,Z6)=0),"✗ حُذف من المبيعات — مستبعد من الحساب",IF(N6="","✗ لم تصل من المورد","✓ تم استلام الفاتورة"))) | O6: =IF(OR(M6="",N6=""),"",IF(COUNTIF($Y$5:$Y$154,Z6)=0,"",M6*N6)) | P6: =IF(O6="","",O6*الإعدادات!$B$8) | Q6: =IF(O6="","",O6+P6) | R6: =IF(Y6="","",SUMIFS($M$5:$M$154,$Z$5:$Z$154,Y6)) | S6: =IF(Y6="","",COUNTIFS($Z$5:$Z$154,Y6)) | T6: =IF(Y6="","",SUMIFS($O$5:$O$154,$Z$5:$Z$154,Y6)) | U6: =IF(Y6="","",IF(N(R6)=0,"",T6/R6)) | V6: =IF(Y6="","",N(E6)-T6) | W6: =IF(Y6="","",IF(N(E6)=0,"",V6/E6)) | X6: =IF(Y6="","",IF(S6=0,"⏳ لا توجد فواتير شراء",IF(COUNTIFS($Z$5:$Z$154,Y6,$N$5:$N$154,">0")=S6,"✓ اكتملت جميع الفواتير ("&S6&")","⚠ وصل "&COUNTIFS($Z$5:$Z$154,Y6,$N$5:$N$154,">0")&" من "&S6&" فواتير"))) | Y6: =IF(TRIM(A6)="","",IF(ISNUMBER(VALUE(TRIM(A6))),TEXT(VALUE(TRIM(A6)),"0"),TRIM(A6))) | Z6: =IF(TRIM(H6)="","",IF(ISNUMBER(VALUE(TRIM(H6))),TEXT(VALUE(TRIM(H6)),"0"),TRIM(H6)))
A7: 048432 | B7: =IF(Y7="","",IFERROR(INDEX('قائمة الأصناف'!$B$3:$B$1000,MATCH(Y7,'قائمة الأصناف'!$C$3:$C$1000,0)),"⚠ كود غير معرف")) | C7: 3797 | D7: 4 | E7: =IF(OR(C7="",D7=""),"",C7*D7) | F7: =IF(E7="","",E7*الإعدادات!$B$8) | G7: =IF(E7="","",E7+F7) | H7: 048432 | I7: =IF(Z7="","",IF(COUNTIF($Y$5:$Y$154,Z7)=0,"⚠ الصنف غير موجود في المبيعات",IFERROR(INDEX('قائمة الأصناف'!$B$3:$B$1000,MATCH(Z7,'قائمة الأصناف'!$C$3:$C$1000,0)),"⚠ كود غير معرف"))) | J7: =IF(AND(Z7="",TRIM(K7)="",M7="",N7=""),"",IF(AND(Z7<>"",COUNTIF($Y$5:$Y$154,Z7)=0),"✗ حُذف من المبيعات — مستبعد من الحساب",IF(N7="","✗ لم تصل من المورد","✓ تم استلام الفاتورة"))) | O7: =IF(OR(M7="",N7=""),"",IF(COUNTIF($Y$5:$Y$154,Z7)=0,"",M7*N7)) | P7: =IF(O7="","",O7*الإعدادات!$B$8) | Q7: =IF(O7="","",O7+P7) | R7: =IF(Y7="","",SUMIFS($M$5:$M$154,$Z$5:$Z$154,Y7)) | S7: =IF(Y7="","",COUNTIFS($Z$5:$Z$154,Y7)) | T7: =IF(Y7="","",SUMIFS($O$5:$O$154,$Z$5:$Z$154,Y7)) | U7: =IF(Y7="","",IF(N(R7)=0,"",T7/R7)) | V7: =IF(Y7="","",N(E7)-T7) | W7: =IF(Y7="","",IF(N(E7)=0,"",V7/E7)) | X7: =IF(Y7="","",IF(S7=0,"⏳ لا توجد فواتير شراء",IF(COUNTIFS($Z$5:$Z$154,Y7,$N$5:$N$154,">0")=S7,"✓ اكتملت جميع الفواتير ("&S7&")","⚠ وصل "&COUNTIFS($Z$5:$Z$154,Y7,$N$5:$N$154,">0")&" من "&S7&" فواتير"))) | Y7: =IF(TRIM(A7)="","",IF(ISNUMBER(VALUE(TRIM(A7))),TEXT(VALUE(TRIM(A7)),"0"),TRIM(A7))) | Z7: =IF(TRIM(H7)="","",IF(ISNUMBER(VALUE(TRIM(H7))),TEXT(VALUE(TRIM(H7)),"0"),TRIM(H7)))
A8: 048024 | B8: =IF(Y8="","",IFERROR(INDEX('قائمة الأصناف'!$B$3:$B$1000,MATCH(Y8,'قائمة الأصناف'!$C$3:$C$1000,0)),"⚠ كود غير معرف")) | C8: 5690 | D8: 4 | E8: =IF(OR(C8="",D8=""),"",C8*D8) | F8: =IF(E8="","",E8*الإعدادات!$B$8) | G8: =IF(E8="","",E8+F8) | H8: 048024 | I8: =IF(Z8="","",IF(COUNTIF($Y$5:$Y$154,Z8)=0,"⚠ الصنف غير موجود في المبيعات",IFERROR(INDEX('قائمة الأصناف'!$B$3:$B$1000,MATCH(Z8,'قائمة الأصناف'!$C$3:$C$1000,0)),"⚠ كود غير معرف"))) | J8: =IF(AND(Z8="",TRIM(K8)="",M8="",N8=""),"",IF(AND(Z8<>"",COUNTIF($Y$5:$Y$154,Z8)=0),"✗ حُذف من المبيعات — مستبعد من الحساب",IF(N8="","✗ لم تصل من المورد","✓ تم استلام الفاتورة"))) | O8: =IF(OR(M8="",N8=""),"",IF(COUNTIF($Y$5:$Y$154,Z8)=0,"",M8*N8)) | P8: =IF(O8="","",O8*الإعدادات!$B$8) | Q8: =IF(O8="","",O8+P8) | R8: =IF(Y8="","",SUMIFS($M$5:$M$154,$Z$5:$Z$154,Y8)) | S8: =IF(Y8="","",COUNTIFS($Z$5:$Z$154,Y8)) | T8: =IF(Y8="","",SUMIFS($O$5:$O$154,$Z$5:$Z$154,Y8)) | U8: =IF(Y8="","",IF(N(R8)=0,"",T8/R8)) | V8: =IF(Y8="","",N(E8)-T8) | W8: =IF(Y8="","",IF(N(E8)=0,"",V8/E8)) | X8: =IF(Y8="","",IF(S8=0,"⏳ لا توجد فواتير شراء",IF(COUNTIFS($Z$5:$Z$154,Y8,$N$5:$N$154,">0")=S8,"✓ اكتملت جميع الفواتير ("&S8&")","⚠ وصل "&COUNTIFS($Z$5:$Z$154,Y8,$N$5:$N$154,">0")&" من "&S8&" فواتير"))) | Y8: =IF(TRIM(A8)="","",IF(ISNUMBER(VALUE(TRIM(A8))),TEXT(VALUE(TRIM(A8)),"0"),TRIM(A8))) | Z8: =IF(TRIM(H8)="","",IF(ISNUMBER(VALUE(TRIM(H8))),TEXT(VALUE(TRIM(H8)),"0"),TRIM(H8)))
A9: 036252 | B9: =IF(Y9="","",IFERROR(INDEX('قائمة الأصناف'!$B$3:$B$1000,MATCH(Y9,'قائمة الأصناف'!$C$3:$C$1000,0)),"⚠ كود غير معرف")) | C9: 10496 | D9: 6 | E9: =IF(OR(C9="",D9=""),"",C9*D9) | F9: =IF(E9="","",E9*الإعدادات!$B$8) | G9: =IF(E9="","",E9+F9) | H9: 036252 | I9: =IF(Z9="","",IF(COUNTIF($Y$5:$Y$154,Z9)=0,"⚠ الصنف غير موجود في المبيعات",IFERROR(INDEX('قائمة الأصناف'!$B$3:$B$1000,MATCH(Z9,'قائمة الأصناف'!$C$3:$C$1000,0)),"⚠ كود غير معرف"))) | J9: =IF(AND(Z9="",TRIM(K9)="",M9="",N9=""),"",IF(AND(Z9<>"",COUNTIF($Y$5:$Y$154,Z9)=0),"✗ حُذف من المبيعات — مستبعد من الحساب",IF(N9="","✗ لم تصل من المورد","✓ تم استلام الفاتورة"))) | O9: =IF(OR(M9="",N9=""),"",IF(COUNTIF($Y$5:$Y$154,Z9)=0,"",M9*N9)) | P9: =IF(O9="","",O9*الإعدادات!$B$8) | Q9: =IF(O9="","",O9+P9) | R9: =IF(Y9="","",SUMIFS($M$5:$M$154,$Z$5:$Z$154,Y9)) | S9: =IF(Y9="","",COUNTIFS($Z$5:$Z$154,Y9)) | T9: =IF(Y9="","",SUMIFS($O$5:$O$154,$Z$5:$Z$154,Y9)) | U9: =IF(Y9="","",IF(N(R9)=0,"",T9/R9)) | V9: =IF(Y9="","",N(E9)-T9) | W9: =IF(Y9="","",IF(N(E9)=0,"",V9/E9)) | X9: =IF(Y9="","",IF(S9=0,"⏳ لا توجد فواتير شراء",IF(COUNTIFS($Z$5:$Z$154,Y9,$N$5:$N$154,">0")=S9,"✓ اكتملت جميع الفواتير ("&S9&")","⚠ وصل "&COUNTIFS($Z$5:$Z$154,Y9,$N$5:$N$154,">0")&" من "&S9&" فواتير"))) | Y9: =IF(TRIM(A9)="","",IF(ISNUMBER(VALUE(TRIM(A9))),TEXT(VALUE(TRIM(A9)),"0"),TRIM(A9))) | Z9: =IF(TRIM(H9)="","",IF(ISNUMBER(VALUE(TRIM(H9))),TEXT(VALUE(TRIM(H9)),"0"),TRIM(H9)))
A10: 048203 | B10: =IF(Y10="","",IFERROR(INDEX('قائمة الأصناف'!$B$3:$B$1000,MATCH(Y10,'قائمة الأصناف'!$C$3:$C$1000,0)),"⚠ كود غير معرف")) | C10: 6187 | D10: 5.9 | E10: =IF(OR(C10="",D10=""),"",C10*D10) | F10: =IF(E10="","",E10*الإعدادات!$B$8) | G10: =IF(E10="","",E10+F10) | H10: 048203 | I10: =IF(Z10="","",IF(COUNTIF($Y$5:$Y$154,Z10)=0,"⚠ الصنف غير موجود في المبيعات",IFERROR(INDEX('قائمة الأصناف'!$B$3:$B$1000,MATCH(Z10,'قائمة الأصناف'!$C$3:$C$1000,0)),"⚠ كود غير معرف"))) | J10: =IF(AND(Z10="",TRIM(K10)="",M10="",N10=""),"",IF(AND(Z10<>"",COUNTIF($Y$5:$Y$154,Z10)=0),"✗ حُذف من المبيعات — مستبعد من الحساب",IF(N10="","✗ لم تصل من المورد","✓ تم استلام الفاتورة"))) | O10: =IF(OR(M10="",N10=""),"",IF(COUNTIF($Y$5:$Y$154,Z10)=0,"",M10*N10)) | P10: =IF(O10="","",O10*الإعدادات!$B$8) | Q10: =IF(O10="","",O10+P10) | R10: =IF(Y10="","",SUMIFS($M$5:$M$154,$Z$5:$Z$154,Y10)) | S10: =IF(Y10="","",COUNTIFS($Z$5:$Z$154,Y10)) | T10: =IF(Y10="","",SUMIFS($O$5:$O$154,$Z$5:$Z$154,Y10)) | U10: =IF(Y10="","",IF(N(R10)=0,"",T10/R10)) | V10: =IF(Y10="","",N(E10)-T10) | W10: =IF(Y10="","",IF(N(E10)=0,"",V10/E10)) | X10: =IF(Y10="","",IF(S10=0,"⏳ لا توجد فواتير شراء",IF(COUNTIFS($Z$5:$Z$154,Y10,$N$5:$N$154,">0")=S10,"✓ اكتملت جميع الفواتير ("&S10&")","⚠ وصل "&COUNTIFS($Z$5:$Z$154,Y10,$N$5:$N$154,">0")&" من "&S10&" فواتير"))) | Y10: =IF(TRIM(A10)="","",IF(ISNUMBER(VALUE(TRIM(A10))),TEXT(VALUE(TRIM(A10)),"0"),TRIM(A10))) | Z10: =IF(TRIM(H10)="","",IF(ISNUMBER(VALUE(TRIM(H10))),TEXT(VALUE(TRIM(H10)),"0"),TRIM(H10)))
A11: 036330 | B11: =IF(Y11="","",IFERROR(INDEX('قائمة الأصناف'!$B$3:$B$1000,MATCH(Y11,'قائمة الأصناف'!$C$3:$C$1000,0)),"⚠ كود غير معرف")) | C11: 1728 | D11: 6 | E11: =IF(OR(C11="",D11=""),"",C11*D11) | F11: =IF(E11="","",E11*الإعدادات!$B$8) | G11: =IF(E11="","",E11+F11) | H11: 036330 | I11: =IF(Z11="","",IF(COUNTIF($Y$5:$Y$154,Z11)=0,"⚠ الصنف غير موجود في المبيعات",IFERROR(INDEX('قائمة الأصناف'!$B$3:$B$1000,MATCH(Z11,'قائمة الأصناف'!$C$3:$C$1000,0)),"⚠ كود غير معرف"))) | J11: =IF(AND(Z11="",TRIM(K11)="",M11="",N11=""),"",IF(AND(Z11<>"",COUNTIF($Y$5:$Y$154,Z11)=0),"✗ حُذف من المبيعات — مستبعد من الحساب",IF(N11="","✗ لم تصل من المورد","✓ تم استلام الفاتورة"))) | O11: =IF(OR(M11="",N11=""),"",IF(COUNTIF($Y$5:$Y$154,Z11)=0,"",M11*N11)) | P11: =IF(O11="","",O11*الإعدادات!$B$8) | Q11: =IF(O11="","",O11+P11) | R11: =IF(Y11="","",SUMIFS($M$5:$M$154,$Z$5:$Z$154,Y11)) | S11: =IF(Y11="","",COUNTIFS($Z$5:$Z$154,Y11)) | T11: =IF(Y11="","",SUMIFS($O$5:$O$154,$Z$5:$Z$154,Y11)) | U11: =IF(Y11="","",IF(N(R11)=0,"",T11/R11)) | V11: =IF(Y11="","",N(E11)-T11) | W11: =IF(Y11="","",IF(N(E11)=0,"",V11/E11)) | X11: =IF(Y11="","",IF(S11=0,"⏳ لا توجد فواتير شراء",IF(COUNTIFS($Z$5:$Z$154,Y11,$N$5:$N$154,">0")=S11,"✓ اكتملت جميع الفواتير ("&S11&")","⚠ وصل "&COUNTIFS($Z$5:$Z$154,Y11,$N$5:$N$154,">0")&" من "&S11&" فواتير"))) | Y11: =IF(TRIM(A11)="","",IF(ISNUMBER(VALUE(TRIM(A11))),TEXT(VALUE(TRIM(A11)),"0"),TRIM(A11))) | Z11: =IF(TRIM(H11)="","",IF(ISNUMBER(VALUE(TRIM(H11))),TEXT(VALUE(TRIM(H11)),"0"),TRIM(H11)))
B12: =IF(Y12="","",IFERROR(INDEX('قائمة الأصناف'!$B$3:$B$1000,MATCH(Y12,'قائمة الأصناف'!$C$3:$C$1000,0)),"⚠ كود غير معرف")) | E12: =IF(OR(C12="",D12=""),"",C12*D12) | F12: =IF(E12="","",E12*الإعدادات!$B$8) | G12: =IF(E12="","",E12+F12) | I12: =IF(Z12="","",IF(COUNTIF($Y$5:$Y$154,Z12)=0,"⚠ الصنف غير موجود في المبيعات",IFERROR(INDEX('قائمة الأصناف'!$B$3:$B$1000,MATCH(Z12,'قائمة الأصناف'!$C$3:$C$1000,0)),"⚠ كود غير معرف"))) | J12: =IF(AND(Z12="",TRIM(K12)="",M12="",N12=""),"",IF(AND(Z12<>"",COUNTIF($Y$5:$Y$154,Z12)=0),"✗ حُذف من المبيعات — مستبعد من الحساب",IF(N12="","✗ لم تصل من المورد","✓ تم استلام الفاتورة"))) | O12: =IF(OR(M12="",N12=""),"",IF(COUNTIF($Y$5:$Y$154,Z12)=0,"",M12*N12)) | P12: =IF(O12="","",O12*الإعدادات!$B$8) | Q12: =IF(O12="","",O12+P12) | R12: =IF(Y12="","",SUMIFS($M$5:$M$154,$Z$5:$Z$154,Y12)) | S12: =IF(Y12="","",COUNTIFS($Z$5:$Z$154,Y12)) | T12: =IF(Y12="","",SUMIFS($O$5:$O$154,$Z$5:$Z$154,Y12)) | U12: =IF(Y12="","",IF(N(R12)=0,"",T12/R12)) | V12: =IF(Y12="","",N(E12)-T12) | W12: =IF(Y12="","",IF(N(E12)=0,"",V12/E12)) | X12: =IF(Y12="","",IF(S12=0,"⏳ لا توجد فواتير شراء",IF(COUNTIFS($Z$5:$Z$154,Y12,$N$5:$N$154,">0")=S12,"✓ اكتملت جميع الفواتير ("&S12&")","⚠ وصل "&COUNTIFS($Z$5:$Z$154,Y12,$N$5:$N$154,">0")&" من "&S12&" فواتير"))) | Y12: =IF(TRIM(A12)="","",IF(ISNUMBER(VALUE(TRIM(A12))),TEXT(VALUE(TRIM(A12)),"0"),TRIM(A12))) | Z12: =IF(TRIM(H12)="","",IF(ISNUMBER(VALUE(TRIM(H12))),TEXT(VALUE(TRIM(H12)),"0"),TRIM(H12)))
B13: =IF(Y13="","",IFERROR(INDEX('قائمة الأصناف'!$B$3:$B$1000,MATCH(Y13,'قائمة الأصناف'!$C$3:$C$1000,0)),"⚠ كود غير معرف")) | E13: =IF(OR(C13="",D13=""),"",C13*D13) | F13: =IF(E13="","",E13*الإعدادات!$B$8) | G13: =IF(E13="","",E13+F13) | I13: =IF(Z13="","",IF(COUNTIF($Y$5:$Y$154,Z13)=0,"⚠ الصنف غير موجود في المبيعات",IFERROR(INDEX('قائمة الأصناف'!$B$3:$B$1000,MATCH(Z13,'قائمة الأصناف'!$C$3:$C$1000,0)),"⚠ كود غير معرف"))) | J13: =IF(AND(Z13="",TRIM(K13)="",M13="",N13=""),"",IF(AND(Z13<>"",COUNTIF($Y$5:$Y$154,Z13)=0),"✗ حُذف من المبيعات — مستبعد من الحساب",IF(N13="","✗ لم تصل من المورد","✓ تم استلام الفاتورة"))) | O13: =IF(OR(M13="",N13=""),"",IF(COUNTIF($Y$5:$Y$154,Z13)=0,"",M13*N13)) | P13: =IF(O13="","",O13*الإعدادات!$B$8) | Q13: =IF(O13="","",O13+P13) | R13: =IF(Y13="","",SUMIFS($M$5:$M$154,$Z$5:$Z$154,Y13)) | S13: =IF(Y13="","",COUNTIFS($Z$5:$Z$154,Y13)) | T13: =IF(Y13="","",SUMIFS($O$5:$O$154,$Z$5:$Z$154,Y13)) | U13: =IF(Y13="","",IF(N(R13)=0,"",T13/R13)) | V13: =IF(Y13="","",N(E13)-T13) | W13: =IF(Y13="","",IF(N(E13)=0,"",V13/E13)) | X13: =IF(Y13="","",IF(S13=0,"⏳ لا توجد فواتير شراء",IF(COUNTIFS($Z$5:$Z$154,Y13,$N$5:$N$154,">0")=S13,"✓ اكتملت جميع الفواتير ("&S13&")","⚠ وصل "&COUNTIFS($Z$5:$Z$154,Y13,$N$5:$N$154,">0")&" من "&S13&" فواتير"))) | Y13: =IF(TRIM(A13)="","",IF(ISNUMBER(VALUE(TRIM(A13))),TEXT(VALUE(TRIM(A13)),"0"),TRIM(A13))) | Z13: =IF(TRIM(H13)="","",IF(ISNUMBER(VALUE(TRIM(H13))),TEXT(VALUE(TRIM(H13)),"0"),TRIM(H13)))
B14: =IF(Y14="","",IFERROR(INDEX('قائمة الأصناف'!$B$3:$B$1000,MATCH(Y14,'قائمة الأصناف'!$C$3:$C$1000,0)),"⚠ كود غير معرف")) | E14: =IF(OR(C14="",D14=""),"",C14*D14) | F14: =IF(E14="","",E14*الإعدادات!$B$8) | G14: =IF(E14="","",E14+F14) | I14: =IF(Z14="","",IF(COUNTIF($Y$5:$Y$154,Z14)=0,"⚠ الصنف غير موجود في المبيعات",IFERROR(INDEX('قائمة الأصناف'!$B$3:$B$1000,MATCH(Z14,'قائمة الأصناف'!$C$3:$C$1000,0)),"⚠ كود غير معرف"))) | J14: =IF(AND(Z14="",TRIM(K14)="",M14="",N14=""),"",IF(AND(Z14<>"",COUNTIF($Y$5:$Y$154,Z14)=0),"✗ حُذف من المبيعات — مستبعد من الحساب",IF(N14="","✗ لم تصل من المورد","✓ تم استلام الفاتورة"))) | O14: =IF(OR(M14="",N14=""),"",IF(COUNTIF($Y$5:$Y$154,Z14)=0,"",M14*N14)) | P14: =IF(O14="","",O14*الإعدادات!$B$8) | Q14: =IF(O14="","",O14+P14) | R14: =IF(Y14="","",SUMIFS($M$5:$M$154,$Z$5:$Z$154,Y14)) | S14: =IF(Y14="","",COUNTIFS($Z$5:$Z$154,Y14)) | T14: =IF(Y14="","",SUMIFS($O$5:$O$154,$Z$5:$Z$154,Y14)) | U14: =IF(Y14="","",IF(N(R14)=0,"",T14/R14)) | V14: =IF(Y14="","",N(E14)-T14) | W14: =IF(Y14="","",IF(N(E14)=0,"",V14/E14)) | X14: =IF(Y14="","",IF(S14=0,"⏳ لا توجد فواتير شراء",IF(COUNTIFS($Z$5:$Z$154,Y14,$N$5:$N$154,">0")=S14,"✓ اكتملت جميع الفواتير ("&S14&")","⚠ وصل "&COUNTIFS($Z$5:$Z$154,Y14,$N$5:$N$154,">0")&" من "&S14&" فواتير"))) | Y14: =IF(TRIM(A14)="","",IF(ISNUMBER(VALUE(TRIM(A14))),TEXT(VALUE(TRIM(A14)),"0"),TRIM(A14))) | Z14: =IF(TRIM(H14)="","",IF(ISNUMBER(VALUE(TRIM(H14))),TEXT(VALUE(TRIM(H14)),"0"),TRIM(H14)))
B15: =IF(Y15="","",IFERROR(INDEX('قائمة الأصناف'!$B$3:$B$1000,MATCH(Y15,'قائمة الأصناف'!$C$3:$C$1000,0)),"⚠ كود غير معرف")) | E15: =IF(OR(C15="",D15=""),"",C15*D15) | F15: =IF(E15="","",E15*الإعدادات!$B$8) | G15: =IF(E15="","",E15+F15) | I15: =IF(Z15="","",IF(COUNTIF($Y$5:$Y$154,Z15)=0,"⚠ الصنف غير موجود في المبيعات",IFERROR(INDEX('قائمة الأصناف'!$B$3:$B$1000,MATCH(Z15,'قائمة الأصناف'!$C$3:$C$1000,0)),"⚠ كود غير معرف"))) | J15: =IF(AND(Z15="",TRIM(K15)="",M15="",N15=""),"",IF(AND(Z15<>"",COUNTIF($Y$5:$Y$154,Z15)=0),"✗ حُذف من المبيعات — مستبعد من الحساب",IF(N15="","✗ لم تصل من المورد","✓ تم استلام الفاتورة"))) | O15: =IF(OR(M15="",N15=""),"",IF(COUNTIF($Y$5:$Y$154,Z15)=0,"",M15*N15)) | P15: =IF(O15="","",O15*الإعدادات!$B$8) | Q15: =IF(O15="","",O15+P15) | R15: =IF(Y15="","",SUMIFS($M$5:$M$154,$Z$5:$Z$154,Y15)) | S15: =IF(Y15="","",COUNTIFS($Z$5:$Z$154,Y15)) | T15: =IF(Y15="","",SUMIFS($O$5:$O$154,$Z$5:$Z$154,Y15)) | U15: =IF(Y15="","",IF(N(R15)=0,"",T15/R15)) | V15: =IF(Y15="","",N(E15)-T15) | W15: =IF(Y15="","",IF(N(E15)=0,"",V15/E15)) | X15: =IF(Y15="","",IF(S15=0,"⏳ لا توجد فواتير شراء",IF(COUNTIFS($Z$5:$Z$154,Y15,$N$5:$N$154,">0")=S15,"✓ اكتملت جميع الفواتير ("&S15&")","⚠ وصل "&COUNTIFS($Z$5:$Z$154,Y15,$N$5:$N$154,">0")&" من "&S15&" فواتير"))) | Y15: =IF(TRIM(A15)="","",IF(ISNUMBER(VALUE(TRIM(A15))),TEXT(VALUE(TRIM(A15)),"0"),TRIM(A15))) | Z15: =IF(TRIM(H15)="","",IF(ISNUMBER(VALUE(TRIM(H15))),TEXT(VALUE(TRIM(H15)),"0"),TRIM(H15)))
B16: =IF(Y16="","",IFERROR(INDEX('قائمة الأصناف'!$B$3:$B$1000,MATCH(Y16,'قائمة الأصناف'!$C$3:$C$1000,0)),"⚠ كود غير معرف")) | E16: =IF(OR(C16="",D16=""),"",C16*D16) | F16: =IF(E16="","",E16*الإعدادات!$B$8) | G16: =IF(E16="","",E16+F16) | I16: =IF(Z16="","",IF(COUNTIF($Y$5:$Y$154,Z16)=0,"⚠ الصنف غير موجود في المبيعات",IFERROR(INDEX('قائمة الأصناف'!$B$3:$B$1000,MATCH(Z16,'قائمة الأصناف'!$C$3:$C$1000,0)),"⚠ كود غير معرف"))) | J16: =IF(AND(Z16="",TRIM(K16)="",M16="",N16=""),"",IF(AND(Z16<>"",COUNTIF($Y$5:$Y$154,Z16)=0),"✗ حُذف من المبيعات — مستبعد من الحساب",IF(N16="","✗ لم تصل من المورد","✓ تم استلام الفاتورة"))) | O16: =IF(OR(M16="",N16=""),"",IF(COUNTIF($Y$5:$Y$154,Z16)=0,"",M16*N16)) | P16: =IF(O16="","",O16*الإعدادات!$B$8) | Q16: =IF(O16="","",O16+P16) | R16: =IF(Y16="","",SUMIFS($M$5:$M$154,$Z$5:$Z$154,Y16)) | S16: =IF(Y16="","",COUNTIFS($Z$5:$Z$154,Y16)) | T16: =IF(Y16="","",SUMIFS($O$5:$O$154,$Z$5:$Z$154,Y16)) | U16: =IF(Y16="","",IF(N(R16)=0,"",T16/R16)) | V16: =IF(Y16="","",N(E16)-T16) | W16: =IF(Y16="","",IF(N(E16)=0,"",V16/E16)) | X16: =IF(Y16="","",IF(S16=0,"⏳ لا توجد فواتير شراء",IF(COUNTIFS($Z$5:$Z$154,Y16,$N$5:$N$154,">0")=S16,"✓ اكتملت جميع الفواتير ("&S16&")","⚠ وصل "&COUNTIFS($Z$5:$Z$154,Y16,$N$5:$N$154,">0")&" من "&S16&" فواتير"))) | Y16: =IF(TRIM(A16)="","",IF(ISNUMBER(VALUE(TRIM(A16))),TEXT(VALUE(TRIM(A16)),"0"),TRIM(A16))) | Z16: =IF(TRIM(H16)="","",IF(ISNUMBER(VALUE(TRIM(H16))),TEXT(VALUE(TRIM(H16)),"0"),TRIM(H16)))
B17: =IF(Y17="","",IFERROR(INDEX('قائمة الأصناف'!$B$3:$B$1000,MATCH(Y17,'قائمة الأصناف'!$C$3:$C$1000,0)),"⚠ كود غير معرف")) | E17: =IF(OR(C17="",D17=""),"",C17*D17) | F17: =IF(E17="","",E17*الإعدادات!$B$8) | G17: =IF(E17="","",E17+F17) | I17: =IF(Z17="","",IF(COUNTIF($Y$5:$Y$154,Z17)=0,"⚠ الصنف غير موجود في المبيعات",IFERROR(INDEX('قائمة الأصناف'!$B$3:$B$1000,MATCH(Z17,'قائمة الأصناف'!$C$3:$C$1000,0)),"⚠ كود غير معرف"))) | J17: =IF(AND(Z17="",TRIM(K17)="",M17="",N17=""),"",IF(AND(Z17<>"",COUNTIF($Y$5:$Y$154,Z17)=0),"✗ حُذف من المبيعات — مستبعد من الحساب",IF(N17="","✗ لم تصل من المورد","✓ تم استلام الفاتورة"))) | O17: =IF(OR(M17="",N17=""),"",IF(COUNTIF($Y$5:$Y$154,Z17)=0,"",M17*N17)) | P17: =IF(O17="","",O17*الإعدادات!$B$8) | Q17: =IF(O17="","",O17+P17) | R17: =IF(Y17="","",SUMIFS($M$5:$M$154,$Z$5:$Z$154,Y17)) | S17: =IF(Y17="","",COUNTIFS($Z$5:$Z$154,Y17)) | T17: =IF(Y17="","",SUMIFS($O$5:$O$154,$Z$5:$Z$154,Y17)) | U17: =IF(Y17="","",IF(N(R17)=0,"",T17/R17)) | V17: =IF(Y17="","",N(E17)-T17) | W17: =IF(Y17="","",IF(N(E17)=0,"",V17/E17)) | X17: =IF(Y17="","",IF(S17=0,"⏳ لا توجد فواتير شراء",IF(COUNTIFS($Z$5:$Z$154,Y17,$N$5:$N$154,">0")=S17,"✓ اكتملت جميع الفواتير ("&S17&")","⚠ وصل "&COUNTIFS($Z$5:$Z$154,Y17,$N$5:$N$154,">0")&" من "&S17&" فواتير"))) | Y17: =IF(TRIM(A17)="","",IF(ISNUMBER(VALUE(TRIM(A17))),TEXT(VALUE(TRIM(A17)),"0"),TRIM(A17))) | Z17: =IF(TRIM(H17)="","",IF(ISNUMBER(VALUE(TRIM(H17))),TEXT(VALUE(TRIM(H17)),"0"),TRIM(H17)))
B18: =IF(Y18="","",IFERROR(INDEX('قائمة الأصناف'!$B$3:$B$1000,MATCH(Y18,'قائمة الأصناف'!$C$3:$C$1000,0)),"⚠ كود غير معرف")) | E18: =IF(OR(C18="",D18=""),"",C18*D18) | F18: =IF(E18="","",E18*الإعدادات!$B$8) | G18: =IF(E18="","",E18+F18) | I18: =IF(Z18="","",IF(COUNTIF($Y$5:$Y$154,Z18)=0,"⚠ الصنف غير موجود في المبيعات",IFERROR(INDEX('قائمة الأصناف'!$B$3:$B$1000,MATCH(Z18,'قائمة الأصناف'!$C$3:$C$1000,0)),"⚠ كود غير معرف"))) | J18: =IF(AND(Z18="",TRIM(K18)="",M18="",N18=""),"",IF(AND(Z18<>"",COUNTIF($Y$5:$Y$154,Z18)=0),"✗ حُذف من المبيعات — مستبعد من الحساب",IF(N18="","✗ لم تصل من المورد","✓ تم استلام الفاتورة"))) | O18: =IF(OR(M18="",N18=""),"",IF(COUNTIF($Y$5:$Y$154,Z18)=0,"",M18*N18)) | P18: =IF(O18="","",O18*الإعدادات!$B$8) | Q18: =IF(O18="","",O18+P18) | R18: =IF(Y18="","",SUMIFS($M$5:$M$154,$Z$5:$Z$154,Y18)) | S18: =IF(Y18="","",COUNTIFS($Z$5:$Z$154,Y18)) | T18: =IF(Y18="","",SUMIFS($O$5:$O$154,$Z$5:$Z$154,Y18)) | U18: =IF(Y18="","",IF(N(R18)=0,"",T18/R18)) | V18: =IF(Y18="","",N(E18)-T18) | W18: =IF(Y18="","",IF(N(E18)=0,"",V18/E18)) | X18: =IF(Y18="","",IF(S18=0,"⏳ لا توجد فواتير شراء",IF(COUNTIFS($Z$5:$Z$154,Y18,$N$5:$N$154,">0")=S18,"✓ اكتملت جميع الفواتير ("&S18&")","⚠ وصل "&COUNTIFS($Z$5:$Z$154,Y18,$N$5:$N$154,">0")&" من "&S18&" فواتير"))) | Y18: =IF(TRIM(A18)="","",IF(ISNUMBER(VALUE(TRIM(A18))),TEXT(VALUE(TRIM(A18)),"0"),TRIM(A18))) | Z18: =IF(TRIM(H18)="","",IF(ISNUMBER(VALUE(TRIM(H18))),TEXT(VALUE(TRIM(H18)),"0"),TRIM(H18)))
B19: =IF(Y19="","",IFERROR(INDEX('قائمة الأصناف'!$B$3:$B$1000,MATCH(Y19,'قائمة الأصناف'!$C$3:$C$1000,0)),"⚠ كود غير معرف")) | E19: =IF(OR(C19="",D19=""),"",C19*D19) | F19: =IF(E19="","",E19*الإعدادات!$B$8) | G19: =IF(E19="","",E19+F19) | I19: =IF(Z19="","",IF(COUNTIF($Y$5:$Y$154,Z19)=0,"⚠ الصنف غير موجود في المبيعات",IFERROR(INDEX('قائمة الأصناف'!$B$3:$B$1000,MATCH(Z19,'قائمة الأصناف'!$C$3:$C$1000,0)),"⚠ كود غير معرف"))) | J19: =IF(AND(Z19="",TRIM(K19)="",M19="",N19=""),"",IF(AND(Z19<>"",COUNTIF($Y$5:$Y$154,Z19)=0),"✗ حُذف من المبيعات — مستبعد من الحساب",IF(N19="","✗ لم تصل من المورد","✓ تم استلام الفاتورة"))) | O19: =IF(OR(M19="",N19=""),"",IF(COUNTIF($Y$5:$Y$154,Z19)=0,"",M19*N19)) | P19: =IF(O19="","",O19*الإعدادات!$B$8) | Q19: =IF(O19="","",O19+P19) | R19: =IF(Y19="","",SUMIFS($M$5:$M$154,$Z$5:$Z$154,Y19)) | S19: =IF(Y19="","",COUNTIFS($Z$5:$Z$154,Y19)) | T19: =IF(Y19="","",SUMIFS($O$5:$O$154,$Z$5:$Z$154,Y19)) | U19: =IF(Y19="","",IF(N(R19)=0,"",T19/R19)) | V19: =IF(Y19="","",N(E19)-T19) | W19: =IF(Y19="","",IF(N(E19)=0,"",V19/E19)) | X19: =IF(Y19="","",IF(S19=0,"⏳ لا توجد فواتير شراء",IF(COUNTIFS($Z$5:$Z$154,Y19,$N$5:$N$154,">0")=S19,"✓ اكتملت جميع الفواتير ("&S19&")","⚠ وصل "&COUNTIFS($Z$5:$Z$154,Y19,$N$5:$N$154,">0")&" من "&S19&" فواتير"))) | Y19: =IF(TRIM(A19)="","",IF(ISNUMBER(VALUE(TRIM(A19))),TEXT(VALUE(TRIM(A19)),"0"),TRIM(A19))) | Z19: =IF(TRIM(H19)="","",IF(ISNUMBER(VALUE(TRIM(H19))),TEXT(VALUE(TRIM(H19)),"0"),TRIM(H19)))
B20: =IF(Y20="","",IFERROR(INDEX('قائمة الأصناف'!$B$3:$B$1000,MATCH(Y20,'قائمة الأصناف'!$C$3:$C$1000,0)),"⚠ كود غير معرف")) | E20: =IF(OR(C20="",D20=""),"",C20*D20) | F20: =IF(E20="","",E20*الإعدادات!$B$8) | G20: =IF(E20="","",E20+F20) | I20: =IF(Z20="","",IF(COUNTIF($Y$5:$Y$154,Z20)=0,"⚠ الصنف غير موجود في المبيعات",IFERROR(INDEX('قائمة الأصناف'!$B$3:$B$1000,MATCH(Z20,'قائمة الأصناف'!$C$3:$C$1000,0)),"⚠ كود غير معرف"))) | J20: =IF(AND(Z20="",TRIM(K20)="",M20="",N20=""),"",IF(AND(Z20<>"",COUNTIF($Y$5:$Y$154,Z20)=0),"✗ حُذف من المبيعات — مستبعد من الحساب",IF(N20="","✗ لم تصل من المورد","✓ تم استلام الفاتورة"))) | O20: =IF(OR(M20="",N20=""),"",IF(COUNTIF($Y$5:$Y$154,Z20)=0,"",M20*N20)) | P20: =IF(O20="","",O20*الإعدادات!$B$8) | Q20: =IF(O20="","",O20+P20) | R20: =IF(Y20="","",SUMIFS($M$5:$M$154,$Z$5:$Z$154,Y20)) | S20: =IF(Y20="","",COUNTIFS($Z$5:$Z$154,Y20)) | T20: =IF(Y20="","",SUMIFS($O$5:$O$154,$Z$5:$Z$154,Y20)) | U20: =IF(Y20="","",IF(N(R20)=0,"",T20/R20)) | V20: =IF(Y20="","",N(E20)-T20) | W20: =IF(Y20="","",IF(N(E20)=0,"",V20/E20)) | X20: =IF(Y20="","",IF(S20=0,"⏳ لا توجد فواتير شراء",IF(COUNTIFS($Z$5:$Z$154,Y20,$N$5:$N$154,">0")=S20,"✓ اكتملت جميع الفواتير ("&S20&")","⚠ وصل "&COUNTIFS($Z$5:$Z$154,Y20,$N$5:$N$154,">0")&" من "&S20&" فواتير"))) | Y20: =IF(TRIM(A20)="","",IF(ISNUMBER(VALUE(TRIM(A20))),TEXT(VALUE(TRIM(A20)),"0"),TRIM(A20))) | Z20: =IF(TRIM(H20)="","",IF(ISNUMBER(VALUE(TRIM(H20))),TEXT(VALUE(TRIM(H20)),"0"),TRIM(H20)))
B21: =IF(Y21="","",IFERROR(INDEX('قائمة الأصناف'!$B$3:$B$1000,MATCH(Y21,'قائمة الأصناف'!$C$3:$C$1000,0)),"⚠ كود غير معرف")) | E21: =IF(OR(C21="",D21=""),"",C21*D21) | F21: =IF(E21="","",E21*الإعدادات!$B$8) | G21: =IF(E21="","",E21+F21) | I21: =IF(Z21="","",IF(COUNTIF($Y$5:$Y$154,Z21)=0,"⚠ الصنف غير موجود في المبيعات",IFERROR(INDEX('قائمة الأصناف'!$B$3:$B$1000,MATCH(Z21,'قائمة الأصناف'!$C$3:$C$1000,0)),"⚠ كود غير معرف"))) | J21: =IF(AND(Z21="",TRIM(K21)="",M21="",N21=""),"",IF(AND(Z21<>"",COUNTIF($Y$5:$Y$154,Z21)=0),"✗ حُذف من المبيعات — مستبعد من الحساب",IF(N21="","✗ لم تصل من المورد","✓ تم استلام الفاتورة"))) | O21: =IF(OR(M21="",N21=""),"",IF(COUNTIF($Y$5:$Y$154,Z21)=0,"",M21*N21)) | P21: =IF(O21="","",O21*الإعدادات!$B$8) | Q21: =IF(O21="","",O21+P21) | R21: =IF(Y21="","",SUMIFS($M$5:$M$154,$Z$5:$Z$154,Y21)) | S21: =IF(Y21="","",COUNTIFS($Z$5:$Z$154,Y21)) | T21: =IF(Y21="","",SUMIFS($O$5:$O$154,$Z$5:$Z$154,Y21)) | U21: =IF(Y21="","",IF(N(R21)=0,"",T21/R21)) | V21: =IF(Y21="","",N(E21)-T21) | W21: =IF(Y21="","",IF(N(E21)=0,"",V21/E21)) | X21: =IF(Y21="","",IF(S21=0,"⏳ لا توجد فواتير شراء",IF(COUNTIFS($Z$5:$Z$154,Y21,$N$5:$N$154,">0")=S21,"✓ اكتملت جميع الفواتير ("&S21&")","⚠ وصل "&COUNTIFS($Z$5:$Z$154,Y21,$N$5:$N$154,">0")&" من "&S21&" فواتير"))) | Y21: =IF(TRIM(A21)="","",IF(ISNUMBER(VALUE(TRIM(A21))),TEXT(VALUE(TRIM(A21)),"0"),TRIM(A21))) | Z21: =IF(TRIM(H21)="","",IF(ISNUMBER(VALUE(TRIM(H21))),TEXT(VALUE(TRIM(H21)),"0"),TRIM(H21)))
B22: =IF(Y22="","",IFERROR(INDEX('قائمة الأصناف'!$B$3:$B$1000,MATCH(Y22,'قائمة الأصناف'!$C$3:$C$1000,0)),"⚠ كود غير معرف")) | E22: =IF(OR(C22="",D22=""),"",C22*D22) | F22: =IF(E22="","",E22*الإعدادات!$B$8) | G22: =IF(E22="","",E22+F22) | I22: =IF(Z22="","",IF(COUNTIF($Y$5:$Y$154,Z22)=0,"⚠ الصنف غير موجود في المبيعات",IFERROR(INDEX('قائمة الأصناف'!$B$3:$B$1000,MATCH(Z22,'قائمة الأصناف'!$C$3:$C$1000,0)),"⚠ كود غير معرف"))) | J22: =IF(AND(Z22="",TRIM(K22)="",M22="",N22=""),"",IF(AND(Z22<>"",COUNTIF($Y$5:$Y$154,Z22)=0),"✗ حُذف من المبيعات — مستبعد من الحساب",IF(N22="","✗ لم تصل من المورد","✓ تم استلام الفاتورة"))) | O22: =IF(OR(M22="",N22=""),"",IF(COUNTIF($Y$5:$Y$154,Z22)=0,"",M22*N22)) | P22: =IF(O22="","",O22*الإعدادات!$B$8) | Q22: =IF(O22="","",O22+P22) | R22: =IF(Y22="","",SUMIFS($M$5:$M$154,$Z$5:$Z$154,Y22)) | S22: =IF(Y22="","",COUNTIFS($Z$5:$Z$154,Y22)) | T22: =IF(Y22="","",SUMIFS($O$5:$O$154,$Z$5:$Z$154,Y22)) | U22: =IF(Y22="","",IF(N(R22)=0,"",T22/R22)) | V22: =IF(Y22="","",N(E22)-T22) | W22: =IF(Y22="","",IF(N(E22)=0,"",V22/E22)) | X22: =IF(Y22="","",IF(S22=0,"⏳ لا توجد فواتير شراء",IF(COUNTIFS($Z$5:$Z$154,Y22,$N$5:$N$154,">0")=S22,"✓ اكتملت جميع الفواتير ("&S22&")","⚠ وصل "&COUNTIFS($Z$5:$Z$154,Y22,$N$5:$N$154,">0")&" من "&S22&" فواتير"))) | Y22: =IF(TRIM(A22)="","",IF(ISNUMBER(VALUE(TRIM(A22))),TEXT(VALUE(TRIM(A22)),"0"),TRIM(A22))) | Z22: =IF(TRIM(H22)="","",IF(ISNUMBER(VALUE(TRIM(H22))),TEXT(VALUE(TRIM(H22)),"0"),TRIM(H22)))
B23: =IF(Y23="","",IFERROR(INDEX('قائمة الأصناف'!$B$3:$B$1000,MATCH(Y23,'قائمة الأصناف'!$C$3:$C$1000,0)),"⚠ كود غير معرف")) | E23: =IF(OR(C23="",D23=""),"",C23*D23) | F23: =IF(E23="","",E23*الإعدادات!$B$8) | G23: =IF(E23="","",E23+F23) | I23: =IF(Z23="","",IF(COUNTIF($Y$5:$Y$154,Z23)=0,"⚠ الصنف غير موجود في المبيعات",IFERROR(INDEX('قائمة الأصناف'!$B$3:$B$1000,MATCH(Z23,'قائمة الأصناف'!$C$3:$C$1000,0)),"⚠ كود غير معرف"))) | J23: =IF(AND(Z23="",TRIM(K23)="",M23="",N23=""),"",IF(AND(Z23<>"",COUNTIF($Y$5:$Y$154,Z23)=0),"✗ حُذف من المبيعات — مستبعد من الحساب",IF(N23="","✗ لم تصل من المورد","✓ تم استلام الفاتورة"))) | O23: =IF(OR(M23="",N23=""),"",IF(COUNTIF($Y$5:$Y$154,Z23)=0,"",M23*N23)) | P23: =IF(O23="","",O23*الإعدادات!$B$8) | Q23: =IF(O23="","",O23+P23) | R23: =IF(Y23="","",SUMIFS($M$5:$M$154,$Z$5:$Z$154,Y23)) | S23: =IF(Y23="","",COUNTIFS($Z$5:$Z$154,Y23)) | T23: =IF(Y23="","",SUMIFS($O$5:$O$154,$Z$5:$Z$154,Y23)) | U23: =IF(Y23="","",IF(N(R23)=0,"",T23/R23)) | V23: =IF(Y23="","",N(E23)-T23) | W23: =IF(Y23="","",IF(N(E23)=0,"",V23/E23)) | X23: =IF(Y23="","",IF(S23=0,"⏳ لا توجد فواتير شراء",IF(COUNTIFS($Z$5:$Z$154,Y23,$N$5:$N$154,">0")=S23,"✓ اكتملت جميع الفواتير ("&S23&")","⚠ وصل "&COUNTIFS($Z$5:$Z$154,Y23,$N$5:$N$154,">0")&" من "&S23&" فواتير"))) | Y23: =IF(TRIM(A23)="","",IF(ISNUMBER(VALUE(TRIM(A23))),TEXT(VALUE(TRIM(A23)),"0"),TRIM(A23))) | Z23: =IF(TRIM(H23)="","",IF(ISNUMBER(VALUE(TRIM(H23))),TEXT(VALUE(TRIM(H23)),"0"),TRIM(H23)))
... B154: =IF(Y154="","",IFERROR(INDEX('قائمة الأصناف'!$B$3:$B$1000,MATCH(Y154,'قائمة الأصناف'!$C$3:$C$1000,0)),"⚠ كود غير معرف")) | E154: =IF(OR(C154="",D154=""),"",C154*D154) | F154: =IF(E154="","",E154*الإعدادات!$B$8) | G154: =IF(E154="","",E154+F154) | I154: =IF(Z154="","",IF(COUNTIF($Y$5:$Y$154,Z154)=0,"⚠ الصنف غير موجود في المبيعات",IFERROR(INDEX('قائمة الأصناف'!$B$3:$B$1000,MATCH(Z154,'قائمة الأصناف'!$C$3:$C$1000,0)),"⚠ كود غير معرف"))) | J154: =IF(AND(Z154="",TRIM(K154)="",M154="",N154=""),"",IF(AND(Z154<>"",COUNTIF($Y$5:$Y$154,Z154)=0),"✗ حُذف من المبيعات — مستبعد من الحساب",IF(N154="","✗ لم تصل من المورد","✓ تم استلام الفاتورة"))) | O154: =IF(OR(M154="",N154=""),"",IF(COUNTIF($Y$5:$Y$154,Z154)=0,"",M154*N154)) | P154: =IF(O154="","",O154*الإعدادات!$B$8) | Q154: =IF(O154="","",O154+P154) | R154: =IF(Y154="","",SUMIFS($M$5:$M$154,$Z$5:$Z$154,Y154)) | S154: =IF(Y154="","",COUNTIFS($Z$5:$Z$154,Y154)) | T154: =IF(Y154="","",SUMIFS($O$5:$O$154,$Z$5:$Z$154,Y154)) | U154: =IF(Y154="","",IF(N(R154)=0,"",T154/R154)) | V154: =IF(Y154="","",N(E154)-T154) | W154: =IF(Y154="","",IF(N(E154)=0,"",V154/E154)) | X154: =IF(Y154="","",IF(S154=0,"⏳ لا توجد فواتير شراء",IF(COUNTIFS($Z$5:$Z$154,Y154,$N$5:$N$154,">0")=S154,"✓ اكتملت جميع الفواتير ("&S154&")","⚠ وصل "&COUNTIFS($Z$5:$Z$154,Y154,$N$5:$N$154,">0")&" من "&S154&" فواتير"))) | Y154: =IF(TRIM(A154)="","",IF(ISNUMBER(VALUE(TRIM(A154))),TEXT(VALUE(TRIM(A154)),"0"),TRIM(A154))) | Z154: =IF(TRIM(H154)="","",IF(ISNUMBER(VALUE(TRIM(H154))),TEXT(VALUE(TRIM(H154)),"0"),TRIM(H154)))
A155: الإجماليات | C155: =SUM(C5:C154) | E155: =SUM(E5:E154) | F155: =SUM(F5:F154) | G155: =SUM(G5:G154) | M155: =SUM(M5:M154) | O155: =SUM(O5:O154) | P155: =SUM(P5:P154) | Q155: =SUM(Q5:Q154) | T155: =SUM(T5:T154) | V155: =SUM(V5:V154) | W155: =IF(N(E155)=0,"",V155/E155)

Sheet يوم 2
A1: رقم اليوم: | B1: 2 | C1: التاريخ: | D1: =IF($B$1<=الإعدادات!$B$6,DATE(الإعدادات!$B$3,الإعدادات!$B$4,$B$1),"") | E1: اليوم: | F1: =IF($D$1="","",CHOOSE(WEEKDAY($D$1),"الأحد","الاثنين","الثلاثاء","الأربعاء","الخميس","الجمعة","السبت")) | H1: =IF($B$1<=الإعدادات!$B$6,"✓ يوم فعّال ضمن شهر "&الإعدادات!$B$5,"✗ خارج نطاق الشهر المحدد — لا تُدخل بيانات هنا")
A3: جدول المبيعات اليومية | H3: جدول المشتريات وفواتير الموردين (سطر لكل فاتورة — يسمح بأكثر من فاتورة لنفس الصنف) | R3: تحليل الربحية لكل صنف مبيع (تلقائي)
A4: كود الصنف | B4: اسم الصنف (تلقائي) | C4: الكمية المباعة | D4: سعر البيع | E4: الإجمالي قبل الضريبة | F4: الضريبة | G4: الإجمالي شامل الضريبة | H4: كود الصنف | I4: اسم الصنف (تلقائي) | J4: حالة الفاتورة | K4: اسم المورد | L4: رقم الفاتورة | M4: الكمية المشتراة | N4: سعر الشراء | O4: الإجمالي قبل الضريبة | P4: الضريبة | Q4: الإجمالي شامل الضريبة | R4: إجمالي الكمية المشتراة | S4: عدد فواتير الشراء | T4: إجمالي تكلفة الشراء | U4: متوسط سعر الشراء | V4: صافي الربح (قبل الضريبة) | W4: هامش الربح % | X4: حالة فواتير الصنف (إجمالي)
A5: 048394 | B5: =IF(Y5="","",IFERROR(INDEX('قائمة الأصناف'!$B$3:$B$1000,MATCH(Y5,'قائمة الأصناف'!$C$3:$C$1000,0)),"⚠ كود غير معرف")) | C5: 312 | D5: 6 | E5: =IF(OR(C5="",D5=""),"",C5*D5) | F5: =IF(E5="","",E5*الإعدادات!$B$8) | G5: =IF(E5="","",E5+F5) | H5: 048394 | I5: =IF(Z5="","",IF(COUNTIF($Y$5:$Y$154,Z5)=0,"⚠ الصنف غير موجود في المبيعات",IFERROR(INDEX('قائمة الأصناف'!$B$3:$B$1000,MATCH(Z5,'قائمة الأصناف'!$C$3:$C$1000,0)),"⚠ كود غير معرف"))) | J5: =IF(AND(Z5="",TRIM(K5)="",M5="",N5=""),"",IF(AND(Z5<>"",COUNTIF($Y$5:$Y$154,Z5)=0),"✗ حُذف من المبيعات — مستبعد من الحساب",IF(N5="","✗ لم تصل من المورد","✓ تم استلام الفاتورة"))) | O5: =IF(OR(M5="",N5=""),"",IF(COUNTIF($Y$5:$Y$154,Z5)=0,"",M5*N5)) | P5: =IF(O5="","",O5*الإعدادات!$B$8) | Q5: =IF(O5="","",O5+P5) | R5: =IF(Y5="","",SUMIFS($M$5:$M$154,$Z$5:$Z$154,Y5)) | S5: =IF(Y5="","",COUNTIFS($Z$5:$Z$154,Y5)) | T5: =IF(Y5="","",SUMIFS($O$5:$O$154,$Z$5:$Z$154,Y5)) | U5: =IF(Y5="","",IF(N(R5)=0,"",T5/R5)) | V5: =IF(Y5="","",N(E5)-T5) | W5: =IF(Y5="","",IF(N(E5)=0,"",V5/E5)) | X5: =IF(Y5="","",IF(S5=0,"⏳ لا توجد فواتير شراء",IF(COUNTIFS($Z$5:$Z$154,Y5,$N$5:$N$154,">0")=S5,"✓ اكتملت جميع الفواتير ("&S5&")","⚠ وصل "&COUNTIFS($Z$5:$Z$154,Y5,$N$5:$N$154,">0")&" من "&S5&" فواتير"))) | Y5: =IF(TRIM(A5)="","",IF(ISNUMBER(VALUE(TRIM(A5))),TEXT(VALUE(TRIM(A5)),"0"),TRIM(A5))) | Z5: =IF(TRIM(H5)="","",IF(ISNUMBER(VALUE(TRIM(H5))),TEXT(VALUE(TRIM(H5)),"0"),TRIM(H5)))
A6: 048679 | B6: =IF(Y6="","",IFERROR(INDEX('قائمة الأصناف'!$B$3:$B$1000,MATCH(Y6,'قائمة الأصناف'!$C$3:$C$1000,0)),"⚠ كود غير معرف")) | C6: 476 | D6: 8 | E6: =IF(OR(C6="",D6=""),"",C6*D6) | F6: =IF(E6="","",E6*الإعدادات!$B$8) | G6: =IF(E6="","",E6+F6) | H6: 048679 | I6: =IF(Z6="","",IF(COUNTIF($Y$5:$Y$154,Z6)=0,"⚠ الصنف غير موجود في المبيعات",IFERROR(INDEX('قائمة الأصناف'!$B$3:$B$1000,MATCH(Z6,'قائمة الأصناف'!$C$3:$C$1000,0)),"⚠ كود غير معرف"))) | J6: =IF(AND(Z6="",TRIM(K6)="",M6="",N6=""),"",IF(AND(Z6<>"",COUNTIF($Y$5:$Y$154,Z6)=0),"✗ حُذف من المبيعات — مستبعد من الحساب",IF(N6="","✗ لم تصل من المورد","✓ تم استلام الفاتورة"))) | O6: =IF(OR(M6="",N6=""),"",IF(COUNTIF($Y$5:$Y$154,Z6)=0,"",M6*N6)) | P6: =IF(O6="","",O6*الإعدادات!$B$8) | Q6: =IF(O6="","",O6+P6) | R6: =IF(Y6="","",SUMIFS($M$5:$M$154,$Z$5:$Z$154,Y6)) | S6: =IF(Y6="","",COUNTIFS($Z$5:$Z$154,Y6)) | T6: =IF(Y6="","",SUMIFS($O$5:$O$154,$Z$5:$Z$154,Y6)) | U6: =IF(Y6="","",IF(N(R6)=0,"",T6/R6)) | V6: =IF(Y6="","",N(E6)-T6) | W6: =IF(Y6="","",IF(N(E6)=0,"",V6/E6)) | X6: =IF(Y6="","",IF(S6=0,"⏳ لا توجد فواتير شراء",IF(COUNTIFS($Z$5:$Z$154,Y6,$N$5:$N$154,">0")=S6,"✓ اكتملت جميع الفواتير ("&S6&")","⚠ وصل "&COUNTIFS($Z$5:$Z$154,Y6,$N$5:$N$154,">0")&" من "&S6&" فواتير"))) | Y6: =IF(TRIM(A6)="","",IF(ISNUMBER(VALUE(TRIM(A6))),TEXT(VALUE(TRIM(A6)),"0"),TRIM(A6))) | Z6: =IF(TRIM(H6)="","",IF(ISNUMBER(VALUE(TRIM(H6))),TEXT(VALUE(TRIM(H6)),"0"),TRIM(H6)))
A7: 048683 | B7: =IF(Y7="","",IFERROR(INDEX('قائمة الأصناف'!$B$3:$B$1000,MATCH(Y7,'قائمة الأصناف'!$C$3:$C$1000,0)),"⚠ كود غير معرف")) | C7: 528 | D7: 8 | E7: =IF(OR(C7="",D7=""),"",C7*D7) | F7: =IF(E7="","",E7*الإعدادات!$B$8) | G7: =IF(E7="","",E7+F7) | H7: 048683 | I7: =IF(Z7="","",IF(COUNTIF($Y$5:$Y$154,Z7)=0,"⚠ الصنف غير موجود في المبيعات",IFERROR(INDEX('قائمة الأصناف'!$B$3:$B$1000,MATCH(Z7,'قائمة الأصناف'!$C$3:$C$1000,0)),"⚠ كود غير معرف"))) | J7: =IF(AND(Z7="",TRIM(K7)="",M7="",N7=""),"",IF(AND(Z7<>"",COUNTIF($Y$5:$Y$154,Z7)=0),"✗ حُذف من المبيعات — مستبعد من الحساب",IF(N7="","✗ لم تصل من المورد","✓ تم استلام الفاتورة"))) | O7: =IF(OR(M7="",N7=""),"",IF(COUNTIF($Y$5:$Y$154,Z7)=0,"",M7*N7)) | P7: =IF(O7="","",O7*الإعدادات!$B$8) | Q7: =IF(O7="","",O7+P7) | R7: =IF(Y7="","",SUMIFS($M$5:$M$154,$Z$5:$Z$154,Y7)) | S7: =IF(Y7="","",COUNTIFS($Z$5:$Z$154,Y7)) | T7: =IF(Y7="","",SUMIFS($O$5:$O$154,$Z$5:$Z$154,Y7)) | U7: =IF(Y7="","",IF(N(R7)=0,"",T7/R7)) | V7: =IF(Y7="","",N(E7)-T7) | W7: =IF(Y7="","",IF(N(E7)=0,"",V7/E7)) | X7: =IF(Y7="","",IF(S7=0,"⏳ لا توجد فواتير شراء",IF(COUNTIFS($Z$5:$Z$154,Y7,$N$5:$N$154,">0")=S7,"✓ اكتملت جميع الفواتير ("&S7&")","⚠ وصل "&COUNTIFS($Z$5:$Z$154,Y7,$N$5:$N$154,">0")&" من "&S7&" فواتير"))) | Y7: =IF(TRIM(A7)="","",IF(ISNUMBER(VALUE(TRIM(A7))),TEXT(VALUE(TRIM(A7)),"0"),TRIM(A7))) | Z7: =IF(TRIM(H7)="","",IF(ISNUMBER(VALUE(TRIM(H7))),TEXT(VALUE(TRIM(H7)),"0"),TRIM(H7)))
A8: 048217 | B8: =IF(Y8="","",IFERROR(INDEX('قائمة الأصناف'!$B$3:$B$1000,MATCH(Y8,'قائمة الأصناف'!$C$3:$C$1000,0)),"⚠ كود غير معرف")) | C8: 1752 | D8: 3 | E8: =IF(OR(C8="",D8=""),"",C8*D8) | F8: =IF(E8="","",E8*الإعدادات!$B$8) | G8: =IF(E8="","",E8+F8) | H8: 048217 | I8: =IF(Z8="","",IF(COUNTIF($Y$5:$Y$154,Z8)=0,"⚠ الصنف غير موجود في المبيعات",IFERROR(INDEX('قائمة الأصناف'!$B$3:$B$1000,MATCH(Z8,'قائمة الأصناف'!$C$3:$C$1000,0)),"⚠ كود غير معرف"))) | J8: =IF(AND(Z8="",TRIM(K8)="",M8="",N8=""),"",IF(AND(Z8<>"",COUNTIF($Y$5:$Y$154,Z8)=0),"✗ حُذف من المبيعات — مستبعد من الحساب",IF(N8="","✗ لم تصل من المورد","✓ تم استلام الفاتورة"))) | O8: =IF(OR(M8="",N8=""),"",IF(COUNTIF($Y$5:$Y$154,Z8)=0,"",M8*N8)) | P8: =IF(O8="","",O8*الإعدادات!$B$8) | Q8: =IF(O8="","",O8+P8) | R8: =IF(Y8="","",SUMIFS($M$5:$M$154,$Z$5:$Z$154,Y8)) | S8: =IF(Y8="","",COUNTIFS($Z$5:$Z$154,Y8)) | T8: =IF(Y8="","",SUMIFS($O$5:$O$154,$Z$5:$Z$154,Y8)) | U8: =IF(Y8="","",IF(N(R8)=0,"",T8/R8)) | V8: =IF(Y8="","",N(E8)-T8) | W8: =IF(Y8="","",IF(N(E8)=0,"",V8/E8)) | X8: =IF(Y8="","",IF(S8=0,"⏳ لا توجد فواتير شراء",IF(COUNTIFS($Z$5:$Z$154,Y8,$N$5:$N$154,">0")=S8,"✓ اكتملت جميع الفواتير ("&S8&")","⚠ وصل "&COUNTIFS($Z$5:$Z$154,Y8,$N$5:$N$154,">0")&" من "&S8&" فواتير"))) | Y8: =IF(TRIM(A8)="","",IF(ISNUMBER(VALUE(TRIM(A8))),TEXT(VALUE(TRIM(A8)),"0"),TRIM(A8))) | Z8: =IF(TRIM(H8)="","",IF(ISNUMBER(VALUE(TRIM(H8))),TEXT(VALUE(TRIM(H8)),"0"),TRIM(H8)))
A9: 048402 | B9: =IF(Y9="","",IFERROR(INDEX('قائمة الأصناف'!$B$3:$B$1000,MATCH(Y9,'قائمة الأصناف'!$C$3:$C$1000,0)),"⚠ كود غير معرف")) | C9: 1176 | D9: 3 | E9: =IF(OR(C9="",D9=""),"",C9*D9) | F9: =IF(E9="","",E9*الإعدادات!$B$8) | G9: =IF(E9="","",E9+F9) | H9: 048402 | I9: =IF(Z9="","",IF(COUNTIF($Y$5:$Y$154,Z9)=0,"⚠ الصنف غير موجود في المبيعات",IFERROR(INDEX('قائمة الأصناف'!$B$3:$B$1000,MATCH(Z9,'قائمة الأصناف'!$C$3:$C$1000,0)),"⚠ كود غير معرف"))) | J9: =IF(AND(Z9="",TRIM(K9)="",M9="",N9=""),"",IF(AND(Z9<>"",COUNTIF($Y$5:$Y$154,Z9)=0),"✗ حُذف من المبيعات — مستبعد من الحساب",IF(N9="","✗ لم تصل من المورد","✓ تم استلام الفاتورة"))) | O9: =IF(OR(M9="",N9=""),"",IF(COUNTIF($Y$5:$Y$154,Z9)=0,"",M9*N9)) | P9: =IF(O9="","",O9*الإعدادات!$B$8) | Q9: =IF(O9="","",O9+P9) | R9: =IF(Y9="","",SUMIFS($M$5:$M$154,$Z$5:$Z$154,Y9)) | S9: =IF(Y9="","",COUNTIFS($Z$5:$Z$154,Y9)) | T9: =IF(Y9="","",SUMIFS($O$5:$O$154,$Z$5:$Z$154,Y9)) | U9: =IF(Y9="","",IF(N(R9)=0,"",T9/R9)) | V9: =IF(Y9="","",N(E9)-T9) | W9: =IF(Y9="","",IF(N(E9)=0,"",V9/E9)) | X9: =IF(Y9="","",IF(S9=0,"⏳ لا توجد فواتير شراء",IF(COUNTIFS($Z$5:$Z$154,Y9,$N$5:$N$154,">0")=S9,"✓ اكتملت جميع الفواتير ("&S9&")","⚠ وصل "&COUNTIFS($Z$5:$Z$154,Y9,$N$5:$N$154,">0")&" من "&S9&" فواتير"))) | Y9: =IF(TRIM(A9)="","",IF(ISNUMBER(VALUE(TRIM(A9))),TEXT(VALUE(TRIM(A9)),"0"),TRIM(A9))) | Z9: =IF(TRIM(H9)="","",IF(ISNUMBER(VALUE(TRIM(H9))),TEXT(VALUE(TRIM(H9)),"0"),TRIM(H9)))
A10: 047906 | B10: =IF(Y10="","",IFERROR(INDEX('قائمة الأصناف'!$B$3:$B$1000,MATCH(Y10,'قائمة الأصناف'!$C$3:$C$1000,0)),"⚠ كود غير معرف")) | C10: 4945 | D10: 5.5 | E10: =IF(OR(C10="",D10=""),"",C10*D10) | F10: =IF(E10="","",E10*الإعدادات!$B$8) | G10: =IF(E10="","",E10+F10) | H10: 047906 | I10: =IF(Z10="","",IF(COUNTIF($Y$5:$Y$154,Z10)=0,"⚠ الصنف غير موجود في المبيعات",IFERROR(INDEX('قائمة الأصناف'!$B$3:$B$1000,MATCH(Z10,'قائمة الأصناف'!$C$3:$C$1000,0)),"⚠ كود غير معرف"))) | J10: =IF(AND(Z10="",TRIM(K10)="",M10="",N10=""),"",IF(AND(Z10<>"",COUNTIF($Y$5:$Y$154,Z10)=0),"✗ حُذف من المبيعات — مستبعد من الحساب",IF(N10="","✗ لم تصل من المورد","✓ تم استلام الفاتورة"))) | O10: =IF(OR(M10="",N10=""),"",IF(COUNTIF($Y$5:$Y$154,Z10)=0,"",M10*N10)) | P10: =IF(O10="","",O10*الإعدادات!$B$8) | Q10: =IF(O10="","",O10+P10) | R10: =IF(Y10="","",SUMIFS($M$5:$M$154,$Z$5:$Z$154,Y10)) | S10: =IF(Y10="","",COUNTIFS($Z$5:$Z$154,Y10)) | T10: =IF(Y10="","",SUMIFS($O$5:$O$154,$Z$5:$Z$154,Y10)) | U10: =IF(Y10="","",IF(N(R10)=0,"",T10/R10)) | V10: =IF(Y10="","",N(E10)-T10) | W10: =IF(Y10="","",IF(N(E10)=0,"",V10/E10)) | X10: =IF(Y10="","",IF(S10=0,"⏳ لا توجد فواتير شراء",IF(COUNTIFS($Z$5:$Z$154,Y10,$N$5:$N$154,">0")=S10,"✓ اكتملت جميع الفواتير ("&S10&")","⚠ وصل "&COUNTIFS($Z$5:$Z$154,Y10,$N$5:$N$154,">0")&" من "&S10&" فواتير"))) | Y10: =IF(TRIM(A10)="","",IF(ISNUMBER(VALUE(TRIM(A10))),TEXT(VALUE(TRIM(A10)),"0"),TRIM(A10))) | Z10: =IF(TRIM(H10)="","",IF(ISNUMBER(VALUE(TRIM(H10))),TEXT(VALUE(TRIM(H10)),"0"),TRIM(H10)))
A11: 048586 | B11: =IF(Y11="","",IFERROR(INDEX('قائمة الأصناف'!$B$3:$B$1000,MATCH(Y11,'قائمة الأصناف'!$C$3:$C$1000,0)),"⚠ كود غير معرف")) | C11: 2400 | D11: 6.25 | E11: =IF(OR(C11="",D11=""),"",C11*D11) | F11: =IF(E11="","",E11*الإعدادات!$B$8) | G11: =IF(E11="","",E11+F11) | H11: 048586 | I11: =IF(Z11="","",IF(COUNTIF($Y$5:$Y$154,Z11)=0,"⚠ الصنف غير موجود في المبيعات",IFERROR(INDEX('قائمة الأصناف'!$B$3:$B$1000,MATCH(Z11,'قائمة الأصناف'!$C$3:$C$1000,0)),"⚠ كود غير معرف"))) | J11: =IF(AND(Z11="",TRIM(K11)="",M11="",N11=""),"",IF(AND(Z11<>"",COUNTIF($Y$5:$Y$154,Z11)=0),"✗ حُذف من المبيعات — مستبعد من الحساب",IF(N11="","✗ لم تصل من المورد","✓ تم استلام الفاتورة"))) | O11: =IF(OR(M11="",N11=""),"",IF(COUNTIF($Y$5:$Y$154,Z11)=0,"",M11*N11)) | P11: =IF(O11="","",O11*الإعدادات!$B$8) | Q11: =IF(O11="","",O11+P11) | R11: =IF(Y11="","",SUMIFS($M$5:$M$154,$Z$5:$Z$154,Y11)) | S11: =IF(Y11="","",COUNTIFS($Z$5:$Z$154,Y11)) | T11: =IF(Y11="","",SUMIFS($O$5:$O$154,$Z$5:$Z$154,Y11)) | U11: =IF(Y11="","",IF(N(R11)=0,"",T11/R11)) | V11: =IF(Y11="","",N(E11)-T11) | W11: =IF(Y11="","",IF(N(E11)=0,"",V11/E11)) | X11: =IF(Y11="","",IF(S11=0,"⏳ لا توجد فواتير شراء",IF(COUNTIFS($Z$5:$Z$154,Y11,$N$5:$N$154,">0")=S11,"✓ اكتملت جميع الفواتير ("&S11&")","⚠ وصل "&COUNTIFS($Z$5:$Z$154,Y11,$N$5:$N$154,">0")&" من "&S11&" فواتير"))) | Y11: =IF(TRIM(A11)="","",IF(ISNUMBER(VALUE(TRIM(A11))),TEXT(VALUE(TRIM(A11)),"0"),TRIM(A11))) | Z11: =IF(TRIM(H11)="","",IF(ISNUMBER(VALUE(TRIM(H11))),TEXT(VALUE(TRIM(H11)),"0"),TRIM(H11)))
B12: =IF(Y12="","",IFERROR(INDEX('قائمة الأصناف'!$B$3:$B$1000,MATCH(Y12,'قائمة الأصناف'!$C$3:$C$1000,0)),"⚠ كود غير معرف")) | E12: =IF(OR(C12="",D12=""),"",C12*D12) | F12: =IF(E12="","",E12*الإعدادات!$B$8) | G12: =IF(E12="","",E12+F12) | I12: =IF(Z12="","",IF(COUNTIF($Y$5:$Y$154,Z12)=0,"⚠ الصنف غير موجود في المبيعات",IFERROR(INDEX('قائمة الأصناف'!$B$3:$B$1000,MATCH(Z12,'قائمة الأصناف'!$C$3:$C$1000,0)),"⚠ كود غير معرف"))) | J12: =IF(AND(Z12="",TRIM(K12)="",M12="",N12=""),"",IF(AND(Z12<>"",COUNTIF($Y$5:$Y$154,Z12)=0),"✗ حُذف من المبيعات — مستبعد من الحساب",IF(N12="","✗ لم تصل من المورد","✓ تم استلام الفاتورة"))) | O12: =IF(OR(M12="",N12=""),"",IF(COUNTIF($Y$5:$Y$154,Z12)=0,"",M12*N12)) | P12: =IF(O12="","",O12*الإعدادات!$B$8) | Q12: =IF(O12="","",O12+P12) | R12: =IF(Y12="","",SUMIFS($M$5:$M$154,$Z$5:$Z$154,Y12)) | S12: =IF(Y12="","",COUNTIFS($Z$5:$Z$154,Y12)) | T12: =IF(Y12="","",SUMIFS($O$5:$O$154,$Z$5:$Z$154,Y12)) | U12: =IF(Y12="","",IF(N(R12)=0,"",T12/R12)) | V12: =IF(Y12="","",N(E12)-T12) | W12: =IF(Y12="","",IF(N(E12)=0,"",V12/E12)) | X12: =IF(Y12="","",IF(S12=0,"⏳ لا توجد فواتير شراء",IF(COUNTIFS($Z$5:$Z$154,Y12,$N$5:$N$154,">0")=S12,"✓ اكتملت جميع الفواتير ("&S12&")","⚠ وصل "&COUNTIFS($Z$5:$Z$154,Y12,$N$5:$N$154,">0")&" من "&S12&" فواتير"))) | Y12: =IF(TRIM(A12)="","",IF(ISNUMBER(VALUE(TRIM(A12))),TEXT(VALUE(TRIM(A12)),"0"),TRIM(A12))) | Z12: =IF(TRIM(H12)="","",IF(ISNUMBER(VALUE(TRIM(H12))),TEXT(VALUE(TRIM(H12)),"0"),TRIM(H12)))
B13: =IF(Y13="","",IFERROR(INDEX('قائمة الأصناف'!$B$3:$B$1000,MATCH(Y13,'قائمة الأصناف'!$C$3:$C$1000,0)),"⚠ كود غير معرف")) | E13: =IF(OR(C13="",D13=""),"",C13*D13) | F13: =IF(E13="","",E13*الإعدادات!$B$8) | G13: =IF(E13="","",E13+F13) | I13: =IF(Z13="","",IF(COUNTIF($Y$5:$Y$154,Z13)=0,"⚠ الصنف غير موجود في المبيعات",IFERROR(INDEX('قائمة الأصناف'!$B$3:$B$1000,MATCH(Z13,'قائمة الأصناف'!$C$3:$C$1000,0)),"⚠ كود غير معرف"))) | J13: =IF(AND(Z13="",TRIM(K13)="",M13="",N13=""),"",IF(AND(Z13<>"",COUNTIF($Y$5:$Y$154,Z13)=0),"✗ حُذف من المبيعات — مستبعد من الحساب",IF(N13="","✗ لم تصل من المورد","✓ تم استلام الفاتورة"))) | O13: =IF(OR(M13="",N13=""),"",IF(COUNTIF($Y$5:$Y$154,Z13)=0,"",M13*N13)) | P13: =IF(O13="","",O13*الإعدادات!$B$8) | Q13: =IF(O13="","",O13+P13) | R13: =IF(Y13="","",SUMIFS($M$5:$M$154,$Z$5:$Z$154,Y13)) | S13: =IF(Y13="","",COUNTIFS($Z$5:$Z$154,Y13)) | T13: =IF(Y13="","",SUMIFS($O$5:$O$154,$Z$5:$Z$154,Y13)) | U13: =IF(Y13="","",IF(N(R13)=0,"",T13/R13)) | V13: =IF(Y13="","",N(E13)-T13) | W13: =IF(Y13="","",IF(N(E13)=0,"",V13/E13)) | X13: =IF(Y13="","",IF(S13=0,"⏳ لا توجد فواتير شراء",IF(COUNTIFS($Z$5:$Z$154,Y13,$N$5:$N$154,">0")=S13,"✓ اكتملت جميع الفواتير ("&S13&")","⚠ وصل "&COUNTIFS($Z$5:$Z$154,Y13,$N$5:$N$154,">0")&" من "&S13&" فواتير"))) | Y13: =IF(TRIM(A13)="","",IF(ISNUMBER(VALUE(TRIM(A13))),TEXT(VALUE(TRIM(A13)),"0"),TRIM(A13))) | Z13: =IF(TRIM(H13)="","",IF(ISNUMBER(VALUE(TRIM(H13))),TEXT(VALUE(TRIM(H13)),"0"),TRIM(H13)))
B14: =IF(Y14="","",IFERROR(INDEX('قائمة الأصناف'!$B$3:$B$1000,MATCH(Y14,'قائمة الأصناف'!$C$3:$C$1000,0)),"⚠ كود غير معرف")) | E14: =IF(OR(C14="",D14=""),"",C14*D14) | F14: =IF(E14="","",E14*الإعدادات!$B$8) | G14: =IF(E14="","",E14+F14) | I14: =IF(Z14="","",IF(COUNTIF($Y$5:$Y$154,Z14)=0,"⚠ الصنف غير موجود في المبيعات",IFERROR(INDEX('قائمة الأصناف'!$B$3:$B$1000,MATCH(Z14,'قائمة الأصناف'!$C$3:$C$1000,0)),"⚠ كود غير معرف"))) | J14: =IF(AND(Z14="",TRIM(K14)="",M14="",N14=""),"",IF(AND(Z14<>"",COUNTIF($Y$5:$Y$154,Z14)=0),"✗ حُذف من المبيعات — مستبعد من الحساب",IF(N14="","✗ لم تصل من المورد","✓ تم استلام الفاتورة"))) | O14: =IF(OR(M14="",N14=""),"",IF(COUNTIF($Y$5:$Y$154,Z14)=0,"",M14*N14)) | P14: =IF(O14="","",O14*الإعدادات!$B$8) | Q14: =IF(O14="","",O14+P14) | R14: =IF(Y14="","",SUMIFS($M$5:$M$154,$Z$5:$Z$154,Y14)) | S14: =IF(Y14="","",COUNTIFS($Z$5:$Z$154,Y14)) | T14: =IF(Y14="","",SUMIFS($O$5:$O$154,$Z$5:$Z$154,Y14)) | U14: =IF(Y14="","",IF(N(R14)=0,"",T14/R14)) | V14: =IF(Y14="","",N(E14)-T14) | W14: =IF(Y14="","",IF(N(E14)=0,"",V14/E14)) | X14: =IF(Y14="","",IF(S14=0,"⏳ لا توجد فواتير شراء",IF(COUNTIFS($Z$5:$Z$154,Y14,$N$5:$N$154,">0")=S14,"✓ اكتملت جميع الفواتير ("&S14&")","⚠ وصل "&COUNTIFS($Z$5:$Z$154,Y14,$N$5:$N$154,">0")&" من "&S14&" فواتير"))) | Y14: =IF(TRIM(A14)="","",IF(ISNUMBER(VALUE(TRIM(A14))),TEXT(VALUE(TRIM(A14)),"0"),TRIM(A14))) | Z14: =IF(TRIM(H14)="","",IF(ISNUMBER(VALUE(TRIM(H14))),TEXT(VALUE(TRIM(H14)),"0"),TRIM(H14)))
B15: =IF(Y15="","",IFERROR(INDEX('قائمة الأصناف'!$B$3:$B$1000,MATCH(Y15,'قائمة الأصناف'!$C$3:$C$1000,0)),"⚠ كود غير معرف")) | E15: =IF(OR(C15="",D15=""),"",C15*D15) | F15: =IF(E15="","",E15*الإعدادات!$B$8) | G15: =IF(E15="","",E15+F15) | I15: =IF(Z15="","",IF(COUNTIF($Y$5:$Y$154,Z15)=0,"⚠ الصنف غير موجود في المبيعات",IFERROR(INDEX('قائمة الأصناف'!$B$3:$B$1000,MATCH(Z15,'قائمة الأصناف'!$C$3:$C$1000,0)),"⚠ كود غير معرف"))) | J15: =IF(AND(Z15="",TRIM(K15)="",M15="",N15=""),"",IF(AND(Z15<>"",COUNTIF($Y$5:$Y$154,Z15)=0),"✗ حُذف من المبيعات — مستبعد من الحساب",IF(N15="","✗ لم تصل من المورد","✓ تم استلام الفاتورة"))) | O15: =IF(OR(M15="",N15=""),"",IF(COUNTIF($Y$5:$Y$154,Z15)=0,"",M15*N15)) | P15: =IF(O15="","",O15*الإعدادات!$B$8) | Q15: =IF(O15="","",O15+P15) | R15: =IF(Y15="","",SUMIFS($M$5:$M$154,$Z$5:$Z$154,Y15)) | S15: =IF(Y15="","",COUNTIFS($Z$5:$Z$154,Y15)) | T15: =IF(Y15="","",SUMIFS($O$5:$O$154,$Z$5:$Z$154,Y15)) | U15: =IF(Y15="","",IF(N(R15)=0,"",T15/R15)) | V15: =IF(Y15="","",N(E15)-T15) | W15: =IF(Y15="","",IF(N(E15)=0,"",V15/E15)) | X15: =IF(Y15="","",IF(S15=0,"⏳ لا توجد فواتير شراء",IF(COUNTIFS($Z$5:$Z$154,Y15,$N$5:$N$154,">0")=S15,"✓ اكتملت جميع الفواتير ("&S15&")","⚠ وصل "&COUNTIFS($Z$5:$Z$154,Y15,$N$5:$N$154,">0")&" من "&S15&" فواتير"))) | Y15: =IF(TRIM(A15)="","",IF(ISNUMBER(VALUE(TRIM(A15))),TEXT(VALUE(TRIM(A15)),"0"),TRIM(A15))) | Z15: =IF(TRIM(H15)="","",IF(ISNUMBER(VALUE(TRIM(H15))),TEXT(VALUE(TRIM(H15)),"0"),TRIM(H15)))
