Workbook

Sheet الملخص
A1: ملخص أرصدة العملاء
A2: كل الأرقام معادلات مرتبطة بالكشوف — اضغط اسم الحساب للانتقال إلى كشفه. تاريخ التدقيق: 31/10/2026
B4: عدد الحسابات | D4: إجمالي المبيعات | E4: إجمالي المحصّل والخصومات | F4: صافي المستحق لنا | G4: حسابات عليها رصيد | I4: ملاحظات تدقيق
B5: =COUNTA(B9:B51) -> 43 | D5: =SUMIFS('سجل الحركات'!J4:J323,'سجل الحركات'!E4:E323,"بضاعة") -> 265724.21 | E5: =E52 -> 214533 | F5: =F52 -> 52221.21 | G5: =COUNTIF(K9:K51,"مستحق لنا") -> 24 | I5: =COUNTA('ملاحظات التدقيق'!B5:B1000) -> 48
A8: # | B8: الحساب | C8: عدد الحركات | D8: إجمالي المدين | E8: إجمالي الدائن | F8: الرصيد | G8: ضريبة القيمة المضافة | H8: أول حركة | I8: آخر حركة | J8: آخر سداد | K8: الحالة
A9: 1 | B9: محمد زبون | C9: =COUNTA('محمد زبون'!D7:D1000) -> 12 | D9: ='محمد زبون'!F4 -> 498 | E9: ='محمد زبون'!G4 -> 498 | F9: ='محمد زبون'!H4 -> 0 | G9: ='محمد زبون'!I4 -> 0 | H9: ='محمد زبون'!D4 -> 46311 | I9: ='محمد زبون'!E4 -> 46324 | J9: ='محمد زبون'!J4 -> 46324 | K9: ='محمد زبون'!K4 -> مسدد
A10: 2 | B10: فضل | C10: =COUNTA(فضل!D7:D1000) -> 2 | D10: =فضل!F4 -> 90 | E10: =فضل!G4 -> 90 | F10: =فضل!H4 -> 0 | G10: =فضل!I4 -> 0 | H10: =فضل!D4 -> 46321 | I10: =فضل!E4 -> 46324 | J10: =فضل!J4 -> 46324 | K10: =فضل!K4 -> مسدد
A11: 3 | B11: قصي جابر | C11: =COUNTA('قصي جابر'!D7:D1000) -> 9 | D11: ='قصي جابر'!F4 -> 10070 | E11: ='قصي جابر'!G4 -> 5450 | F11: ='قصي جابر'!H4 -> 4620 | G11: ='قصي جابر'!I4 -> 0 | H11: ='قصي جابر'!D4 -> 46297 | I11: ='قصي جابر'!E4 -> 46325 | J11: ='قصي جابر'!J4 -> 46325 | K11: ='قصي جابر'!K4 -> مستحق لنا
A12: 4 | B12: مصنع امداد | C12: =COUNTA('مصنع امداد'!D7:D1000) -> 5 | D12: ='مصنع امداد'!F4 -> 2432.75 | E12: ='مصنع امداد'!G4 -> 1132.75 | F12: ='مصنع امداد'!H4 -> 1300 | G12: ='مصنع امداد'!I4 -> 147.75 | H12: ='مصنع امداد'!D4 -> 46298 | I12: ='مصنع امداد'!E4 -> 46320 | J12: ='مصنع امداد'!J4 -> 46300 | K12: ='مصنع امداد'!K4 -> مستحق لنا
A13: 5 | B13: هارون | C13: =COUNTA(هارون!D7:D1000) -> 2 | D13: =هارون!F4 -> 5400 | E13: =هارون!G4 -> 4000 | F13: =هارون!H4 -> 1400 | G13: =هارون!I4 -> 0 | H13: =هارون!D4 -> 46320 | I13: =هارون!E4 -> 46321 | J13: =هارون!J4 -> 46321 | K13: =هارون!K4 -> مستحق لنا
A14: 6 | B14: ثمار مجني | C14: =COUNTA(مجني!D7:D1000) -> 2 | D14: =مجني!F4 -> 4508 | E14: =مجني!G4 -> 4508 | F14: =مجني!H4 -> 0 | G14: =مجني!I4 -> 588 | H14: =مجني!D4 -> 46297 | I14: =مجني!E4 -> 46300 | J14: =مجني!J4 -> 46300 | K14: =مجني!K4 -> مسدد
A15: 7 | B15: علاء | C15: =COUNTA(علاء!D7:D1000) -> 11 | D15: =علاء!F4 -> 3481 | E15: =علاء!G4 -> 2375 | F15: =علاء!H4 -> 1106 | G15: =علاء!I4 -> 0 | H15: =علاء!D4 -> 46308 | I15: =علاء!E4 -> 46325 | J15: =علاء!J4 -> 46320 | K15: =علاء!K4 -> مستحق لنا
A16: 8 | B16: مامون بنغالي | C16: =COUNTA('مامون بنغالي'!D7:D1000) -> 2 | D16: ='مامون بنغالي'!F4 -> 2600 | E16: ='مامون بنغالي'!G4 -> 2600 | F16: ='مامون بنغالي'!H4 -> 0 | G16: ='مامون بنغالي'!I4 -> 0 | H16: ='مامون بنغالي'!D4 -> 46317 | I16: ='مامون بنغالي'!E4 -> 46320 | J16: ='مامون بنغالي'!J4 -> 46320 | K16: ='مامون بنغالي'!K4 -> مسدد
A17: 9 | B17: عرب بركات | C17: =COUNTA('عرب بركات'!D7:D1000) -> 2 | D17: ='عرب بركات'!F4 -> 6560.75 | E17: ='عرب بركات'!G4 -> 0 | F17: ='عرب بركات'!H4 -> 6560.75 | G17: ='عرب بركات'!I4 -> 855.75 | H17: ='عرب بركات'!D4 -> 46317 | I17: ='عرب بركات'!E4 -> 46321 | J17: ='عرب بركات'!J4 | K17: ='عرب بركات'!K4 -> مستحق لنا
A18: 10 | B18: أبو احمد السوري | C18: =COUNTA('ابو احمد السوري'!D7:D1000) -> 12 | D18: ='ابو احمد السوري'!F4 -> 1271 | E18: ='ابو احمد السوري'!G4 -> 1270 | F18: ='ابو احمد السوري'!H4 -> 1 | G18: ='ابو احمد السوري'!I4 -> 0 | H18: ='ابو احمد السوري'!D4 -> 46298 | I18: ='ابو احمد السوري'!E4 -> 46316 | J18: ='ابو احمد السوري'!J4 -> 46316 | K18: ='ابو احمد السوري'!K4 -> مستحق لنا
A19: 11 | B19: هشام ناجي | C19: =COUNTA('هشام ناجي'!D7:D1000) -> 8 | D19: ='هشام ناجي'!F4 -> 7846 | E19: ='هشام ناجي'!G4 -> 7821 | F19: ='هشام ناجي'!H4 -> 25 | G19: ='هشام ناجي'!I4 -> 0 | H19: ='هشام ناجي'!D4 -> 46309 | I19: ='هشام ناجي'!E4 -> 46319 | J19: ='هشام ناجي'!J4 -> 46319 | K19: ='هشام ناجي'!K4 -> مستحق لنا
A20: 12 | B20: عصام المصري | C20: =COUNTA('عصام المصري'!D7:D1000) -> 7 | D20: ='عصام المصري'!F4 -> 1739 | E20: ='عصام المصري'!G4 -> 690 | F20: ='عصام المصري'!H4 -> 1049 | G20: ='عصام المصري'!I4 -> 54 | H20: ='عصام المصري'!D4 -> 46307 | I20: ='عصام المصري'!E4 -> 46325 | J20: ='عصام المصري'!J4 -> 46311 | K20: ='عصام المصري'!K4 -> مستحق لنا
A21: 13 | B21: الحساني | C21: =COUNTA(الحساني!D7:D1000) -> 2 | D21: =الحساني!F4 -> 6626.3 | E21: =الحساني!G4 -> 6626.3 | F21: =الحساني!H4 -> 0 | G21: =الحساني!I4 -> 864.3 | H21: =الحساني!D4 -> 46314 | I21: =الحساني!E4 -> 46315 | J21: =الحساني!J4 -> 46315 | K21: =الحساني!K4 -> مسدد
A22: 14 | B22: سليم يمني | C22: =COUNTA('سليم يمني'!D7:D1000) -> 2 | D22: ='سليم يمني'!F4 -> 300 | E22: ='سليم يمني'!G4 -> 300 | F22: ='سليم يمني'!H4 -> 0 | G22: ='سليم يمني'!I4 -> 0 | H22: ='سليم يمني'!D4 -> 46315 | I22: ='سليم يمني'!E4 -> 46322 | J22: ='سليم يمني'!J4 -> 46322 | K22: ='سليم يمني'!K4 -> مسدد
A23: 15 | B23: ناصر اكرم | C23: =COUNTA('ناصر اكرم'!D7:D1000) -> 7 | D23: ='ناصر اكرم'!F4 -> 2190 | E23: ='ناصر اكرم'!G4 -> 2190 | F23: ='ناصر اكرم'!H4 -> 0 | G23: ='ناصر اكرم'!I4 -> 0 | H23: ='ناصر اكرم'!D4 -> 46314 | I23: ='ناصر اكرم'!E4 -> 46322 | J23: ='ناصر اكرم'!J4 -> 46322 | K23: ='ناصر اكرم'!K4 -> مسدد
A24: 16 | B24: مدحت تركي | C24: =COUNTA('مدحت تركي'!D7:D1000) -> 1 | D24: ='مدحت تركي'!F4 -> 1400 | E24: ='مدحت تركي'!G4 -> 0 | F24: ='مدحت تركي'!H4 -> 1400 | G24: ='مدحت تركي'!I4 -> 0 | H24: ='مدحت تركي'!D4 -> 46318 | I24: ='مدحت تركي'!E4 -> 46318 | J24: ='مدحت تركي'!J4 | K24: ='مدحت تركي'!K4 -> مستحق لنا
A25: 17 | B25: امين بنغالي | C25: =COUNTA('امين بنغالي'!D7:D1000) -> 12 | D25: ='امين بنغالي'!F4 -> 7880 | E25: ='امين بنغالي'!G4 -> 5425 | F25: ='امين بنغالي'!H4 -> 2455 | G25: ='امين بنغالي'!I4 -> 0 | H25: ='امين بنغالي'!D4 -> 46314 | I25: ='امين بنغالي'!E4 -> 46325 | J25: ='امين بنغالي'!J4 -> 46325 | K25: ='امين بنغالي'!K4 -> مستحق لنا
A26: 18 | B26: محمود الساعي | C26: =COUNTA('محمود الساعي'!D7:D1000) -> 4 | D26: ='محمود الساعي'!F4 -> 4275 | E26: ='محمود الساعي'!G4 -> 4275 | F26: ='محمود الساعي'!H4 -> 0 | G26: ='محمود الساعي'!I4 -> 0 | H26: ='محمود الساعي'!D4 -> 46316 | I26: ='محمود الساعي'!E4 -> 46323 | J26: ='محمود الساعي'!J4 -> 46323 | K26: ='محمود الساعي'!K4 -> مسدد
A27: 19 | B27: سليمان اليمني | C27: =COUNTA('سليمان اليمني'!D7:D1000) -> 2 | D27: ='سليمان اليمني'!F4 -> 160 | E27: ='سليمان اليمني'!G4 -> 160 | F27: ='سليمان اليمني'!H4 -> 0 | G27: ='سليمان اليمني'!I4 -> 0 | H27: ='سليمان اليمني'!D4 -> 46309 | I27: ='سليمان اليمني'!E4 -> 46311 | J27: ='سليمان اليمني'!J4 -> 46311 | K27: ='سليمان اليمني'!K4 -> مسدد
A28: 20 | B28: كامل | C28: =COUNTA(كامل!D7:D1000) -> 1 | D28: =كامل!F4 -> 568.1 | E28: =كامل!G4 -> 0 | F28: =كامل!H4 -> 568.1 | G28: =كامل!I4 -> 74.1 | H28: =كامل!D4 -> 46313 | I28: =كامل!E4 -> 46313 | J28: =كامل!J4 | K28: =كامل!K4 -> مستحق لنا
A29: 21 | B29: امجد | C29: =COUNTA(امجد!D7:D1000) -> 3 | D29: =امجد!F4 -> 75 | E29: =امجد!G4 -> 75 | F29: =امجد!H4 -> 0 | G29: =امجد!I4 -> 0 | H29: =امجد!D4 -> 46322 | I29: =امجد!E4 -> 46323 | J29: =امجد!J4 -> 46323 | K29: =امجد!K4 -> مسدد
A30: 22 | B30: الكعبي كاش | C30: =COUNTA('الكعبي كاش'!D7:D1000) -> 10 | D30: ='الكعبي كاش'!F4 -> 10430 | E30: ='الكعبي كاش'!G4 -> 6760 | F30: ='الكعبي كاش'!H4 -> 3670 | G30: ='الكعبي كاش'!I4 -> 0 | H30: ='الكعبي كاش'!D4 -> 46298 | I30: ='الكعبي كاش'!E4 -> 46317 | J30: ='الكعبي كاش'!J4 -> 46308 | K30: ='الكعبي كاش'!K4 -> مستحق لنا
A31: 23 | B31: الكعبي حوالة | C31: =COUNTA('الكعبي حوالة'!D7:D1000) -> 8 | D31: ='الكعبي حوالة'!F4 -> 7636 | E31: ='الكعبي حوالة'!G4 -> 0 | F31: ='الكعبي حوالة'!H4 -> 7636 | G31: ='الكعبي حوالة'!I4 -> 996 | H31: ='الكعبي حوالة'!D4 -> 46307 | I31: ='الكعبي حوالة'!E4 -> 46309 | J31: ='الكعبي حوالة'!J4 | K31: ='الكعبي حوالة'!K4 -> مستحق لنا
A32: 24 | B32: محمد عادل | C32: =COUNTA('محمد عادل'!D7:D1000) -> 11 | D32: ='محمد عادل'!F4 -> 10835.55 | E32: ='محمد عادل'!G4 -> 10835 | F32: ='محمد عادل'!H4 -> 0.55 | G32: ='محمد عادل'!I4 -> 547.25 | H32: ='محمد عادل'!D4 -> 46307 | I32: ='محمد عادل'!E4 -> 46321 | J32: ='محمد عادل'!J4 -> 46321 | K32: ='محمد عادل'!K4 -> مستحق لنا
A33: 25 | B33: فيض الكرم | C33: =COUNTA('فيض الكرم'!D7:D1000) -> 4 | D33: ='فيض الكرم'!F4 -> 5037 | E33: ='فيض الكرم'!G4 -> 5035 | F33: ='فيض الكرم'!H4 -> 2 | G33: ='فيض الكرم'!I4 -> 657 | H33: ='فيض الكرم'!D4 -> 46313 | I33: ='فيض الكرم'!E4 -> 46321 | J33: ='فيض الكرم'!J4 -> 46321 | K33: ='فيض الكرم'!K4 -> مستحق لنا
A34: 26 | B34: سامر اليمني | C34: =COUNTA('سامر اليمني'!D7:D1000) -> 8 | D34: ='سامر اليمني'!F4 -> 720 | E34: ='سامر اليمني'!G4 -> 715 | F34: ='سامر اليمني'!H4 -> 5 | G34: ='سامر اليمني'!I4 -> 0 | H34: ='سامر اليمني'!D4 -> 46305 | I34: ='سامر اليمني'!E4 -> 46313 | J34: ='سامر اليمني'!J4 -> 46313 | K34: ='سامر اليمني'!K4 -> مستحق لنا
A35: 27 | B35: صلاح الصعيدي | C35: =COUNTA('صلاح الصعيدي'!D7:D1000) -> 8 | D35: ='صلاح الصعيدي'!F4 -> 285 | E35: ='صلاح الصعيدي'!G4 -> 285 | F35: ='صلاح الصعيدي'!H4 -> 0 | G35: ='صلاح الصعيدي'!I4 -> 0 | H35: ='صلاح الصعيدي'!D4 -> 46308 | I35: ='صلاح الصعيدي'!E4 -> 46325 | J35: ='صلاح الصعيدي'!J4 -> 46325 | K35: ='صلاح الصعيدي'!K4 -> مسدد
A36: 28 | B36: نور بنغالي | C36: =COUNTA('نور بنغالي'!D7:D1000) -> 20 | D36: ='نور بنغالي'!F4 -> 4308 | E36: ='نور بنغالي'!G4 -> 3540 | F36: ='نور بنغالي'!H4 -> 768 | G36: ='نور بنغالي'!I4 -> 0 | H36: ='نور بنغالي'!D4 -> 46299 | I36: ='نور بنغالي'!E4 -> 46325 | J36: ='نور بنغالي'!J4 -> 46325 | K36: ='نور بنغالي'!K4 -> مستحق لنا
A37: 29 | B37: طيبات العصر | C37: =COUNTA('طيبات العصر'!D7:D1000) -> 8 | D37: ='طيبات العصر'!F4 -> 6728.5 | E37: ='طيبات العصر'!G4 -> 6730 | F37: ='طيبات العصر'!H4 -> -1.5 | G37: ='طيبات العصر'!I4 -> 850.5 | H37: ='طيبات العصر'!D4 -> 46299 | I37: ='طيبات العصر'!E4 -> 46316 | J37: ='طيبات العصر'!J4 -> 46316 | K37: ='طيبات العصر'!K4 -> رصيد للعميل
A38: 30 | B38: محيط دلتا | C38: =COUNTA('محيط دلتا'!D7:D1000) -> 8 | D38: ='محيط دلتا'!F4 -> 4171.36 | E38: ='محيط دلتا'!G4 -> 4169 | F38: ='محيط دلتا'!H4 -> 2.36 | G38: ='محيط دلتا'!I4 -> 361.19 | H38: ='محيط دلتا'!D4 -> 46297 | I38: ='محيط دلتا'!E4 -> 46309 | J38: ='محيط دلتا'!J4 -> 46309 | K38: ='محيط دلتا'!K4 -> مستحق لنا
A39: 31 | B39: أبو عجاج | C39: =COUNTA(ابوعجاج!D7:D1000) -> 6 | D39: =ابوعجاج!F4 -> 9508 | E39: =ابوعجاج!G4 -> 7308 | F39: =ابوعجاج!H4 -> 2200 | G39: =ابوعجاج!I4 -> 528 | H39: =ابوعجاج!D4 -> 46301 | I39: =ابوعجاج!E4 -> 46319 | J39: =ابوعجاج!J4 -> 46319 | K39: =ابوعجاج!K4 -> مستحق لنا
A40: 32 | B40: ماجد بسطه | C40: =COUNTA('ماجد بسطة'!D7:D1000) -> 8 | D40: ='ماجد بسطة'!F4 -> 1224 | E40: ='ماجد بسطة'!G4 -> 900 | F40: ='ماجد بسطة'!H4 -> 324 | G40: ='ماجد بسطة'!I4 -> 0 | H40: ='ماجد بسطة'!D4 -> 46314 | I40: ='ماجد بسطة'!E4 -> 46321 | J40: ='ماجد بسطة'!J4 -> 46321 | K40: ='ماجد بسطة'!K4 -> مستحق لنا
A41: 33 | B41: سليم بنغالي | C41: =COUNTA('سليم بنغالي'!D7:D1000) -> 17 | D41: ='سليم بنغالي'!F4 -> 11030 | E41: ='سليم بنغالي'!G4 -> 11030 | F41: ='سليم بنغالي'!H4 -> 0 | G41: ='سليم بنغالي'!I4 -> 0 | H41: ='سليم بنغالي'!D4 -> 46303 | I41: ='سليم بنغالي'!E4 -> 46323 | J41: ='سليم بنغالي'!J4 -> 46319 | K41: ='سليم بنغالي'!K4 -> مسدد
A42: 34 | B42: التخصص الذهبي | C42: =COUNTA('التخصص الذهبي'!D7:D1000) -> 44 | D42: ='التخصص الذهبي'!F4 -> 56681.2 | E42: ='التخصص الذهبي'!G4 -> 43938 | F42: ='التخصص الذهبي'!H4 -> 12743.2 | G42: ='التخصص الذهبي'!I4 -> 7393.2 | H42: ='التخصص الذهبي'!D4 -> 46308 | I42: ='التخصص الذهبي'!E4 -> 46325 | J42: ='التخصص الذهبي'!J4 -> 46325 | K42: ='التخصص الذهبي'!K4 -> مستحق لنا
A43: 35 | B43: عبدالرحمن قدري | C43: =COUNTA('عبدالرحمن قدري'!D7:D1000) -> 4 | D43: ='عبدالرحمن قدري'!F4 -> 7826 | E43: ='عبدالرحمن قدري'!G4 -> 7826 | F43: ='عبدالرحمن قدري'!H4 -> 0 | G43: ='عبدالرحمن قدري'!I4 -> 0 | H43: ='عبدالرحمن قدري'!D4 -> 46323 | I43: ='عبدالرحمن قدري'!E4 -> 46325 | J43: ='عبدالرحمن قدري'!J4 -> 46325 | K43: ='عبدالرحمن قدري'!K4 -> مسدد
...

Sheet سجل الحركات
A1: سجل الحركات الموحّد — كل الحسابات (مرتبط بالكشوف)
A2: كل خانة هنا معادلة تقرأ من الكشف الأصلي؛ أي تعديل في الكشوف ينعكس هنا. الحركات الجديدة المضافة لاحقاً في الكشوف لا تظهر هنا تلقائياً.
A3: الحساب | B3: التاريخ | C3: البيان | D3: الصنف الموحد | E3: نوع الحركة | F3: العدد | G3: السعر | H3: قبل الضريبة | I3: الضريبة | J3: مدين | K3: دائن
A4: محمد زبون | B4: ='محمد زبون'!C7 -> 46311 | C4: ='محمد زبون'!D7 -> تفاح سلة | D4: تفاح سلة | E4: بضاعة | F4: =IF('محمد زبون'!E7="","",'محمد زبون'!E7) -> 1 | G4: =IF('محمد زبون'!F7="","",'محمد زبون'!F7) -> 60 | H4: =IF(F4="","",ROUND(F4*G4,2)) -> 60 | I4: =IF(F4="","",ROUND(H4*IF(N('محمد زبون'!G7)>1,'محمد زبون'!G7-1,0),2)) -> 0 | J4: =N('محمد زبون'!H7) -> 60 | K4: =N('محمد زبون'!I7) -> 0
A5: محمد زبون | B5: ='محمد زبون'!C8 -> 46311 | C5: ='محمد زبون'!D8 -> رمان وسط | D5: رمان وسط | E5: بضاعة | F5: =IF('محمد زبون'!E8="","",'محمد زبون'!E8) -> 1 | G5: =IF('محمد زبون'!F8="","",'محمد زبون'!F8) -> 19 | H5: =IF(F5="","",ROUND(F5*G5,2)) -> 19 | I5: =IF(F5="","",ROUND(H5*IF(N('محمد زبون'!G8)>1,'محمد زبون'!G8-1,0),2)) -> 0 | J5: =N('محمد زبون'!H8) -> 19 | K5: =N('محمد زبون'!I8) -> 0
A6: محمد زبون | B6: ='محمد زبون'!C9 -> 46312 | C6: ='محمد زبون'!D9 -> سداد | E6: سداد | F6: =IF('محمد زبون'!E9="","",'محمد زبون'!E9) | G6: =IF('محمد زبون'!F9="","",'محمد زبون'!F9) | H6: =IF(F6="","",ROUND(F6*G6,2)) | I6: =IF(F6="","",ROUND(H6*IF(N('محمد زبون'!G9)>1,'محمد زبون'!G9-1,0),2)) | J6: =N('محمد زبون'!H9) -> 0 | K6: =N('محمد زبون'!I9) -> 79
A7: محمد زبون | B7: ='محمد زبون'!C10 -> 46312 | C7: ='محمد زبون'!D10 -> تفاح سلة | D7: تفاح سلة | E7: بضاعة | F7: =IF('محمد زبون'!E10="","",'محمد زبون'!E10) -> 1 | G7: =IF('محمد زبون'!F10="","",'محمد زبون'!F10) -> 60 | H7: =IF(F7="","",ROUND(F7*G7,2)) -> 60 | I7: =IF(F7="","",ROUND(H7*IF(N('محمد زبون'!G10)>1,'محمد زبون'!G10-1,0),2)) -> 0 | J7: =N('محمد زبون'!H10) -> 60 | K7: =N('محمد زبون'!I10) -> 0
A8: محمد زبون | B8: ='محمد زبون'!C11 -> 46312 | C8: ='محمد زبون'!D11 -> رمان وسط | D8: رمان وسط | E8: بضاعة | F8: =IF('محمد زبون'!E11="","",'محمد زبون'!E11) -> 1 | G8: =IF('محمد زبون'!F11="","",'محمد زبون'!F11) -> 19 | H8: =IF(F8="","",ROUND(F8*G8,2)) -> 19 | I8: =IF(F8="","",ROUND(H8*IF(N('محمد زبون'!G11)>1,'محمد زبون'!G11-1,0),2)) -> 0 | J8: =N('محمد زبون'!H11) -> 19 | K8: =N('محمد زبون'!I11) -> 0
A9: محمد زبون | B9: ='محمد زبون'!C12 -> 46313 | C9: ='محمد زبون'!D12 -> سداد | E9: سداد | F9: =IF('محمد زبون'!E12="","",'محمد زبون'!E12) | G9: =IF('محمد زبون'!F12="","",'محمد زبون'!F12) | H9: =IF(F9="","",ROUND(F9*G9,2)) | I9: =IF(F9="","",ROUND(H9*IF(N('محمد زبون'!G12)>1,'محمد زبون'!G12-1,0),2)) | J9: =N('محمد زبون'!H12) -> 0 | K9: =N('محمد زبون'!I12) -> 79
A10: محمد زبون | B10: ='محمد زبون'!C13 -> 46313 | C10: ='محمد زبون'!D13 -> تفاح سلة | D10: تفاح سلة | E10: بضاعة | F10: =IF('محمد زبون'!E13="","",'محمد زبون'!E13) -> 2 | G10: =IF('محمد زبون'!F13="","",'محمد زبون'!F13) -> 60 | H10: =IF(F10="","",ROUND(F10*G10,2)) -> 120 | I10: =IF(F10="","",ROUND(H10*IF(N('محمد زبون'!G13)>1,'محمد زبون'!G13-1,0),2)) -> 0 | J10: =N('محمد زبون'!H13) -> 120 | K10: =N('محمد زبون'!I13) -> 0
A11: محمد زبون | B11: ='محمد زبون'!C14 -> 46314 | C11: ='محمد زبون'!D14 -> سداد | E11: سداد | F11: =IF('محمد زبون'!E14="","",'محمد زبون'!E14) | G11: =IF('محمد زبون'!F14="","",'محمد زبون'!F14) | H11: =IF(F11="","",ROUND(F11*G11,2)) | I11: =IF(F11="","",ROUND(H11*IF(N('محمد زبون'!G14)>1,'محمد زبون'!G14-1,0),2)) | J11: =N('محمد زبون'!H14) -> 0 | K11: =N('محمد زبون'!I14) -> 120
A12: محمد زبون | B12: ='محمد زبون'!C15 -> 46318 | C12: ='محمد زبون'!D15 -> تفاح سلة | D12: تفاح سلة | E12: بضاعة | F12: =IF('محمد زبون'!E15="","",'محمد زبون'!E15) -> 3 | G12: =IF('محمد زبون'!F15="","",'محمد زبون'!F15) -> 55 | H12: =IF(F12="","",ROUND(F12*G12,2)) -> 165 | I12: =IF(F12="","",ROUND(H12*IF(N('محمد زبون'!G15)>1,'محمد زبون'!G15-1,0),2)) -> 0 | J12: =N('محمد زبون'!H15) -> 165 | K12: =N('محمد زبون'!I15) -> 0
A13: محمد زبون | B13: ='محمد زبون'!C16 -> 46320 | C13: ='محمد زبون'!D16 -> سداد | E13: سداد | F13: =IF('محمد زبون'!E16="","",'محمد زبون'!E16) | G13: =IF('محمد زبون'!F16="","",'محمد زبون'!F16) | H13: =IF(F13="","",ROUND(F13*G13,2)) | I13: =IF(F13="","",ROUND(H13*IF(N('محمد زبون'!G16)>1,'محمد زبون'!G16-1,0),2)) | J13: =N('محمد زبون'!H16) -> 0 | K13: =N('محمد زبون'!I16) -> 165
A14: محمد زبون | B14: ='محمد زبون'!C17 -> 46321 | C14: ='محمد زبون'!D17 -> تفاح سلة | D14: تفاح سلة | E14: بضاعة | F14: =IF('محمد زبون'!E17="","",'محمد زبون'!E17) -> 1 | G14: =IF('محمد زبون'!F17="","",'محمد زبون'!F17) -> 55 | H14: =IF(F14="","",ROUND(F14*G14,2)) -> 55 | I14: =IF(F14="","",ROUND(H14*IF(N('محمد زبون'!G17)>1,'محمد زبون'!G17-1,0),2)) -> 0 | J14: =N('محمد زبون'!H17) -> 55 | K14: =N('محمد زبون'!I17) -> 0
A15: محمد زبون | B15: ='محمد زبون'!C18 -> 46324 | C15: ='محمد زبون'!D18 -> سداد | E15: سداد | F15: =IF('محمد زبون'!E18="","",'محمد زبون'!E18) | G15: =IF('محمد زبون'!F18="","",'محمد زبون'!F18) | H15: =IF(F15="","",ROUND(F15*G15,2)) | I15: =IF(F15="","",ROUND(H15*IF(N('محمد زبون'!G18)>1,'محمد زبون'!G18-1,0),2)) | J15: =N('محمد زبون'!H18) -> 0 | K15: =N('محمد زبون'!I18) -> 55
A16: فضل | B16: =فضل!C7 -> 46321 | C16: =فضل!D7 -> افندي | D16: افندي | E16: بضاعة | F16: =IF(فضل!E7="","",فضل!E7) -> 1 | G16: =IF(فضل!F7="","",فضل!F7) -> 90 | H16: =IF(F16="","",ROUND(F16*G16,2)) -> 90 | I16: =IF(F16="","",ROUND(H16*IF(N(فضل!G7)>1,فضل!G7-1,0),2)) -> 0 | J16: =N(فضل!H7) -> 90 | K16: =N(فضل!I7) -> 0
A17: فضل | B17: =فضل!C8 -> 46324 | C17: =فضل!D8 -> سداد | E17: سداد | F17: =IF(فضل!E8="","",فضل!E8) | G17: =IF(فضل!F8="","",فضل!F8) | H17: =IF(F17="","",ROUND(F17*G17,2)) | I17: =IF(F17="","",ROUND(H17*IF(N(فضل!G8)>1,فضل!G8-1,0),2)) | J17: =N(فضل!H8) -> 0 | K17: =N(فضل!I8) -> 90
A18: قصي جابر | B18: ='قصي جابر'!C7 -> 46297 | C18: ='قصي جابر'!D7 -> فراولة | D18: فراولة | E18: بضاعة | F18: =IF('قصي جابر'!E7="","",'قصي جابر'!E7) -> 20 | G18: =IF('قصي جابر'!F7="","",'قصي جابر'!F7) -> 110 | H18: =IF(F18="","",ROUND(F18*G18,2)) -> 2200 | I18: =IF(F18="","",ROUND(H18*IF(N('قصي جابر'!G7)>1,'قصي جابر'!G7-1,0),2)) -> 0 | J18: =N('قصي جابر'!H7) -> 2200 | K18: =N('قصي جابر'!I7) -> 0
A19: قصي جابر | B19: ='قصي جابر'!C8 -> 46298 | C19: ='قصي جابر'!D8 -> سداد | E19: سداد | F19: =IF('قصي جابر'!E8="","",'قصي جابر'!E8) | G19: =IF('قصي جابر'!F8="","",'قصي جابر'!F8) | H19: =IF(F19="","",ROUND(F19*G19,2)) | I19: =IF(F19="","",ROUND(H19*IF(N('قصي جابر'!G8)>1,'قصي جابر'!G8-1,0),2)) | J19: =N('قصي جابر'!H8) -> 0 | K19: =N('قصي جابر'!I8) -> 2200
A20: قصي جابر | B20: ='قصي جابر'!C9 -> 46303 | C20: ='قصي جابر'!D9 -> فراولة | D20: فراولة | E20: بضاعة | F20: =IF('قصي جابر'!E9="","",'قصي جابر'!E9) -> 10 | G20: =IF('قصي جابر'!F9="","",'قصي جابر'!F9) -> 125 | H20: =IF(F20="","",ROUND(F20*G20,2)) -> 1250 | I20: =IF(F20="","",ROUND(H20*IF(N('قصي جابر'!G9)>1,'قصي جابر'!G9-1,0),2)) -> 0 | J20: =N('قصي جابر'!H9) -> 1250 | K20: =N('قصي جابر'!I9) -> 0
A21: قصي جابر | B21: ='قصي جابر'!C10 -> 46308 | C21: ='قصي جابر'!D10 -> سداد | E21: سداد | F21: =IF('قصي جابر'!E10="","",'قصي جابر'!E10) | G21: =IF('قصي جابر'!F10="","",'قصي جابر'!F10) | H21: =IF(F21="","",ROUND(F21*G21,2)) | I21: =IF(F21="","",ROUND(H21*IF(N('قصي جابر'!G10)>1,'قصي جابر'!G10-1,0),2)) | J21: =N('قصي جابر'!H10) -> 0 | K21: =N('قصي جابر'!I10) -> 1250
A22: قصي جابر | B22: ='قصي جابر'!C11 -> 46317 | C22: ='قصي جابر'!D11 -> فراولة | D22: فراولة | E22: بضاعة | F22: =IF('قصي جابر'!E11="","",'قصي جابر'!E11) -> 20 | G22: =IF('قصي جابر'!F11="","",'قصي جابر'!F11) -> 128 | H22: =IF(F22="","",ROUND(F22*G22,2)) -> 2560 | I22: =IF(F22="","",ROUND(H22*IF(N('قصي جابر'!G11)>1,'قصي جابر'!G11-1,0),2)) -> 0 | J22: =N('قصي جابر'!H11) -> 2560 | K22: =N('قصي جابر'!I11) -> 0
A23: قصي جابر | B23: ='قصي جابر'!C12 -> 46319 | C23: ='قصي جابر'!D12 -> فراولة | D23: فراولة | E23: بضاعة | F23: =IF('قصي جابر'!E12="","",'قصي جابر'!E12) -> 12 | G23: =IF('قصي جابر'!F12="","",'قصي جابر'!F12) -> 130 | H23: =IF(F23="","",ROUND(F23*G23,2)) -> 1560 | I23: =IF(F23="","",ROUND(H23*IF(N('قصي جابر'!G12)>1,'قصي جابر'!G12-1,0),2)) -> 0 | J23: =N('قصي جابر'!H12) -> 1560 | K23: =N('قصي جابر'!I12) -> 0
A24: قصي جابر | B24: ='قصي جابر'!C13 -> 46323 | C24: ='قصي جابر'!D13 -> سداد دفعه | E24: سداد | F24: =IF('قصي جابر'!E13="","",'قصي جابر'!E13) | G24: =IF('قصي جابر'!F13="","",'قصي جابر'!F13) | H24: =IF(F24="","",ROUND(F24*G24,2)) | I24: =IF(F24="","",ROUND(H24*IF(N('قصي جابر'!G13)>1,'قصي جابر'!G13-1,0),2)) | J24: =N('قصي جابر'!H13) -> 0 | K24: =N('قصي جابر'!I13) -> 1000
A25: قصي جابر | B25: ='قصي جابر'!C14 -> 46324 | C25: ='قصي جابر'!D14 -> فراولة | D25: فراولة | E25: بضاعة | F25: =IF('قصي جابر'!E14="","",'قصي جابر'!E14) -> 20 | G25: =IF('قصي جابر'!F14="","",'قصي جابر'!F14) -> 125 | H25: =IF(F25="","",ROUND(F25*G25,2)) -> 2500 | I25: =IF(F25="","",ROUND(H25*IF(N('قصي جابر'!G14)>1,'قصي جابر'!G14-1,0),2)) -> 0 | J25: =N('قصي جابر'!H14) -> 2500 | K25: =N('قصي جابر'!I14) -> 0
A26: قصي جابر | B26: ='قصي جابر'!C15 -> 46325 | C26: ='قصي جابر'!D15 -> سداد دفعه | E26: سداد | F26: =IF('قصي جابر'!E15="","",'قصي جابر'!E15) | G26: =IF('قصي جابر'!F15="","",'قصي جابر'!F15) | H26: =IF(F26="","",ROUND(F26*G26,2)) | I26: =IF(F26="","",ROUND(H26*IF(N('قصي جابر'!G15)>1,'قصي جابر'!G15-1,0),2)) | J26: =N('قصي جابر'!H15) -> 0 | K26: =N('قصي جابر'!I15) -> 1000
A27: مصنع امداد | B27: ='مصنع امداد'!C7 -> 46298 | C27: ='مصنع امداد'!D7 -> بخاره تركي | D27: بخاره تركي | E27: بضاعة | F27: =IF('مصنع امداد'!E7="","",'مصنع امداد'!E7) -> 15 | G27: =IF('مصنع امداد'!F7="","",'مصنع امداد'!F7) -> 21 | H27: =IF(F27="","",ROUND(F27*G27,2)) -> 315 | I27: =IF(F27="","",ROUND(H27*IF(N('مصنع امداد'!G7)>1,'مصنع امداد'!G7-1,0),2)) -> 47.25 | J27: =N('مصنع امداد'!H7) -> 362.25 | K27: =N('مصنع امداد'!I7) -> 0
A28: مصنع امداد | B28: ='مصنع امداد'!C8 -> 46300 | C28: ='مصنع امداد'!D8 -> افوكادو | D28: افوكادو | E28: بضاعة | F28: =IF('مصنع امداد'!E8="","",'مصنع امداد'!E8) -> 20 | G28: =IF('مصنع امداد'!F8="","",'مصنع امداد'!F8) -> 33.5 | H28: =IF(F28="","",ROUND(F28*G28,2)) -> 670 | I28: =IF(F28="","",ROUND(H28*IF(N('مصنع امداد'!G8)>1,'مصنع امداد'!G8-1,0),2)) -> 100.5 | J28: =N('مصنع امداد'!H8) -> 770.5 | K28: =N('مصنع امداد'!I8) -> 0
A29: مصنع امداد | B29: ='مصنع امداد'!C9 -> 46300 | C29: ='مصنع امداد'!D9 -> سداد مقاصه مع جبار البيشي | E29: مقاصة | F29: =IF('مصنع امداد'!E9="","",'مصنع امداد'!E9) | G29: =IF('مصنع امداد'!F9="","",'مصنع امداد'!F9) | H29: =IF(F29="","",ROUND(F29*G29,2)) | I29: =IF(F29="","",ROUND(H29*IF(N('مصنع امداد'!G9)>1,'مصنع امداد'!G9-1,0),2)) | J29: =N('مصنع امداد'!H9) -> 0 | K29: =N('مصنع امداد'!I9) -> 362.25
A30: مصنع امداد | B30: ='مصنع امداد'!C10 -> 46300 | C30: ='مصنع امداد'!D10 -> سداد مقاصه مع جبار البيشي | E30: مقاصة | F30: =IF('مصنع امداد'!E10="","",'مصنع امداد'!E10) | G30: =IF('مصنع امداد'!F10="","",'مصنع امداد'!F10) | H30: =IF(F30="","",ROUND(F30*G30,2)) | I30: =IF(F30="","",ROUND(H30*IF(N('مصنع امداد'!G10)>1,'مصنع امداد'!G10-1,0),2)) | J30: =N('مصنع امداد'!H10) -> 0 | K30: =N('مصنع امداد'!I10) -> 770.5
A31: مصنع امداد | B31: ='مصنع امداد'!C11 -> 46320 | C31: ='مصنع امداد'!D11 -> فراولة | D31: فراولة | E31: بضاعة | F31: =IF('مصنع امداد'!E11="","",'مصنع امداد'!E11) -> 10 | G31: =IF('مصنع امداد'!F11="","",'مصنع امداد'!F11) -> 130 | H31: =IF(F31="","",ROUND(F31*G31,2)) -> 1300 | I31: =IF(F31="","",ROUND(H31*IF(N('مصنع امداد'!G11)>1,'مصنع امداد'!G11-1,0),2)) -> 0 | J31: =N('مصنع امداد'!H11) -> 1300 | K31: =N('مصنع امداد'!I11) -> 0
A32: هارون | B32: =هارون!C7 -> 46320 | C32: =هارون!D7 -> فراولة | D32: فراولة | E32: بضاعة | F32: =IF(هارون!E7="","",هارون!E7) -> 40 | G32: =IF(هارون!F7="","",هارون!F7) -> 135 | H32: =IF(F32="","",ROUND(F32*G32,2)) -> 5400 | I32: =IF(F32="","",ROUND(H32*IF(N(هارون!G7)>1,هارون!G7-1,0),2)) -> 0 | J32: =N(هارون!H7) -> 5400 | K32: =N(هارون!I7) -> 0
A33: هارون | B33: =هارون!C8 -> 46321 | C33: =هارون!D8 -> سداد دفعه | E33: سداد | F33: =IF(هارون!E8="","",هارون!E8) | G33: =IF(هارون!F8="","",هارون!F8) | H33: =IF(F33="","",ROUND(F33*G33,2)) | I33: =IF(F33="","",ROUND(H33*IF(N(هارون!G8)>1,هارون!G8-1,0),2)) | J33: =N(هارون!H8) -> 0 | K33: =N(هارون!I8) -> 4000
A34: ثمار مجني | B34: =مجني!C7 -> 46297 | C34: =مجني!D7 -> فراولة | D34: فراولة | E34: بضاعة | F34: =IF(مجني!E7="","",مجني!E7) -> 40 | G34: =IF(مجني!F7="","",مجني!F7) -> 98 | H34: =IF(F34="","",ROUND(F34*G34,2)) -> 3920 | I34: =IF(F34="","",ROUND(H34*IF(N(مجني!G7)>1,مجني!G7-1,0),2)) -> 588 | J34: =N(مجني!H7) -> 4508 | K34: =N(مجني!I7) -> 0
A35: ثمار مجني | B35: =مجني!C8 -> 46300 | C35: =مجني!D8 -> مقاصة مع جبار البيشي | E35: مقاصة | F35: =IF(مجني!E8="","",مجني!E8) | G35: =IF(مجني!F8="","",مجني!F8) | H35: =IF(F35="","",ROUND(F35*G35,2)) | I35: =IF(F35="","",ROUND(H35*IF(N(مجني!G8)>1,مجني!G8-1,0),2)) | J35: =N(مجني!H8) -> 0 | K35: =N(مجني!I8) -> 4508
A36: علاء | B36: =علاء!C7 -> 46308 | C36: =علاء!D7 -> رمان وسط | D36: رمان وسط | E36: بضاعة | F36: =IF(علاء!E7="","",علاء!E7) -> 20 | G36: =IF(علاء!F7="","",علاء!F7) -> 18 | H36: =IF(F36="","",ROUND(F36*G36,2)) -> 360 | I36: =IF(F36="","",ROUND(H36*IF(N(علاء!G7)>1,علاء!G7-1,0),2)) -> 0 | J36: =N(علاء!H7) -> 360 | K36: =N(علاء!I7) -> 0
A37: علاء | B37: =علاء!C8 -> 46309 | C37: =علاء!D8 -> سداد | E37: سداد | F37: =IF(علاء!E8="","",علاء!E8) | G37: =IF(علاء!F8="","",علاء!F8) | H37: =IF(F37="","",ROUND(F37*G37,2)) | I37: =IF(F37="","",ROUND(H37*IF(N(علاء!G8)>1,علاء!G8-1,0),2)) | J37: =N(علاء!H8) -> 0 | K37: =N(علاء!I8) -> 360
A38: علاء | B38: =علاء!C9 -> 46311 | C38: =علاء!D9 -> تفاح سلة | D38: تفاح سلة | E38: بضاعة | F38: =IF(علاء!E9="","",علاء!E9) -> 10 | G38: =IF(علاء!F9="","",علاء!F9) -> 59 | H38: =IF(F38="","",ROUND(F38*G38,2)) -> 590 | I38: =IF(F38="","",ROUND(H38*IF(N(علاء!G9)>1,علاء!G9-1,0),2)) -> 0 | J38: =N(علاء!H9) -> 590 | K38: =N(علاء!I9) -> 0
A39: علاء | B39: =علاء!C10 -> 46313 | C39: =علاء!D10 -> سداد | E39: سداد | F39: =IF(علاء!E10="","",علاء!E10) | G39: =IF(علاء!F10="","",علاء!F10) | H39: =IF(F39="","",ROUND(F39*G39,2)) | I39: =IF(F39="","",ROUND(H39*IF(N(علاء!G10)>1,علاء!G10-1,0),2)) | J39: =N(علاء!H10) -> 0 | K39: =N(علاء!I10) -> 590
A40: علاء | B40: =علاء!C11 -> 46315 | C40: =علاء!D11 -> رمان وسط | D40: رمان وسط | E40: بضاعة | F40: =IF(علاء!E11="","",علاء!E11) -> 40 | G40: =IF(علاء!F11="","",علاء!F11) -> 19 | H40: =IF(F40="","",ROUND(F40*G40,2)) -> 760 | I40: =IF(F40="","",ROUND(H40*IF(N(علاء!G11)>1,علاء!G11-1,0),2)) -> 0 | J40: =N(علاء!H11) -> 760 | K40: =N(علاء!I11) -> 0
...

Sheet تحليل الأصناف
A1: تحليل المبيعات حسب الصنف
A2: يشمل حركات البضاعة في الاتجاه الطبيعي فقط (نوع الحركة = بضاعة) من سجل الحركات. الأسماء موحّدة (مثال: نكترين/نكتارين).
A3: # | B3: الصنف | C3: الكمية (صندوق) | D3: عدد الحركات | E3: القيمة قبل الضريبة | F3: الضريبة | G3: الإجمالي | H3: متوسط السعر | I3: أقل سعر | J3: أعلى سعر | K3: % من الإجمالي
A4: 1 | B4: فراولة | C4: =SUMIFS('سجل الحركات'!$F$4:$F$323,'سجل الحركات'!$D$4:$D$323,B4,'سجل الحركات'!$E$4:$E$323,"بضاعة") -> 559 | D4: =COUNTIFS('سجل الحركات'!$D$4:$D$323,B4,'سجل الحركات'!$E$4:$E$323,"بضاعة") -> 36 | E4: =SUMIFS('سجل الحركات'!$H$4:$H$323,'سجل الحركات'!$D$4:$D$323,B4,'سجل الحركات'!$E$4:$E$323,"بضاعة") -> 68383.3 | F4: =SUMIFS('سجل الحركات'!$I$4:$I$323,'سجل الحركات'!$D$4:$D$323,B4,'سجل الحركات'!$E$4:$E$323,"بضاعة") -> 2111.6 | G4: =E4+F4 -> 70494.9 | H4: =IF(C4=0,"",E4/C4) -> 122.33148 | I4: =_xlfn.MINIFS('سجل الحركات'!$G$4:$G$323,'سجل الحركات'!$D$4:$D$323,B4,'سجل الحركات'!$E$4:$E$323,"بضاعة") -> 98 | J4: =_xlfn.MAXIFS('سجل الحركات'!$G$4:$G$323,'سجل الحركات'!$D$4:$D$323,B4,'سجل الحركات'!$E$4:$E$323,"بضاعة") -> 140 | K4: =IF($G$40=0,"",G4/$G$40) -> 0.26529347
A5: 2 | B5: افندي | C5: =SUMIFS('سجل الحركات'!$F$4:$F$323,'سجل الحركات'!$D$4:$D$323,B5,'سجل الحركات'!$E$4:$E$323,"بضاعة") -> 409 | D5: =COUNTIFS('سجل الحركات'!$D$4:$D$323,B5,'سجل الحركات'!$E$4:$E$323,"بضاعة") -> 10 | E5: =SUMIFS('سجل الحركات'!$H$4:$H$323,'سجل الحركات'!$D$4:$D$323,B5,'سجل الحركات'!$E$4:$E$323,"بضاعة") -> 28081 | F5: =SUMIFS('سجل الحركات'!$I$4:$I$323,'سجل الحركات'!$D$4:$D$323,B5,'سجل الحركات'!$E$4:$E$323,"بضاعة") -> 1894.5 | G5: =E5+F5 -> 29975.5 | H5: =IF(C5=0,"",E5/C5) -> 68.657702 | I5: =_xlfn.MINIFS('سجل الحركات'!$G$4:$G$323,'سجل الحركات'!$D$4:$D$323,B5,'سجل الحركات'!$E$4:$E$323,"بضاعة") -> 45 | J5: =_xlfn.MAXIFS('سجل الحركات'!$G$4:$G$323,'سجل الحركات'!$D$4:$D$323,B5,'سجل الحركات'!$E$4:$E$323,"بضاعة") -> 90 | K5: =IF($G$40=0,"",G5/$G$40) -> 0.1128068
A6: 3 | B6: عنب تركي | C6: =SUMIFS('سجل الحركات'!$F$4:$F$323,'سجل الحركات'!$D$4:$D$323,B6,'سجل الحركات'!$E$4:$E$323,"بضاعة") -> 334 | D6: =COUNTIFS('سجل الحركات'!$D$4:$D$323,B6,'سجل الحركات'!$E$4:$E$323,"بضاعة") -> 11 | E6: =SUMIFS('سجل الحركات'!$H$4:$H$323,'سجل الحركات'!$D$4:$D$323,B6,'سجل الحركات'!$E$4:$E$323,"بضاعة") -> 21068 | F6: =SUMIFS('سجل الحركات'!$I$4:$I$323,'سجل الحركات'!$D$4:$D$323,B6,'سجل الحركات'!$E$4:$E$323,"بضاعة") -> 2976.6 | G6: =E6+F6 -> 24044.6 | H6: =IF(C6=0,"",E6/C6) -> 63.077844 | I6: =_xlfn.MINIFS('سجل الحركات'!$G$4:$G$323,'سجل الحركات'!$D$4:$D$323,B6,'سجل الحركات'!$E$4:$E$323,"بضاعة") -> 53 | J6: =_xlfn.MAXIFS('سجل الحركات'!$G$4:$G$323,'سجل الحركات'!$D$4:$D$323,B6,'سجل الحركات'!$E$4:$E$323,"بضاعة") -> 78 | K6: =IF($G$40=0,"",G6/$G$40) -> 0.090487047
A7: 4 | B7: كيوي | C7: =SUMIFS('سجل الحركات'!$F$4:$F$323,'سجل الحركات'!$D$4:$D$323,B7,'سجل الحركات'!$E$4:$E$323,"بضاعة") -> 534 | D7: =COUNTIFS('سجل الحركات'!$D$4:$D$323,B7,'سجل الحركات'!$E$4:$E$323,"بضاعة") -> 14 | E7: =SUMIFS('سجل الحركات'!$H$4:$H$323,'سجل الحركات'!$D$4:$D$323,B7,'سجل الحركات'!$E$4:$E$323,"بضاعة") -> 18661 | F7: =SUMIFS('سجل الحركات'!$I$4:$I$323,'سجل الحركات'!$D$4:$D$323,B7,'سجل الحركات'!$E$4:$E$323,"بضاعة") -> 2716.8 | G7: =E7+F7 -> 21377.8 | H7: =IF(C7=0,"",E7/C7) -> 34.945693 | I7: =_xlfn.MINIFS('سجل الحركات'!$G$4:$G$323,'سجل الحركات'!$D$4:$D$323,B7,'سجل الحركات'!$E$4:$E$323,"بضاعة") -> 33 | J7: =_xlfn.MAXIFS('سجل الحركات'!$G$4:$G$323,'سجل الحركات'!$D$4:$D$323,B7,'سجل الحركات'!$E$4:$E$323,"بضاعة") -> 45 | K7: =IF($G$40=0,"",G7/$G$40) -> 0.080451078
A8: 5 | B8: رمان وسط | C8: =SUMIFS('سجل الحركات'!$F$4:$F$323,'سجل الحركات'!$D$4:$D$323,B8,'سجل الحركات'!$E$4:$E$323,"بضاعة") -> 1019 | D8: =COUNTIFS('سجل الحركات'!$D$4:$D$323,B8,'سجل الحركات'!$E$4:$E$323,"بضاعة") -> 20 | E8: =SUMIFS('سجل الحركات'!$H$4:$H$323,'سجل الحركات'!$D$4:$D$323,B8,'سجل الحركات'!$E$4:$E$323,"بضاعة") -> 17360 | F8: =SUMIFS('سجل الحركات'!$I$4:$I$323,'سجل الحركات'!$D$4:$D$323,B8,'سجل الحركات'!$E$4:$E$323,"بضاعة") -> 1653.3 | G8: =E8+F8 -> 19013.3 | H8: =IF(C8=0,"",E8/C8) -> 17.03631 | I8: =_xlfn.MINIFS('سجل الحركات'!$G$4:$G$323,'سجل الحركات'!$D$4:$D$323,B8,'سجل الحركات'!$E$4:$E$323,"بضاعة") -> 16 | J8: =_xlfn.MAXIFS('سجل الحركات'!$G$4:$G$323,'سجل الحركات'!$D$4:$D$323,B8,'سجل الحركات'!$E$4:$E$323,"بضاعة") -> 20 | K8: =IF($G$40=0,"",G8/$G$40) -> 0.071552755
A9: 6 | B9: كاكا لبناني | C9: =SUMIFS('سجل الحركات'!$F$4:$F$323,'سجل الحركات'!$D$4:$D$323,B9,'سجل الحركات'!$E$4:$E$323,"بضاعة") -> 680 | D9: =COUNTIFS('سجل الحركات'!$D$4:$D$323,B9,'سجل الحركات'!$E$4:$E$323,"بضاعة") -> 10 | E9: =SUMIFS('سجل الحركات'!$H$4:$H$323,'سجل الحركات'!$D$4:$D$323,B9,'سجل الحركات'!$E$4:$E$323,"بضاعة") -> 13562 | F9: =SUMIFS('سجل الحركات'!$I$4:$I$323,'سجل الحركات'!$D$4:$D$323,B9,'سجل الحركات'!$E$4:$E$323,"بضاعة") -> 267.75 | G9: =E9+F9 -> 13829.75 | H9: =IF(C9=0,"",E9/C9) -> 19.944118 | I9: =_xlfn.MINIFS('سجل الحركات'!$G$4:$G$323,'سجل الحركات'!$D$4:$D$323,B9,'سجل الحركات'!$E$4:$E$323,"بضاعة") -> 17 | J9: =_xlfn.MAXIFS('سجل الحركات'!$G$4:$G$323,'سجل الحركات'!$D$4:$D$323,B9,'سجل الحركات'!$E$4:$E$323,"بضاعة") -> 25 | K9: =IF($G$40=0,"",G9/$G$40) -> 0.0520455
A10: 7 | B10: برتقال عصير | C10: =SUMIFS('سجل الحركات'!$F$4:$F$323,'سجل الحركات'!$D$4:$D$323,B10,'سجل الحركات'!$E$4:$E$323,"بضاعة") -> 159 | D10: =COUNTIFS('سجل الحركات'!$D$4:$D$323,B10,'سجل الحركات'!$E$4:$E$323,"بضاعة") -> 2 | E10: =SUMIFS('سجل الحركات'!$H$4:$H$323,'سجل الحركات'!$D$4:$D$323,B10,'سجل الحركات'!$E$4:$E$323,"بضاعة") -> 13271 | F10: =SUMIFS('سجل الحركات'!$I$4:$I$323,'سجل الحركات'!$D$4:$D$323,B10,'سجل الحركات'!$E$4:$E$323,"بضاعة") -> 1990.65 | G10: =E10+F10 -> 15261.65 | H10: =IF(C10=0,"",E10/C10) -> 83.465409 | I10: =_xlfn.MINIFS('سجل الحركات'!$G$4:$G$323,'سجل الحركات'!$D$4:$D$323,B10,'سجل الحركات'!$E$4:$E$323,"بضاعة") -> 78 | J10: =_xlfn.MAXIFS('سجل الحركات'!$G$4:$G$323,'سجل الحركات'!$D$4:$D$323,B10,'سجل الحركات'!$E$4:$E$323,"بضاعة") -> 89 | K10: =IF($G$40=0,"",G10/$G$40) -> 0.05743417
A11: 8 | B11: رمان مصري | C11: =SUMIFS('سجل الحركات'!$F$4:$F$323,'سجل الحركات'!$D$4:$D$323,B11,'سجل الحركات'!$E$4:$E$323,"بضاعة") -> 1016 | D11: =COUNTIFS('سجل الحركات'!$D$4:$D$323,B11,'سجل الحركات'!$E$4:$E$323,"بضاعة") -> 15 | E11: =SUMIFS('سجل الحركات'!$H$4:$H$323,'سجل الحركات'!$D$4:$D$323,B11,'سجل الحركات'!$E$4:$E$323,"بضاعة") -> 13101 | F11: =SUMIFS('سجل الحركات'!$I$4:$I$323,'سجل الحركات'!$D$4:$D$323,B11,'سجل الحركات'!$E$4:$E$323,"بضاعة") -> 144.86 | G11: =E11+F11 -> 13245.86 | H11: =IF(C11=0,"",E11/C11) -> 12.894685 | I11: =_xlfn.MINIFS('سجل الحركات'!$G$4:$G$323,'سجل الحركات'!$D$4:$D$323,B11,'سجل الحركات'!$E$4:$E$323,"بضاعة") -> 10.435 | J11: =_xlfn.MAXIFS('سجل الحركات'!$G$4:$G$323,'سجل الحركات'!$D$4:$D$323,B11,'سجل الحركات'!$E$4:$E$323,"بضاعة") -> 15 | K11: =IF($G$40=0,"",G11/$G$40) -> 0.049848147
A12: 9 | B12: ليمون تركي | C12: =SUMIFS('سجل الحركات'!$F$4:$F$323,'سجل الحركات'!$D$4:$D$323,B12,'سجل الحركات'!$E$4:$E$323,"بضاعة") -> 270 | D12: =COUNTIFS('سجل الحركات'!$D$4:$D$323,B12,'سجل الحركات'!$E$4:$E$323,"بضاعة") -> 3 | E12: =SUMIFS('سجل الحركات'!$H$4:$H$323,'سجل الحركات'!$D$4:$D$323,B12,'سجل الحركات'!$E$4:$E$323,"بضاعة") -> 9700 | F12: =SUMIFS('سجل الحركات'!$I$4:$I$323,'سجل الحركات'!$D$4:$D$323,B12,'سجل الحركات'!$E$4:$E$323,"بضاعة") -> 1455 | G12: =E12+F12 -> 11155 | H12: =IF(C12=0,"",E12/C12) -> 35.925926 | I12: =_xlfn.MINIFS('سجل الحركات'!$G$4:$G$323,'سجل الحركات'!$D$4:$D$323,B12,'سجل الحركات'!$E$4:$E$323,"بضاعة") -> 30 | J12: =_xlfn.MAXIFS('سجل الحركات'!$G$4:$G$323,'سجل الحركات'!$D$4:$D$323,B12,'سجل الحركات'!$E$4:$E$323,"بضاعة") -> 50 | K12: =IF($G$40=0,"",G12/$G$40) -> 0.041979613
A13: 10 | B13: كعك علبة | C13: =SUMIFS('سجل الحركات'!$F$4:$F$323,'سجل الحركات'!$D$4:$D$323,B13,'سجل الحركات'!$E$4:$E$323,"بضاعة") -> 190 | D13: =COUNTIFS('سجل الحركات'!$D$4:$D$323,B13,'سجل الحركات'!$E$4:$E$323,"بضاعة") -> 5 | E13: =SUMIFS('سجل الحركات'!$H$4:$H$323,'سجل الحركات'!$D$4:$D$323,B13,'سجل الحركات'!$E$4:$E$323,"بضاعة") -> 7210 | F13: =SUMIFS('سجل الحركات'!$I$4:$I$323,'سجل الحركات'!$D$4:$D$323,B13,'سجل الحركات'!$E$4:$E$323,"بضاعة") -> 367.5 | G13: =E13+F13 -> 7577.5 | H13: =IF(C13=0,"",E13/C13) -> 37.947368 | I13: =_xlfn.MINIFS('سجل الحركات'!$G$4:$G$323,'سجل الحركات'!$D$4:$D$323,B13,'سجل الحركات'!$E$4:$E$323,"بضاعة") -> 35 | J13: =_xlfn.MAXIFS('سجل الحركات'!$G$4:$G$323,'سجل الحركات'!$D$4:$D$323,B13,'سجل الحركات'!$E$4:$E$323,"بضاعة") -> 40 | K13: =IF($G$40=0,"",G13/$G$40) -> 0.028516407
A14: 11 | B14: بخارة تركي | C14: =SUMIFS('سجل الحركات'!$F$4:$F$323,'سجل الحركات'!$D$4:$D$323,B14,'سجل الحركات'!$E$4:$E$323,"بضاعة") -> 280 | D14: =COUNTIFS('سجل الحركات'!$D$4:$D$323,B14,'سجل الحركات'!$E$4:$E$323,"بضاعة") -> 2 | E14: =SUMIFS('سجل الحركات'!$H$4:$H$323,'سجل الحركات'!$D$4:$D$323,B14,'سجل الحركات'!$E$4:$E$323,"بضاعة") -> 5920 | F14: =SUMIFS('سجل الحركات'!$I$4:$I$323,'سجل الحركات'!$D$4:$D$323,B14,'سجل الحركات'!$E$4:$E$323,"بضاعة") -> 850.5 | G14: =E14+F14 -> 6770.5 | H14: =IF(C14=0,"",E14/C14) -> 21.142857 | I14: =_xlfn.MINIFS('سجل الحركات'!$G$4:$G$323,'سجل الحركات'!$D$4:$D$323,B14,'سجل الحركات'!$E$4:$E$323,"بضاعة") -> 21 | J14: =_xlfn.MAXIFS('سجل الحركات'!$G$4:$G$323,'سجل الحركات'!$D$4:$D$323,B14,'سجل الحركات'!$E$4:$E$323,"بضاعة") -> 25 | K14: =IF($G$40=0,"",G14/$G$40) -> 0.025479424
A15: 12 | B15: تفاح سلة | C15: =SUMIFS('سجل الحركات'!$F$4:$F$323,'سجل الحركات'!$D$4:$D$323,B15,'سجل الحركات'!$E$4:$E$323,"بضاعة") -> 83 | D15: =COUNTIFS('سجل الحركات'!$D$4:$D$323,B15,'سجل الحركات'!$E$4:$E$323,"بضاعة") -> 13 | E15: =SUMIFS('سجل الحركات'!$H$4:$H$323,'سجل الحركات'!$D$4:$D$323,B15,'سجل الحركات'!$E$4:$E$323,"بضاعة") -> 4560 | F15: =SUMIFS('سجل الحركات'!$I$4:$I$323,'سجل الحركات'!$D$4:$D$323,B15,'سجل الحركات'!$E$4:$E$323,"بضاعة") -> 0 | G15: =E15+F15 -> 4560 | H15: =IF(C15=0,"",E15/C15) -> 54.939759 | I15: =_xlfn.MINIFS('سجل الحركات'!$G$4:$G$323,'سجل الحركات'!$D$4:$D$323,B15,'سجل الحركات'!$E$4:$E$323,"بضاعة") -> 52 | J15: =_xlfn.MAXIFS('سجل الحركات'!$G$4:$G$323,'سجل الحركات'!$D$4:$D$323,B15,'سجل الحركات'!$E$4:$E$323,"بضاعة") -> 60 | K15: =IF($G$40=0,"",G15/$G$40) -> 0.017160649
... A39: 36 | B39: بطاطا | C39: =SUMIFS('سجل الحركات'!$F$4:$F$323,'سجل الحركات'!$D$4:$D$323,B39,'سجل الحركات'!$E$4:$E$323,"بضاعة") -> 5 | D39: =COUNTIFS('سجل الحركات'!$D$4:$D$323,B39,'سجل الحركات'!$E$4:$E$323,"بضاعة") -> 1 | E39: =SUMIFS('سجل الحركات'!$H$4:$H$323,'سجل الحركات'!$D$4:$D$323,B39,'سجل الحركات'!$E$4:$E$323,"بضاعة") -> 50 | F39: =SUMIFS('سجل الحركات'!$I$4:$I$323,'سجل الحركات'!$D$4:$D$323,B39,'سجل الحركات'!$E$4:$E$323,"بضاعة") -> 0 | G39: =E39+F39 -> 50 | H39: =IF(C39=0,"",E39/C39) -> 10 | I39: =_xlfn.MINIFS('سجل الحركات'!$G$4:$G$323,'سجل الحركات'!$D$4:$D$323,B39,'سجل الحركات'!$E$4:$E$323,"بضاعة") -> 10 | J39: =_xlfn.MAXIFS('سجل الحركات'!$G$4:$G$323,'سجل الحركات'!$D$4:$D$323,B39,'سجل الحركات'!$E$4:$E$323,"بضاعة") -> 10 | K39: =IF($G$40=0,"",G39/$G$40) -> 0.00018816501
B40: الإجمالي | C40: =SUM(C4:C39) -> 6795 | D40: =SUM(D4:D39) -> 194 | E40: =SUM(E4:E39) -> 246842.48 | F40: =SUM(F4:F39) -> 18881.74 | G40: =SUM(G4:G39) -> 265724.22

Sheet مطابقة المقاصات
A1: مطابقة الحوالات والمقاصات بين ملف الموردين وملف العملاء
A2: كل سداد تم بحوالة من عميل إلى مورد (أو بمقاصة) يجب أن يُسجَّل بنفس المبلغ في الحسابين. هذه الورقة قيم ثابتة لحظة التدقيق.
A3: التاريخ | B3: الملف | C3: الحساب | D3: البيان | E3: المبلغ | F3: الطرف المقابل | G3: ملف الطرف المقابل | H3: تاريخ القيد المقابل | I3: مبلغ القيد المقابل | J3: الفرق | K3: النتيجة
A4: 46303 | B4: الموردين | C4: البشري | D4: مقاصه مع رجب | E4: 2300 | F4: رجب | G4: - | K4: لا يوجد قيد مقاصة مقابل في حساب "رجب المصري" (إن كان هو المقصود)
A5: 46304 | B5: الموردين | C5: جبار البيشي | D5: مقاصه مع صادق مكه | E5: 8935.5 | F5: صادق مكه | G5: - | K5: لا يوجد حساب للطرف المقابل في الملفين
A6: 46308 | B6: الموردين | C6: جبار البيشي | D6: حوالة نقاوة بلس | E6: 5037 | F6: نقاوة بلس | G6: العملاء | H6: 46308 | I6: 3450 | J6: 1587 | K6: فرق في المبلغ
A7: 46299 | B7: الموردين | C7: جبار البيشي | D7: سداد حوالة مجني | E7: 4508 | F7: ثمار مجني | G7: العملاء | H7: 46300 | I7: 4508 | J7: 0 | K7: مطابق المبلغ — فرق تاريخ 1 يوم
A8: 46299 | B8: الموردين | C8: جبار البيشي | D8: سداد حوالة مصنع امداد | E8: 362.25 | F8: مصنع امداد | G8: العملاء | H8: 46300 | I8: 362.25 | J8: 0 | K8: مطابق المبلغ — فرق تاريخ 1 يوم
A9: 46300 | B9: الموردين | C9: جبار البيشي | D9: سداد فاتورة مصنع امداد افوكادو مقاصه | E9: 770.5 | F9: مصنع امداد | G9: العملاء | H9: 46300 | I9: 770.5 | J9: 0 | K9: مطابق
A10: 46301 | B10: الموردين | C10: جبار البيشي | D10: سداد مقاصه مع فاتورة أبو عجاج رمان | E10: 4048 | F10: أبو عجاج | G10: العملاء | H10: 46301 | I10: 4048 | J10: 0 | K10: مطابق
A11: 46301 | B11: الموردين | C11: عبر الإقليم | D11: سداد حوالة محيط دلتا | E11: 2769 | F11: محيط دلتا | G11: العملاء | H11: 46301 | I11: 2769 | J11: 0 | K11: مطابق
A12: 46306 | B12: الموردين | C12: جبار البيشي | D12: حوالة نقاوة بلس | E12: 7728 | F12: نقاوة بلس | G12: العملاء | H12: 46305 | I12: 7728 | J12: 0 | K12: مطابق المبلغ — فرق تاريخ 1 يوم
A13: 46309 | B13: الموردين | C13: عبر الإقليم | D13: سداد حوالة محيط دلتا /12871 | E13: 1400 | F13: محيط دلتا | G13: العملاء | H13: 46309 | I13: 1400 | J13: 0 | K13: مطابق
A14: 46313 | B14: الموردين | C14: جبار البيشي | D14: حوالة نقاوة بلس | E14: 2428 | F14: نقاوة بلس | G14: العملاء | H14: 46313 | I14: 2428 | J14: 0 | K14: مطابق
A15: 46315 | B15: الموردين | C15: جبار البيشي | D15: حوالة الحساني | E15: 6626.3 | F15: الحساني | G15: العملاء | H15: 46315 | I15: 6626.3 | J15: 0 | K15: مطابق
A16: 46317 | B16: الموردين | C16: جبار البيشي | D16: حوالة بنكية محمد عادل | E16: 3000 | F16: محمد عادل | G16: العملاء | H16: 46317 | I16: 3000 | J16: 0 | K16: مطابق
A17: 46320 | B17: الموردين | C17: جبار البيشي | D17: حوالة بنكية نقاوة بلس | E17: 7000 | F17: نقاوة بلس | G17: العملاء | H17: 46320 | I17: 7000 | J17: 0 | K17: مطابق
... A22: 46323 | B22: الموردين | C22: جبار البيشي | D22: حوالة بنكية نقاوة بلس | E22: 4326 | F22: نقاوة بلس | G22: العملاء | H22: 46323 | I22: 4326 | J22: 0 | K22: مطابق

Sheet ملاحظات التدقيق
A1: ملاحظات التدقيق والتصحيحات — ملف العملاء
A2: عالية = تؤثر على الرصيد وتحتاج متابعة فورية · متوسطة = خطأ تسجيل صُحح أو يحتاج تأكيد · منخفضة = تنسيق/هيكلة. عمود "القيمة الأصلية" يحفظ ما كان في الملف قبل التعديل.
B3: عالية | C3: =COUNTIF(D5:D2000,"عالية") -> 3 | D3: متوسطة | E3: =COUNTIF(D5:D2000,"متوسطة") -> 27 | F3: منخفضة | G3: =COUNTIF(D5:D2000,"منخفضة") -> 18
A4: # | B4: الحساب | C4: الخلية/الصف | D4: الخطورة | E4: التصنيف | F4: الملاحظة | G4: القيمة الأصلية | H4: الإجراء المتخذ
A5: 1 | B5: مطابقة | C5: - | D5: عالية | E5: مطابقة المقاصات | F5: جبار البيشي (الموردين) 09/10: "مقاصه مع صادق مكه" بمبلغ 8,935.50 — لا يوجد حساب للطرف المقابل في الملفين | H5: يرجى المطابقة مع الطرف وتصحيح أحد القيدين
A6: 2 | B6: مطابقة | C6: - | D6: عالية | E6: مطابقة المقاصات | F6: جبار البيشي (الموردين) 13/10: "حوالة نقاوة بلس" بمبلغ 5,037.00 — فرق في المبلغ (المسجل عند نقاوة بلس: 3,450.00، الفرق 1,587.00) | H6: يرجى المطابقة مع الطرف وتصحيح أحد القيدين
A7: 3 | B7: مطابقة | C7: - | D7: عالية | E7: مطابقة المقاصات | F7: البشري (الموردين) 08/10: "مقاصه مع رجب" بمبلغ 2,300.00 — لا يوجد قيد مقاصة مقابل في حساب "رجب المصري" (إن كان هو المقصود) | H7: يرجى المطابقة مع الطرف وتصحيح أحد القيدين
A8: 4 | B8: طيبات العصر | C8: 7 | D8: متوسطة | E8: اتجاه القيد | F8: بضاعة مسجلة في الدائن (عكس باقي الحركات) — غالباً بضاعة اشتريناها من هذا العميل أو مرتجع. أُبقيت كما هي؛ يرجى التأكيد. | G8: افوكادو 1140 | H8: بدون تغيير
A9: 5 | B9: سليم بنغالي | C9: 13 | D9: متوسطة | E9: اتجاه القيد | F9: بضاعة مسجلة في الدائن (عكس باقي الحركات) — غالباً بضاعة اشتريناها من هذا العميل أو مرتجع. أُبقيت كما هي؛ يرجى التأكيد. | G9: فراولة 1200 | H9: بدون تغيير
A10: 6 | B10: سليم بنغالي | C10: 16 | D10: متوسطة | E10: اتجاه القيد | F10: بضاعة مسجلة في الدائن (عكس باقي الحركات) — غالباً بضاعة اشتريناها من هذا العميل أو مرتجع. أُبقيت كما هي؛ يرجى التأكيد. | G10: فراولة 2340 | H10: بدون تغيير
A11: 7 | B11: سليم بنغالي | C11: 18 | D11: متوسطة | E11: اتجاه القيد | F11: سداد مسجل في المدين — يعني دفعة دفعناها لهذا العميل (مقابل بضاعة اشتريناها منه) . أُبقي كما هو؛ يرجى التأكيد. | G11: سداد دفعة 850 | H11: بدون تغيير
A12: 8 | B12: سليم بنغالي | C12: 19 | D12: متوسطة | E12: اتجاه القيد | F12: سداد مسجل في المدين — يعني دفعة دفعناها لهذا العميل (مقابل بضاعة اشتريناها منه) . أُبقي كما هو؛ يرجى التأكيد. | G12: سداد 150 | H12: بدون تغيير
A13: 9 | B13: سليم بنغالي | C13: 20 | D13: متوسطة | E13: اتجاه القيد | F13: سداد مسجل في المدين — يعني دفعة دفعناها لهذا العميل (مقابل بضاعة اشتريناها منه) . أُبقي كما هو؛ يرجى التأكيد. | G13: تم خصم من سليم 30 | H13: بدون تغيير
A14: 10 | B14: متجر منافس | C14: 17 | D14: متوسطة | E14: اتجاه القيد | F14: بضاعة مسجلة في الدائن (عكس باقي الحركات) — غالباً بضاعة اشتريناها من هذا العميل أو مرتجع. أُبقيت كما هي؛ يرجى التأكيد. | G14: اناناس خصم 375 | H14: بدون تغيير
A15: 11 | B15: متجر منافس | C15: 18 | D15: متوسطة | E15: اتجاه القيد | F15: بضاعة مسجلة في الدائن (عكس باقي الحركات) — غالباً بضاعة اشتريناها من هذا العميل أو مرتجع. أُبقيت كما هي؛ يرجى التأكيد. | G15: رمان خصم 14 | H15: بدون تغيير
A16: 12 | B16: عام | C16: - | D16: متوسطة | E16: تكرار حساب | F16: "عبدالرحمن قدري" له حساب في ملف الموردين وملف العملاء معاً — يُنصح بمتابعة صافي الرصيد بين الحسابين
A17: 13 | B17: قصي جابر | C17: C4:C6 | D17: متوسطة | E17: تواريخ | F17: 3 تاريخ مخزّن بالخطأ (Excel قلب اليوم والشهر فأصبحت التواريخ في أشهر أخرى من السنة). التصحيح تم بمطابقة اسم اليوم. أمثلة (المخزّن←الصحيح): 10/02←02/10، 10/03←03/10، 10/08←08/10 | G17: 3 خلية | H17: صُححت كلها إلى أكتوبر 2026
A18: 14 | B18: مصنع امداد | C18: C4:C7 | D18: متوسطة | E18: تواريخ | F18: 4 تاريخ مخزّن بالخطأ (Excel قلب اليوم والشهر فأصبحت التواريخ في أشهر أخرى من السنة). التصحيح تم بمطابقة اسم اليوم. أمثلة (المخزّن←الصحيح): 10/03←03/10، 10/05←05/10، 10/05←05/10، 10/05←05/10 | G18: 4 خلية | H18: صُححت كلها إلى أكتوبر 2026
A19: 15 | B19: مجني | C19: C4:C4 | D19: متوسطة | E19: تواريخ | F19: 1 تاريخ مخزّن بالخطأ (Excel قلب اليوم والشهر فأصبحت التواريخ في أشهر أخرى من السنة). التصحيح تم بمطابقة اسم اليوم. أمثلة (المخزّن←الصحيح): 10/02←02/10 | G19: 1 خلية | H19: صُححت كلها إلى أكتوبر 2026
A20: 16 | B20: ابو احمد السوري | C20: C4:C5 | D20: متوسطة | E20: تواريخ | F20: 2 تاريخ مخزّن بالخطأ (Excel قلب اليوم والشهر فأصبحت التواريخ في أشهر أخرى من السنة). التصحيح تم بمطابقة اسم اليوم. أمثلة (المخزّن←الصحيح): 10/03←03/10، 10/03←03/10 | G20: 2 خلية | H20: صُححت كلها إلى أكتوبر 2026
A21: 17 | B21: عصام المصري | C21: C4:C5 | D21: متوسطة | E21: تواريخ | F21: 2 تاريخ مخزّن بالخطأ (Excel قلب اليوم والشهر فأصبحت التواريخ في أشهر أخرى من السنة). التصحيح تم بمطابقة اسم اليوم. أمثلة (المخزّن←الصحيح): 10/12←12/10، 10/12←12/10 | G21: 2 خلية | H21: صُححت كلها إلى أكتوبر 2026
A22: 18 | B22: الكعبي كاش | C22: C4:C8 | D22: متوسطة | E22: تواريخ | F22: 5 تاريخ مخزّن بالخطأ (Excel قلب اليوم والشهر فأصبحت التواريخ في أشهر أخرى من السنة). التصحيح تم بمطابقة اسم اليوم. أمثلة (المخزّن←الصحيح): 10/03←03/10، 10/04←04/10، 10/08←08/10، 10/08←08/10… | G22: 5 خلية | H22: صُححت كلها إلى أكتوبر 2026
A23: 19 | B23: الكعبي حوالة | C23: C5:C7 | D23: متوسطة | E23: تواريخ | F23: 3 تاريخ مخزّن بالخطأ (Excel قلب اليوم والشهر فأصبحت التواريخ في أشهر أخرى من السنة). التصحيح تم بمطابقة اسم اليوم. أمثلة (المخزّن←الصحيح): 10/12←12/10، 10/12←12/10، 10/12←12/10 | G23: 3 خلية | H23: صُححت كلها إلى أكتوبر 2026
A24: 20 | B24: محمد عادل | C24: C4:C4 | D24: متوسطة | E24: تواريخ | F24: 1 تاريخ مخزّن بالخطأ (Excel قلب اليوم والشهر فأصبحت التواريخ في أشهر أخرى من السنة). التصحيح تم بمطابقة اسم اليوم. أمثلة (المخزّن←الصحيح): 10/12←12/10 | G24: 1 خلية | H24: صُححت كلها إلى أكتوبر 2026
A25: 21 | B25: سامر اليمني | C25: C5:C5 | D25: متوسطة | E25: تواريخ | F25: 1 تاريخ مخزّن بالخطأ (Excel قلب اليوم والشهر فأصبحت التواريخ في أشهر أخرى من السنة). التصحيح تم بمطابقة اسم اليوم. أمثلة (المخزّن←الصحيح): 10/11←11/10 | G25: 1 خلية | H25: صُححت كلها إلى أكتوبر 2026
A26: 22 | B26: نور بنغالي | C26: C4:C8 | D26: متوسطة | E26: تواريخ | F26: 4 تاريخ مخزّن بالخطأ (Excel قلب اليوم والشهر فأصبحت التواريخ في أشهر أخرى من السنة). التصحيح تم بمطابقة اسم اليوم. أمثلة (المخزّن←الصحيح): 10/04←04/10، 10/07←07/10، 10/08←08/10، 10/12←12/10 | G26: 4 خلية | H26: صُححت كلها إلى أكتوبر 2026
A27: 23 | B27: طيبات العصر | C27: C4:C8 | D27: متوسطة | E27: تواريخ | F27: 5 تاريخ مخزّن بالخطأ (Excel قلب اليوم والشهر فأصبحت التواريخ في أشهر أخرى من السنة). التصحيح تم بمطابقة اسم اليوم. أمثلة (المخزّن←الصحيح): 10/04←04/10، 10/06←06/10، 10/06←06/10، 10/06←06/10… | G27: 5 خلية | H27: صُححت كلها إلى أكتوبر 2026
A28: 24 | B28: محيط دلتا | C28: C4:C10 | D28: متوسطة | E28: تواريخ | F28: 7 تاريخ مخزّن بالخطأ (Excel قلب اليوم والشهر فأصبحت التواريخ في أشهر أخرى من السنة). التصحيح تم بمطابقة اسم اليوم. أمثلة (المخزّن←الصحيح): 10/02←02/10، 10/02←02/10، 10/02←02/10، 10/02←02/10… | G28: 7 خلية | H28: صُححت كلها إلى أكتوبر 2026
... A33: 29 | B33: بلال بنغالي | C33: C4:C6 | D33: متوسطة | E33: تواريخ | F33: 3 تاريخ مخزّن بالخطأ (Excel قلب اليوم والشهر فأصبحت التواريخ في أشهر أخرى من السنة). التصحيح تم بمطابقة اسم اليوم. أمثلة (المخزّن←الصحيح): 10/08←08/10، 10/09←09/10، 10/12←12/10 | G33: 3 خلية | H33: صُححت كلها إلى أكتوبر 2026
A34: 30 | B34: محسن | C34: - | D34: متوسطة | E34: هيكلة | F34: الورقة بلا عنوان "كشف حساب" والجدول مُزاح صفاً للأعلى (يختلف عن باقي الكشوف) | H34: أُعيد بناؤها بالقالب الموحد
A35: 31 | B35: مجني | C35: B2 | D35: منخفضة | E35: تسمية | F35: اسم الورقة يختلف عن اسم الحساب في العنوان "ثمار مجني" | H35: اعتُمد اسم العنوان في الكشف
A36: 32 | B36: الكعبي حوالة | C36: C4 | D36: منخفضة | E36: تواريخ | F36: صيغة تاريخ غير سليمة "12//10/2026" | G36: 12//10/2026 | H36: صُححت
A37: 33 | B37: مصنع امداد | C37: 9 | D37: منخفضة | E37: معادلات | F37: صف إجماليات يدوي خارج الجدول: [('G9', 'الإجمالي'), ('H9', '=SUM(H4:H8)'), ('I9', '=SUM(I4:I8)')] | H37: استُبدل بلوحة ملخص أعلى الكشف تغطي كل الحركات
A38: 34 | B38: مصنع امداد | C38: 10 | D38: منخفضة | E38: معادلات | F38: صف إجماليات يدوي خارج الجدول: [('G10', 'الباقي'), ('H10', '=H9-I9')] | H38: استُبدل بلوحة ملخص أعلى الكشف تغطي كل الحركات
A39: 35 | B39: امين بنغالي | C39: 16 | D39: منخفضة | E39: معادلات | F39: صف إجماليات يدوي خارج الجدول: [('G16', 'الإجمالي'), ('H16', '=SUM(H4:H15)'), ('I16', '=SUM(I4:I15)')] | H39: استُبدل بلوحة ملخص أعلى الكشف تغطي كل الحركات
A40: 36 | B40: امين بنغالي | C40: 17 | D40: منخفضة | E40: معادلات | F40: صف إجماليات يدوي خارج الجدول: [('G17', 'الباقي'), ('H17', '=H16-I16')] | H40: استُبدل بلوحة ملخص أعلى الكشف تغطي كل الحركات
A41: 37 | B41: امجد | C41: H5 | D41: منخفضة | E41: معادلات | F41: مبلغ مكتوب يدوياً بدل المعادلة | G41: 55 | H41: استُبدل بمعادلة
A42: 38 | B42: الكعبي كاش | C42: 17 | D42: منخفضة | E42: معادلات | F42: صف إجماليات يدوي خارج الجدول: [('G17', 'الإجمالي '), ('H17', '=SUM(H11:H13)')] | H42: استُبدل بلوحة ملخص أعلى الكشف تغطي كل الحركات
A43: 39 | B43: الكعبي حوالة | C43: H4 | D43: منخفضة | E43: معادلات | F43: مبلغ مكتوب يدوياً بدل المعادلة | G43: 1207.5 | H43: استُبدل بمعادلة
A44: 40 | B44: التخصص الذهبي | C44: H10:H47 | D44: منخفضة | E44: معادلات | F44: 28 معادلة تضرب في 1.15 ثابتة بدل خانة الضريبة — تغيير خانة الضريبة لا يؤثر على المبلغ | G44: E×F×1.15 | H44: وُحدت إلى: العدد×السعر×(الضريبة إن وجدت)
...

Sheet محمد زبون
B1: كشف حساب — محمد زبون
B2: حساب عميل — المدين: مبيعات (مستحق لنا) · الدائن: تحصيلات وخصومات
B3: ملخص | D3: من تاريخ | E3: إلى تاريخ | F3: إجمالي المدين | G3: إجمالي الدائن | H3: الرصيد | I3: ضريبة القيمة المضافة | J3: آخر سداد | K3: الحالة | L3: الخانات الصفراء = إدخال يدوي · باقي الأعمدة معادلات. للإضافة: اكتب في أول صف فارغ.
D4: =IF(COUNT(C7:C1000)=0,"",MIN(C7:C1000)) -> 46311 | E4: =IF(COUNT(C7:C1000)=0,"",MAX(C7:C1000)) -> 46324 | F4: =SUM(H7:H1000) -> 498 | G4: =SUM(I7:I1000) -> 498 | H4: =ROUND(F4-G4,2) -> 0 | I4: =ROUND(SUMPRODUCT((G7:G1000>1)*E7:E1000*F7:F1000*(G7:G1000-1)),2) -> 0 | J4: =IF(COUNTIFS(I7:I1000,">0",E7:E1000,"")=0,"",_xlfn.MAXIFS(C7:C1000,I7:I1000,">0",E7:E1000,"")) -> 46324 | K4: =IF(ABS(H4)<0.01,"مسدد",IF(H4>0,"مستحق لنا","رصيد للعميل")) -> مسدد
B5: ← العودة للملخص
B6: اليوم | C6: التاريخ | D6: البيان / الصنف | E6: العدد | F6: السعر | G6: ضريبة (1.15 أو 0) | H6: مدين (لنا) | I6: دائن (محصّل) | J6: الرصيد التراكمي | K6: المرجع (سند/فاتورة) | L6: ملاحظات التدقيق
B7: =IF(C7="","",CHOOSE(WEEKDAY(C7),"الأحد","الاثنين","الثلاثاء","الأربعاء","الخميس","الجمعة","السبت")) -> الجمعة | C7: 46311 | D7: تفاح سلة | E7: 1 | F7: 60 | G7: 0 | H7: =ROUND(E7*F7*IF(G7>1,G7,1),2) -> 60 | J7: =IF(COUNTA(C7:D7)=0,"",ROUND(SUM(H$7:H7)-SUM(I$7:I7),2)) -> 60 | L7: خانة الضريبة فارغة
B8: =IF(C8="","",CHOOSE(WEEKDAY(C8),"الأحد","الاثنين","الثلاثاء","الأربعاء","الخميس","الجمعة","السبت")) -> الجمعة | C8: 46311 | D8: رمان وسط | E8: 1 | F8: 19 | G8: 0 | H8: =ROUND(E8*F8*IF(G8>1,G8,1),2) -> 19 | J8: =IF(COUNTA(C8:D8)=0,"",ROUND(SUM(H$7:H8)-SUM(I$7:I8),2)) -> 79 | L8: خانة الضريبة فارغة
B9: =IF(C9="","",CHOOSE(WEEKDAY(C9),"الأحد","الاثنين","الثلاثاء","الأربعاء","الخميس","الجمعة","السبت")) -> السبت | C9: 46312 | D9: سداد | I9: 79 | J9: =IF(COUNTA(C9:D9)=0,"",ROUND(SUM(H$7:H9)-SUM(I$7:I9),2)) -> 0
B10: =IF(C10="","",CHOOSE(WEEKDAY(C10),"الأحد","الاثنين","الثلاثاء","الأربعاء","الخميس","الجمعة","السبت")) -> السبت | C10: 46312 | D10: تفاح سلة | E10: 1 | F10: 60 | G10: 0 | H10: =ROUND(E10*F10*IF(G10>1,G10,1),2) -> 60 | J10: =IF(COUNTA(C10:D10)=0,"",ROUND(SUM(H$7:H10)-SUM(I$7:I10),2)) -> 60 | L10: خانة الضريبة فارغة
B11: =IF(C11="","",CHOOSE(WEEKDAY(C11),"الأحد","الاثنين","الثلاثاء","الأربعاء","الخميس","الجمعة","السبت")) -> السبت | C11: 46312 | D11: رمان وسط | E11: 1 | F11: 19 | G11: 0 | H11: =ROUND(E11*F11*IF(G11>1,G11,1),2) -> 19 | J11: =IF(COUNTA(C11:D11)=0,"",ROUND(SUM(H$7:H11)-SUM(I$7:I11),2)) -> 79 | L11: خانة الضريبة فارغة
B12: =IF(C12="","",CHOOSE(WEEKDAY(C12),"الأحد","الاثنين","الثلاثاء","الأربعاء","الخميس","الجمعة","السبت")) -> الأحد | C12: 46313 | D12: سداد | I12: 79 | J12: =IF(COUNTA(C12:D12)=0,"",ROUND(SUM(H$7:H12)-SUM(I$7:I12),2)) -> 0
B13: =IF(C13="","",CHOOSE(WEEKDAY(C13),"الأحد","الاثنين","الثلاثاء","الأربعاء","الخميس","الجمعة","السبت")) -> الأحد | C13: 46313 | D13: تفاح سلة | E13: 2 | F13: 60 | G13: 0 | H13: =ROUND(E13*F13*IF(G13>1,G13,1),2) -> 120 | J13: =IF(COUNTA(C13:D13)=0,"",ROUND(SUM(H$7:H13)-SUM(I$7:I13),2)) -> 120 | L13: خانة الضريبة فارغة
B14: =IF(C14="","",CHOOSE(WEEKDAY(C14),"الأحد","الاثنين","الثلاثاء","الأربعاء","الخميس","الجمعة","السبت")) -> الاثنين | C14: 46314 | D14: سداد | I14: 120 | J14: =IF(COUNTA(C14:D14)=0,"",ROUND(SUM(H$7:H14)-SUM(I$7:I14),2)) -> 0
B15: =IF(C15="","",CHOOSE(WEEKDAY(C15),"الأحد","الاثنين","الثلاثاء","الأربعاء","الخميس","الجمعة","السبت")) -> الجمعة | C15: 46318 | D15: تفاح سلة | E15: 3 | F15: 55 | G15: 0 | H15: =ROUND(E15*F15*IF(G15>1,G15,1),2) -> 165 | J15: =IF(COUNTA(C15:D15)=0,"",ROUND(SUM(H$7:H15)-SUM(I$7:I15),2)) -> 165
B16: =IF(C16="","",CHOOSE(WEEKDAY(C16),"الأحد","الاثنين","الثلاثاء","الأربعاء","الخميس","الجمعة","السبت")) -> الأحد | C16: 46320 | D16: سداد | I16: 165 | J16: =IF(COUNTA(C16:D16)=0,"",ROUND(SUM(H$7:H16)-SUM(I$7:I16),2)) -> 0
B17: =IF(C17="","",CHOOSE(WEEKDAY(C17),"الأحد","الاثنين","الثلاثاء","الأربعاء","الخميس","الجمعة","السبت")) -> الاثنين | C17: 46321 | D17: تفاح سلة | E17: 1 | F17: 55 | G17: 0 | H17: =ROUND(E17*F17*IF(G17>1,G17,1),2) -> 55 | J17: =IF(COUNTA(C17:D17)=0,"",ROUND(SUM(H$7:H17)-SUM(I$7:I17),2)) -> 55
B18: =IF(C18="","",CHOOSE(WEEKDAY(C18),"الأحد","الاثنين","الثلاثاء","الأربعاء","الخميس","الجمعة","السبت")) -> الخميس | C18: 46324 | D18: سداد | I18: 55 | J18: =IF(COUNTA(C18:D18)=0,"",ROUND(SUM(H$7:H18)-SUM(I$7:I18),2)) -> 0
B19: =IF(C19="","",CHOOSE(WEEKDAY(C19),"الأحد","الاثنين","الثلاثاء","الأربعاء","الخميس","الجمعة","السبت")) | J19: =IF(COUNTA(C19:D19)=0,"",ROUND(SUM(H$7:H19)-SUM(I$7:I19),2))
B20: =IF(C20="","",CHOOSE(WEEKDAY(C20),"الأحد","الاثنين","الثلاثاء","الأربعاء","الخميس","الجمعة","السبت")) | J20: =IF(COUNTA(C20:D20)=0,"",ROUND(SUM(H$7:H20)-SUM(I$7:I20),2))
B21: =IF(C21="","",CHOOSE(WEEKDAY(C21),"الأحد","الاثنين","الثلاثاء","الأربعاء","الخميس","الجمعة","السبت")) | J21: =IF(COUNTA(C21:D21)=0,"",ROUND(SUM(H$7:H21)-SUM(I$7:I21),2))
B22: =IF(C22="","",CHOOSE(WEEKDAY(C22),"الأحد","الاثنين","الثلاثاء","الأربعاء","الخميس","الجمعة","السبت")) | J22: =IF(COUNTA(C22:D22)=0,"",ROUND(SUM(H$7:H22)-SUM(I$7:I22),2))
B23: =IF(C23="","",CHOOSE(WEEKDAY(C23),"الأحد","الاثنين","الثلاثاء","الأربعاء","الخميس","الجمعة","السبت")) | J23: =IF(COUNTA(C23:D23)=0,"",ROUND(SUM(H$7:H23)-SUM(I$7:I23),2))
B24: =IF(C24="","",CHOOSE(WEEKDAY(C24),"الأحد","الاثنين","الثلاثاء","الأربعاء","الخميس","الجمعة","السبت")) | J24: =IF(COUNTA(C24:D24)=0,"",ROUND(SUM(H$7:H24)-SUM(I$7:I24),2))
B25: =IF(C25="","",CHOOSE(WEEKDAY(C25),"الأحد","الاثنين","الثلاثاء","الأربعاء","الخميس","الجمعة","السبت")) | J25: =IF(COUNTA(C25:D25)=0,"",ROUND(SUM(H$7:H25)-SUM(I$7:I25),2))
B26: =IF(C26="","",CHOOSE(WEEKDAY(C26),"الأحد","الاثنين","الثلاثاء","الأربعاء","الخميس","الجمعة","السبت")) | J26: =IF(COUNTA(C26:D26)=0,"",ROUND(SUM(H$7:H26)-SUM(I$7:I26),2))
B27: =IF(C27="","",CHOOSE(WEEKDAY(C27),"الأحد","الاثنين","الثلاثاء","الأربعاء","الخميس","الجمعة","السبت")) | J27: =IF(COUNTA(C27:D27)=0,"",ROUND(SUM(H$7:H27)-SUM(I$7:I27),2))
B28: =IF(C28="","",CHOOSE(WEEKDAY(C28),"الأحد","الاثنين","الثلاثاء","الأربعاء","الخميس","الجمعة","السبت")) | J28: =IF(COUNTA(C28:D28)=0,"",ROUND(SUM(H$7:H28)-SUM(I$7:I28),2))
B29: =IF(C29="","",CHOOSE(WEEKDAY(C29),"الأحد","الاثنين","الثلاثاء","الأربعاء","الخميس","الجمعة","السبت")) | J29: =IF(COUNTA(C29:D29)=0,"",ROUND(SUM(H$7:H29)-SUM(I$7:I29),2))
B30: =IF(C30="","",CHOOSE(WEEKDAY(C30),"الأحد","الاثنين","الثلاثاء","الأربعاء","الخميس","الجمعة","السبت")) | J30: =IF(COUNTA(C30:D30)=0,"",ROUND(SUM(H$7:H30)-SUM(I$7:I30),2))
... B58: =IF(C58="","",CHOOSE(WEEKDAY(C58),"الأحد","الاثنين","الثلاثاء","الأربعاء","الخميس","الجمعة","السبت")) | J58: =IF(COUNTA(C58:D58)=0,"",ROUND(SUM(H$7:H58)-SUM(I$7:I58),2))

Sheet فضل
B1: كشف حساب — فضل
B2: حساب عميل — المدين: مبيعات (مستحق لنا) · الدائن: تحصيلات وخصومات
B3: ملخص | D3: من تاريخ | E3: إلى تاريخ | F3: إجمالي المدين | G3: إجمالي الدائن | H3: الرصيد | I3: ضريبة القيمة المضافة | J3: آخر سداد | K3: الحالة | L3: الخانات الصفراء = إدخال يدوي · باقي الأعمدة معادلات. للإضافة: اكتب في أول صف فارغ.
D4: =IF(COUNT(C7:C1000)=0,"",MIN(C7:C1000)) -> 46321 | E4: =IF(COUNT(C7:C1000)=0,"",MAX(C7:C1000)) -> 46324 | F4: =SUM(H7:H1000) -> 90 | G4: =SUM(I7:I1000) -> 90 | H4: =ROUND(F4-G4,2) -> 0 | I4: =ROUND(SUMPRODUCT((G7:G1000>1)*E7:E1000*F7:F1000*(G7:G1000-1)),2) -> 0 | J4: =IF(COUNTIFS(I7:I1000,">0",E7:E1000,"")=0,"",_xlfn.MAXIFS(C7:C1000,I7:I1000,">0",E7:E1000,"")) -> 46324 | K4: =IF(ABS(H4)<0.01,"مسدد",IF(H4>0,"مستحق لنا","رصيد للعميل")) -> مسدد
B5: ← العودة للملخص
B6: اليوم | C6: التاريخ | D6: البيان / الصنف | E6: العدد | F6: السعر | G6: ضريبة (1.15 أو 0) | H6: مدين (لنا) | I6: دائن (محصّل) | J6: الرصيد التراكمي | K6: المرجع (سند/فاتورة) | L6: ملاحظات التدقيق
B7: =IF(C7="","",CHOOSE(WEEKDAY(C7),"الأحد","الاثنين","الثلاثاء","الأربعاء","الخميس","الجمعة","السبت")) -> الاثنين | C7: 46321 | D7: افندي | E7: 1 | F7: 90 | G7: 0 | H7: =ROUND(E7*F7*IF(G7>1,G7,1),2) -> 90 | J7: =IF(COUNTA(C7:D7)=0,"",ROUND(SUM(H$7:H7)-SUM(I$7:I7),2)) -> 90
B8: =IF(C8="","",CHOOSE(WEEKDAY(C8),"الأحد","الاثنين","الثلاثاء","الأربعاء","الخميس","الجمعة","السبت")) -> الخميس | C8: 46324 | D8: سداد | I8: 90 | J8: =IF(COUNTA(C8:D8)=0,"",ROUND(SUM(H$7:H8)-SUM(I$7:I8),2)) -> 0
B9: =IF(C9="","",CHOOSE(WEEKDAY(C9),"الأحد","الاثنين","الثلاثاء","الأربعاء","الخميس","الجمعة","السبت")) | J9: =IF(COUNTA(C9:D9)=0,"",ROUND(SUM(H$7:H9)-SUM(I$7:I9),2))
B10: =IF(C10="","",CHOOSE(WEEKDAY(C10),"الأحد","الاثنين","الثلاثاء","الأربعاء","الخميس","الجمعة","السبت")) | J10: =IF(COUNTA(C10:D10)=0,"",ROUND(SUM(H$7:H10)-SUM(I$7:I10),2))
B11: =IF(C11="","",CHOOSE(WEEKDAY(C11),"الأحد","الاثنين","الثلاثاء","الأربعاء","الخميس","الجمعة","السبت")) | J11: =IF(COUNTA(C11:D11)=0,"",ROUND(SUM(H$7:H11)-SUM(I$7:I11),2))
B12: =IF(C12="","",CHOOSE(WEEKDAY(C12),"الأحد","الاثنين","الثلاثاء","الأربعاء","الخميس","الجمعة","السبت")) | J12: =IF(COUNTA(C12:D12)=0,"",ROUND(SUM(H$7:H12)-SUM(I$7:I12),2))
B13: =IF(C13="","",CHOOSE(WEEKDAY(C13),"الأحد","الاثنين","الثلاثاء","الأربعاء","الخميس","الجمعة","السبت")) | J13: =IF(COUNTA(C13:D13)=0,"",ROUND(SUM(H$7:H13)-SUM(I$7:I13),2))
B14: =IF(C14="","",CHOOSE(WEEKDAY(C14),"الأحد","الاثنين","الثلاثاء","الأربعاء","الخميس","الجمعة","السبت")) | J14: =IF(COUNTA(C14:D14)=0,"",ROUND(SUM(H$7:H14)-SUM(I$7:I14),2))
B15: =IF(C15="","",CHOOSE(WEEKDAY(C15),"الأحد","الاثنين","الثلاثاء","الأربعاء","الخميس","الجمعة","السبت")) | J15: =IF(COUNTA(C15:D15)=0,"",ROUND(SUM(H$7:H15)-SUM(I$7:I15),2))
B16: =IF(C16="","",CHOOSE(WEEKDAY(C16),"الأحد","الاثنين","الثلاثاء","الأربعاء","الخميس","الجمعة","السبت")) | J16: =IF(COUNTA(C16:D16)=0,"",ROUND(SUM(H$7:H16)-SUM(I$7:I16),2))
B17: =IF(C17="","",CHOOSE(WEEKDAY(C17),"الأحد","الاثنين","الثلاثاء","الأربعاء","الخميس","الجمعة","السبت")) | J17: =IF(COUNTA(C17:D17)=0,"",ROUND(SUM(H$7:H17)-SUM(I$7:I17),2))
B18: =IF(C18="","",CHOOSE(WEEKDAY(C18),"الأحد","الاثنين","الثلاثاء","الأربعاء","الخميس","الجمعة","السبت")) | J18: =IF(COUNTA(C18:D18)=0,"",ROUND(SUM(H$7:H18)-SUM(I$7:I18),2))
B19: =IF(C19="","",CHOOSE(WEEKDAY(C19),"الأحد","الاثنين","الثلاثاء","الأربعاء","الخميس","الجمعة","السبت")) | J19: =IF(COUNTA(C19:D19)=0,"",ROUND(SUM(H$7:H19)-SUM(I$7:I19),2))
B20: =IF(C20="","",CHOOSE(WEEKDAY(C20),"الأحد","الاثنين","الثلاثاء","الأربعاء","الخميس","الجمعة","السبت")) | J20: =IF(COUNTA(C20:D20)=0,"",ROUND(SUM(H$7:H20)-SUM(I$7:I20),2))
... B48: =IF(C48="","",CHOOSE(WEEKDAY(C48),"الأحد","الاثنين","الثلاثاء","الأربعاء","الخميس","الجمعة","السبت")) | J48: =IF(COUNTA(C48:D48)=0,"",ROUND(SUM(H$7:H48)-SUM(I$7:I48),2))

Sheet قصي جابر
B1: كشف حساب — قصي جابر
B2: حساب عميل — المدين: مبيعات (مستحق لنا) · الدائن: تحصيلات وخصومات
B3: ملخص | D3: من تاريخ | E3: إلى تاريخ | F3: إجمالي المدين | G3: إجمالي الدائن | H3: الرصيد | I3: ضريبة القيمة المضافة | J3: آخر سداد | K3: الحالة | L3: الخانات الصفراء = إدخال يدوي · باقي الأعمدة معادلات. للإضافة: اكتب في أول صف فارغ.
D4: =IF(COUNT(C7:C1000)=0,"",MIN(C7:C1000)) -> 46297 | E4: =IF(COUNT(C7:C1000)=0,"",MAX(C7:C1000)) -> 46325 | F4: =SUM(H7:H1000) -> 10070 | G4: =SUM(I7:I1000) -> 5450 | H4: =ROUND(F4-G4,2) -> 4620 | I4: =ROUND(SUMPRODUCT((G7:G1000>1)*E7:E1000*F7:F1000*(G7:G1000-1)),2) -> 0 | J4: =IF(COUNTIFS(I7:I1000,">0",E7:E1000,"")=0,"",_xlfn.MAXIFS(C7:C1000,I7:I1000,">0",E7:E1000,"")) -> 46325 | K4: =IF(ABS(H4)<0.01,"مسدد",IF(H4>0,"مستحق لنا","رصيد للعميل")) -> مستحق لنا
B5: ← العودة للملخص
