Workbook

Sheet الملخص
A1: ملخص أرصدة الموردين
A2: كل الأرقام معادلات مرتبطة بالكشوف — اضغط اسم الحساب للانتقال إلى كشفه. تاريخ التدقيق: 31/10/2026
B4: عدد الحسابات | D4: إجمالي المشتريات | E4: إجمالي المدفوع والخصومات | F4: صافي المستحق علينا | G4: حسابات عليها رصيد | I4: ملاحظات تدقيق
B5: =COUNTA(B9:B31) -> 23 | D5: =SUMIFS('سجل الحركات'!J4:J229,'سجل الحركات'!E4:E229,"بضاعة") -> 325170.1 | E5: =E32 -> 227481.3 | F5: =F32 -> 97748.8 | G5: =COUNTIF(K9:K31,"مستحق علينا") -> 15 | I5: =COUNTA('ملاحظات التدقيق'!B5:B1000) -> 37
A8: # | B8: الحساب | C8: عدد الحركات | D8: إجمالي المدين | E8: إجمالي الدائن | F8: الرصيد | G8: ضريبة القيمة المضافة | H8: أول حركة | I8: آخر حركة | J8: آخر سداد | K8: الحالة
A9: 1 | B9: المزارع المبدع | C9: =COUNTA('المزارع المبدع'!D7:D1000) -> 2 | D9: ='المزارع المبدع'!F4 -> 60 | E9: ='المزارع المبدع'!G4 -> 60 | F9: ='المزارع المبدع'!H4 -> 0 | G9: ='المزارع المبدع'!I4 -> 0 | H9: ='المزارع المبدع'!D4 -> 46296 | I9: ='المزارع المبدع'!E4 -> 46297 | J9: ='المزارع المبدع'!J4 | K9: ='المزارع المبدع'!K4 -> مسدد
A10: 2 | B10: العلواني | C10: =COUNTA(العلواني!D7:D1000) -> 2 | D10: =العلواني!F4 -> 3622.5 | E10: =العلواني!G4 -> 2000 | F10: =العلواني!H4 -> 1622.5 | G10: =العلواني!I4 -> 472.5 | H10: =العلواني!D4 -> 46318 | I10: =العلواني!E4 -> 46324 | J10: =العلواني!J4 -> 46324 | K10: =العلواني!K4 -> مستحق علينا
A11: 3 | B11: رجب المصري | C11: =COUNTA('رجب المصري'!D7:D1000) -> 1 | D11: ='رجب المصري'!F4 -> 3047.5 | E11: ='رجب المصري'!G4 -> 0 | F11: ='رجب المصري'!H4 -> 3047.5 | G11: ='رجب المصري'!I4 -> 397.5 | H11: ='رجب المصري'!D4 -> 46324 | I11: ='رجب المصري'!E4 -> 46324 | J11: ='رجب المصري'!J4 | K11: ='رجب المصري'!K4 -> مستحق علينا
A12: 4 | B12: الجوهرة | C12: =COUNTA(الجوهرة!D7:D1000) -> 6 | D12: =الجوهرة!F4 -> 11365.45 | E12: =الجوهرة!G4 -> 6000 | F12: =الجوهرة!H4 -> 5365.45 | G12: =الجوهرة!I4 -> 1482.45 | H12: =الجوهرة!D4 -> 46318 | I12: =الجوهرة!E4 -> 46325 | J12: =الجوهرة!J4 -> 46325 | K12: =الجوهرة!K4 -> مستحق علينا
A13: 5 | B13: جبار البيشي | C13: =COUNTA('جبار البيشي'!D7:D1000) -> 63 | D13: ='جبار البيشي'!F4 -> 146146.6 | E13: ='جبار البيشي'!G4 -> 117176.55 | F13: ='جبار البيشي'!H4 -> 28970.05 | G13: ='جبار البيشي'!I4 -> 19062.6 | H13: ='جبار البيشي'!D4 -> 46297 | I13: ='جبار البيشي'!E4 -> 46325 | J13: ='جبار البيشي'!J4 -> 46324 | K13: ='جبار البيشي'!K4 -> مستحق علينا
A14: 6 | B14: عزم الإنجاز | C14: =COUNTA('عزم الانجاز'!D7:D1000) -> 6 | D14: ='عزم الانجاز'!F4 -> 3312 | E14: ='عزم الانجاز'!G4 -> 3310 | F14: ='عزم الانجاز'!H4 -> 2 | G14: ='عزم الانجاز'!I4 -> 432 | H14: ='عزم الانجاز'!D4 -> 46317 | I14: ='عزم الانجاز'!E4 -> 46324 | J14: ='عزم الانجاز'!J4 -> 46324 | K14: ='عزم الانجاز'!K4 -> مستحق علينا
A15: 7 | B15: ثمار العالمي | C15: =COUNTA('ثمار العالمي'!D7:D1000) -> 2 | D15: ='ثمار العالمي'!F4 -> 349.6 | E15: ='ثمار العالمي'!G4 -> 350 | F15: ='ثمار العالمي'!H4 -> -0.4 | G15: ='ثمار العالمي'!I4 -> 45.6 | H15: ='ثمار العالمي'!D4 -> 46305 | I15: ='ثمار العالمي'!E4 -> 46306 | J15: ='ثمار العالمي'!J4 -> 46306 | K15: ='ثمار العالمي'!K4 -> رصيد لنا
A16: 8 | B16: عبدالرحمن قدري | C16: =COUNTA('عبدالرحمن قدري'!D7:D1000) -> 2 | D16: ='عبدالرحمن قدري'!F4 -> 460 | E16: ='عبدالرحمن قدري'!G4 -> 460 | F16: ='عبدالرحمن قدري'!H4 -> 0 | G16: ='عبدالرحمن قدري'!I4 -> 60 | H16: ='عبدالرحمن قدري'!D4 -> 46313 | I16: ='عبدالرحمن قدري'!E4 -> 46321 | J16: ='عبدالرحمن قدري'!J4 -> 46321 | K16: ='عبدالرحمن قدري'!K4 -> مسدد
A17: 9 | B17: معتصم الحصباني | C17: =COUNTA('معتصم الحصباني'!D7:D1000) -> 2 | D17: ='معتصم الحصباني'!F4 -> 2850.85 | E17: ='معتصم الحصباني'!G4 -> 0 | F17: ='معتصم الحصباني'!H4 -> 2850.85 | G17: ='معتصم الحصباني'!I4 -> 371.85 | H17: ='معتصم الحصباني'!D4 -> 46324 | I17: ='معتصم الحصباني'!E4 -> 46324 | J17: ='معتصم الحصباني'!J4 | K17: ='معتصم الحصباني'!K4 -> مستحق علينا
A18: 10 | B18: عبر الإقليم | C18: =COUNTA('عبر الاقليم'!D7:D1000) -> 28 | D18: ='عبر الاقليم'!F4 -> 34935.65 | E18: ='عبر الاقليم'!G4 -> 20673 | F18: ='عبر الاقليم'!H4 -> 14262.65 | G18: ='عبر الاقليم'!I4 -> 3394.65 | H18: ='عبر الاقليم'!D4 -> 46297 | I18: ='عبر الاقليم'!E4 -> 46324 | J18: ='عبر الاقليم'!J4 -> 46322 | K18: ='عبر الاقليم'!K4 -> مستحق علينا
A19: 11 | B19: العجم | C19: =COUNTA(العجم!D7:D1000) -> 12 | D19: =العجم!F4 -> 15680.25 | E19: =العجم!G4 -> 13900 | F19: =العجم!H4 -> 1780.25 | G19: =العجم!I4 -> 2045.25 | H19: =العجم!D4 -> 46308 | I19: =العجم!E4 -> 46321 | J19: =العجم!J4 -> 46321 | K19: =العجم!K4 -> مستحق علينا
A20: 12 | B20: البشري | C20: =COUNTA(البشري!D7:D1000) -> 25 | D20: =البشري!F4 -> 37806.25 | E20: =البشري!G4 -> 24500 | F20: =البشري!H4 -> 13306.25 | G20: =البشري!I4 -> 4931.25 | H20: =البشري!D4 -> 46303 | I20: =البشري!E4 -> 46324 | J20: =البشري!J4 -> 46324 | K20: =البشري!K4 -> مستحق علينا
A21: 13 | B21: نجمة العالم | C21: =COUNTA('نجمة العالم'!D7:D1000) -> 4 | D21: ='نجمة العالم'!F4 -> 9008 | E21: ='نجمة العالم'!G4 -> 3700 | F21: ='نجمة العالم'!H4 -> 5308 | G21: ='نجمة العالم'!I4 -> 888 | H21: ='نجمة العالم'!D4 -> 46320 | I21: ='نجمة العالم'!E4 -> 46324 | J21: ='نجمة العالم'!J4 -> 46324 | K21: ='نجمة العالم'!K4 -> مستحق علينا
A22: 14 | B22: الأغذية الطازجة | C22: =COUNTA('الاغذية الطازجة'!D7:D1000) -> 7 | D22: ='الاغذية الطازجة'!F4 -> 24788.25 | E22: ='الاغذية الطازجة'!G4 -> 7000 | F22: ='الاغذية الطازجة'!H4 -> 17788.25 | G22: ='الاغذية الطازجة'!I4 -> 3233.25 | H22: ='الاغذية الطازجة'!D4 -> 46310 | I22: ='الاغذية الطازجة'!E4 -> 46325 | J22: ='الاغذية الطازجة'!J4 -> 46324 | K22: ='الاغذية الطازجة'!K4 -> مستحق علينا
A23: 15 | B23: جوري فروت | C23: =COUNTA('جوري فروت'!D7:D1000) -> 4 | D23: ='جوري فروت'!F4 -> 2925.6 | E23: ='جوري فروت'!G4 -> 2410 | F23: ='جوري فروت'!H4 -> 515.6 | G23: ='جوري فروت'!I4 -> 381.6 | H23: ='جوري فروت'!D4 -> 46323 | I23: ='جوري فروت'!E4 -> 46324 | J23: ='جوري فروت'!J4 -> 46324 | K23: ='جوري فروت'!K4 -> مستحق علينا
A24: 16 | B24: جابر القرشي | C24: =COUNTA('جابر القرشي'!D7:D1000) -> 1 | D24: ='جابر القرشي'!F4 -> 3956 | E24: ='جابر القرشي'!G4 -> 0 | F24: ='جابر القرشي'!H4 -> 3956 | G24: ='جابر القرشي'!I4 -> 516 | H24: ='جابر القرشي'!D4 -> 46325 | I24: ='جابر القرشي'!E4 -> 46325 | J24: ='جابر القرشي'!J4 | K24: ='جابر القرشي'!K4 -> مستحق علينا
A25: 17 | B25: ثلاجة نخيل | C25: =COUNTA('ثلاجة نخيل'!D7:D1000) -> 3 | D25: ='ثلاجة نخيل'!F4 -> 3391.35 | E25: ='ثلاجة نخيل'!G4 -> 3390 | F25: ='ثلاجة نخيل'!H4 -> 1.35 | G25: ='ثلاجة نخيل'!I4 -> 442.35 | H25: ='ثلاجة نخيل'!D4 -> 46310 | I25: ='ثلاجة نخيل'!E4 -> 46325 | J25: ='ثلاجة نخيل'!J4 -> 46325 | K25: ='ثلاجة نخيل'!K4 -> مستحق علينا
A26: 18 | B26: اباصرة | C26: =COUNTA(اباصرة!D7:D1000) -> 2 | D26: =اباصرة!F4 -> 603.75 | E26: =اباصرة!G4 -> 603.75 | F26: =اباصرة!H4 -> 0 | G26: =اباصرة!I4 -> 157.5 | H26: =اباصرة!D4 -> 46316 | I26: =اباصرة!E4 -> 46319 | J26: =اباصرة!J4 | K26: =اباصرة!K4 -> مسدد
A27: 19 | B27: عبدالقادر | C27: =COUNTA(عبدالقادر!D7:D1000) -> 9 | D27: =عبدالقادر!F4 -> 4505 | E27: =عبدالقادر!G4 -> 4505 | F27: =عبدالقادر!H4 -> 0 | G27: =عبدالقادر!I4 -> 0 | H27: =عبدالقادر!D4 -> 46299 | I27: =عبدالقادر!E4 -> 46317 | J27: =عبدالقادر!J4 -> 46317 | K27: =عبدالقادر!K4 -> مسدد
A28: 20 | B28: نخبة الاغصان | C28: =COUNTA('نخبه الاغصان'!D7:D1000) -> 28 | D28: ='نخبه الاغصان'!F4 -> 5778 | E28: ='نخبه الاغصان'!G4 -> 6806 | F28: ='نخبه الاغصان'!H4 -> -1028 | G28: ='نخبه الاغصان'!I4 -> 351 | H28: ='نخبه الاغصان'!D4 -> 46297 | I28: ='نخبه الاغصان'!E4 -> 46324 | J28: ='نخبه الاغصان'!J4 -> 46323 | K28: ='نخبه الاغصان'!K4 -> رصيد لنا
A29: 21 | B29: فصل الاعمال | C29: =COUNTA('فصل الاعمال'!D7:D1000) -> 9 | D29: ='فصل الاعمال'!F4 -> 4197.5 | E29: ='فصل الاعمال'!G4 -> 4197 | F29: ='فصل الاعمال'!H4 -> 0.5 | G29: ='فصل الاعمال'!I4 -> 547.5 | H29: ='فصل الاعمال'!D4 -> 46299 | I29: ='فصل الاعمال'!E4 -> 46317 | J29: ='فصل الاعمال'!J4 -> 46317 | K29: ='فصل الاعمال'!K4 -> مستحق علينا
A30: 22 | B30: توت المتقدمة | C30: =COUNTA('توت المتقدمة'!D7:D1000) -> 6 | D30: ='توت المتقدمة'!F4 -> 4140 | E30: ='توت المتقدمة'!G4 -> 4140 | F30: ='توت المتقدمة'!H4 -> 0 | G30: ='توت المتقدمة'!I4 -> 540 | H30: ='توت المتقدمة'!D4 -> 46312 | I30: ='توت المتقدمة'!E4 -> 46321 | J30: ='توت المتقدمة'!J4 -> 46321 | K30: ='توت المتقدمة'!K4 -> مسدد
A31: 23 | B31: حمدان | C31: =COUNTA(حمدان!D7:D1000) -> 2 | D31: =حمدان!F4 -> 2300 | E31: =حمدان!G4 -> 2300 | F31: =حمدان!H4 -> 0 | G31: =حمدان!I4 -> 300 | H31: =حمدان!D4 -> 46304 | I31: =حمدان!E4 -> 46306 | J31: =حمدان!J4 -> 46306 | K31: =حمدان!K4 -> مسدد
B32: الإجمالي | C32: =SUM(C9:C31) -> 226 | D32: =SUM(D9:D31) -> 325230.1 | E32: =SUM(E9:E31) -> 227481.3 | F32: =SUM(F9:F31) -> 97748.8 | G32: =SUM(G9:G31) -> 40052.85

Sheet سجل الحركات
A1: سجل الحركات الموحّد — كل الحسابات (مرتبط بالكشوف)
A2: كل خانة هنا معادلة تقرأ من الكشف الأصلي؛ أي تعديل في الكشوف ينعكس هنا. الحركات الجديدة المضافة لاحقاً في الكشوف لا تظهر هنا تلقائياً.
A3: الحساب | B3: التاريخ | C3: البيان | D3: الصنف الموحد | E3: نوع الحركة | F3: العدد | G3: السعر | H3: قبل الضريبة | I3: الضريبة | J3: مدين | K3: دائن
A4: المزارع المبدع | B4: ='المزارع المبدع'!C7 -> 46296 | C4: ='المزارع المبدع'!D7 -> حبحب | D4: حبحب | E4: بضاعة (عكسي) | F4: =IF('المزارع المبدع'!E7="","",'المزارع المبدع'!E7) -> 2 | G4: =IF('المزارع المبدع'!F7="","",'المزارع المبدع'!F7) -> 30 | H4: =IF(F4="","",ROUND(F4*G4,2)) -> 60 | I4: =IF(F4="","",ROUND(H4*IF(N('المزارع المبدع'!G7)>1,'المزارع المبدع'!G7-1,0),2)) -> 0 | J4: =N('المزارع المبدع'!H7) -> 0 | K4: =N('المزارع المبدع'!I7) -> 60
A5: المزارع المبدع | B5: ='المزارع المبدع'!C8 -> 46297 | C5: ='المزارع المبدع'!D8 -> سداد | E5: سداد | F5: =IF('المزارع المبدع'!E8="","",'المزارع المبدع'!E8) | G5: =IF('المزارع المبدع'!F8="","",'المزارع المبدع'!F8) | H5: =IF(F5="","",ROUND(F5*G5,2)) | I5: =IF(F5="","",ROUND(H5*IF(N('المزارع المبدع'!G8)>1,'المزارع المبدع'!G8-1,0),2)) | J5: =N('المزارع المبدع'!H8) -> 60 | K5: =N('المزارع المبدع'!I8) -> 0
A6: العلواني | B6: =العلواني!C7 -> 46318 | C6: =العلواني!D7 -> ليمون | D6: ليمون تركي | E6: بضاعة | F6: =IF(العلواني!E7="","",العلواني!E7) -> 70 | G6: =IF(العلواني!F7="","",العلواني!F7) -> 45 | H6: =IF(F6="","",ROUND(F6*G6,2)) -> 3150 | I6: =IF(F6="","",ROUND(H6*IF(N(العلواني!G7)>1,العلواني!G7-1,0),2)) -> 472.5 | J6: =N(العلواني!H7) -> 3622.5 | K6: =N(العلواني!I7) -> 0
A7: العلواني | B7: =العلواني!C8 -> 46324 | C7: =العلواني!D8 -> سداد سند/76204 | E7: سداد | F7: =IF(العلواني!E8="","",العلواني!E8) | G7: =IF(العلواني!F8="","",العلواني!F8) | H7: =IF(F7="","",ROUND(F7*G7,2)) | I7: =IF(F7="","",ROUND(H7*IF(N(العلواني!G8)>1,العلواني!G8-1,0),2)) | J7: =N(العلواني!H8) -> 0 | K7: =N(العلواني!I8) -> 2000
A8: رجب المصري | B8: ='رجب المصري'!C7 -> 46324 | C8: ='رجب المصري'!D7 -> عنب تركي | D8: عنب تركي | E8: بضاعة | F8: =IF('رجب المصري'!E7="","",'رجب المصري'!E7) -> 53 | G8: =IF('رجب المصري'!F7="","",'رجب المصري'!F7) -> 50 | H8: =IF(F8="","",ROUND(F8*G8,2)) -> 2650 | I8: =IF(F8="","",ROUND(H8*IF(N('رجب المصري'!G7)>1,'رجب المصري'!G7-1,0),2)) -> 397.5 | J8: =N('رجب المصري'!H7) -> 3047.5 | K8: =N('رجب المصري'!I7) -> 0
A9: الجوهرة | B9: =الجوهرة!C7 -> 46318 | C9: =الجوهرة!D7 -> برتقال عصير | D9: برتقال عصير | E9: بضاعة | F9: =IF(الجوهرة!E7="","",الجوهرة!E7) -> 79 | G9: =IF(الجوهرة!F7="","",الجوهرة!F7) -> 85 | H9: =IF(F9="","",ROUND(F9*G9,2)) -> 6715 | I9: =IF(F9="","",ROUND(H9*IF(N(الجوهرة!G7)>1,الجوهرة!G7-1,0),2)) -> 1007.25 | J9: =N(الجوهرة!H7) -> 7722.25 | K9: =N(الجوهرة!I7) -> 0
A10: الجوهرة | B10: =الجوهرة!C8 -> 46319 | C10: =الجوهرة!D8 -> سداد سند/19041 | E10: سداد | F10: =IF(الجوهرة!E8="","",الجوهرة!E8) | G10: =IF(الجوهرة!F8="","",الجوهرة!F8) | H10: =IF(F10="","",ROUND(F10*G10,2)) | I10: =IF(F10="","",ROUND(H10*IF(N(الجوهرة!G8)>1,الجوهرة!G8-1,0),2)) | J10: =N(الجوهرة!H8) -> 0 | K10: =N(الجوهرة!I8) -> 1000
A11: الجوهرة | B11: =الجوهرة!C9 -> 46321 | C11: =الجوهرة!D9 -> سداد سند/19096 | E11: سداد | F11: =IF(الجوهرة!E9="","",الجوهرة!E9) | G11: =IF(الجوهرة!F9="","",الجوهرة!F9) | H11: =IF(F11="","",ROUND(F11*G11,2)) | I11: =IF(F11="","",ROUND(H11*IF(N(الجوهرة!G9)>1,الجوهرة!G9-1,0),2)) | J11: =N(الجوهرة!H9) -> 0 | K11: =N(الجوهرة!I9) -> 1000
A12: الجوهرة | B12: =الجوهرة!C10 -> 46323 | C12: =الجوهرة!D10 -> سداد سند/19147 | E12: سداد | F12: =IF(الجوهرة!E10="","",الجوهرة!E10) | G12: =IF(الجوهرة!F10="","",الجوهرة!F10) | H12: =IF(F12="","",ROUND(F12*G12,2)) | I12: =IF(F12="","",ROUND(H12*IF(N(الجوهرة!G10)>1,الجوهرة!G10-1,0),2)) | J12: =N(الجوهرة!H10) -> 0 | K12: =N(الجوهرة!I10) -> 2000
A13: الجوهرة | B13: =الجوهرة!C11 -> 46324 | C13: =الجوهرة!D11 -> كيوي | D13: كيوي | E13: بضاعة | F13: =IF(الجوهرة!E11="","",الجوهرة!E11) -> 96 | G13: =IF(الجوهرة!F11="","",الجوهرة!F11) -> 33 | H13: =IF(F13="","",ROUND(F13*G13,2)) -> 3168 | I13: =IF(F13="","",ROUND(H13*IF(N(الجوهرة!G11)>1,الجوهرة!G11-1,0),2)) -> 475.2 | J13: =N(الجوهرة!H11) -> 3643.2 | K13: =N(الجوهرة!I11) -> 0
A14: الجوهرة | B14: =الجوهرة!C12 -> 46325 | C14: =الجوهرة!D12 -> سداد سند/19203 | E14: سداد | F14: =IF(الجوهرة!E12="","",الجوهرة!E12) | G14: =IF(الجوهرة!F12="","",الجوهرة!F12) | H14: =IF(F14="","",ROUND(F14*G14,2)) | I14: =IF(F14="","",ROUND(H14*IF(N(الجوهرة!G12)>1,الجوهرة!G12-1,0),2)) | J14: =N(الجوهرة!H12) -> 0 | K14: =N(الجوهرة!I12) -> 2000
A15: جبار البيشي | B15: ='جبار البيشي'!C7 -> 46297 | C15: ='جبار البيشي'!D7 -> فراولة | D15: فراولة | E15: بضاعة | F15: =IF('جبار البيشي'!E7="","",'جبار البيشي'!E7) -> 60 | G15: =IF('جبار البيشي'!F7="","",'جبار البيشي'!F7) -> 85 | H15: =IF(F15="","",ROUND(F15*G15,2)) -> 5100 | I15: =IF(F15="","",ROUND(H15*IF(N('جبار البيشي'!G7)>1,'جبار البيشي'!G7-1,0),2)) -> 765 | J15: =N('جبار البيشي'!H7) -> 5865 | K15: =N('جبار البيشي'!I7) -> 0
A16: جبار البيشي | B16: ='جبار البيشي'!C8 -> 46298 | C16: ='جبار البيشي'!D8 -> بخارة تركي | D16: بخارة تركي | E16: بضاعة | F16: =IF('جبار البيشي'!E8="","",'جبار البيشي'!E8) -> 295 | G16: =IF('جبار البيشي'!F8="","",'جبار البيشي'!F8) -> 20 | H16: =IF(F16="","",ROUND(F16*G16,2)) -> 5900 | I16: =IF(F16="","",ROUND(H16*IF(N('جبار البيشي'!G8)>1,'جبار البيشي'!G8-1,0),2)) -> 885 | J16: =N('جبار البيشي'!H8) -> 6785 | K16: =N('جبار البيشي'!I8) -> 0
A17: جبار البيشي | B17: ='جبار البيشي'!C9 -> 46298 | C17: ='جبار البيشي'!D9 -> فراولة | D17: فراولة | E17: بضاعة | F17: =IF('جبار البيشي'!E9="","",'جبار البيشي'!E9) -> 33 | G17: =IF('جبار البيشي'!F9="","",'جبار البيشي'!F9) -> 80 | H17: =IF(F17="","",ROUND(F17*G17,2)) -> 2640 | I17: =IF(F17="","",ROUND(H17*IF(N('جبار البيشي'!G9)>1,'جبار البيشي'!G9-1,0),2)) -> 396 | J17: =N('جبار البيشي'!H9) -> 3036 | K17: =N('جبار البيشي'!I9) -> 0
A18: جبار البيشي | B18: ='جبار البيشي'!C10 -> 46299 | C18: ='جبار البيشي'!D10 -> سداد حوالة مجني | E18: حوالة | F18: =IF('جبار البيشي'!E10="","",'جبار البيشي'!E10) | G18: =IF('جبار البيشي'!F10="","",'جبار البيشي'!F10) | H18: =IF(F18="","",ROUND(F18*G18,2)) | I18: =IF(F18="","",ROUND(H18*IF(N('جبار البيشي'!G10)>1,'جبار البيشي'!G10-1,0),2)) | J18: =N('جبار البيشي'!H10) -> 0 | K18: =N('جبار البيشي'!I10) -> 4508
A19: جبار البيشي | B19: ='جبار البيشي'!C11 -> 46299 | C19: ='جبار البيشي'!D11 -> سداد حوالة مصنع امداد | E19: حوالة | F19: =IF('جبار البيشي'!E11="","",'جبار البيشي'!E11) | G19: =IF('جبار البيشي'!F11="","",'جبار البيشي'!F11) | H19: =IF(F19="","",ROUND(F19*G19,2)) | I19: =IF(F19="","",ROUND(H19*IF(N('جبار البيشي'!G11)>1,'جبار البيشي'!G11-1,0),2)) | J19: =N('جبار البيشي'!H11) -> 0 | K19: =N('جبار البيشي'!I11) -> 362.25
A20: جبار البيشي | B20: ='جبار البيشي'!C12 -> 46300 | C20: ='جبار البيشي'!D12 -> سداد فاتورة مصنع امداد افوكادو مقاصه | E20: مقاصة | F20: =IF('جبار البيشي'!E12="","",'جبار البيشي'!E12) | G20: =IF('جبار البيشي'!F12="","",'جبار البيشي'!F12) | H20: =IF(F20="","",ROUND(F20*G20,2)) | I20: =IF(F20="","",ROUND(H20*IF(N('جبار البيشي'!G12)>1,'جبار البيشي'!G12-1,0),2)) | J20: =N('جبار البيشي'!H12) -> 0 | K20: =N('جبار البيشي'!I12) -> 770.5
A21: جبار البيشي | B21: ='جبار البيشي'!C13 -> 46301 | C21: ='جبار البيشي'!D13 -> رمان وسط | D21: رمان وسط | E21: بضاعة | F21: =IF('جبار البيشي'!E13="","",'جبار البيشي'!E13) -> 215 | G21: =IF('جبار البيشي'!F13="","",'جبار البيشي'!F13) -> 16 | H21: =IF(F21="","",ROUND(F21*G21,2)) -> 3440 | I21: =IF(F21="","",ROUND(H21*IF(N('جبار البيشي'!G13)>1,'جبار البيشي'!G13-1,0),2)) -> 516 | J21: =N('جبار البيشي'!H13) -> 3956 | K21: =N('جبار البيشي'!I13) -> 0
A22: جبار البيشي | B22: ='جبار البيشي'!C14 -> 46301 | C22: ='جبار البيشي'!D14 -> نكتارين | D22: نكتارين | E22: بضاعة | F22: =IF('جبار البيشي'!E14="","",'جبار البيشي'!E14) -> 9 | G22: =IF('جبار البيشي'!F14="","",'جبار البيشي'!F14) -> 11 | H22: =IF(F22="","",ROUND(F22*G22,2)) -> 99 | I22: =IF(F22="","",ROUND(H22*IF(N('جبار البيشي'!G14)>1,'جبار البيشي'!G14-1,0),2)) -> 14.85 | J22: =N('جبار البيشي'!H14) -> 113.85 | K22: =N('جبار البيشي'!I14) -> 0
A23: جبار البيشي | B23: ='جبار البيشي'!C15 -> 46301 | C23: ='جبار البيشي'!D15 -> سداد مقاصه مع فاتورة أبو عجاج رمان | E23: مقاصة | F23: =IF('جبار البيشي'!E15="","",'جبار البيشي'!E15) | G23: =IF('جبار البيشي'!F15="","",'جبار البيشي'!F15) | H23: =IF(F23="","",ROUND(F23*G23,2)) | I23: =IF(F23="","",ROUND(H23*IF(N('جبار البيشي'!G15)>1,'جبار البيشي'!G15-1,0),2)) | J23: =N('جبار البيشي'!H15) -> 0 | K23: =N('جبار البيشي'!I15) -> 4048
A24: جبار البيشي | B24: ='جبار البيشي'!C16 -> 46302 | C24: ='جبار البيشي'!D16 -> نكتارين | D24: نكتارين | E24: بضاعة | F24: =IF('جبار البيشي'!E16="","",'جبار البيشي'!E16) -> 26 | G24: =IF('جبار البيشي'!F16="","",'جبار البيشي'!F16) -> 11 | H24: =IF(F24="","",ROUND(F24*G24,2)) -> 286 | I24: =IF(F24="","",ROUND(H24*IF(N('جبار البيشي'!G16)>1,'جبار البيشي'!G16-1,0),2)) -> 42.9 | J24: =N('جبار البيشي'!H16) -> 328.9 | K24: =N('جبار البيشي'!I16) -> 0
A25: جبار البيشي | B25: ='جبار البيشي'!C17 -> 46303 | C25: ='جبار البيشي'!D17 -> فراولة | D25: فراولة | E25: بضاعة | F25: =IF('جبار البيشي'!E17="","",'جبار البيشي'!E17) -> 80 | G25: =IF('جبار البيشي'!F17="","",'جبار البيشي'!F17) -> 95 | H25: =IF(F25="","",ROUND(F25*G25,2)) -> 7600 | I25: =IF(F25="","",ROUND(H25*IF(N('جبار البيشي'!G17)>1,'جبار البيشي'!G17-1,0),2)) -> 1140 | J25: =N('جبار البيشي'!H17) -> 8740 | K25: =N('جبار البيشي'!I17) -> 0
A26: جبار البيشي | B26: ='جبار البيشي'!C18 -> 46304 | C26: ='جبار البيشي'!D18 -> رمان وسط | D26: رمان وسط | E26: بضاعة | F26: =IF('جبار البيشي'!E18="","",'جبار البيشي'!E18) -> 220 | G26: =IF('جبار البيشي'!F18="","",'جبار البيشي'!F18) -> 15 | H26: =IF(F26="","",ROUND(F26*G26,2)) -> 3300 | I26: =IF(F26="","",ROUND(H26*IF(N('جبار البيشي'!G18)>1,'جبار البيشي'!G18-1,0),2)) -> 495 | J26: =N('جبار البيشي'!H18) -> 3795 | K26: =N('جبار البيشي'!I18) -> 0
A27: جبار البيشي | B27: ='جبار البيشي'!C19 -> 46304 | C27: ='جبار البيشي'!D19 -> فراولة | D27: فراولة | E27: بضاعة | F27: =IF('جبار البيشي'!E19="","",'جبار البيشي'!E19) -> 74 | G27: =IF('جبار البيشي'!F19="","",'جبار البيشي'!F19) -> 100 | H27: =IF(F27="","",ROUND(F27*G27,2)) -> 7400 | I27: =IF(F27="","",ROUND(H27*IF(N('جبار البيشي'!G19)>1,'جبار البيشي'!G19-1,0),2)) -> 1110 | J27: =N('جبار البيشي'!H19) -> 8510 | K27: =N('جبار البيشي'!I19) -> 0
A28: جبار البيشي | B28: ='جبار البيشي'!C20 -> 46304 | C28: ='جبار البيشي'!D20 -> ليمون تركي | D28: ليمون تركي | E28: بضاعة | F28: =IF('جبار البيشي'!E20="","",'جبار البيشي'!E20) -> 100 | G28: =IF('جبار البيشي'!F20="","",'جبار البيشي'!F20) -> 30 | H28: =IF(F28="","",ROUND(F28*G28,2)) -> 3000 | I28: =IF(F28="","",ROUND(H28*IF(N('جبار البيشي'!G20)>1,'جبار البيشي'!G20-1,0),2)) -> 450 | J28: =N('جبار البيشي'!H20) -> 3450 | K28: =N('جبار البيشي'!I20) -> 0
A29: جبار البيشي | B29: ='جبار البيشي'!C21 -> 46304 | C29: ='جبار البيشي'!D21 -> مقاصه مع صادق مكه | E29: مقاصة | F29: =IF('جبار البيشي'!E21="","",'جبار البيشي'!E21) | G29: =IF('جبار البيشي'!F21="","",'جبار البيشي'!F21) | H29: =IF(F29="","",ROUND(F29*G29,2)) | I29: =IF(F29="","",ROUND(H29*IF(N('جبار البيشي'!G21)>1,'جبار البيشي'!G21-1,0),2)) | J29: =N('جبار البيشي'!H21) -> 0 | K29: =N('جبار البيشي'!I21) -> 8935.5
A30: جبار البيشي | B30: ='جبار البيشي'!C22 -> 46305 | C30: ='جبار البيشي'!D22 -> كمثري عكاظ | D30: كمثري عكاظ | E30: بضاعة | F30: =IF('جبار البيشي'!E22="","",'جبار البيشي'!E22) -> 112 | G30: =IF('جبار البيشي'!F22="","",'جبار البيشي'!F22) -> 6 | H30: =IF(F30="","",ROUND(F30*G30,2)) -> 672 | I30: =IF(F30="","",ROUND(H30*IF(N('جبار البيشي'!G22)>1,'جبار البيشي'!G22-1,0),2)) -> 100.8 | J30: =N('جبار البيشي'!H22) -> 772.8 | K30: =N('جبار البيشي'!I22) -> 0
A31: جبار البيشي | B31: ='جبار البيشي'!C23 -> 46305 | C31: ='جبار البيشي'!D23 -> بخارة صحن | D31: بخارة صحن | E31: بضاعة | F31: =IF('جبار البيشي'!E23="","",'جبار البيشي'!E23) -> 24 | G31: =IF('جبار البيشي'!F23="","",'جبار البيشي'!F23) -> 9 | H31: =IF(F31="","",ROUND(F31*G31,2)) -> 216 | I31: =IF(F31="","",ROUND(H31*IF(N('جبار البيشي'!G23)>1,'جبار البيشي'!G23-1,0),2)) -> 32.4 | J31: =N('جبار البيشي'!H23) -> 248.4 | K31: =N('جبار البيشي'!I23) -> 0
A32: جبار البيشي | B32: ='جبار البيشي'!C24 -> 46305 | C32: ='جبار البيشي'!D24 -> عنب مشكل | D32: عنب مشكل | E32: بضاعة | F32: =IF('جبار البيشي'!E24="","",'جبار البيشي'!E24) -> 16 | G32: =IF('جبار البيشي'!F24="","",'جبار البيشي'!F24) -> 8 | H32: =IF(F32="","",ROUND(F32*G32,2)) -> 128 | I32: =IF(F32="","",ROUND(H32*IF(N('جبار البيشي'!G24)>1,'جبار البيشي'!G24-1,0),2)) -> 19.2 | J32: =N('جبار البيشي'!H24) -> 147.2 | K32: =N('جبار البيشي'!I24) -> 0
A33: جبار البيشي | B33: ='جبار البيشي'!C25 -> 46306 | C33: ='جبار البيشي'!D25 -> ليمون تركي | D33: ليمون تركي | E33: بضاعة | F33: =IF('جبار البيشي'!E25="","",'جبار البيشي'!E25) -> 100 | G33: =IF('جبار البيشي'!F25="","",'جبار البيشي'!F25) -> 25 | H33: =IF(F33="","",ROUND(F33*G33,2)) -> 2500 | I33: =IF(F33="","",ROUND(H33*IF(N('جبار البيشي'!G25)>1,'جبار البيشي'!G25-1,0),2)) -> 375 | J33: =N('جبار البيشي'!H25) -> 2875 | K33: =N('جبار البيشي'!I25) -> 0
A34: جبار البيشي | B34: ='جبار البيشي'!C26 -> 46306 | C34: ='جبار البيشي'!D26 -> كمثري صحن | D34: كمثري صحن | E34: بضاعة | F34: =IF('جبار البيشي'!E26="","",'جبار البيشي'!E26) -> 48 | G34: =IF('جبار البيشي'!F26="","",'جبار البيشي'!F26) -> 8 | H34: =IF(F34="","",ROUND(F34*G34,2)) -> 384 | I34: =IF(F34="","",ROUND(H34*IF(N('جبار البيشي'!G26)>1,'جبار البيشي'!G26-1,0),2)) -> 57.6 | J34: =N('جبار البيشي'!H26) -> 441.6 | K34: =N('جبار البيشي'!I26) -> 0
A35: جبار البيشي | B35: ='جبار البيشي'!C27 -> 46306 | C35: ='جبار البيشي'!D27 -> عنب مشكل | D35: عنب مشكل | E35: بضاعة | F35: =IF('جبار البيشي'!E27="","",'جبار البيشي'!E27) -> 48 | G35: =IF('جبار البيشي'!F27="","",'جبار البيشي'!F27) -> 8 | H35: =IF(F35="","",ROUND(F35*G35,2)) -> 384 | I35: =IF(F35="","",ROUND(H35*IF(N('جبار البيشي'!G27)>1,'جبار البيشي'!G27-1,0),2)) -> 57.6 | J35: =N('جبار البيشي'!H27) -> 441.6 | K35: =N('جبار البيشي'!I27) -> 0
A36: جبار البيشي | B36: ='جبار البيشي'!C28 -> 46306 | C36: ='جبار البيشي'!D28 -> حوالة نقاوة بلس | E36: حوالة | F36: =IF('جبار البيشي'!E28="","",'جبار البيشي'!E28) | G36: =IF('جبار البيشي'!F28="","",'جبار البيشي'!F28) | H36: =IF(F36="","",ROUND(F36*G36,2)) | I36: =IF(F36="","",ROUND(H36*IF(N('جبار البيشي'!G28)>1,'جبار البيشي'!G28-1,0),2)) | J36: =N('جبار البيشي'!H28) -> 0 | K36: =N('جبار البيشي'!I28) -> 7728
A37: جبار البيشي | B37: ='جبار البيشي'!C29 -> 46307 | C37: ='جبار البيشي'!D29 -> كمثري صحن | D37: كمثري صحن | E37: بضاعة | F37: =IF('جبار البيشي'!E29="","",'جبار البيشي'!E29) -> 40 | G37: =IF('جبار البيشي'!F29="","",'جبار البيشي'!F29) -> 8 | H37: =IF(F37="","",ROUND(F37*G37,2)) -> 320 | I37: =IF(F37="","",ROUND(H37*IF(N('جبار البيشي'!G29)>1,'جبار البيشي'!G29-1,0),2)) -> 48 | J37: =N('جبار البيشي'!H29) -> 368 | K37: =N('جبار البيشي'!I29) -> 0
A38: جبار البيشي | B38: ='جبار البيشي'!C30 -> 46307 | C38: ='جبار البيشي'!D30 -> بخارة صحن | D38: بخارة صحن | E38: بضاعة | F38: =IF('جبار البيشي'!E30="","",'جبار البيشي'!E30) -> 16 | G38: =IF('جبار البيشي'!F30="","",'جبار البيشي'!F30) -> 8 | H38: =IF(F38="","",ROUND(F38*G38,2)) -> 128 | I38: =IF(F38="","",ROUND(H38*IF(N('جبار البيشي'!G30)>1,'جبار البيشي'!G30-1,0),2)) -> 19.2 | J38: =N('جبار البيشي'!H30) -> 147.2 | K38: =N('جبار البيشي'!I30) -> 0
A39: جبار البيشي | B39: ='جبار البيشي'!C31 -> 46307 | C39: ='جبار البيشي'!D31 -> كمثري عكاظ | D39: كمثري عكاظ | E39: بضاعة | F39: =IF('جبار البيشي'!E31="","",'جبار البيشي'!E31) -> 96 | G39: =IF('جبار البيشي'!F31="","",'جبار البيشي'!F31) -> 7 | H39: =IF(F39="","",ROUND(F39*G39,2)) -> 672 | I39: =IF(F39="","",ROUND(H39*IF(N('جبار البيشي'!G31)>1,'جبار البيشي'!G31-1,0),2)) -> 100.8 | J39: =N('جبار البيشي'!H31) -> 772.8 | K39: =N('جبار البيشي'!I31) -> 0
A40: جبار البيشي | B40: ='جبار البيشي'!C32 -> 46307 | C40: ='جبار البيشي'!D32 -> كمثري عكاظ | D40: كمثري عكاظ | E40: بضاعة | F40: =IF('جبار البيشي'!E32="","",'جبار البيشي'!E32) -> 15 | G40: =IF('جبار البيشي'!F32="","",'جبار البيشي'!F32) -> 5 | H40: =IF(F40="","",ROUND(F40*G40,2)) -> 75 | I40: =IF(F40="","",ROUND(H40*IF(N('جبار البيشي'!G32)>1,'جبار البيشي'!G32-1,0),2)) -> 11.25 | J40: =N('جبار البيشي'!H32) -> 86.25 | K40: =N('جبار البيشي'!I32) -> 0
...

Sheet تحليل الأصناف
A1: تحليل المشتريات حسب الصنف
A2: يشمل حركات البضاعة في الاتجاه الطبيعي فقط (نوع الحركة = بضاعة) من سجل الحركات. الأسماء موحّدة (مثال: نكترين/نكتارين).
A3: # | B3: الصنف | C3: الكمية (صندوق) | D3: عدد الحركات | E3: القيمة قبل الضريبة | F3: الضريبة | G3: الإجمالي | H3: متوسط السعر | I3: أقل سعر | J3: أعلى سعر | K3: % من الإجمالي
A4: 1 | B4: فراولة | C4: =SUMIFS('سجل الحركات'!$F$4:$F$229,'سجل الحركات'!$D$4:$D$229,B4,'سجل الحركات'!$E$4:$E$229,"بضاعة") -> 835 | D4: =COUNTIFS('سجل الحركات'!$D$4:$D$229,B4,'سجل الحركات'!$E$4:$E$229,"بضاعة") -> 22 | E4: =SUMIFS('سجل الحركات'!$H$4:$H$229,'سجل الحركات'!$D$4:$D$229,B4,'سجل الحركات'!$E$4:$E$229,"بضاعة") -> 82715 | F4: =SUMIFS('سجل الحركات'!$I$4:$I$229,'سجل الحركات'!$D$4:$D$229,B4,'سجل الحركات'!$E$4:$E$229,"بضاعة") -> 11637 | G4: =E4+F4 -> 94352 | H4: =IF(C4=0,"",E4/C4) -> 99.05988 | I4: =_xlfn.MINIFS('سجل الحركات'!$G$4:$G$229,'سجل الحركات'!$D$4:$D$229,B4,'سجل الحركات'!$E$4:$E$229,"بضاعة") -> 61 | J4: =_xlfn.MAXIFS('سجل الحركات'!$G$4:$G$229,'سجل الحركات'!$D$4:$D$229,B4,'سجل الحركات'!$E$4:$E$229,"بضاعة") -> 120 | K4: =IF($G$37=0,"",G4/$G$37) -> 0.29016198
A5: 2 | B5: رمان وسط | C5: =SUMIFS('سجل الحركات'!$F$4:$F$229,'سجل الحركات'!$D$4:$D$229,B5,'سجل الحركات'!$E$4:$E$229,"بضاعة") -> 1766 | D5: =COUNTIFS('سجل الحركات'!$D$4:$D$229,B5,'سجل الحركات'!$E$4:$E$229,"بضاعة") -> 9 | E5: =SUMIFS('سجل الحركات'!$H$4:$H$229,'سجل الحركات'!$D$4:$D$229,B5,'سجل الحركات'!$E$4:$E$229,"بضاعة") -> 27921 | F5: =SUMIFS('سجل الحركات'!$I$4:$I$229,'سجل الحركات'!$D$4:$D$229,B5,'سجل الحركات'!$E$4:$E$229,"بضاعة") -> 4188.15 | G5: =E5+F5 -> 32109.15 | H5: =IF(C5=0,"",E5/C5) -> 15.810306 | I5: =_xlfn.MINIFS('سجل الحركات'!$G$4:$G$229,'سجل الحركات'!$D$4:$D$229,B5,'سجل الحركات'!$E$4:$E$229,"بضاعة") -> 15 | J5: =_xlfn.MAXIFS('سجل الحركات'!$G$4:$G$229,'سجل الحركات'!$D$4:$D$229,B5,'سجل الحركات'!$E$4:$E$229,"بضاعة") -> 17 | K5: =IF($G$37=0,"",G5/$G$37) -> 0.098745703
A6: 3 | B6: افندي افريقي | C6: =SUMIFS('سجل الحركات'!$F$4:$F$229,'سجل الحركات'!$D$4:$D$229,B6,'سجل الحركات'!$E$4:$E$229,"بضاعة") -> 304 | D6: =COUNTIFS('سجل الحركات'!$D$4:$D$229,B6,'سجل الحركات'!$E$4:$E$229,"بضاعة") -> 4 | E6: =SUMIFS('سجل الحركات'!$H$4:$H$229,'سجل الحركات'!$D$4:$D$229,B6,'سجل الحركات'!$E$4:$E$229,"بضاعة") -> 21280 | F6: =SUMIFS('سجل الحركات'!$I$4:$I$229,'سجل الحركات'!$D$4:$D$229,B6,'سجل الحركات'!$E$4:$E$229,"بضاعة") -> 3192 | G6: =E6+F6 -> 24472 | H6: =IF(C6=0,"",E6/C6) -> 70 | I6: =_xlfn.MINIFS('سجل الحركات'!$G$4:$G$229,'سجل الحركات'!$D$4:$D$229,B6,'سجل الحركات'!$E$4:$E$229,"بضاعة") -> 70 | J6: =_xlfn.MAXIFS('سجل الحركات'!$G$4:$G$229,'سجل الحركات'!$D$4:$D$229,B6,'سجل الحركات'!$E$4:$E$229,"بضاعة") -> 70 | K6: =IF($G$37=0,"",G6/$G$37) -> 0.075259072
A7: 4 | B7: عنب تركي | C7: =SUMIFS('سجل الحركات'!$F$4:$F$229,'سجل الحركات'!$D$4:$D$229,B7,'سجل الحركات'!$E$4:$E$229,"بضاعة") -> 345 | D7: =COUNTIFS('سجل الحركات'!$D$4:$D$229,B7,'سجل الحركات'!$E$4:$E$229,"بضاعة") -> 6 | E7: =SUMIFS('سجل الحركات'!$H$4:$H$229,'سجل الحركات'!$D$4:$D$229,B7,'سجل الحركات'!$E$4:$E$229,"بضاعة") -> 20760 | F7: =SUMIFS('سجل الحركات'!$I$4:$I$229,'سجل الحركات'!$D$4:$D$229,B7,'سجل الحركات'!$E$4:$E$229,"بضاعة") -> 3114 | G7: =E7+F7 -> 23874 | H7: =IF(C7=0,"",E7/C7) -> 60.173913 | I7: =_xlfn.MINIFS('سجل الحركات'!$G$4:$G$229,'سجل الحركات'!$D$4:$D$229,B7,'سجل الحركات'!$E$4:$E$229,"بضاعة") -> 50 | J7: =_xlfn.MAXIFS('سجل الحركات'!$G$4:$G$229,'سجل الحركات'!$D$4:$D$229,B7,'سجل الحركات'!$E$4:$E$229,"بضاعة") -> 65 | K7: =IF($G$37=0,"",G7/$G$37) -> 0.073420035
A8: 5 | B8: كيوي | C8: =SUMIFS('سجل الحركات'!$F$4:$F$229,'سجل الحركات'!$D$4:$D$229,B8,'سجل الحركات'!$E$4:$E$229,"بضاعة") -> 662 | D8: =COUNTIFS('سجل الحركات'!$D$4:$D$229,B8,'سجل الحركات'!$E$4:$E$229,"بضاعة") -> 7 | E8: =SUMIFS('سجل الحركات'!$H$4:$H$229,'سجل الحركات'!$D$4:$D$229,B8,'سجل الحركات'!$E$4:$E$229,"بضاعة") -> 18361 | F8: =SUMIFS('سجل الحركات'!$I$4:$I$229,'سجل الحركات'!$D$4:$D$229,B8,'سجل الحركات'!$E$4:$E$229,"بضاعة") -> 2754.15 | G8: =E8+F8 -> 21115.15 | H8: =IF(C8=0,"",E8/C8) -> 27.73565 | I8: =_xlfn.MINIFS('سجل الحركات'!$G$4:$G$229,'سجل الحركات'!$D$4:$D$229,B8,'سجل الحركات'!$E$4:$E$229,"بضاعة") -> 20 | J8: =_xlfn.MAXIFS('سجل الحركات'!$G$4:$G$229,'سجل الحركات'!$D$4:$D$229,B8,'سجل الحركات'!$E$4:$E$229,"بضاعة") -> 40 | K8: =IF($G$37=0,"",G8/$G$37) -> 0.064935706
A9: 6 | B9: رمان مصري | C9: =SUMIFS('سجل الحركات'!$F$4:$F$229,'سجل الحركات'!$D$4:$D$229,B9,'سجل الحركات'!$E$4:$E$229,"بضاعة") -> 1481 | D9: =COUNTIFS('سجل الحركات'!$D$4:$D$229,B9,'سجل الحركات'!$E$4:$E$229,"بضاعة") -> 10 | E9: =SUMIFS('سجل الحركات'!$H$4:$H$229,'سجل الحركات'!$D$4:$D$229,B9,'سجل الحركات'!$E$4:$E$229,"بضاعة") -> 15484 | F9: =SUMIFS('سجل الحركات'!$I$4:$I$229,'سجل الحركات'!$D$4:$D$229,B9,'سجل الحركات'!$E$4:$E$229,"بضاعة") -> 2157 | G9: =E9+F9 -> 17641 | H9: =IF(C9=0,"",E9/C9) -> 10.455098 | I9: =_xlfn.MINIFS('سجل الحركات'!$G$4:$G$229,'سجل الحركات'!$D$4:$D$229,B9,'سجل الحركات'!$E$4:$E$229,"بضاعة") -> 10 | J9: =_xlfn.MAXIFS('سجل الحركات'!$G$4:$G$229,'سجل الحركات'!$D$4:$D$229,B9,'سجل الحركات'!$E$4:$E$229,"بضاعة") -> 11.5 | K9: =IF($G$37=0,"",G9/$G$37) -> 0.054251606
A10: 7 | B10: كاكا لبناني | C10: =SUMIFS('سجل الحركات'!$F$4:$F$229,'سجل الحركات'!$D$4:$D$229,B10,'سجل الحركات'!$E$4:$E$229,"بضاعة") -> 849 | D10: =COUNTIFS('سجل الحركات'!$D$4:$D$229,B10,'سجل الحركات'!$E$4:$E$229,"بضاعة") -> 5 | E10: =SUMIFS('سجل الحركات'!$H$4:$H$229,'سجل الحركات'!$D$4:$D$229,B10,'سجل الحركات'!$E$4:$E$229,"بضاعة") -> 13680 | F10: =SUMIFS('سجل الحركات'!$I$4:$I$229,'سجل الحركات'!$D$4:$D$229,B10,'سجل الحركات'!$E$4:$E$229,"بضاعة") -> 2052 | G10: =E10+F10 -> 15732 | H10: =IF(C10=0,"",E10/C10) -> 16.113074 | I10: =_xlfn.MINIFS('سجل الحركات'!$G$4:$G$229,'سجل الحركات'!$D$4:$D$229,B10,'سجل الحركات'!$E$4:$E$229,"بضاعة") -> 16 | J10: =_xlfn.MAXIFS('سجل الحركات'!$G$4:$G$229,'سجل الحركات'!$D$4:$D$229,B10,'سجل الحركات'!$E$4:$E$229,"بضاعة") -> 20 | K10: =IF($G$37=0,"",G10/$G$37) -> 0.048380832
A11: 8 | B11: برتقال عصير | C11: =SUMIFS('سجل الحركات'!$F$4:$F$229,'سجل الحركات'!$D$4:$D$229,B11,'سجل الحركات'!$E$4:$E$229,"بضاعة") -> 159 | D11: =COUNTIFS('سجل الحركات'!$D$4:$D$229,B11,'سجل الحركات'!$E$4:$E$229,"بضاعة") -> 2 | E11: =SUMIFS('سجل الحركات'!$H$4:$H$229,'سجل الحركات'!$D$4:$D$229,B11,'سجل الحركات'!$E$4:$E$229,"بضاعة") -> 12635 | F11: =SUMIFS('سجل الحركات'!$I$4:$I$229,'سجل الحركات'!$D$4:$D$229,B11,'سجل الحركات'!$E$4:$E$229,"بضاعة") -> 1895.25 | G11: =E11+F11 -> 14530.25 | H11: =IF(C11=0,"",E11/C11) -> 79.465409 | I11: =_xlfn.MINIFS('سجل الحركات'!$G$4:$G$229,'سجل الحركات'!$D$4:$D$229,B11,'سجل الحركات'!$E$4:$E$229,"بضاعة") -> 74 | J11: =_xlfn.MAXIFS('سجل الحركات'!$G$4:$G$229,'سجل الحركات'!$D$4:$D$229,B11,'سجل الحركات'!$E$4:$E$229,"بضاعة") -> 85 | K11: =IF($G$37=0,"",G11/$G$37) -> 0.044685074
A12: 9 | B12: تفاح سلة | C12: =SUMIFS('سجل الحركات'!$F$4:$F$229,'سجل الحركات'!$D$4:$D$229,B12,'سجل الحركات'!$E$4:$E$229,"بضاعة") -> 280 | D12: =COUNTIFS('سجل الحركات'!$D$4:$D$229,B12,'سجل الحركات'!$E$4:$E$229,"بضاعة") -> 4 | E12: =SUMIFS('سجل الحركات'!$H$4:$H$229,'سجل الحركات'!$D$4:$D$229,B12,'سجل الحركات'!$E$4:$E$229,"بضاعة") -> 12406 | F12: =SUMIFS('سجل الحركات'!$I$4:$I$229,'سجل الحركات'!$D$4:$D$229,B12,'سجل الحركات'!$E$4:$E$229,"بضاعة") -> 1860.9 | G12: =E12+F12 -> 14266.9 | H12: =IF(C12=0,"",E12/C12) -> 44.307143 | I12: =_xlfn.MINIFS('سجل الحركات'!$G$4:$G$229,'سجل الحركات'!$D$4:$D$229,B12,'سجل الحركات'!$E$4:$E$229,"بضاعة") -> 42 | J12: =_xlfn.MAXIFS('سجل الحركات'!$G$4:$G$229,'سجل الحركات'!$D$4:$D$229,B12,'سجل الحركات'!$E$4:$E$229,"بضاعة") -> 50 | K12: =IF($G$37=0,"",G12/$G$37) -> 0.04387519
A13: 10 | B13: ليمون تركي | C13: =SUMIFS('سجل الحركات'!$F$4:$F$229,'سجل الحركات'!$D$4:$D$229,B13,'سجل الحركات'!$E$4:$E$229,"بضاعة") -> 270 | D13: =COUNTIFS('سجل الحركات'!$D$4:$D$229,B13,'سجل الحركات'!$E$4:$E$229,"بضاعة") -> 3 | E13: =SUMIFS('سجل الحركات'!$H$4:$H$229,'سجل الحركات'!$D$4:$D$229,B13,'سجل الحركات'!$E$4:$E$229,"بضاعة") -> 8650 | F13: =SUMIFS('سجل الحركات'!$I$4:$I$229,'سجل الحركات'!$D$4:$D$229,B13,'سجل الحركات'!$E$4:$E$229,"بضاعة") -> 1297.5 | G13: =E13+F13 -> 9947.5 | H13: =IF(C13=0,"",E13/C13) -> 32.037037 | I13: =_xlfn.MINIFS('سجل الحركات'!$G$4:$G$229,'سجل الحركات'!$D$4:$D$229,B13,'سجل الحركات'!$E$4:$E$229,"بضاعة") -> 25 | J13: =_xlfn.MAXIFS('سجل الحركات'!$G$4:$G$229,'سجل الحركات'!$D$4:$D$229,B13,'سجل الحركات'!$E$4:$E$229,"بضاعة") -> 45 | K13: =IF($G$37=0,"",G13/$G$37) -> 0.030591681
A14: 11 | B14: افندي | C14: =SUMIFS('سجل الحركات'!$F$4:$F$229,'سجل الحركات'!$D$4:$D$229,B14,'سجل الحركات'!$E$4:$E$229,"بضاعة") -> 219 | D14: =COUNTIFS('سجل الحركات'!$D$4:$D$229,B14,'سجل الحركات'!$E$4:$E$229,"بضاعة") -> 3 | E14: =SUMIFS('سجل الحركات'!$H$4:$H$229,'سجل الحركات'!$D$4:$D$229,B14,'سجل الحركات'!$E$4:$E$229,"بضاعة") -> 8465 | F14: =SUMIFS('سجل الحركات'!$I$4:$I$229,'سجل الحركات'!$D$4:$D$229,B14,'سجل الحركات'!$E$4:$E$229,"بضاعة") -> 939.75 | G14: =E14+F14 -> 9404.75 | H14: =IF(C14=0,"",E14/C14) -> 38.652968 | I14: =_xlfn.MINIFS('سجل الحركات'!$G$4:$G$229,'سجل الحركات'!$D$4:$D$229,B14,'سجل الحركات'!$E$4:$E$229,"بضاعة") -> 35 | J14: =_xlfn.MAXIFS('سجل الحركات'!$G$4:$G$229,'سجل الحركات'!$D$4:$D$229,B14,'سجل الحركات'!$E$4:$E$229,"بضاعة") -> 55 | K14: =IF($G$37=0,"",G14/$G$37) -> 0.028922555
A15: 12 | B15: تفاح | C15: =SUMIFS('سجل الحركات'!$F$4:$F$229,'سجل الحركات'!$D$4:$D$229,B15,'سجل الحركات'!$E$4:$E$229,"بضاعة") -> 154 | D15: =COUNTIFS('سجل الحركات'!$D$4:$D$229,B15,'سجل الحركات'!$E$4:$E$229,"بضاعة") -> 4 | E15: =SUMIFS('سجل الحركات'!$H$4:$H$229,'سجل الحركات'!$D$4:$D$229,B15,'سجل الحركات'!$E$4:$E$229,"بضاعة") -> 6952 | F15: =SUMIFS('سجل الحركات'!$I$4:$I$229,'سجل الحركات'!$D$4:$D$229,B15,'سجل الحركات'!$E$4:$E$229,"بضاعة") -> 1041.6 | G15: =E15+F15 -> 7993.6 | H15: =IF(C15=0,"",E15/C15) -> 45.142857 | I15: =_xlfn.MINIFS('سجل الحركات'!$G$4:$G$229,'سجل الحركات'!$D$4:$D$229,B15,'سجل الحركات'!$E$4:$E$229,"بضاعة") -> 8 | J15: =_xlfn.MAXIFS('سجل الحركات'!$G$4:$G$229,'سجل الحركات'!$D$4:$D$229,B15,'سجل الحركات'!$E$4:$E$229,"بضاعة") -> 48 | K15: =IF($G$37=0,"",G15/$G$37) -> 0.024582826
... A36: 33 | B36: عنب اسود | C36: =SUMIFS('سجل الحركات'!$F$4:$F$229,'سجل الحركات'!$D$4:$D$229,B36,'سجل الحركات'!$E$4:$E$229,"بضاعة") -> 5 | D36: =COUNTIFS('سجل الحركات'!$D$4:$D$229,B36,'سجل الحركات'!$E$4:$E$229,"بضاعة") -> 1 | E36: =SUMIFS('سجل الحركات'!$H$4:$H$229,'سجل الحركات'!$D$4:$D$229,B36,'سجل الحركات'!$E$4:$E$229,"بضاعة") -> 165 | F36: =SUMIFS('سجل الحركات'!$I$4:$I$229,'سجل الحركات'!$D$4:$D$229,B36,'سجل الحركات'!$E$4:$E$229,"بضاعة") -> 0 | G36: =E36+F36 -> 165 | H36: =IF(C36=0,"",E36/C36) -> 33 | I36: =_xlfn.MINIFS('سجل الحركات'!$G$4:$G$229,'سجل الحركات'!$D$4:$D$229,B36,'سجل الحركات'!$E$4:$E$229,"بضاعة") -> 33 | J36: =_xlfn.MAXIFS('سجل الحركات'!$G$4:$G$229,'سجل الحركات'!$D$4:$D$229,B36,'سجل الحركات'!$E$4:$E$229,"بضاعة") -> 33 | K36: =IF($G$37=0,"",G36/$G$37) -> 0.00050742673
B37: الإجمالي | C37: =SUM(C4:C36) -> 9213 | D37: =SUM(D4:D36) -> 131 | E37: =SUM(E4:E36) -> 285196 | F37: =SUM(F4:F36) -> 39974.1 | G37: =SUM(G4:G36) -> 325170.1

Sheet مطابقة المقاصات
A1: مطابقة الحوالات والمقاصات بين ملف الموردين وملف العملاء
A2: كل سداد تم بحوالة من عميل إلى مورد (أو بمقاصة) يجب أن يُسجَّل بنفس المبلغ في الحسابين. هذه الورقة قيم ثابتة لحظة التدقيق.
A3: التاريخ | B3: الملف | C3: الحساب | D3: البيان | E3: المبلغ | F3: الطرف المقابل | G3: ملف الطرف المقابل | H3: تاريخ القيد المقابل | I3: مبلغ القيد المقابل | J3: الفرق | K3: النتيجة
A4: 46303 | B4: الموردين | C4: البشري | D4: مقاصه مع رجب | E4: 2300 | F4: رجب | G4: - | K4: لا يوجد قيد مقاصة مقابل في حساب "رجب المصري" (إن كان هو المقصود)
A5: 46304 | B5: الموردين | C5: جبار البيشي | D5: مقاصه مع صادق مكه | E5: 8935.5 | F5: صادق مكه | G5: - | K5: لا يوجد حساب للطرف المقابل في الملفين
A6: 46308 | B6: الموردين | C6: جبار البيشي | D6: حوالة نقاوة بلس | E6: 5037 | F6: نقاوة بلس | G6: العملاء | H6: 46308 | I6: 3450 | J6: 1587 | K6: فرق في المبلغ
A7: 46299 | B7: الموردين | C7: جبار البيشي | D7: سداد حوالة مجني | E7: 4508 | F7: ثمار مجني | G7: العملاء | H7: 46300 | I7: 4508 | J7: 0 | K7: مطابق المبلغ — فرق تاريخ 1 يوم
A8: 46299 | B8: الموردين | C8: جبار البيشي | D8: سداد حوالة مصنع امداد | E8: 362.25 | F8: مصنع امداد | G8: العملاء | H8: 46300 | I8: 362.25 | J8: 0 | K8: مطابق المبلغ — فرق تاريخ 1 يوم
A9: 46300 | B9: الموردين | C9: جبار البيشي | D9: سداد فاتورة مصنع امداد افوكادو مقاصه | E9: 770.5 | F9: مصنع امداد | G9: العملاء | H9: 46300 | I9: 770.5 | J9: 0 | K9: مطابق
A10: 46301 | B10: الموردين | C10: جبار البيشي | D10: سداد مقاصه مع فاتورة أبو عجاج رمان | E10: 4048 | F10: أبو عجاج | G10: العملاء | H10: 46301 | I10: 4048 | J10: 0 | K10: مطابق
A11: 46301 | B11: الموردين | C11: عبر الإقليم | D11: سداد حوالة محيط دلتا | E11: 2769 | F11: محيط دلتا | G11: العملاء | H11: 46301 | I11: 2769 | J11: 0 | K11: مطابق
A12: 46306 | B12: الموردين | C12: جبار البيشي | D12: حوالة نقاوة بلس | E12: 7728 | F12: نقاوة بلس | G12: العملاء | H12: 46305 | I12: 7728 | J12: 0 | K12: مطابق المبلغ — فرق تاريخ 1 يوم
A13: 46309 | B13: الموردين | C13: عبر الإقليم | D13: سداد حوالة محيط دلتا /12871 | E13: 1400 | F13: محيط دلتا | G13: العملاء | H13: 46309 | I13: 1400 | J13: 0 | K13: مطابق
A14: 46313 | B14: الموردين | C14: جبار البيشي | D14: حوالة نقاوة بلس | E14: 2428 | F14: نقاوة بلس | G14: العملاء | H14: 46313 | I14: 2428 | J14: 0 | K14: مطابق
A15: 46315 | B15: الموردين | C15: جبار البيشي | D15: حوالة الحساني | E15: 6626.3 | F15: الحساني | G15: العملاء | H15: 46315 | I15: 6626.3 | J15: 0 | K15: مطابق
A16: 46317 | B16: الموردين | C16: جبار البيشي | D16: حوالة بنكية محمد عادل | E16: 3000 | F16: محمد عادل | G16: العملاء | H16: 46317 | I16: 3000 | J16: 0 | K16: مطابق
A17: 46320 | B17: الموردين | C17: جبار البيشي | D17: حوالة بنكية نقاوة بلس | E17: 7000 | F17: نقاوة بلس | G17: العملاء | H17: 46320 | I17: 7000 | J17: 0 | K17: مطابق
... A22: 46323 | B22: الموردين | C22: جبار البيشي | D22: حوالة بنكية نقاوة بلس | E22: 4326 | F22: نقاوة بلس | G22: العملاء | H22: 46323 | I22: 4326 | J22: 0 | K22: مطابق

Sheet ملاحظات التدقيق
A1: ملاحظات التدقيق والتصحيحات — ملف الموردين
A2: عالية = تؤثر على الرصيد وتحتاج متابعة فورية · متوسطة = خطأ تسجيل صُحح أو يحتاج تأكيد · منخفضة = تنسيق/هيكلة. عمود "القيمة الأصلية" يحفظ ما كان في الملف قبل التعديل.
B3: عالية | C3: =COUNTIF(D5:D2000,"عالية") -> 4 | D3: متوسطة | E3: =COUNTIF(D5:D2000,"متوسطة") -> 21 | F3: منخفضة | G3: =COUNTIF(D5:D2000,"منخفضة") -> 12
A4: # | B4: الحساب | C4: الخلية/الصف | D4: الخطورة | E4: التصنيف | F4: الملاحظة | G4: القيمة الأصلية | H4: الإجراء المتخذ
A5: 1 | B5: مطابقة | C5: - | D5: عالية | E5: مطابقة المقاصات | F5: جبار البيشي (الموردين) 09/10: "مقاصه مع صادق مكه" بمبلغ 8,935.50 — لا يوجد حساب للطرف المقابل في الملفين | H5: يرجى المطابقة مع الطرف وتصحيح أحد القيدين
A6: 2 | B6: مطابقة | C6: - | D6: عالية | E6: مطابقة المقاصات | F6: جبار البيشي (الموردين) 13/10: "حوالة نقاوة بلس" بمبلغ 5,037.00 — فرق في المبلغ (المسجل عند نقاوة بلس: 3,450.00، الفرق 1,587.00) | H6: يرجى المطابقة مع الطرف وتصحيح أحد القيدين
A7: 3 | B7: مطابقة | C7: - | D7: عالية | E7: مطابقة المقاصات | F7: البشري (الموردين) 08/10: "مقاصه مع رجب" بمبلغ 2,300.00 — لا يوجد قيد مقاصة مقابل في حساب "رجب المصري" (إن كان هو المقصود) | H7: يرجى المطابقة مع الطرف وتصحيح أحد القيدين
A8: 4 | B8: نخبه الاغصان | C8: I6 | D8: عالية | E8: معادلات | F8: معادلة =SUM(I4:I24) مكتوبة داخل صف حركة "رمان مصري" وتشمل خليتها نفسها (مرجع دائري) — قد تضاعف أو تُصفّر الرصيد عند إعادة الحساب | G8: ‏=SUM(I4:I24) | H8: حُذفت؛ الصف يحمل مبلغ الحركة فقط
A9: 5 | B9: حمدان | C9: E5 | D9: متوسطة | E9: إدخال | F9: نص "سداد" مكتوب في خانة العدد | G9: سداد | H9: نُقل إلى البيان
A10: 6 | B10: المزارع المبدع | C10: 4 | D10: متوسطة | E10: اتجاه القيد | F10: بضاعة مسجلة في الدائن (عكس باقي الحركات) — غالباً بضاعة مُباعة لهذا المورد أو مرتجع. أُبقيت كما هي؛ يرجى التأكيد. | G10: حبحب 60 | H10: بدون تغيير
A11: 7 | B11: المزارع المبدع | C11: 5 | D11: متوسطة | E11: اتجاه القيد | F11: سداد مسجل في المدين — يعني دفعة استلمناها من هذا المورد (مقابل بضاعة باعها له) . أُبقي كما هو؛ يرجى التأكيد. | G11: سداد 60 | H11: بدون تغيير
A12: 8 | B12: اباصرة | C12: 5 | D12: متوسطة | E12: اتجاه القيد | F12: بضاعة مسجلة في الدائن (عكس باقي الحركات) — غالباً بضاعة مُباعة لهذا المورد أو مرتجع. أُبقيت كما هي؛ يرجى التأكيد. | G12: فراولة 603.75 | H12: بدون تغيير
A13: 9 | B13: نخبه الاغصان | C13: 12 | D13: متوسطة | E13: اتجاه القيد | F13: بضاعة مسجلة في الدائن (عكس باقي الحركات) — غالباً بضاعة مُباعة لهذا المورد أو مرتجع. أُبقيت كما هي؛ يرجى التأكيد. | G13: فراولة 2500 | H13: بدون تغيير
A14: 10 | B14: نخبه الاغصان | C14: 18 | D14: متوسطة | E14: اتجاه القيد | F14: بضاعة مسجلة في الدائن (عكس باقي الحركات) — غالباً بضاعة مُباعة لهذا المورد أو مرتجع. أُبقيت كما هي؛ يرجى التأكيد. | G14: بطاطا 80 | H14: بدون تغيير
A15: 11 | B15: نخبه الاغصان | C15: 21 | D15: متوسطة | E15: اتجاه القيد | F15: بضاعة مسجلة في الدائن (عكس باقي الحركات) — غالباً بضاعة مُباعة لهذا المورد أو مرتجع. أُبقيت كما هي؛ يرجى التأكيد. | G15: فراولة 1230 | H15: بدون تغيير
A16: 12 | B16: نخبه الاغصان | C16: 31 | D16: متوسطة | E16: اتجاه القيد | F16: بضاعة مسجلة في الدائن (عكس باقي الحركات) — غالباً بضاعة مُباعة لهذا المورد أو مرتجع. أُبقيت كما هي؛ يرجى التأكيد. | G16: فراولة 2684 | H16: بدون تغيير
A17: 13 | B17: عام | C17: - | D17: متوسطة | E17: تكرار حساب | F17: "عبدالرحمن قدري" له حساب في ملف الموردين وملف العملاء معاً — يُنصح بمتابعة صافي الرصيد بين الحسابين
A18: 14 | B18: المزارع المبدع | C18: C4:C5 | D18: متوسطة | E18: تواريخ | F18: 2 تاريخ مخزّن بالخطأ (Excel قلب اليوم والشهر فأصبحت التواريخ في أشهر أخرى من السنة). التصحيح تم بمطابقة اسم اليوم. أمثلة (المخزّن←الصحيح): 10/01←01/10، 10/02←02/10 | G18: 2 خلية | H18: صُححت كلها إلى أكتوبر 2026
A19: 15 | B19: جبار البيشي | C19: C4:C29 | D19: متوسطة | E19: تواريخ | F19: 23 تاريخ مخزّن بالخطأ (Excel قلب اليوم والشهر فأصبحت التواريخ في أشهر أخرى من السنة). التصحيح تم بمطابقة اسم اليوم. أمثلة (المخزّن←الصحيح): 10/02←02/10، 10/03←03/10، 10/03←03/10، 10/04←04/10… | G19: 23 خلية | H19: صُححت كلها إلى أكتوبر 2026
A20: 16 | B20: ثمار العالمي | C20: C5:C5 | D20: متوسطة | E20: تواريخ | F20: 1 تاريخ مخزّن بالخطأ (Excel قلب اليوم والشهر فأصبحت التواريخ في أشهر أخرى من السنة). التصحيح تم بمطابقة اسم اليوم. أمثلة (المخزّن←الصحيح): 10/11←11/10 | G20: 1 خلية | H20: صُححت كلها إلى أكتوبر 2026
A21: 17 | B21: عبر الاقليم | C21: C4:C17 | D21: متوسطة | E21: تواريخ | F21: 12 تاريخ مخزّن بالخطأ (Excel قلب اليوم والشهر فأصبحت التواريخ في أشهر أخرى من السنة). التصحيح تم بمطابقة اسم اليوم. أمثلة (المخزّن←الصحيح): 10/02←02/10، 10/03←03/10، 10/04←04/10، 10/06←06/10… | G21: 12 خلية | H21: صُححت كلها إلى أكتوبر 2026
A22: 18 | B22: البشري | C22: C4:C9 | D22: متوسطة | E22: تواريخ | F22: 6 تاريخ مخزّن بالخطأ (Excel قلب اليوم والشهر فأصبحت التواريخ في أشهر أخرى من السنة). التصحيح تم بمطابقة اسم اليوم. أمثلة (المخزّن←الصحيح): 10/08←08/10، 10/08←08/10، 10/08←08/10، 10/09←09/10… | G22: 6 خلية | H22: صُححت كلها إلى أكتوبر 2026
A23: 19 | B23: الاغذية الطازجة | C23: B4 | D23: متوسطة | E23: تواريخ | F23: اسم اليوم "الاحد" لا يطابق التاريخ 15/10/2026 (الخميس) | G23: الاحد | H23: اعتُمد التاريخ؛ يرجى التأكد من التاريخ الفعلي
A24: 20 | B24: ثلاجة نخيل | C24: B4 | D24: متوسطة | E24: تواريخ | F24: اسم اليوم "الاحد" لا يطابق التاريخ 15/10/2026 (الخميس) | G24: الاحد | H24: اعتُمد التاريخ؛ يرجى التأكد من التاريخ الفعلي
A25: 21 | B25: ثلاجة نخيل | C25: B5 | D25: متوسطة | E25: تواريخ | F25: اسم اليوم "الثلاثاء" لا يطابق التاريخ 17/10/2026 (السبت) | G25: الثلاثاء | H25: اعتُمد التاريخ؛ يرجى التأكد من التاريخ الفعلي
A26: 22 | B26: عبدالقادر | C26: C4:C5 | D26: متوسطة | E26: تواريخ | F26: 2 تاريخ مخزّن بالخطأ (Excel قلب اليوم والشهر فأصبحت التواريخ في أشهر أخرى من السنة). التصحيح تم بمطابقة اسم اليوم. أمثلة (المخزّن←الصحيح): 10/04←04/10، 10/09←09/10 | G26: 2 خلية | H26: صُححت كلها إلى أكتوبر 2026
A27: 23 | B27: نخبه الاغصان | C27: C4:C14 | D27: متوسطة | E27: تواريخ | F27: 11 تاريخ مخزّن بالخطأ (Excel قلب اليوم والشهر فأصبحت التواريخ في أشهر أخرى من السنة). التصحيح تم بمطابقة اسم اليوم. أمثلة (المخزّن←الصحيح): 10/02←02/10، 10/02←02/10، 10/02←02/10، 10/03←03/10… | G27: 11 خلية | H27: صُححت كلها إلى أكتوبر 2026
A28: 24 | B28: فصل الاعمال | C28: C4:C7 | D28: متوسطة | E28: تواريخ | F28: 4 تاريخ مخزّن بالخطأ (Excel قلب اليوم والشهر فأصبحت التواريخ في أشهر أخرى من السنة). التصحيح تم بمطابقة اسم اليوم. أمثلة (المخزّن←الصحيح): 10/04←04/10، 10/07←07/10، 10/09←09/10، 10/11←11/10 | G28: 4 خلية | H28: صُححت كلها إلى أكتوبر 2026
A29: 25 | B29: حمدان | C29: C4:C5 | D29: متوسطة | E29: تواريخ | F29: 2 تاريخ مخزّن بالخطأ (Excel قلب اليوم والشهر فأصبحت التواريخ في أشهر أخرى من السنة). التصحيح تم بمطابقة اسم اليوم. أمثلة (المخزّن←الصحيح): 10/09←09/10، 10/11←11/10 | G29: 2 خلية | H29: صُححت كلها إلى أكتوبر 2026
... A34: 30 | B34: العجم | C34: H10:H14 | D34: منخفضة | E34: معادلات | F34: 3 معادلة تضرب في 1.15 ثابتة بدل خانة الضريبة — تغيير خانة الضريبة لا يؤثر على المبلغ | G34: E×F×1.15 | H34: وُحدت إلى: العدد×السعر×(الضريبة إن وجدت)
A35: 31 | B35: البشري | C35: H5 | D35: منخفضة | E35: معادلات | F35: مبلغ مكتوب يدوياً بدل المعادلة | G35: 2300 | H35: استُبدل بمعادلة
A36: 32 | B36: البشري | C36: H10:H28 | D36: منخفضة | E36: معادلات | F36: 10 معادلة تضرب في 1.15 ثابتة بدل خانة الضريبة — تغيير خانة الضريبة لا يؤثر على المبلغ | G36: E×F×1.15 | H36: وُحدت إلى: العدد×السعر×(الضريبة إن وجدت)
A37: 33 | B37: الاغذية الطازجة | C37: H10:H10 | D37: منخفضة | E37: معادلات | F37: 1 معادلة تضرب في 1.15 ثابتة بدل خانة الضريبة — تغيير خانة الضريبة لا يؤثر على المبلغ | G37: E×F×1.15 | H37: وُحدت إلى: العدد×السعر×(الضريبة إن وجدت)
A38: 34 | B38: ثلاجة نخيل | C38: H5:H5 | D38: منخفضة | E38: معادلات | F38: 1 معادلة تضرب في 1.15 ثابتة بدل خانة الضريبة — تغيير خانة الضريبة لا يؤثر على المبلغ | G38: E×F×1.15 | H38: وُحدت إلى: العدد×السعر×(الضريبة إن وجدت)
A39: 35 | B39: نخبه الاغصان | C39: H4 | D39: منخفضة | E39: معادلات | F39: مبلغ مكتوب يدوياً بدل المعادلة | G39: 96 | H39: استُبدل بمعادلة
A40: 36 | B40: نخبه الاغصان | C40: H15:H29 | D40: منخفضة | E40: معادلات | F40: 7 معادلة تضرب في 1.15 ثابتة بدل خانة الضريبة — تغيير خانة الضريبة لا يؤثر على المبلغ | G40: E×F×1.15 | H40: وُحدت إلى: العدد×السعر×(الضريبة إن وجدت)
A41: 37 | B41: ورقة1 | C41: - | D41: منخفضة | E41: هيكلة | F41: ورقة فارغة بلا بيانات | H41: حُذفت من الملف

Sheet المزارع المبدع
B1: كشف حساب — المزارع المبدع
B2: حساب مورد — المدين: مشتريات (مستحق علينا) · الدائن: مدفوعات وخصومات
B3: ملخص | D3: من تاريخ | E3: إلى تاريخ | F3: إجمالي المدين | G3: إجمالي الدائن | H3: الرصيد | I3: ضريبة القيمة المضافة | J3: آخر سداد | K3: الحالة | L3: الخانات الصفراء = إدخال يدوي · باقي الأعمدة معادلات. للإضافة: اكتب في أول صف فارغ.
D4: =IF(COUNT(C7:C1000)=0,"",MIN(C7:C1000)) -> 46296 | E4: =IF(COUNT(C7:C1000)=0,"",MAX(C7:C1000)) -> 46297 | F4: =SUM(H7:H1000) -> 60 | G4: =SUM(I7:I1000) -> 60 | H4: =ROUND(F4-G4,2) -> 0 | I4: =ROUND(SUMPRODUCT((G7:G1000>1)*E7:E1000*F7:F1000*(G7:G1000-1)),2) -> 0 | J4: =IF(COUNTIFS(I7:I1000,">0",E7:E1000,"")=0,"",_xlfn.MAXIFS(C7:C1000,I7:I1000,">0",E7:E1000,"")) | K4: =IF(ABS(H4)<0.01,"مسدد",IF(H4>0,"مستحق علينا","رصيد لنا")) -> مسدد
B5: ← العودة للملخص
B6: اليوم | C6: التاريخ | D6: البيان / الصنف | E6: العدد | F6: السعر | G6: ضريبة (1.15 أو 0) | H6: مدين (علينا) | I6: دائن (مدفوع) | J6: الرصيد التراكمي | K6: المرجع (سند/فاتورة) | L6: ملاحظات التدقيق
B7: =IF(C7="","",CHOOSE(WEEKDAY(C7),"الأحد","الاثنين","الثلاثاء","الأربعاء","الخميس","الجمعة","السبت")) -> الخميس | C7: 46296 | D7: حبحب | E7: 2 | F7: 30 | G7: 0 | I7: =ROUND(E7*F7*IF(G7>1,G7,1),2) -> 60 | J7: =IF(COUNTA(C7:D7)=0,"",ROUND(SUM(H$7:H7)-SUM(I$7:I7),2)) -> -60 | L7: قيد عكسي: يرجى التأكيد
B8: =IF(C8="","",CHOOSE(WEEKDAY(C8),"الأحد","الاثنين","الثلاثاء","الأربعاء","الخميس","الجمعة","السبت")) -> الجمعة | C8: 46297 | D8: سداد | H8: 60 | J8: =IF(COUNTA(C8:D8)=0,"",ROUND(SUM(H$7:H8)-SUM(I$7:I8),2)) -> 0 | L8: قيد عكسي: يرجى التأكيد
B9: =IF(C9="","",CHOOSE(WEEKDAY(C9),"الأحد","الاثنين","الثلاثاء","الأربعاء","الخميس","الجمعة","السبت")) | J9: =IF(COUNTA(C9:D9)=0,"",ROUND(SUM(H$7:H9)-SUM(I$7:I9),2))
B10: =IF(C10="","",CHOOSE(WEEKDAY(C10),"الأحد","الاثنين","الثلاثاء","الأربعاء","الخميس","الجمعة","السبت")) | J10: =IF(COUNTA(C10:D10)=0,"",ROUND(SUM(H$7:H10)-SUM(I$7:I10),2))
B11: =IF(C11="","",CHOOSE(WEEKDAY(C11),"الأحد","الاثنين","الثلاثاء","الأربعاء","الخميس","الجمعة","السبت")) | J11: =IF(COUNTA(C11:D11)=0,"",ROUND(SUM(H$7:H11)-SUM(I$7:I11),2))
B12: =IF(C12="","",CHOOSE(WEEKDAY(C12),"الأحد","الاثنين","الثلاثاء","الأربعاء","الخميس","الجمعة","السبت")) | J12: =IF(COUNTA(C12:D12)=0,"",ROUND(SUM(H$7:H12)-SUM(I$7:I12),2))
B13: =IF(C13="","",CHOOSE(WEEKDAY(C13),"الأحد","الاثنين","الثلاثاء","الأربعاء","الخميس","الجمعة","السبت")) | J13: =IF(COUNTA(C13:D13)=0,"",ROUND(SUM(H$7:H13)-SUM(I$7:I13),2))
B14: =IF(C14="","",CHOOSE(WEEKDAY(C14),"الأحد","الاثنين","الثلاثاء","الأربعاء","الخميس","الجمعة","السبت")) | J14: =IF(COUNTA(C14:D14)=0,"",ROUND(SUM(H$7:H14)-SUM(I$7:I14),2))
B15: =IF(C15="","",CHOOSE(WEEKDAY(C15),"الأحد","الاثنين","الثلاثاء","الأربعاء","الخميس","الجمعة","السبت")) | J15: =IF(COUNTA(C15:D15)=0,"",ROUND(SUM(H$7:H15)-SUM(I$7:I15),2))
B16: =IF(C16="","",CHOOSE(WEEKDAY(C16),"الأحد","الاثنين","الثلاثاء","الأربعاء","الخميس","الجمعة","السبت")) | J16: =IF(COUNTA(C16:D16)=0,"",ROUND(SUM(H$7:H16)-SUM(I$7:I16),2))
B17: =IF(C17="","",CHOOSE(WEEKDAY(C17),"الأحد","الاثنين","الثلاثاء","الأربعاء","الخميس","الجمعة","السبت")) | J17: =IF(COUNTA(C17:D17)=0,"",ROUND(SUM(H$7:H17)-SUM(I$7:I17),2))
B18: =IF(C18="","",CHOOSE(WEEKDAY(C18),"الأحد","الاثنين","الثلاثاء","الأربعاء","الخميس","الجمعة","السبت")) | J18: =IF(COUNTA(C18:D18)=0,"",ROUND(SUM(H$7:H18)-SUM(I$7:I18),2))
B19: =IF(C19="","",CHOOSE(WEEKDAY(C19),"الأحد","الاثنين","الثلاثاء","الأربعاء","الخميس","الجمعة","السبت")) | J19: =IF(COUNTA(C19:D19)=0,"",ROUND(SUM(H$7:H19)-SUM(I$7:I19),2))
B20: =IF(C20="","",CHOOSE(WEEKDAY(C20),"الأحد","الاثنين","الثلاثاء","الأربعاء","الخميس","الجمعة","السبت")) | J20: =IF(COUNTA(C20:D20)=0,"",ROUND(SUM(H$7:H20)-SUM(I$7:I20),2))
... B48: =IF(C48="","",CHOOSE(WEEKDAY(C48),"الأحد","الاثنين","الثلاثاء","الأربعاء","الخميس","الجمعة","السبت")) | J48: =IF(COUNTA(C48:D48)=0,"",ROUND(SUM(H$7:H48)-SUM(I$7:I48),2))

Sheet العلواني
B1: كشف حساب — العلواني
B2: حساب مورد — المدين: مشتريات (مستحق علينا) · الدائن: مدفوعات وخصومات
B3: ملخص | D3: من تاريخ | E3: إلى تاريخ | F3: إجمالي المدين | G3: إجمالي الدائن | H3: الرصيد | I3: ضريبة القيمة المضافة | J3: آخر سداد | K3: الحالة | L3: الخانات الصفراء = إدخال يدوي · باقي الأعمدة معادلات. للإضافة: اكتب في أول صف فارغ.
D4: =IF(COUNT(C7:C1000)=0,"",MIN(C7:C1000)) -> 46318 | E4: =IF(COUNT(C7:C1000)=0,"",MAX(C7:C1000)) -> 46324 | F4: =SUM(H7:H1000) -> 3622.5 | G4: =SUM(I7:I1000) -> 2000 | H4: =ROUND(F4-G4,2) -> 1622.5 | I4: =ROUND(SUMPRODUCT((G7:G1000>1)*E7:E1000*F7:F1000*(G7:G1000-1)),2) -> 472.5 | J4: =IF(COUNTIFS(I7:I1000,">0",E7:E1000,"")=0,"",_xlfn.MAXIFS(C7:C1000,I7:I1000,">0",E7:E1000,"")) -> 46324 | K4: =IF(ABS(H4)<0.01,"مسدد",IF(H4>0,"مستحق علينا","رصيد لنا")) -> مستحق علينا
B5: ← العودة للملخص
B6: اليوم | C6: التاريخ | D6: البيان / الصنف | E6: العدد | F6: السعر | G6: ضريبة (1.15 أو 0) | H6: مدين (علينا) | I6: دائن (مدفوع) | J6: الرصيد التراكمي | K6: المرجع (سند/فاتورة) | L6: ملاحظات التدقيق
B7: =IF(C7="","",CHOOSE(WEEKDAY(C7),"الأحد","الاثنين","الثلاثاء","الأربعاء","الخميس","الجمعة","السبت")) -> الجمعة | C7: 46318 | D7: ليمون | E7: 70 | F7: 45 | G7: 1.15 | H7: =ROUND(E7*F7*IF(G7>1,G7,1),2) -> 3622.5 | J7: =IF(COUNTA(C7:D7)=0,"",ROUND(SUM(H$7:H7)-SUM(I$7:I7),2)) -> 3622.5
B8: =IF(C8="","",CHOOSE(WEEKDAY(C8),"الأحد","الاثنين","الثلاثاء","الأربعاء","الخميس","الجمعة","السبت")) -> الخميس | C8: 46324 | D8: سداد سند/76204 | I8: 2000 | J8: =IF(COUNTA(C8:D8)=0,"",ROUND(SUM(H$7:H8)-SUM(I$7:I8),2)) -> 1622.5 | K8: سند 76204
B9: =IF(C9="","",CHOOSE(WEEKDAY(C9),"الأحد","الاثنين","الثلاثاء","الأربعاء","الخميس","الجمعة","السبت")) | J9: =IF(COUNTA(C9:D9)=0,"",ROUND(SUM(H$7:H9)-SUM(I$7:I9),2))
B10: =IF(C10="","",CHOOSE(WEEKDAY(C10),"الأحد","الاثنين","الثلاثاء","الأربعاء","الخميس","الجمعة","السبت")) | J10: =IF(COUNTA(C10:D10)=0,"",ROUND(SUM(H$7:H10)-SUM(I$7:I10),2))
B11: =IF(C11="","",CHOOSE(WEEKDAY(C11),"الأحد","الاثنين","الثلاثاء","الأربعاء","الخميس","الجمعة","السبت")) | J11: =IF(COUNTA(C11:D11)=0,"",ROUND(SUM(H$7:H11)-SUM(I$7:I11),2))
B12: =IF(C12="","",CHOOSE(WEEKDAY(C12),"الأحد","الاثنين","الثلاثاء","الأربعاء","الخميس","الجمعة","السبت")) | J12: =IF(COUNTA(C12:D12)=0,"",ROUND(SUM(H$7:H12)-SUM(I$7:I12),2))
B13: =IF(C13="","",CHOOSE(WEEKDAY(C13),"الأحد","الاثنين","الثلاثاء","الأربعاء","الخميس","الجمعة","السبت")) | J13: =IF(COUNTA(C13:D13)=0,"",ROUND(SUM(H$7:H13)-SUM(I$7:I13),2))
B14: =IF(C14="","",CHOOSE(WEEKDAY(C14),"الأحد","الاثنين","الثلاثاء","الأربعاء","الخميس","الجمعة","السبت")) | J14: =IF(COUNTA(C14:D14)=0,"",ROUND(SUM(H$7:H14)-SUM(I$7:I14),2))
B15: =IF(C15="","",CHOOSE(WEEKDAY(C15),"الأحد","الاثنين","الثلاثاء","الأربعاء","الخميس","الجمعة","السبت")) | J15: =IF(COUNTA(C15:D15)=0,"",ROUND(SUM(H$7:H15)-SUM(I$7:I15),2))
B16: =IF(C16="","",CHOOSE(WEEKDAY(C16),"الأحد","الاثنين","الثلاثاء","الأربعاء","الخميس","الجمعة","السبت")) | J16: =IF(COUNTA(C16:D16)=0,"",ROUND(SUM(H$7:H16)-SUM(I$7:I16),2))
B17: =IF(C17="","",CHOOSE(WEEKDAY(C17),"الأحد","الاثنين","الثلاثاء","الأربعاء","الخميس","الجمعة","السبت")) | J17: =IF(COUNTA(C17:D17)=0,"",ROUND(SUM(H$7:H17)-SUM(I$7:I17),2))
B18: =IF(C18="","",CHOOSE(WEEKDAY(C18),"الأحد","الاثنين","الثلاثاء","الأربعاء","الخميس","الجمعة","السبت")) | J18: =IF(COUNTA(C18:D18)=0,"",ROUND(SUM(H$7:H18)-SUM(I$7:I18),2))
B19: =IF(C19="","",CHOOSE(WEEKDAY(C19),"الأحد","الاثنين","الثلاثاء","الأربعاء","الخميس","الجمعة","السبت")) | J19: =IF(COUNTA(C19:D19)=0,"",ROUND(SUM(H$7:H19)-SUM(I$7:I19),2))
B20: =IF(C20="","",CHOOSE(WEEKDAY(C20),"الأحد","الاثنين","الثلاثاء","الأربعاء","الخميس","الجمعة","السبت")) | J20: =IF(COUNTA(C20:D20)=0,"",ROUND(SUM(H$7:H20)-SUM(I$7:I20),2))
... B48: =IF(C48="","",CHOOSE(WEEKDAY(C48),"الأحد","الاثنين","الثلاثاء","الأربعاء","الخميس","الجمعة","السبت")) | J48: =IF(COUNTA(C48:D48)=0,"",ROUND(SUM(H$7:H48)-SUM(I$7:I48),2))

Sheet رجب المصري
B1: كشف حساب — رجب المصري
B2: حساب مورد — المدين: مشتريات (مستحق علينا) · الدائن: مدفوعات وخصومات
B3: ملخص | D3: من تاريخ | E3: إلى تاريخ | F3: إجمالي المدين | G3: إجمالي الدائن | H3: الرصيد | I3: ضريبة القيمة المضافة | J3: آخر سداد | K3: الحالة | L3: الخانات الصفراء = إدخال يدوي · باقي الأعمدة معادلات. للإضافة: اكتب في أول صف فارغ.
D4: =IF(COUNT(C7:C1000)=0,"",MIN(C7:C1000)) -> 46324 | E4: =IF(COUNT(C7:C1000)=0,"",MAX(C7:C1000)) -> 46324 | F4: =SUM(H7:H1000) -> 3047.5 | G4: =SUM(I7:I1000) -> 0 | H4: =ROUND(F4-G4,2) -> 3047.5 | I4: =ROUND(SUMPRODUCT((G7:G1000>1)*E7:E1000*F7:F1000*(G7:G1000-1)),2) -> 397.5 | J4: =IF(COUNTIFS(I7:I1000,">0",E7:E1000,"")=0,"",_xlfn.MAXIFS(C7:C1000,I7:I1000,">0",E7:E1000,"")) | K4: =IF(ABS(H4)<0.01,"مسدد",IF(H4>0,"مستحق علينا","رصيد لنا")) -> مستحق علينا
B5: ← العودة للملخص
B6: اليوم | C6: التاريخ | D6: البيان / الصنف | E6: العدد | F6: السعر | G6: ضريبة (1.15 أو 0) | H6: مدين (علينا) | I6: دائن (مدفوع) | J6: الرصيد التراكمي | K6: المرجع (سند/فاتورة) | L6: ملاحظات التدقيق
B7: =IF(C7="","",CHOOSE(WEEKDAY(C7),"الأحد","الاثنين","الثلاثاء","الأربعاء","الخميس","الجمعة","السبت")) -> الخميس | C7: 46324 | D7: عنب تركي | E7: 53 | F7: 50 | G7: 1.15 | H7: =ROUND(E7*F7*IF(G7>1,G7,1),2) -> 3047.5 | J7: =IF(COUNTA(C7:D7)=0,"",ROUND(SUM(H$7:H7)-SUM(I$7:I7),2)) -> 3047.5
B8: =IF(C8="","",CHOOSE(WEEKDAY(C8),"الأحد","الاثنين","الثلاثاء","الأربعاء","الخميس","الجمعة","السبت")) | J8: =IF(COUNTA(C8:D8)=0,"",ROUND(SUM(H$7:H8)-SUM(I$7:I8),2))
B9: =IF(C9="","",CHOOSE(WEEKDAY(C9),"الأحد","الاثنين","الثلاثاء","الأربعاء","الخميس","الجمعة","السبت")) | J9: =IF(COUNTA(C9:D9)=0,"",ROUND(SUM(H$7:H9)-SUM(I$7:I9),2))
B10: =IF(C10="","",CHOOSE(WEEKDAY(C10),"الأحد","الاثنين","الثلاثاء","الأربعاء","الخميس","الجمعة","السبت")) | J10: =IF(COUNTA(C10:D10)=0,"",ROUND(SUM(H$7:H10)-SUM(I$7:I10),2))
B11: =IF(C11="","",CHOOSE(WEEKDAY(C11),"الأحد","الاثنين","الثلاثاء","الأربعاء","الخميس","الجمعة","السبت")) | J11: =IF(COUNTA(C11:D11)=0,"",ROUND(SUM(H$7:H11)-SUM(I$7:I11),2))
B12: =IF(C12="","",CHOOSE(WEEKDAY(C12),"الأحد","الاثنين","الثلاثاء","الأربعاء","الخميس","الجمعة","السبت")) | J12: =IF(COUNTA(C12:D12)=0,"",ROUND(SUM(H$7:H12)-SUM(I$7:I12),2))
B13: =IF(C13="","",CHOOSE(WEEKDAY(C13),"الأحد","الاثنين","الثلاثاء","الأربعاء","الخميس","الجمعة","السبت")) | J13: =IF(COUNTA(C13:D13)=0,"",ROUND(SUM(H$7:H13)-SUM(I$7:I13),2))
B14: =IF(C14="","",CHOOSE(WEEKDAY(C14),"الأحد","الاثنين","الثلاثاء","الأربعاء","الخميس","الجمعة","السبت")) | J14: =IF(COUNTA(C14:D14)=0,"",ROUND(SUM(H$7:H14)-SUM(I$7:I14),2))
B15: =IF(C15="","",CHOOSE(WEEKDAY(C15),"الأحد","الاثنين","الثلاثاء","الأربعاء","الخميس","الجمعة","السبت")) | J15: =IF(COUNTA(C15:D15)=0,"",ROUND(SUM(H$7:H15)-SUM(I$7:I15),2))
B16: =IF(C16="","",CHOOSE(WEEKDAY(C16),"الأحد","الاثنين","الثلاثاء","الأربعاء","الخميس","الجمعة","السبت")) | J16: =IF(COUNTA(C16:D16)=0,"",ROUND(SUM(H$7:H16)-SUM(I$7:I16),2))
B17: =IF(C17="","",CHOOSE(WEEKDAY(C17),"الأحد","الاثنين","الثلاثاء","الأربعاء","الخميس","الجمعة","السبت")) | J17: =IF(COUNTA(C17:D17)=0,"",ROUND(SUM(H$7:H17)-SUM(I$7:I17),2))
B18: =IF(C18="","",CHOOSE(WEEKDAY(C18),"الأحد","الاثنين","الثلاثاء","الأربعاء","الخميس","الجمعة","السبت")) | J18: =IF(COUNTA(C18:D18)=0,"",ROUND(SUM(H$7:H18)-SUM(I$7:I18),2))
B19: =IF(C19="","",CHOOSE(WEEKDAY(C19),"الأحد","الاثنين","الثلاثاء","الأربعاء","الخميس","الجمعة","السبت")) | J19: =IF(COUNTA(C19:D19)=0,"",ROUND(SUM(H$7:H19)-SUM(I$7:I19),2))
... B47: =IF(C47="","",CHOOSE(WEEKDAY(C47),"الأحد","الاثنين","الثلاثاء","الأربعاء","الخميس","الجمعة","السبت")) | J47: =IF(COUNTA(C47:D47)=0,"",ROUND(SUM(H$7:H47)-SUM(I$7:I47),2))

Sheet الجوهرة
B1: كشف حساب — الجوهرة
B2: حساب مورد — المدين: مشتريات (مستحق علينا) · الدائن: مدفوعات وخصومات
B3: ملخص | D3: من تاريخ | E3: إلى تاريخ | F3: إجمالي المدين | G3: إجمالي الدائن | H3: الرصيد | I3: ضريبة القيمة المضافة | J3: آخر سداد | K3: الحالة | L3: الخانات الصفراء = إدخال يدوي · باقي الأعمدة معادلات. للإضافة: اكتب في أول صف فارغ.
D4: =IF(COUNT(C7:C1000)=0,"",MIN(C7:C1000)) -> 46318 | E4: =IF(COUNT(C7:C1000)=0,"",MAX(C7:C1000)) -> 46325 | F4: =SUM(H7:H1000) -> 11365.45 | G4: =SUM(I7:I1000) -> 6000 | H4: =ROUND(F4-G4,2) -> 5365.45 | I4: =ROUND(SUMPRODUCT((G7:G1000>1)*E7:E1000*F7:F1000*(G7:G1000-1)),2) -> 1482.45 | J4: =IF(COUNTIFS(I7:I1000,">0",E7:E1000,"")=0,"",_xlfn.MAXIFS(C7:C1000,I7:I1000,">0",E7:E1000,"")) -> 46325 | K4: =IF(ABS(H4)<0.01,"مسدد",IF(H4>0,"مستحق علينا","رصيد لنا")) -> مستحق علينا
B5: ← العودة للملخص
B6: اليوم | C6: التاريخ | D6: البيان / الصنف | E6: العدد | F6: السعر | G6: ضريبة (1.15 أو 0) | H6: مدين (علينا) | I6: دائن (مدفوع) | J6: الرصيد التراكمي | K6: المرجع (سند/فاتورة) | L6: ملاحظات التدقيق
B7: =IF(C7="","",CHOOSE(WEEKDAY(C7),"الأحد","الاثنين","الثلاثاء","الأربعاء","الخميس","الجمعة","السبت")) -> الجمعة | C7: 46318 | D7: برتقال عصير | E7: 79 | F7: 85 | G7: 1.15 | H7: =ROUND(E7*F7*IF(G7>1,G7,1),2) -> 7722.25 | J7: =IF(COUNTA(C7:D7)=0,"",ROUND(SUM(H$7:H7)-SUM(I$7:I7),2)) -> 7722.25
B8: =IF(C8="","",CHOOSE(WEEKDAY(C8),"الأحد","الاثنين","الثلاثاء","الأربعاء","الخميس","الجمعة","السبت")) -> السبت | C8: 46319 | D8: سداد سند/19041 | I8: 1000 | J8: =IF(COUNTA(C8:D8)=0,"",ROUND(SUM(H$7:H8)-SUM(I$7:I8),2)) -> 6722.25 | K8: سند 19041
B9: =IF(C9="","",CHOOSE(WEEKDAY(C9),"الأحد","الاثنين","الثلاثاء","الأربعاء","الخميس","الجمعة","السبت")) -> الاثنين | C9: 46321 | D9: سداد سند/19096 | I9: 1000 | J9: =IF(COUNTA(C9:D9)=0,"",ROUND(SUM(H$7:H9)-SUM(I$7:I9),2)) -> 5722.25 | K9: سند 19096
B10: =IF(C10="","",CHOOSE(WEEKDAY(C10),"الأحد","الاثنين","الثلاثاء","الأربعاء","الخميس","الجمعة","السبت")) -> الأربعاء | C10: 46323 | D10: سداد سند/19147 | I10: 2000 | J10: =IF(COUNTA(C10:D10)=0,"",ROUND(SUM(H$7:H10)-SUM(I$7:I10),2)) -> 3722.25 | K10: سند 19147
B11: =IF(C11="","",CHOOSE(WEEKDAY(C11),"الأحد","الاثنين","الثلاثاء","الأربعاء","الخميس","الجمعة","السبت")) -> الخميس | C11: 46324 | D11: كيوي | E11: 96 | F11: 33 | G11: 1.15 | H11: =ROUND(E11*F11*IF(G11>1,G11,1),2) -> 3643.2 | J11: =IF(COUNTA(C11:D11)=0,"",ROUND(SUM(H$7:H11)-SUM(I$7:I11),2)) -> 7365.45
