Workbook

Sheet تعليمات
A1: دليل الاستخدام
A3: طريقة الإدخال
A4: 1 | B4: سجّل العملاء في "دليل العملاء" والأصناف في "دليل الأصناف" (أول صف فارغ).
A5: 2 | B5: في "المبيعات اليومية" أدخل: التاريخ، العميل، الصنف، الكمية، سعر الوحدة، ونوع السعر.
A6: 3 | B6: كود الصنف والإجماليات والضريبة وحالة السطر تُحسب تلقائياً — لا تكتب فيها.
A7: 4 | B7: عمود "حالة السطر" ينبّهك بأي نقص أو خطأ في السطر، وبطاقة "سطور تحتاج مراجعة" تعرض عددها.
A8: 5 | B8: في أوراق الملخص اختر "من تاريخ / إلى تاريخ" لعرض فترة محددة، أو اتركهما فارغين لكل الفترات.
A9: 6 | B9: نسبة الضريبة واسم المنشأة تُعدَّل من ورقة "الإعدادات" فقط.
A10: دليل الألوان
A11: خلفية صفراء + خط أزرق | B11: خلايا إدخال.
A12: خط أسود | B12: معادلات تلقائية — لا تعدّلها.
A13: أحمر | B13: خطأ أو تكرار يحتاج مراجعة.
A14: العمل على Google Sheets و Google Drive
A15: 1 | B15: ارفع الملف إلى Google Drive، ثم انقر عليه بالزر الأيمن ← فتح باستخدام ← جداول بيانات Google.
A16: 2 | B16: للتحويل الكامل: ملف ← حفظ كجداول بيانات Google (يمكن بعدها مشاركته والعمل عليه من أكثر من جهاز).
A17: 3 | B17: كل المعادلات والقوائم المنسدلة والتنسيق الشرطي متوافقة مع Google Sheets و Excel معاً.
A18: 4 | B18: لتنزيله مرة أخرى كملف Excel: ملف ← تنزيل ← Microsoft Excel (.xlsx).
A19: 5 | B19: للتشغيل على الجوال استخدم تطبيق Google Sheets — القوائم المنسدلة تعمل باللمس.
A20: ملاحظات
A21: • | B21: الشاشة تتسع لـ 300 عملية، و100 عميل، و200 صنف. عند امتلاء الصفوف: انسخ آخر صف وألصقه أسفله.
A22: • | B22: الحساب لكل سطر يُقرَّب إلى هللتين؛ في السعر الشامل يُستخرج الصافي = الإجمالي ÷ (1 + نسبة الضريبة).
A23: • | B23: بيانات العمليات الأصلية أُعطيت تاريخ 2026/10/24 (لم يكن في الملف الأصلي عمود تاريخ) — عدّله حسب الحاجة.

Sheet المبيعات اليومية
A1: شاشة المبيعات اليومية وتتبع العملاء
A2: ="تاريخ التقرير: "&TEXT(TODAY(),"yyyy/mm/dd")&" | "&الإعدادات!$B$4&" | نسبة الضريبة: "&TEXT(الإعدادات!$B$5,"0%") -> تاريخ التقرير: 2026/10/24 | مؤسسة توريد الخضار والفواكه | نسبة الضريبة: 15%
A4: إجمالي المبيعات (شامل الضريبة) | C4: إجمالي المبيعات قبل الضريبة | E4: إجمالي الضريبة | G4: مبيعات اليوم (شامل الضريبة) | I4: عدد العمليات المسجلة | K4: سطور تحتاج مراجعة
A5: =SUM($J$9:$J$308) -> 13736.18 | C5: =SUM($H$9:$H$308) -> 11944.5 | E5: =SUM($I$9:$I$308) -> 1791.68 | G5: =SUMIFS($J$9:$J$308,$A$9:$A$308,TODAY()) -> 13736.18 | I5: =COUNTIF($B$9:$B$308,"?*") -> 8 | K5: =COUNTIF($L$9:$L$308,"⚠*") -> 0
A7: الخلايا الصفراء بخط أزرق للإدخال — باقي الأعمدة تُحسب تلقائياً. اترك "نوع السعر" فارغاً ليُعامل كـ "غير شامل الضريبة".
A8: التاريخ | B8: اسم العميل (اختر من القائمة) | C8: اسم الصنف (اختر من القائمة) | D8: كود الصنف (تلقائي) | E8: الكمية | F8: سعر الوحدة | G8: نوع السعر | H8: الإجمالي قبل الضريبة | I8: مبلغ الضريبة | J8: الإجمالي شامل الضريبة | K8: ملاحظات | L8: حالة السطر (تلقائي)
A9: 46319 | B9: شركة التخصص الذهبي -الربوه | C9: بصل كبير | D9: =IF(C9="","",IFERROR(INDEX('دليل الأصناف'!$A$4:$A$203,MATCH(C9,'دليل الأصناف'!$B$4:$B$203,0)),"غير مسجل")) -> 20211 | E9: 470 | F9: 4.5 | G9: غير شامل الضريبة | H9: =IF(OR(E9="",F9=""),0,IF(G9="شامل الضريبة",ROUND(ROUND(E9*F9,2)/(1+الإعدادات!$B$5),2),ROUND(E9*F9,2))) -> 2115 | I9: =IF(OR(E9="",F9=""),0,IF(G9="شامل الضريبة",ROUND(E9*F9,2)-H9,ROUND(H9*الإعدادات!$B$5,2))) -> 317.25 | J9: =H9+I9 -> 2432.25 | K9: توريد صباحي | L9: =IF(AND(B9="",C9="",E9="",F9=""),"",IF(B9="","⚠ اختر العميل",IF(COUNTIF('دليل العملاء'!$B$4:$B$203,B9)=0,"⚠ عميل غير مسجل",IF(C9="","⚠ اختر الصنف",IF(COUNTIF('دليل الأصناف'!$B$4:$B$203,C9)=0,"⚠ صنف غير مسجل",IF(E9="","⚠ أدخل الكمية",IF(F9="","⚠ أدخل السعر",IF(A9="","⚠ أدخل التاريخ","✓ سليم")))))))) -> ✓ سليم
A10: 46319 | B10: شركة التخصص الذهبي -حراء | C10: بطاطس كبير | D10: =IF(C10="","",IFERROR(INDEX('دليل الأصناف'!$A$4:$A$203,MATCH(C10,'دليل الأصناف'!$B$4:$B$203,0)),"غير مسجل")) -> 20213 | E10: 297 | F10: 9.775 | G10: شامل الضريبة | H10: =IF(OR(E10="",F10=""),0,IF(G10="شامل الضريبة",ROUND(ROUND(E10*F10,2)/(1+الإعدادات!$B$5),2),ROUND(E10*F10,2))) -> 2524.5 | I10: =IF(OR(E10="",F10=""),0,IF(G10="شامل الضريبة",ROUND(E10*F10,2)-H10,ROUND(H10*الإعدادات!$B$5,2))) -> 378.68 | J10: =H10+I10 -> 2903.18 | K10: فرع حراء | L10: =IF(AND(B10="",C10="",E10="",F10=""),"",IF(B10="","⚠ اختر العميل",IF(COUNTIF('دليل العملاء'!$B$4:$B$203,B10)=0,"⚠ عميل غير مسجل",IF(C10="","⚠ اختر الصنف",IF(COUNTIF('دليل الأصناف'!$B$4:$B$203,C10)=0,"⚠ صنف غير مسجل",IF(E10="","⚠ أدخل الكمية",IF(F10="","⚠ أدخل السعر",IF(A10="","⚠ أدخل التاريخ","✓ سليم")))))))) -> ✓ سليم
A11: 46319 | B11: شركة التخصص الذهبي -الصفا | C11: بصل ابيض | D11: =IF(C11="","",IFERROR(INDEX('دليل الأصناف'!$A$4:$A$203,MATCH(C11,'دليل الأصناف'!$B$4:$B$203,0)),"غير مسجل")) -> 448660 | E11: 150 | F11: 5 | G11: غير شامل الضريبة | H11: =IF(OR(E11="",F11=""),0,IF(G11="شامل الضريبة",ROUND(ROUND(E11*F11,2)/(1+الإعدادات!$B$5),2),ROUND(E11*F11,2))) -> 750 | I11: =IF(OR(E11="",F11=""),0,IF(G11="شامل الضريبة",ROUND(E11*F11,2)-H11,ROUND(H11*الإعدادات!$B$5,2))) -> 112.5 | J11: =H11+I11 -> 862.5 | K11: طلب خاص | L11: =IF(AND(B11="",C11="",E11="",F11=""),"",IF(B11="","⚠ اختر العميل",IF(COUNTIF('دليل العملاء'!$B$4:$B$203,B11)=0,"⚠ عميل غير مسجل",IF(C11="","⚠ اختر الصنف",IF(COUNTIF('دليل الأصناف'!$B$4:$B$203,C11)=0,"⚠ صنف غير مسجل",IF(E11="","⚠ أدخل الكمية",IF(F11="","⚠ أدخل السعر",IF(A11="","⚠ أدخل التاريخ","✓ سليم")))))))) -> ✓ سليم
A12: 46319 | B12: عبر الإقليم | C12: رمان | D12: =IF(C12="","",IFERROR(INDEX('دليل الأصناف'!$A$4:$A$203,MATCH(C12,'دليل الأصناف'!$B$4:$B$203,0)),"غير مسجل")) -> 20227 | E12: 200 | F12: 9.2 | G12: شامل الضريبة | H12: =IF(OR(E12="",F12=""),0,IF(G12="شامل الضريبة",ROUND(ROUND(E12*F12,2)/(1+الإعدادات!$B$5),2),ROUND(E12*F12,2))) -> 1600 | I12: =IF(OR(E12="",F12=""),0,IF(G12="شامل الضريبة",ROUND(E12*F12,2)-H12,ROUND(H12*الإعدادات!$B$5,2))) -> 240 | J12: =H12+I12 -> 1840 | K12: آجل 30 يوم | L12: =IF(AND(B12="",C12="",E12="",F12=""),"",IF(B12="","⚠ اختر العميل",IF(COUNTIF('دليل العملاء'!$B$4:$B$203,B12)=0,"⚠ عميل غير مسجل",IF(C12="","⚠ اختر الصنف",IF(COUNTIF('دليل الأصناف'!$B$4:$B$203,C12)=0,"⚠ صنف غير مسجل",IF(E12="","⚠ أدخل الكمية",IF(F12="","⚠ أدخل السعر",IF(A12="","⚠ أدخل التاريخ","✓ سليم")))))))) -> ✓ سليم
A13: 46319 | B13: حقيبة الفواكه | C13: تفاح احمر | D13: =IF(C13="","",IFERROR(INDEX('دليل الأصناف'!$A$4:$A$203,MATCH(C13,'دليل الأصناف'!$B$4:$B$203,0)),"غير مسجل")) -> 20225 | E13: 150 | F13: 7.5 | G13: غير شامل الضريبة | H13: =IF(OR(E13="",F13=""),0,IF(G13="شامل الضريبة",ROUND(ROUND(E13*F13,2)/(1+الإعدادات!$B$5),2),ROUND(E13*F13,2))) -> 1125 | I13: =IF(OR(E13="",F13=""),0,IF(G13="شامل الضريبة",ROUND(E13*F13,2)-H13,ROUND(H13*الإعدادات!$B$5,2))) -> 168.75 | J13: =H13+I13 -> 1293.75 | K13: طلب مميز | L13: =IF(AND(B13="",C13="",E13="",F13=""),"",IF(B13="","⚠ اختر العميل",IF(COUNTIF('دليل العملاء'!$B$4:$B$203,B13)=0,"⚠ عميل غير مسجل",IF(C13="","⚠ اختر الصنف",IF(COUNTIF('دليل الأصناف'!$B$4:$B$203,C13)=0,"⚠ صنف غير مسجل",IF(E13="","⚠ أدخل الكمية",IF(F13="","⚠ أدخل السعر",IF(A13="","⚠ أدخل التاريخ","✓ سليم")))))))) -> ✓ سليم
A14: 46319 | B14: فيض الكرم | C14: عنب ابيض | D14: =IF(C14="","",IFERROR(INDEX('دليل الأصناف'!$A$4:$A$203,MATCH(C14,'دليل الأصناف'!$B$4:$B$203,0)),"غير مسجل")) -> 20218 | E14: 80 | F14: 14.375 | G14: شامل الضريبة | H14: =IF(OR(E14="",F14=""),0,IF(G14="شامل الضريبة",ROUND(ROUND(E14*F14,2)/(1+الإعدادات!$B$5),2),ROUND(E14*F14,2))) -> 1000 | I14: =IF(OR(E14="",F14=""),0,IF(G14="شامل الضريبة",ROUND(E14*F14,2)-H14,ROUND(H14*الإعدادات!$B$5,2))) -> 150 | J14: =H14+I14 -> 1150 | K14: كاش | L14: =IF(AND(B14="",C14="",E14="",F14=""),"",IF(B14="","⚠ اختر العميل",IF(COUNTIF('دليل العملاء'!$B$4:$B$203,B14)=0,"⚠ عميل غير مسجل",IF(C14="","⚠ اختر الصنف",IF(COUNTIF('دليل الأصناف'!$B$4:$B$203,C14)=0,"⚠ صنف غير مسجل",IF(E14="","⚠ أدخل الكمية",IF(F14="","⚠ أدخل السعر",IF(A14="","⚠ أدخل التاريخ","✓ سليم")))))))) -> ✓ سليم
A15: 46319 | B15: غصون الفاكهه | C15: برتقال عصير | D15: =IF(C15="","",IFERROR(INDEX('دليل الأصناف'!$A$4:$A$203,MATCH(C15,'دليل الأصناف'!$B$4:$B$203,0)),"غير مسجل")) -> 20221 | E15: 350 | F15: 5 | G15: غير شامل الضريبة | H15: =IF(OR(E15="",F15=""),0,IF(G15="شامل الضريبة",ROUND(ROUND(E15*F15,2)/(1+الإعدادات!$B$5),2),ROUND(E15*F15,2))) -> 1750 | I15: =IF(OR(E15="",F15=""),0,IF(G15="شامل الضريبة",ROUND(E15*F15,2)-H15,ROUND(H15*الإعدادات!$B$5,2))) -> 262.5 | J15: =H15+I15 -> 2012.5 | K15: تسليم موقع | L15: =IF(AND(B15="",C15="",E15="",F15=""),"",IF(B15="","⚠ اختر العميل",IF(COUNTIF('دليل العملاء'!$B$4:$B$203,B15)=0,"⚠ عميل غير مسجل",IF(C15="","⚠ اختر الصنف",IF(COUNTIF('دليل الأصناف'!$B$4:$B$203,C15)=0,"⚠ صنف غير مسجل",IF(E15="","⚠ أدخل الكمية",IF(F15="","⚠ أدخل السعر",IF(A15="","⚠ أدخل التاريخ","✓ سليم")))))))) -> ✓ سليم
A16: 46319 | B16: نقاوه بس | C16: فراوله | D16: =IF(C16="","",IFERROR(INDEX('دليل الأصناف'!$A$4:$A$203,MATCH(C16,'دليل الأصناف'!$B$4:$B$203,0)),"غير مسجل")) -> 20224 | E16: 120 | F16: 10.35 | G16: شامل الضريبة | H16: =IF(OR(E16="",F16=""),0,IF(G16="شامل الضريبة",ROUND(ROUND(E16*F16,2)/(1+الإعدادات!$B$5),2),ROUND(E16*F16,2))) -> 1080 | I16: =IF(OR(E16="",F16=""),0,IF(G16="شامل الضريبة",ROUND(E16*F16,2)-H16,ROUND(H16*الإعدادات!$B$5,2))) -> 162 | J16: =H16+I16 -> 1242 | K16: عميل جديد | L16: =IF(AND(B16="",C16="",E16="",F16=""),"",IF(B16="","⚠ اختر العميل",IF(COUNTIF('دليل العملاء'!$B$4:$B$203,B16)=0,"⚠ عميل غير مسجل",IF(C16="","⚠ اختر الصنف",IF(COUNTIF('دليل الأصناف'!$B$4:$B$203,C16)=0,"⚠ صنف غير مسجل",IF(E16="","⚠ أدخل الكمية",IF(F16="","⚠ أدخل السعر",IF(A16="","⚠ أدخل التاريخ","✓ سليم")))))))) -> ✓ سليم
D17: =IF(C17="","",IFERROR(INDEX('دليل الأصناف'!$A$4:$A$203,MATCH(C17,'دليل الأصناف'!$B$4:$B$203,0)),"غير مسجل")) | H17: =IF(OR(E17="",F17=""),0,IF(G17="شامل الضريبة",ROUND(ROUND(E17*F17,2)/(1+الإعدادات!$B$5),2),ROUND(E17*F17,2))) -> 0 | I17: =IF(OR(E17="",F17=""),0,IF(G17="شامل الضريبة",ROUND(E17*F17,2)-H17,ROUND(H17*الإعدادات!$B$5,2))) -> 0 | J17: =H17+I17 -> 0 | L17: =IF(AND(B17="",C17="",E17="",F17=""),"",IF(B17="","⚠ اختر العميل",IF(COUNTIF('دليل العملاء'!$B$4:$B$203,B17)=0,"⚠ عميل غير مسجل",IF(C17="","⚠ اختر الصنف",IF(COUNTIF('دليل الأصناف'!$B$4:$B$203,C17)=0,"⚠ صنف غير مسجل",IF(E17="","⚠ أدخل الكمية",IF(F17="","⚠ أدخل السعر",IF(A17="","⚠ أدخل التاريخ","✓ سليم"))))))))
D18: =IF(C18="","",IFERROR(INDEX('دليل الأصناف'!$A$4:$A$203,MATCH(C18,'دليل الأصناف'!$B$4:$B$203,0)),"غير مسجل")) | H18: =IF(OR(E18="",F18=""),0,IF(G18="شامل الضريبة",ROUND(ROUND(E18*F18,2)/(1+الإعدادات!$B$5),2),ROUND(E18*F18,2))) -> 0 | I18: =IF(OR(E18="",F18=""),0,IF(G18="شامل الضريبة",ROUND(E18*F18,2)-H18,ROUND(H18*الإعدادات!$B$5,2))) -> 0 | J18: =H18+I18 -> 0 | L18: =IF(AND(B18="",C18="",E18="",F18=""),"",IF(B18="","⚠ اختر العميل",IF(COUNTIF('دليل العملاء'!$B$4:$B$203,B18)=0,"⚠ عميل غير مسجل",IF(C18="","⚠ اختر الصنف",IF(COUNTIF('دليل الأصناف'!$B$4:$B$203,C18)=0,"⚠ صنف غير مسجل",IF(E18="","⚠ أدخل الكمية",IF(F18="","⚠ أدخل السعر",IF(A18="","⚠ أدخل التاريخ","✓ سليم"))))))))
D19: =IF(C19="","",IFERROR(INDEX('دليل الأصناف'!$A$4:$A$203,MATCH(C19,'دليل الأصناف'!$B$4:$B$203,0)),"غير مسجل")) | H19: =IF(OR(E19="",F19=""),0,IF(G19="شامل الضريبة",ROUND(ROUND(E19*F19,2)/(1+الإعدادات!$B$5),2),ROUND(E19*F19,2))) -> 0 | I19: =IF(OR(E19="",F19=""),0,IF(G19="شامل الضريبة",ROUND(E19*F19,2)-H19,ROUND(H19*الإعدادات!$B$5,2))) -> 0 | J19: =H19+I19 -> 0 | L19: =IF(AND(B19="",C19="",E19="",F19=""),"",IF(B19="","⚠ اختر العميل",IF(COUNTIF('دليل العملاء'!$B$4:$B$203,B19)=0,"⚠ عميل غير مسجل",IF(C19="","⚠ اختر الصنف",IF(COUNTIF('دليل الأصناف'!$B$4:$B$203,C19)=0,"⚠ صنف غير مسجل",IF(E19="","⚠ أدخل الكمية",IF(F19="","⚠ أدخل السعر",IF(A19="","⚠ أدخل التاريخ","✓ سليم"))))))))
D20: =IF(C20="","",IFERROR(INDEX('دليل الأصناف'!$A$4:$A$203,MATCH(C20,'دليل الأصناف'!$B$4:$B$203,0)),"غير مسجل")) | H20: =IF(OR(E20="",F20=""),0,IF(G20="شامل الضريبة",ROUND(ROUND(E20*F20,2)/(1+الإعدادات!$B$5),2),ROUND(E20*F20,2))) -> 0 | I20: =IF(OR(E20="",F20=""),0,IF(G20="شامل الضريبة",ROUND(E20*F20,2)-H20,ROUND(H20*الإعدادات!$B$5,2))) -> 0 | J20: =H20+I20 -> 0 | L20: =IF(AND(B20="",C20="",E20="",F20=""),"",IF(B20="","⚠ اختر العميل",IF(COUNTIF('دليل العملاء'!$B$4:$B$203,B20)=0,"⚠ عميل غير مسجل",IF(C20="","⚠ اختر الصنف",IF(COUNTIF('دليل الأصناف'!$B$4:$B$203,C20)=0,"⚠ صنف غير مسجل",IF(E20="","⚠ أدخل الكمية",IF(F20="","⚠ أدخل السعر",IF(A20="","⚠ أدخل التاريخ","✓ سليم"))))))))
D21: =IF(C21="","",IFERROR(INDEX('دليل الأصناف'!$A$4:$A$203,MATCH(C21,'دليل الأصناف'!$B$4:$B$203,0)),"غير مسجل")) | H21: =IF(OR(E21="",F21=""),0,IF(G21="شامل الضريبة",ROUND(ROUND(E21*F21,2)/(1+الإعدادات!$B$5),2),ROUND(E21*F21,2))) -> 0 | I21: =IF(OR(E21="",F21=""),0,IF(G21="شامل الضريبة",ROUND(E21*F21,2)-H21,ROUND(H21*الإعدادات!$B$5,2))) -> 0 | J21: =H21+I21 -> 0 | L21: =IF(AND(B21="",C21="",E21="",F21=""),"",IF(B21="","⚠ اختر العميل",IF(COUNTIF('دليل العملاء'!$B$4:$B$203,B21)=0,"⚠ عميل غير مسجل",IF(C21="","⚠ اختر الصنف",IF(COUNTIF('دليل الأصناف'!$B$4:$B$203,C21)=0,"⚠ صنف غير مسجل",IF(E21="","⚠ أدخل الكمية",IF(F21="","⚠ أدخل السعر",IF(A21="","⚠ أدخل التاريخ","✓ سليم"))))))))
D22: =IF(C22="","",IFERROR(INDEX('دليل الأصناف'!$A$4:$A$203,MATCH(C22,'دليل الأصناف'!$B$4:$B$203,0)),"غير مسجل")) | H22: =IF(OR(E22="",F22=""),0,IF(G22="شامل الضريبة",ROUND(ROUND(E22*F22,2)/(1+الإعدادات!$B$5),2),ROUND(E22*F22,2))) -> 0 | I22: =IF(OR(E22="",F22=""),0,IF(G22="شامل الضريبة",ROUND(E22*F22,2)-H22,ROUND(H22*الإعدادات!$B$5,2))) -> 0 | J22: =H22+I22 -> 0 | L22: =IF(AND(B22="",C22="",E22="",F22=""),"",IF(B22="","⚠ اختر العميل",IF(COUNTIF('دليل العملاء'!$B$4:$B$203,B22)=0,"⚠ عميل غير مسجل",IF(C22="","⚠ اختر الصنف",IF(COUNTIF('دليل الأصناف'!$B$4:$B$203,C22)=0,"⚠ صنف غير مسجل",IF(E22="","⚠ أدخل الكمية",IF(F22="","⚠ أدخل السعر",IF(A22="","⚠ أدخل التاريخ","✓ سليم"))))))))
D23: =IF(C23="","",IFERROR(INDEX('دليل الأصناف'!$A$4:$A$203,MATCH(C23,'دليل الأصناف'!$B$4:$B$203,0)),"غير مسجل")) | H23: =IF(OR(E23="",F23=""),0,IF(G23="شامل الضريبة",ROUND(ROUND(E23*F23,2)/(1+الإعدادات!$B$5),2),ROUND(E23*F23,2))) -> 0 | I23: =IF(OR(E23="",F23=""),0,IF(G23="شامل الضريبة",ROUND(E23*F23,2)-H23,ROUND(H23*الإعدادات!$B$5,2))) -> 0 | J23: =H23+I23 -> 0 | L23: =IF(AND(B23="",C23="",E23="",F23=""),"",IF(B23="","⚠ اختر العميل",IF(COUNTIF('دليل العملاء'!$B$4:$B$203,B23)=0,"⚠ عميل غير مسجل",IF(C23="","⚠ اختر الصنف",IF(COUNTIF('دليل الأصناف'!$B$4:$B$203,C23)=0,"⚠ صنف غير مسجل",IF(E23="","⚠ أدخل الكمية",IF(F23="","⚠ أدخل السعر",IF(A23="","⚠ أدخل التاريخ","✓ سليم"))))))))
D24: =IF(C24="","",IFERROR(INDEX('دليل الأصناف'!$A$4:$A$203,MATCH(C24,'دليل الأصناف'!$B$4:$B$203,0)),"غير مسجل")) | H24: =IF(OR(E24="",F24=""),0,IF(G24="شامل الضريبة",ROUND(ROUND(E24*F24,2)/(1+الإعدادات!$B$5),2),ROUND(E24*F24,2))) -> 0 | I24: =IF(OR(E24="",F24=""),0,IF(G24="شامل الضريبة",ROUND(E24*F24,2)-H24,ROUND(H24*الإعدادات!$B$5,2))) -> 0 | J24: =H24+I24 -> 0 | L24: =IF(AND(B24="",C24="",E24="",F24=""),"",IF(B24="","⚠ اختر العميل",IF(COUNTIF('دليل العملاء'!$B$4:$B$203,B24)=0,"⚠ عميل غير مسجل",IF(C24="","⚠ اختر الصنف",IF(COUNTIF('دليل الأصناف'!$B$4:$B$203,C24)=0,"⚠ صنف غير مسجل",IF(E24="","⚠ أدخل الكمية",IF(F24="","⚠ أدخل السعر",IF(A24="","⚠ أدخل التاريخ","✓ سليم"))))))))
D25: =IF(C25="","",IFERROR(INDEX('دليل الأصناف'!$A$4:$A$203,MATCH(C25,'دليل الأصناف'!$B$4:$B$203,0)),"غير مسجل")) | H25: =IF(OR(E25="",F25=""),0,IF(G25="شامل الضريبة",ROUND(ROUND(E25*F25,2)/(1+الإعدادات!$B$5),2),ROUND(E25*F25,2))) -> 0 | I25: =IF(OR(E25="",F25=""),0,IF(G25="شامل الضريبة",ROUND(E25*F25,2)-H25,ROUND(H25*الإعدادات!$B$5,2))) -> 0 | J25: =H25+I25 -> 0 | L25: =IF(AND(B25="",C25="",E25="",F25=""),"",IF(B25="","⚠ اختر العميل",IF(COUNTIF('دليل العملاء'!$B$4:$B$203,B25)=0,"⚠ عميل غير مسجل",IF(C25="","⚠ اختر الصنف",IF(COUNTIF('دليل الأصناف'!$B$4:$B$203,C25)=0,"⚠ صنف غير مسجل",IF(E25="","⚠ أدخل الكمية",IF(F25="","⚠ أدخل السعر",IF(A25="","⚠ أدخل التاريخ","✓ سليم"))))))))
D26: =IF(C26="","",IFERROR(INDEX('دليل الأصناف'!$A$4:$A$203,MATCH(C26,'دليل الأصناف'!$B$4:$B$203,0)),"غير مسجل")) | H26: =IF(OR(E26="",F26=""),0,IF(G26="شامل الضريبة",ROUND(ROUND(E26*F26,2)/(1+الإعدادات!$B$5),2),ROUND(E26*F26,2))) -> 0 | I26: =IF(OR(E26="",F26=""),0,IF(G26="شامل الضريبة",ROUND(E26*F26,2)-H26,ROUND(H26*الإعدادات!$B$5,2))) -> 0 | J26: =H26+I26 -> 0 | L26: =IF(AND(B26="",C26="",E26="",F26=""),"",IF(B26="","⚠ اختر العميل",IF(COUNTIF('دليل العملاء'!$B$4:$B$203,B26)=0,"⚠ عميل غير مسجل",IF(C26="","⚠ اختر الصنف",IF(COUNTIF('دليل الأصناف'!$B$4:$B$203,C26)=0,"⚠ صنف غير مسجل",IF(E26="","⚠ أدخل الكمية",IF(F26="","⚠ أدخل السعر",IF(A26="","⚠ أدخل التاريخ","✓ سليم"))))))))
D27: =IF(C27="","",IFERROR(INDEX('دليل الأصناف'!$A$4:$A$203,MATCH(C27,'دليل الأصناف'!$B$4:$B$203,0)),"غير مسجل")) | H27: =IF(OR(E27="",F27=""),0,IF(G27="شامل الضريبة",ROUND(ROUND(E27*F27,2)/(1+الإعدادات!$B$5),2),ROUND(E27*F27,2))) -> 0 | I27: =IF(OR(E27="",F27=""),0,IF(G27="شامل الضريبة",ROUND(E27*F27,2)-H27,ROUND(H27*الإعدادات!$B$5,2))) -> 0 | J27: =H27+I27 -> 0 | L27: =IF(AND(B27="",C27="",E27="",F27=""),"",IF(B27="","⚠ اختر العميل",IF(COUNTIF('دليل العملاء'!$B$4:$B$203,B27)=0,"⚠ عميل غير مسجل",IF(C27="","⚠ اختر الصنف",IF(COUNTIF('دليل الأصناف'!$B$4:$B$203,C27)=0,"⚠ صنف غير مسجل",IF(E27="","⚠ أدخل الكمية",IF(F27="","⚠ أدخل السعر",IF(A27="","⚠ أدخل التاريخ","✓ سليم"))))))))
D28: =IF(C28="","",IFERROR(INDEX('دليل الأصناف'!$A$4:$A$203,MATCH(C28,'دليل الأصناف'!$B$4:$B$203,0)),"غير مسجل")) | H28: =IF(OR(E28="",F28=""),0,IF(G28="شامل الضريبة",ROUND(ROUND(E28*F28,2)/(1+الإعدادات!$B$5),2),ROUND(E28*F28,2))) -> 0 | I28: =IF(OR(E28="",F28=""),0,IF(G28="شامل الضريبة",ROUND(E28*F28,2)-H28,ROUND(H28*الإعدادات!$B$5,2))) -> 0 | J28: =H28+I28 -> 0 | L28: =IF(AND(B28="",C28="",E28="",F28=""),"",IF(B28="","⚠ اختر العميل",IF(COUNTIF('دليل العملاء'!$B$4:$B$203,B28)=0,"⚠ عميل غير مسجل",IF(C28="","⚠ اختر الصنف",IF(COUNTIF('دليل الأصناف'!$B$4:$B$203,C28)=0,"⚠ صنف غير مسجل",IF(E28="","⚠ أدخل الكمية",IF(F28="","⚠ أدخل السعر",IF(A28="","⚠ أدخل التاريخ","✓ سليم"))))))))
... D308: =IF(C308="","",IFERROR(INDEX('دليل الأصناف'!$A$4:$A$203,MATCH(C308,'دليل الأصناف'!$B$4:$B$203,0)),"غير مسجل")) | H308: =IF(OR(E308="",F308=""),0,IF(G308="شامل الضريبة",ROUND(ROUND(E308*F308,2)/(1+الإعدادات!$B$5),2),ROUND(E308*F308,2))) -> 0 | I308: =IF(OR(E308="",F308=""),0,IF(G308="شامل الضريبة",ROUND(E308*F308,2)-H308,ROUND(H308*الإعدادات!$B$5,2))) -> 0 | J308: =H308+I308 -> 0 | L308: =IF(AND(B308="",C308="",E308="",F308=""),"",IF(B308="","⚠ اختر العميل",IF(COUNTIF('دليل العملاء'!$B$4:$B$203,B308)=0,"⚠ عميل غير مسجل",IF(C308="","⚠ اختر الصنف",IF(COUNTIF('دليل الأصناف'!$B$4:$B$203,C308)=0,"⚠ صنف غير مسجل",IF(E308="","⚠ أدخل الكمية",IF(F308="","⚠ أدخل السعر",IF(A308="","⚠ أدخل التاريخ","✓ سليم"))))))))
A309: الإجمالي العام | E309: =SUM($E$9:$E$308) -> 1817 | H309: =SUM($H$9:$H$308) -> 11944.5 | I309: =SUM($I$9:$I$308) -> 1791.68 | J309: =SUM($J$9:$J$308) -> 13736.18

Sheet ملخص العملاء
A1: ملخص فواتير وحسابات العملاء
A2: يُحدَّث تلقائياً من ورقة "المبيعات اليومية" — اترك التاريخين فارغين لعرض كل الفترات
A4: من تاريخ | D4: =IF(AND(B4<>"",B5<>"",B4>B5),"⚠ تاريخ البداية بعد تاريخ النهاية","")
A5: إلى تاريخ
A7: م | B7: كود العميل | C7: اسم العميل | D7: عدد العمليات | E7: إجمالي الكمية | F7: الإجمالي قبل الضريبة | G7: إجمالي الضريبة | H7: الإجمالي شامل الضريبة | I7: النسبة من المبيعات | J7: حالة الحساب
A8: =IF(C8="","",1) -> 1 | B8: =IF('دليل العملاء'!$B$4="","",'دليل العملاء'!$A$4) -> 101 | C8: =IF('دليل العملاء'!$B$4="","",'دليل العملاء'!$B$4) -> شركة التخصص الذهبي -النسيم | D8: =IF($C8="","",IF($B$4&$B$5="",COUNTIFS('المبيعات اليومية'!$B$9:$B$308,$C8),COUNTIFS('المبيعات اليومية'!$B$9:$B$308,$C8,'المبيعات اليومية'!$A$9:$A$308,">="&IF($B$4="",0,$B$4),'المبيعات اليومية'!$A$9:$A$308,"<="&IF($B$5="",2958465,$B$5)))) -> 0 | E8: =IF($C8="","",IF($B$4&$B$5="",SUMIFS('المبيعات اليومية'!$E$9:$E$308,'المبيعات اليومية'!$B$9:$B$308,$C8),SUMIFS('المبيعات اليومية'!$E$9:$E$308,'المبيعات اليومية'!$B$9:$B$308,$C8,'المبيعات اليومية'!$A$9:$A$308,">="&IF($B$4="",0,$B$4),'المبيعات اليومية'!$A$9:$A$308,"<="&IF($B$5="",2958465,$B$5)))) -> 0 | F8: =IF($C8="","",IF($B$4&$B$5="",SUMIFS('المبيعات اليومية'!$H$9:$H$308,'المبيعات اليومية'!$B$9:$B$308,$C8),SUMIFS('المبيعات اليومية'!$H$9:$H$308,'المبيعات اليومية'!$B$9:$B$308,$C8,'المبيعات اليومية'!$A$9:$A$308,">="&IF($B$4="",0,$B$4),'المبيعات اليومية'!$A$9:$A$308,"<="&IF($B$5="",2958465,$B$5)))) -> 0 | G8: =IF($C8="","",IF($B$4&$B$5="",SUMIFS('المبيعات اليومية'!$I$9:$I$308,'المبيعات اليومية'!$B$9:$B$308,$C8),SUMIFS('المبيعات اليومية'!$I$9:$I$308,'المبيعات اليومية'!$B$9:$B$308,$C8,'المبيعات اليومية'!$A$9:$A$308,">="&IF($B$4="",0,$B$4),'المبيعات اليومية'!$A$9:$A$308,"<="&IF($B$5="",2958465,$B$5)))) -> 0 | H8: =IF($C8="","",IF($B$4&$B$5="",SUMIFS('المبيعات اليومية'!$J$9:$J$308,'المبيعات اليومية'!$B$9:$B$308,$C8),SUMIFS('المبيعات اليومية'!$J$9:$J$308,'المبيعات اليومية'!$B$9:$B$308,$C8,'المبيعات اليومية'!$A$9:$A$308,">="&IF($B$4="",0,$B$4),'المبيعات اليومية'!$A$9:$A$308,"<="&IF($B$5="",2958465,$B$5)))) -> 0 | I8: =IF(OR($C8="",$H$108=0),"",H8/$H$108) -> 0 | J8: =IF(C8="","",IF(D8>0,"نشط","لا يوجد مبيعات")) -> لا يوجد مبيعات
A9: =IF(C9="","",2) -> 2 | B9: =IF('دليل العملاء'!$B$5="","",'دليل العملاء'!$A$5) -> 102 | C9: =IF('دليل العملاء'!$B$5="","",'دليل العملاء'!$B$5) -> شركة التخصص الذهبي -حراء | D9: =IF($C9="","",IF($B$4&$B$5="",COUNTIFS('المبيعات اليومية'!$B$9:$B$308,$C9),COUNTIFS('المبيعات اليومية'!$B$9:$B$308,$C9,'المبيعات اليومية'!$A$9:$A$308,">="&IF($B$4="",0,$B$4),'المبيعات اليومية'!$A$9:$A$308,"<="&IF($B$5="",2958465,$B$5)))) -> 1 | E9: =IF($C9="","",IF($B$4&$B$5="",SUMIFS('المبيعات اليومية'!$E$9:$E$308,'المبيعات اليومية'!$B$9:$B$308,$C9),SUMIFS('المبيعات اليومية'!$E$9:$E$308,'المبيعات اليومية'!$B$9:$B$308,$C9,'المبيعات اليومية'!$A$9:$A$308,">="&IF($B$4="",0,$B$4),'المبيعات اليومية'!$A$9:$A$308,"<="&IF($B$5="",2958465,$B$5)))) -> 297 | F9: =IF($C9="","",IF($B$4&$B$5="",SUMIFS('المبيعات اليومية'!$H$9:$H$308,'المبيعات اليومية'!$B$9:$B$308,$C9),SUMIFS('المبيعات اليومية'!$H$9:$H$308,'المبيعات اليومية'!$B$9:$B$308,$C9,'المبيعات اليومية'!$A$9:$A$308,">="&IF($B$4="",0,$B$4),'المبيعات اليومية'!$A$9:$A$308,"<="&IF($B$5="",2958465,$B$5)))) -> 2524.5 | G9: =IF($C9="","",IF($B$4&$B$5="",SUMIFS('المبيعات اليومية'!$I$9:$I$308,'المبيعات اليومية'!$B$9:$B$308,$C9),SUMIFS('المبيعات اليومية'!$I$9:$I$308,'المبيعات اليومية'!$B$9:$B$308,$C9,'المبيعات اليومية'!$A$9:$A$308,">="&IF($B$4="",0,$B$4),'المبيعات اليومية'!$A$9:$A$308,"<="&IF($B$5="",2958465,$B$5)))) -> 378.68 | H9: =IF($C9="","",IF($B$4&$B$5="",SUMIFS('المبيعات اليومية'!$J$9:$J$308,'المبيعات اليومية'!$B$9:$B$308,$C9),SUMIFS('المبيعات اليومية'!$J$9:$J$308,'المبيعات اليومية'!$B$9:$B$308,$C9,'المبيعات اليومية'!$A$9:$A$308,">="&IF($B$4="",0,$B$4),'المبيعات اليومية'!$A$9:$A$308,"<="&IF($B$5="",2958465,$B$5)))) -> 2903.18 | I9: =IF(OR($C9="",$H$108=0),"",H9/$H$108) -> 0.21135279 | J9: =IF(C9="","",IF(D9>0,"نشط","لا يوجد مبيعات")) -> نشط
A10: =IF(C10="","",3) -> 3 | B10: =IF('دليل العملاء'!$B$6="","",'دليل العملاء'!$A$6) -> 103 | C10: =IF('دليل العملاء'!$B$6="","",'دليل العملاء'!$B$6) -> شركة التخصص الذهبي -المنار | D10: =IF($C10="","",IF($B$4&$B$5="",COUNTIFS('المبيعات اليومية'!$B$9:$B$308,$C10),COUNTIFS('المبيعات اليومية'!$B$9:$B$308,$C10,'المبيعات اليومية'!$A$9:$A$308,">="&IF($B$4="",0,$B$4),'المبيعات اليومية'!$A$9:$A$308,"<="&IF($B$5="",2958465,$B$5)))) -> 0 | E10: =IF($C10="","",IF($B$4&$B$5="",SUMIFS('المبيعات اليومية'!$E$9:$E$308,'المبيعات اليومية'!$B$9:$B$308,$C10),SUMIFS('المبيعات اليومية'!$E$9:$E$308,'المبيعات اليومية'!$B$9:$B$308,$C10,'المبيعات اليومية'!$A$9:$A$308,">="&IF($B$4="",0,$B$4),'المبيعات اليومية'!$A$9:$A$308,"<="&IF($B$5="",2958465,$B$5)))) -> 0 | F10: =IF($C10="","",IF($B$4&$B$5="",SUMIFS('المبيعات اليومية'!$H$9:$H$308,'المبيعات اليومية'!$B$9:$B$308,$C10),SUMIFS('المبيعات اليومية'!$H$9:$H$308,'المبيعات اليومية'!$B$9:$B$308,$C10,'المبيعات اليومية'!$A$9:$A$308,">="&IF($B$4="",0,$B$4),'المبيعات اليومية'!$A$9:$A$308,"<="&IF($B$5="",2958465,$B$5)))) -> 0 | G10: =IF($C10="","",IF($B$4&$B$5="",SUMIFS('المبيعات اليومية'!$I$9:$I$308,'المبيعات اليومية'!$B$9:$B$308,$C10),SUMIFS('المبيعات اليومية'!$I$9:$I$308,'المبيعات اليومية'!$B$9:$B$308,$C10,'المبيعات اليومية'!$A$9:$A$308,">="&IF($B$4="",0,$B$4),'المبيعات اليومية'!$A$9:$A$308,"<="&IF($B$5="",2958465,$B$5)))) -> 0 | H10: =IF($C10="","",IF($B$4&$B$5="",SUMIFS('المبيعات اليومية'!$J$9:$J$308,'المبيعات اليومية'!$B$9:$B$308,$C10),SUMIFS('المبيعات اليومية'!$J$9:$J$308,'المبيعات اليومية'!$B$9:$B$308,$C10,'المبيعات اليومية'!$A$9:$A$308,">="&IF($B$4="",0,$B$4),'المبيعات اليومية'!$A$9:$A$308,"<="&IF($B$5="",2958465,$B$5)))) -> 0 | I10: =IF(OR($C10="",$H$108=0),"",H10/$H$108) -> 0 | J10: =IF(C10="","",IF(D10>0,"نشط","لا يوجد مبيعات")) -> لا يوجد مبيعات
A11: =IF(C11="","",4) -> 4 | B11: =IF('دليل العملاء'!$B$7="","",'دليل العملاء'!$A$7) -> 104 | C11: =IF('دليل العملاء'!$B$7="","",'دليل العملاء'!$B$7) -> شركة التخصص الذهبي -الصفا | D11: =IF($C11="","",IF($B$4&$B$5="",COUNTIFS('المبيعات اليومية'!$B$9:$B$308,$C11),COUNTIFS('المبيعات اليومية'!$B$9:$B$308,$C11,'المبيعات اليومية'!$A$9:$A$308,">="&IF($B$4="",0,$B$4),'المبيعات اليومية'!$A$9:$A$308,"<="&IF($B$5="",2958465,$B$5)))) -> 1 | E11: =IF($C11="","",IF($B$4&$B$5="",SUMIFS('المبيعات اليومية'!$E$9:$E$308,'المبيعات اليومية'!$B$9:$B$308,$C11),SUMIFS('المبيعات اليومية'!$E$9:$E$308,'المبيعات اليومية'!$B$9:$B$308,$C11,'المبيعات اليومية'!$A$9:$A$308,">="&IF($B$4="",0,$B$4),'المبيعات اليومية'!$A$9:$A$308,"<="&IF($B$5="",2958465,$B$5)))) -> 150 | F11: =IF($C11="","",IF($B$4&$B$5="",SUMIFS('المبيعات اليومية'!$H$9:$H$308,'المبيعات اليومية'!$B$9:$B$308,$C11),SUMIFS('المبيعات اليومية'!$H$9:$H$308,'المبيعات اليومية'!$B$9:$B$308,$C11,'المبيعات اليومية'!$A$9:$A$308,">="&IF($B$4="",0,$B$4),'المبيعات اليومية'!$A$9:$A$308,"<="&IF($B$5="",2958465,$B$5)))) -> 750 | G11: =IF($C11="","",IF($B$4&$B$5="",SUMIFS('المبيعات اليومية'!$I$9:$I$308,'المبيعات اليومية'!$B$9:$B$308,$C11),SUMIFS('المبيعات اليومية'!$I$9:$I$308,'المبيعات اليومية'!$B$9:$B$308,$C11,'المبيعات اليومية'!$A$9:$A$308,">="&IF($B$4="",0,$B$4),'المبيعات اليومية'!$A$9:$A$308,"<="&IF($B$5="",2958465,$B$5)))) -> 112.5 | H11: =IF($C11="","",IF($B$4&$B$5="",SUMIFS('المبيعات اليومية'!$J$9:$J$308,'المبيعات اليومية'!$B$9:$B$308,$C11),SUMIFS('المبيعات اليومية'!$J$9:$J$308,'المبيعات اليومية'!$B$9:$B$308,$C11,'المبيعات اليومية'!$A$9:$A$308,">="&IF($B$4="",0,$B$4),'المبيعات اليومية'!$A$9:$A$308,"<="&IF($B$5="",2958465,$B$5)))) -> 862.5 | I11: =IF(OR($C11="",$H$108=0),"",H11/$H$108) -> 0.062790383 | J11: =IF(C11="","",IF(D11>0,"نشط","لا يوجد مبيعات")) -> نشط
A12: =IF(C12="","",5) -> 5 | B12: =IF('دليل العملاء'!$B$8="","",'دليل العملاء'!$A$8) -> 105 | C12: =IF('دليل العملاء'!$B$8="","",'دليل العملاء'!$B$8) -> شركة التخصص الذهبي -الربوه | D12: =IF($C12="","",IF($B$4&$B$5="",COUNTIFS('المبيعات اليومية'!$B$9:$B$308,$C12),COUNTIFS('المبيعات اليومية'!$B$9:$B$308,$C12,'المبيعات اليومية'!$A$9:$A$308,">="&IF($B$4="",0,$B$4),'المبيعات اليومية'!$A$9:$A$308,"<="&IF($B$5="",2958465,$B$5)))) -> 1 | E12: =IF($C12="","",IF($B$4&$B$5="",SUMIFS('المبيعات اليومية'!$E$9:$E$308,'المبيعات اليومية'!$B$9:$B$308,$C12),SUMIFS('المبيعات اليومية'!$E$9:$E$308,'المبيعات اليومية'!$B$9:$B$308,$C12,'المبيعات اليومية'!$A$9:$A$308,">="&IF($B$4="",0,$B$4),'المبيعات اليومية'!$A$9:$A$308,"<="&IF($B$5="",2958465,$B$5)))) -> 470 | F12: =IF($C12="","",IF($B$4&$B$5="",SUMIFS('المبيعات اليومية'!$H$9:$H$308,'المبيعات اليومية'!$B$9:$B$308,$C12),SUMIFS('المبيعات اليومية'!$H$9:$H$308,'المبيعات اليومية'!$B$9:$B$308,$C12,'المبيعات اليومية'!$A$9:$A$308,">="&IF($B$4="",0,$B$4),'المبيعات اليومية'!$A$9:$A$308,"<="&IF($B$5="",2958465,$B$5)))) -> 2115 | G12: =IF($C12="","",IF($B$4&$B$5="",SUMIFS('المبيعات اليومية'!$I$9:$I$308,'المبيعات اليومية'!$B$9:$B$308,$C12),SUMIFS('المبيعات اليومية'!$I$9:$I$308,'المبيعات اليومية'!$B$9:$B$308,$C12,'المبيعات اليومية'!$A$9:$A$308,">="&IF($B$4="",0,$B$4),'المبيعات اليومية'!$A$9:$A$308,"<="&IF($B$5="",2958465,$B$5)))) -> 317.25 | H12: =IF($C12="","",IF($B$4&$B$5="",SUMIFS('المبيعات اليومية'!$J$9:$J$308,'المبيعات اليومية'!$B$9:$B$308,$C12),SUMIFS('المبيعات اليومية'!$J$9:$J$308,'المبيعات اليومية'!$B$9:$B$308,$C12,'المبيعات اليومية'!$A$9:$A$308,">="&IF($B$4="",0,$B$4),'المبيعات اليومية'!$A$9:$A$308,"<="&IF($B$5="",2958465,$B$5)))) -> 2432.25 | I12: =IF(OR($C12="",$H$108=0),"",H12/$H$108) -> 0.17706888 | J12: =IF(C12="","",IF(D12>0,"نشط","لا يوجد مبيعات")) -> نشط
A13: =IF(C13="","",6) -> 6 | B13: =IF('دليل العملاء'!$B$9="","",'دليل العملاء'!$A$9) -> 106 | C13: =IF('دليل العملاء'!$B$9="","",'دليل العملاء'!$B$9) -> شركة التخصص الذهبي -الرحاب | D13: =IF($C13="","",IF($B$4&$B$5="",COUNTIFS('المبيعات اليومية'!$B$9:$B$308,$C13),COUNTIFS('المبيعات اليومية'!$B$9:$B$308,$C13,'المبيعات اليومية'!$A$9:$A$308,">="&IF($B$4="",0,$B$4),'المبيعات اليومية'!$A$9:$A$308,"<="&IF($B$5="",2958465,$B$5)))) -> 0 | E13: =IF($C13="","",IF($B$4&$B$5="",SUMIFS('المبيعات اليومية'!$E$9:$E$308,'المبيعات اليومية'!$B$9:$B$308,$C13),SUMIFS('المبيعات اليومية'!$E$9:$E$308,'المبيعات اليومية'!$B$9:$B$308,$C13,'المبيعات اليومية'!$A$9:$A$308,">="&IF($B$4="",0,$B$4),'المبيعات اليومية'!$A$9:$A$308,"<="&IF($B$5="",2958465,$B$5)))) -> 0 | F13: =IF($C13="","",IF($B$4&$B$5="",SUMIFS('المبيعات اليومية'!$H$9:$H$308,'المبيعات اليومية'!$B$9:$B$308,$C13),SUMIFS('المبيعات اليومية'!$H$9:$H$308,'المبيعات اليومية'!$B$9:$B$308,$C13,'المبيعات اليومية'!$A$9:$A$308,">="&IF($B$4="",0,$B$4),'المبيعات اليومية'!$A$9:$A$308,"<="&IF($B$5="",2958465,$B$5)))) -> 0 | G13: =IF($C13="","",IF($B$4&$B$5="",SUMIFS('المبيعات اليومية'!$I$9:$I$308,'المبيعات اليومية'!$B$9:$B$308,$C13),SUMIFS('المبيعات اليومية'!$I$9:$I$308,'المبيعات اليومية'!$B$9:$B$308,$C13,'المبيعات اليومية'!$A$9:$A$308,">="&IF($B$4="",0,$B$4),'المبيعات اليومية'!$A$9:$A$308,"<="&IF($B$5="",2958465,$B$5)))) -> 0 | H13: =IF($C13="","",IF($B$4&$B$5="",SUMIFS('المبيعات اليومية'!$J$9:$J$308,'المبيعات اليومية'!$B$9:$B$308,$C13),SUMIFS('المبيعات اليومية'!$J$9:$J$308,'المبيعات اليومية'!$B$9:$B$308,$C13,'المبيعات اليومية'!$A$9:$A$308,">="&IF($B$4="",0,$B$4),'المبيعات اليومية'!$A$9:$A$308,"<="&IF($B$5="",2958465,$B$5)))) -> 0 | I13: =IF(OR($C13="",$H$108=0),"",H13/$H$108) -> 0 | J13: =IF(C13="","",IF(D13>0,"نشط","لا يوجد مبيعات")) -> لا يوجد مبيعات
A14: =IF(C14="","",7) -> 7 | B14: =IF('دليل العملاء'!$B$10="","",'دليل العملاء'!$A$10) -> 107 | C14: =IF('دليل العملاء'!$B$10="","",'دليل العملاء'!$B$10) -> عبر الإقليم | D14: =IF($C14="","",IF($B$4&$B$5="",COUNTIFS('المبيعات اليومية'!$B$9:$B$308,$C14),COUNTIFS('المبيعات اليومية'!$B$9:$B$308,$C14,'المبيعات اليومية'!$A$9:$A$308,">="&IF($B$4="",0,$B$4),'المبيعات اليومية'!$A$9:$A$308,"<="&IF($B$5="",2958465,$B$5)))) -> 1 | E14: =IF($C14="","",IF($B$4&$B$5="",SUMIFS('المبيعات اليومية'!$E$9:$E$308,'المبيعات اليومية'!$B$9:$B$308,$C14),SUMIFS('المبيعات اليومية'!$E$9:$E$308,'المبيعات اليومية'!$B$9:$B$308,$C14,'المبيعات اليومية'!$A$9:$A$308,">="&IF($B$4="",0,$B$4),'المبيعات اليومية'!$A$9:$A$308,"<="&IF($B$5="",2958465,$B$5)))) -> 200 | F14: =IF($C14="","",IF($B$4&$B$5="",SUMIFS('المبيعات اليومية'!$H$9:$H$308,'المبيعات اليومية'!$B$9:$B$308,$C14),SUMIFS('المبيعات اليومية'!$H$9:$H$308,'المبيعات اليومية'!$B$9:$B$308,$C14,'المبيعات اليومية'!$A$9:$A$308,">="&IF($B$4="",0,$B$4),'المبيعات اليومية'!$A$9:$A$308,"<="&IF($B$5="",2958465,$B$5)))) -> 1600 | G14: =IF($C14="","",IF($B$4&$B$5="",SUMIFS('المبيعات اليومية'!$I$9:$I$308,'المبيعات اليومية'!$B$9:$B$308,$C14),SUMIFS('المبيعات اليومية'!$I$9:$I$308,'المبيعات اليومية'!$B$9:$B$308,$C14,'المبيعات اليومية'!$A$9:$A$308,">="&IF($B$4="",0,$B$4),'المبيعات اليومية'!$A$9:$A$308,"<="&IF($B$5="",2958465,$B$5)))) -> 240 | H14: =IF($C14="","",IF($B$4&$B$5="",SUMIFS('المبيعات اليومية'!$J$9:$J$308,'المبيعات اليومية'!$B$9:$B$308,$C14),SUMIFS('المبيعات اليومية'!$J$9:$J$308,'المبيعات اليومية'!$B$9:$B$308,$C14,'المبيعات اليومية'!$A$9:$A$308,">="&IF($B$4="",0,$B$4),'المبيعات اليومية'!$A$9:$A$308,"<="&IF($B$5="",2958465,$B$5)))) -> 1840 | I14: =IF(OR($C14="",$H$108=0),"",H14/$H$108) -> 0.13395282 | J14: =IF(C14="","",IF(D14>0,"نشط","لا يوجد مبيعات")) -> نشط
A15: =IF(C15="","",8) -> 8 | B15: =IF('دليل العملاء'!$B$11="","",'دليل العملاء'!$A$11) -> 108 | C15: =IF('دليل العملاء'!$B$11="","",'دليل العملاء'!$B$11) -> حقيبة الفواكه | D15: =IF($C15="","",IF($B$4&$B$5="",COUNTIFS('المبيعات اليومية'!$B$9:$B$308,$C15),COUNTIFS('المبيعات اليومية'!$B$9:$B$308,$C15,'المبيعات اليومية'!$A$9:$A$308,">="&IF($B$4="",0,$B$4),'المبيعات اليومية'!$A$9:$A$308,"<="&IF($B$5="",2958465,$B$5)))) -> 1 | E15: =IF($C15="","",IF($B$4&$B$5="",SUMIFS('المبيعات اليومية'!$E$9:$E$308,'المبيعات اليومية'!$B$9:$B$308,$C15),SUMIFS('المبيعات اليومية'!$E$9:$E$308,'المبيعات اليومية'!$B$9:$B$308,$C15,'المبيعات اليومية'!$A$9:$A$308,">="&IF($B$4="",0,$B$4),'المبيعات اليومية'!$A$9:$A$308,"<="&IF($B$5="",2958465,$B$5)))) -> 150 | F15: =IF($C15="","",IF($B$4&$B$5="",SUMIFS('المبيعات اليومية'!$H$9:$H$308,'المبيعات اليومية'!$B$9:$B$308,$C15),SUMIFS('المبيعات اليومية'!$H$9:$H$308,'المبيعات اليومية'!$B$9:$B$308,$C15,'المبيعات اليومية'!$A$9:$A$308,">="&IF($B$4="",0,$B$4),'المبيعات اليومية'!$A$9:$A$308,"<="&IF($B$5="",2958465,$B$5)))) -> 1125 | G15: =IF($C15="","",IF($B$4&$B$5="",SUMIFS('المبيعات اليومية'!$I$9:$I$308,'المبيعات اليومية'!$B$9:$B$308,$C15),SUMIFS('المبيعات اليومية'!$I$9:$I$308,'المبيعات اليومية'!$B$9:$B$308,$C15,'المبيعات اليومية'!$A$9:$A$308,">="&IF($B$4="",0,$B$4),'المبيعات اليومية'!$A$9:$A$308,"<="&IF($B$5="",2958465,$B$5)))) -> 168.75 | H15: =IF($C15="","",IF($B$4&$B$5="",SUMIFS('المبيعات اليومية'!$J$9:$J$308,'المبيعات اليومية'!$B$9:$B$308,$C15),SUMIFS('المبيعات اليومية'!$J$9:$J$308,'المبيعات اليومية'!$B$9:$B$308,$C15,'المبيعات اليومية'!$A$9:$A$308,">="&IF($B$4="",0,$B$4),'المبيعات اليومية'!$A$9:$A$308,"<="&IF($B$5="",2958465,$B$5)))) -> 1293.75 | I15: =IF(OR($C15="",$H$108=0),"",H15/$H$108) -> 0.094185574 | J15: =IF(C15="","",IF(D15>0,"نشط","لا يوجد مبيعات")) -> نشط
A16: =IF(C16="","",9) -> 9 | B16: =IF('دليل العملاء'!$B$12="","",'دليل العملاء'!$A$12) -> 109 | C16: =IF('دليل العملاء'!$B$12="","",'دليل العملاء'!$B$12) -> فيض الكرم | D16: =IF($C16="","",IF($B$4&$B$5="",COUNTIFS('المبيعات اليومية'!$B$9:$B$308,$C16),COUNTIFS('المبيعات اليومية'!$B$9:$B$308,$C16,'المبيعات اليومية'!$A$9:$A$308,">="&IF($B$4="",0,$B$4),'المبيعات اليومية'!$A$9:$A$308,"<="&IF($B$5="",2958465,$B$5)))) -> 1 | E16: =IF($C16="","",IF($B$4&$B$5="",SUMIFS('المبيعات اليومية'!$E$9:$E$308,'المبيعات اليومية'!$B$9:$B$308,$C16),SUMIFS('المبيعات اليومية'!$E$9:$E$308,'المبيعات اليومية'!$B$9:$B$308,$C16,'المبيعات اليومية'!$A$9:$A$308,">="&IF($B$4="",0,$B$4),'المبيعات اليومية'!$A$9:$A$308,"<="&IF($B$5="",2958465,$B$5)))) -> 80 | F16: =IF($C16="","",IF($B$4&$B$5="",SUMIFS('المبيعات اليومية'!$H$9:$H$308,'المبيعات اليومية'!$B$9:$B$308,$C16),SUMIFS('المبيعات اليومية'!$H$9:$H$308,'المبيعات اليومية'!$B$9:$B$308,$C16,'المبيعات اليومية'!$A$9:$A$308,">="&IF($B$4="",0,$B$4),'المبيعات اليومية'!$A$9:$A$308,"<="&IF($B$5="",2958465,$B$5)))) -> 1000 | G16: =IF($C16="","",IF($B$4&$B$5="",SUMIFS('المبيعات اليومية'!$I$9:$I$308,'المبيعات اليومية'!$B$9:$B$308,$C16),SUMIFS('المبيعات اليومية'!$I$9:$I$308,'المبيعات اليومية'!$B$9:$B$308,$C16,'المبيعات اليومية'!$A$9:$A$308,">="&IF($B$4="",0,$B$4),'المبيعات اليومية'!$A$9:$A$308,"<="&IF($B$5="",2958465,$B$5)))) -> 150 | H16: =IF($C16="","",IF($B$4&$B$5="",SUMIFS('المبيعات اليومية'!$J$9:$J$308,'المبيعات اليومية'!$B$9:$B$308,$C16),SUMIFS('المبيعات اليومية'!$J$9:$J$308,'المبيعات اليومية'!$B$9:$B$308,$C16,'المبيعات اليومية'!$A$9:$A$308,">="&IF($B$4="",0,$B$4),'المبيعات اليومية'!$A$9:$A$308,"<="&IF($B$5="",2958465,$B$5)))) -> 1150 | I16: =IF(OR($C16="",$H$108=0),"",H16/$H$108) -> 0.08372051 | J16: =IF(C16="","",IF(D16>0,"نشط","لا يوجد مبيعات")) -> نشط
A17: =IF(C17="","",10) -> 10 | B17: =IF('دليل العملاء'!$B$13="","",'دليل العملاء'!$A$13) -> 110 | C17: =IF('دليل العملاء'!$B$13="","",'دليل العملاء'!$B$13) -> غصون الفاكهه | D17: =IF($C17="","",IF($B$4&$B$5="",COUNTIFS('المبيعات اليومية'!$B$9:$B$308,$C17),COUNTIFS('المبيعات اليومية'!$B$9:$B$308,$C17,'المبيعات اليومية'!$A$9:$A$308,">="&IF($B$4="",0,$B$4),'المبيعات اليومية'!$A$9:$A$308,"<="&IF($B$5="",2958465,$B$5)))) -> 1 | E17: =IF($C17="","",IF($B$4&$B$5="",SUMIFS('المبيعات اليومية'!$E$9:$E$308,'المبيعات اليومية'!$B$9:$B$308,$C17),SUMIFS('المبيعات اليومية'!$E$9:$E$308,'المبيعات اليومية'!$B$9:$B$308,$C17,'المبيعات اليومية'!$A$9:$A$308,">="&IF($B$4="",0,$B$4),'المبيعات اليومية'!$A$9:$A$308,"<="&IF($B$5="",2958465,$B$5)))) -> 350 | F17: =IF($C17="","",IF($B$4&$B$5="",SUMIFS('المبيعات اليومية'!$H$9:$H$308,'المبيعات اليومية'!$B$9:$B$308,$C17),SUMIFS('المبيعات اليومية'!$H$9:$H$308,'المبيعات اليومية'!$B$9:$B$308,$C17,'المبيعات اليومية'!$A$9:$A$308,">="&IF($B$4="",0,$B$4),'المبيعات اليومية'!$A$9:$A$308,"<="&IF($B$5="",2958465,$B$5)))) -> 1750 | G17: =IF($C17="","",IF($B$4&$B$5="",SUMIFS('المبيعات اليومية'!$I$9:$I$308,'المبيعات اليومية'!$B$9:$B$308,$C17),SUMIFS('المبيعات اليومية'!$I$9:$I$308,'المبيعات اليومية'!$B$9:$B$308,$C17,'المبيعات اليومية'!$A$9:$A$308,">="&IF($B$4="",0,$B$4),'المبيعات اليومية'!$A$9:$A$308,"<="&IF($B$5="",2958465,$B$5)))) -> 262.5 | H17: =IF($C17="","",IF($B$4&$B$5="",SUMIFS('المبيعات اليومية'!$J$9:$J$308,'المبيعات اليومية'!$B$9:$B$308,$C17),SUMIFS('المبيعات اليومية'!$J$9:$J$308,'المبيعات اليومية'!$B$9:$B$308,$C17,'المبيعات اليومية'!$A$9:$A$308,">="&IF($B$4="",0,$B$4),'المبيعات اليومية'!$A$9:$A$308,"<="&IF($B$5="",2958465,$B$5)))) -> 2012.5 | I17: =IF(OR($C17="",$H$108=0),"",H17/$H$108) -> 0.14651089 | J17: =IF(C17="","",IF(D17>0,"نشط","لا يوجد مبيعات")) -> نشط
A18: =IF(C18="","",11) -> 11 | B18: =IF('دليل العملاء'!$B$14="","",'دليل العملاء'!$A$14) -> 111 | C18: =IF('دليل العملاء'!$B$14="","",'دليل العملاء'!$B$14) -> نقاوه بس | D18: =IF($C18="","",IF($B$4&$B$5="",COUNTIFS('المبيعات اليومية'!$B$9:$B$308,$C18),COUNTIFS('المبيعات اليومية'!$B$9:$B$308,$C18,'المبيعات اليومية'!$A$9:$A$308,">="&IF($B$4="",0,$B$4),'المبيعات اليومية'!$A$9:$A$308,"<="&IF($B$5="",2958465,$B$5)))) -> 1 | E18: =IF($C18="","",IF($B$4&$B$5="",SUMIFS('المبيعات اليومية'!$E$9:$E$308,'المبيعات اليومية'!$B$9:$B$308,$C18),SUMIFS('المبيعات اليومية'!$E$9:$E$308,'المبيعات اليومية'!$B$9:$B$308,$C18,'المبيعات اليومية'!$A$9:$A$308,">="&IF($B$4="",0,$B$4),'المبيعات اليومية'!$A$9:$A$308,"<="&IF($B$5="",2958465,$B$5)))) -> 120 | F18: =IF($C18="","",IF($B$4&$B$5="",SUMIFS('المبيعات اليومية'!$H$9:$H$308,'المبيعات اليومية'!$B$9:$B$308,$C18),SUMIFS('المبيعات اليومية'!$H$9:$H$308,'المبيعات اليومية'!$B$9:$B$308,$C18,'المبيعات اليومية'!$A$9:$A$308,">="&IF($B$4="",0,$B$4),'المبيعات اليومية'!$A$9:$A$308,"<="&IF($B$5="",2958465,$B$5)))) -> 1080 | G18: =IF($C18="","",IF($B$4&$B$5="",SUMIFS('المبيعات اليومية'!$I$9:$I$308,'المبيعات اليومية'!$B$9:$B$308,$C18),SUMIFS('المبيعات اليومية'!$I$9:$I$308,'المبيعات اليومية'!$B$9:$B$308,$C18,'المبيعات اليومية'!$A$9:$A$308,">="&IF($B$4="",0,$B$4),'المبيعات اليومية'!$A$9:$A$308,"<="&IF($B$5="",2958465,$B$5)))) -> 162 | H18: =IF($C18="","",IF($B$4&$B$5="",SUMIFS('المبيعات اليومية'!$J$9:$J$308,'المبيعات اليومية'!$B$9:$B$308,$C18),SUMIFS('المبيعات اليومية'!$J$9:$J$308,'المبيعات اليومية'!$B$9:$B$308,$C18,'المبيعات اليومية'!$A$9:$A$308,">="&IF($B$4="",0,$B$4),'المبيعات اليومية'!$A$9:$A$308,"<="&IF($B$5="",2958465,$B$5)))) -> 1242 | I18: =IF(OR($C18="",$H$108=0),"",H18/$H$108) -> 0.090418151 | J18: =IF(C18="","",IF(D18>0,"نشط","لا يوجد مبيعات")) -> نشط
A19: =IF(C19="","",12) | B19: =IF('دليل العملاء'!$B$15="","",'دليل العملاء'!$A$15) | C19: =IF('دليل العملاء'!$B$15="","",'دليل العملاء'!$B$15) | D19: =IF($C19="","",IF($B$4&$B$5="",COUNTIFS('المبيعات اليومية'!$B$9:$B$308,$C19),COUNTIFS('المبيعات اليومية'!$B$9:$B$308,$C19,'المبيعات اليومية'!$A$9:$A$308,">="&IF($B$4="",0,$B$4),'المبيعات اليومية'!$A$9:$A$308,"<="&IF($B$5="",2958465,$B$5)))) | E19: =IF($C19="","",IF($B$4&$B$5="",SUMIFS('المبيعات اليومية'!$E$9:$E$308,'المبيعات اليومية'!$B$9:$B$308,$C19),SUMIFS('المبيعات اليومية'!$E$9:$E$308,'المبيعات اليومية'!$B$9:$B$308,$C19,'المبيعات اليومية'!$A$9:$A$308,">="&IF($B$4="",0,$B$4),'المبيعات اليومية'!$A$9:$A$308,"<="&IF($B$5="",2958465,$B$5)))) | F19: =IF($C19="","",IF($B$4&$B$5="",SUMIFS('المبيعات اليومية'!$H$9:$H$308,'المبيعات اليومية'!$B$9:$B$308,$C19),SUMIFS('المبيعات اليومية'!$H$9:$H$308,'المبيعات اليومية'!$B$9:$B$308,$C19,'المبيعات اليومية'!$A$9:$A$308,">="&IF($B$4="",0,$B$4),'المبيعات اليومية'!$A$9:$A$308,"<="&IF($B$5="",2958465,$B$5)))) | G19: =IF($C19="","",IF($B$4&$B$5="",SUMIFS('المبيعات اليومية'!$I$9:$I$308,'المبيعات اليومية'!$B$9:$B$308,$C19),SUMIFS('المبيعات اليومية'!$I$9:$I$308,'المبيعات اليومية'!$B$9:$B$308,$C19,'المبيعات اليومية'!$A$9:$A$308,">="&IF($B$4="",0,$B$4),'المبيعات اليومية'!$A$9:$A$308,"<="&IF($B$5="",2958465,$B$5)))) | H19: =IF($C19="","",IF($B$4&$B$5="",SUMIFS('المبيعات اليومية'!$J$9:$J$308,'المبيعات اليومية'!$B$9:$B$308,$C19),SUMIFS('المبيعات اليومية'!$J$9:$J$308,'المبيعات اليومية'!$B$9:$B$308,$C19,'المبيعات اليومية'!$A$9:$A$308,">="&IF($B$4="",0,$B$4),'المبيعات اليومية'!$A$9:$A$308,"<="&IF($B$5="",2958465,$B$5)))) | I19: =IF(OR($C19="",$H$108=0),"",H19/$H$108) | J19: =IF(C19="","",IF(D19>0,"نشط","لا يوجد مبيعات"))
A20: =IF(C20="","",13) | B20: =IF('دليل العملاء'!$B$16="","",'دليل العملاء'!$A$16) | C20: =IF('دليل العملاء'!$B$16="","",'دليل العملاء'!$B$16) | D20: =IF($C20="","",IF($B$4&$B$5="",COUNTIFS('المبيعات اليومية'!$B$9:$B$308,$C20),COUNTIFS('المبيعات اليومية'!$B$9:$B$308,$C20,'المبيعات اليومية'!$A$9:$A$308,">="&IF($B$4="",0,$B$4),'المبيعات اليومية'!$A$9:$A$308,"<="&IF($B$5="",2958465,$B$5)))) | E20: =IF($C20="","",IF($B$4&$B$5="",SUMIFS('المبيعات اليومية'!$E$9:$E$308,'المبيعات اليومية'!$B$9:$B$308,$C20),SUMIFS('المبيعات اليومية'!$E$9:$E$308,'المبيعات اليومية'!$B$9:$B$308,$C20,'المبيعات اليومية'!$A$9:$A$308,">="&IF($B$4="",0,$B$4),'المبيعات اليومية'!$A$9:$A$308,"<="&IF($B$5="",2958465,$B$5)))) | F20: =IF($C20="","",IF($B$4&$B$5="",SUMIFS('المبيعات اليومية'!$H$9:$H$308,'المبيعات اليومية'!$B$9:$B$308,$C20),SUMIFS('المبيعات اليومية'!$H$9:$H$308,'المبيعات اليومية'!$B$9:$B$308,$C20,'المبيعات اليومية'!$A$9:$A$308,">="&IF($B$4="",0,$B$4),'المبيعات اليومية'!$A$9:$A$308,"<="&IF($B$5="",2958465,$B$5)))) | G20: =IF($C20="","",IF($B$4&$B$5="",SUMIFS('المبيعات اليومية'!$I$9:$I$308,'المبيعات اليومية'!$B$9:$B$308,$C20),SUMIFS('المبيعات اليومية'!$I$9:$I$308,'المبيعات اليومية'!$B$9:$B$308,$C20,'المبيعات اليومية'!$A$9:$A$308,">="&IF($B$4="",0,$B$4),'المبيعات اليومية'!$A$9:$A$308,"<="&IF($B$5="",2958465,$B$5)))) | H20: =IF($C20="","",IF($B$4&$B$5="",SUMIFS('المبيعات اليومية'!$J$9:$J$308,'المبيعات اليومية'!$B$9:$B$308,$C20),SUMIFS('المبيعات اليومية'!$J$9:$J$308,'المبيعات اليومية'!$B$9:$B$308,$C20,'المبيعات اليومية'!$A$9:$A$308,">="&IF($B$4="",0,$B$4),'المبيعات اليومية'!$A$9:$A$308,"<="&IF($B$5="",2958465,$B$5)))) | I20: =IF(OR($C20="",$H$108=0),"",H20/$H$108) | J20: =IF(C20="","",IF(D20>0,"نشط","لا يوجد مبيعات"))
A21: =IF(C21="","",14) | B21: =IF('دليل العملاء'!$B$17="","",'دليل العملاء'!$A$17) | C21: =IF('دليل العملاء'!$B$17="","",'دليل العملاء'!$B$17) | D21: =IF($C21="","",IF($B$4&$B$5="",COUNTIFS('المبيعات اليومية'!$B$9:$B$308,$C21),COUNTIFS('المبيعات اليومية'!$B$9:$B$308,$C21,'المبيعات اليومية'!$A$9:$A$308,">="&IF($B$4="",0,$B$4),'المبيعات اليومية'!$A$9:$A$308,"<="&IF($B$5="",2958465,$B$5)))) | E21: =IF($C21="","",IF($B$4&$B$5="",SUMIFS('المبيعات اليومية'!$E$9:$E$308,'المبيعات اليومية'!$B$9:$B$308,$C21),SUMIFS('المبيعات اليومية'!$E$9:$E$308,'المبيعات اليومية'!$B$9:$B$308,$C21,'المبيعات اليومية'!$A$9:$A$308,">="&IF($B$4="",0,$B$4),'المبيعات اليومية'!$A$9:$A$308,"<="&IF($B$5="",2958465,$B$5)))) | F21: =IF($C21="","",IF($B$4&$B$5="",SUMIFS('المبيعات اليومية'!$H$9:$H$308,'المبيعات اليومية'!$B$9:$B$308,$C21),SUMIFS('المبيعات اليومية'!$H$9:$H$308,'المبيعات اليومية'!$B$9:$B$308,$C21,'المبيعات اليومية'!$A$9:$A$308,">="&IF($B$4="",0,$B$4),'المبيعات اليومية'!$A$9:$A$308,"<="&IF($B$5="",2958465,$B$5)))) | G21: =IF($C21="","",IF($B$4&$B$5="",SUMIFS('المبيعات اليومية'!$I$9:$I$308,'المبيعات اليومية'!$B$9:$B$308,$C21),SUMIFS('المبيعات اليومية'!$I$9:$I$308,'المبيعات اليومية'!$B$9:$B$308,$C21,'المبيعات اليومية'!$A$9:$A$308,">="&IF($B$4="",0,$B$4),'المبيعات اليومية'!$A$9:$A$308,"<="&IF($B$5="",2958465,$B$5)))) | H21: =IF($C21="","",IF($B$4&$B$5="",SUMIFS('المبيعات اليومية'!$J$9:$J$308,'المبيعات اليومية'!$B$9:$B$308,$C21),SUMIFS('المبيعات اليومية'!$J$9:$J$308,'المبيعات اليومية'!$B$9:$B$308,$C21,'المبيعات اليومية'!$A$9:$A$308,">="&IF($B$4="",0,$B$4),'المبيعات اليومية'!$A$9:$A$308,"<="&IF($B$5="",2958465,$B$5)))) | I21: =IF(OR($C21="",$H$108=0),"",H21/$H$108) | J21: =IF(C21="","",IF(D21>0,"نشط","لا يوجد مبيعات"))
A22: =IF(C22="","",15) | B22: =IF('دليل العملاء'!$B$18="","",'دليل العملاء'!$A$18) | C22: =IF('دليل العملاء'!$B$18="","",'دليل العملاء'!$B$18) | D22: =IF($C22="","",IF($B$4&$B$5="",COUNTIFS('المبيعات اليومية'!$B$9:$B$308,$C22),COUNTIFS('المبيعات اليومية'!$B$9:$B$308,$C22,'المبيعات اليومية'!$A$9:$A$308,">="&IF($B$4="",0,$B$4),'المبيعات اليومية'!$A$9:$A$308,"<="&IF($B$5="",2958465,$B$5)))) | E22: =IF($C22="","",IF($B$4&$B$5="",SUMIFS('المبيعات اليومية'!$E$9:$E$308,'المبيعات اليومية'!$B$9:$B$308,$C22),SUMIFS('المبيعات اليومية'!$E$9:$E$308,'المبيعات اليومية'!$B$9:$B$308,$C22,'المبيعات اليومية'!$A$9:$A$308,">="&IF($B$4="",0,$B$4),'المبيعات اليومية'!$A$9:$A$308,"<="&IF($B$5="",2958465,$B$5)))) | F22: =IF($C22="","",IF($B$4&$B$5="",SUMIFS('المبيعات اليومية'!$H$9:$H$308,'المبيعات اليومية'!$B$9:$B$308,$C22),SUMIFS('المبيعات اليومية'!$H$9:$H$308,'المبيعات اليومية'!$B$9:$B$308,$C22,'المبيعات اليومية'!$A$9:$A$308,">="&IF($B$4="",0,$B$4),'المبيعات اليومية'!$A$9:$A$308,"<="&IF($B$5="",2958465,$B$5)))) | G22: =IF($C22="","",IF($B$4&$B$5="",SUMIFS('المبيعات اليومية'!$I$9:$I$308,'المبيعات اليومية'!$B$9:$B$308,$C22),SUMIFS('المبيعات اليومية'!$I$9:$I$308,'المبيعات اليومية'!$B$9:$B$308,$C22,'المبيعات اليومية'!$A$9:$A$308,">="&IF($B$4="",0,$B$4),'المبيعات اليومية'!$A$9:$A$308,"<="&IF($B$5="",2958465,$B$5)))) | H22: =IF($C22="","",IF($B$4&$B$5="",SUMIFS('المبيعات اليومية'!$J$9:$J$308,'المبيعات اليومية'!$B$9:$B$308,$C22),SUMIFS('المبيعات اليومية'!$J$9:$J$308,'المبيعات اليومية'!$B$9:$B$308,$C22,'المبيعات اليومية'!$A$9:$A$308,">="&IF($B$4="",0,$B$4),'المبيعات اليومية'!$A$9:$A$308,"<="&IF($B$5="",2958465,$B$5)))) | I22: =IF(OR($C22="",$H$108=0),"",H22/$H$108) | J22: =IF(C22="","",IF(D22>0,"نشط","لا يوجد مبيعات"))
A23: =IF(C23="","",16) | B23: =IF('دليل العملاء'!$B$19="","",'دليل العملاء'!$A$19) | C23: =IF('دليل العملاء'!$B$19="","",'دليل العملاء'!$B$19) | D23: =IF($C23="","",IF($B$4&$B$5="",COUNTIFS('المبيعات اليومية'!$B$9:$B$308,$C23),COUNTIFS('المبيعات اليومية'!$B$9:$B$308,$C23,'المبيعات اليومية'!$A$9:$A$308,">="&IF($B$4="",0,$B$4),'المبيعات اليومية'!$A$9:$A$308,"<="&IF($B$5="",2958465,$B$5)))) | E23: =IF($C23="","",IF($B$4&$B$5="",SUMIFS('المبيعات اليومية'!$E$9:$E$308,'المبيعات اليومية'!$B$9:$B$308,$C23),SUMIFS('المبيعات اليومية'!$E$9:$E$308,'المبيعات اليومية'!$B$9:$B$308,$C23,'المبيعات اليومية'!$A$9:$A$308,">="&IF($B$4="",0,$B$4),'المبيعات اليومية'!$A$9:$A$308,"<="&IF($B$5="",2958465,$B$5)))) | F23: =IF($C23="","",IF($B$4&$B$5="",SUMIFS('المبيعات اليومية'!$H$9:$H$308,'المبيعات اليومية'!$B$9:$B$308,$C23),SUMIFS('المبيعات اليومية'!$H$9:$H$308,'المبيعات اليومية'!$B$9:$B$308,$C23,'المبيعات اليومية'!$A$9:$A$308,">="&IF($B$4="",0,$B$4),'المبيعات اليومية'!$A$9:$A$308,"<="&IF($B$5="",2958465,$B$5)))) | G23: =IF($C23="","",IF($B$4&$B$5="",SUMIFS('المبيعات اليومية'!$I$9:$I$308,'المبيعات اليومية'!$B$9:$B$308,$C23),SUMIFS('المبيعات اليومية'!$I$9:$I$308,'المبيعات اليومية'!$B$9:$B$308,$C23,'المبيعات اليومية'!$A$9:$A$308,">="&IF($B$4="",0,$B$4),'المبيعات اليومية'!$A$9:$A$308,"<="&IF($B$5="",2958465,$B$5)))) | H23: =IF($C23="","",IF($B$4&$B$5="",SUMIFS('المبيعات اليومية'!$J$9:$J$308,'المبيعات اليومية'!$B$9:$B$308,$C23),SUMIFS('المبيعات اليومية'!$J$9:$J$308,'المبيعات اليومية'!$B$9:$B$308,$C23,'المبيعات اليومية'!$A$9:$A$308,">="&IF($B$4="",0,$B$4),'المبيعات اليومية'!$A$9:$A$308,"<="&IF($B$5="",2958465,$B$5)))) | I23: =IF(OR($C23="",$H$108=0),"",H23/$H$108) | J23: =IF(C23="","",IF(D23>0,"نشط","لا يوجد مبيعات"))
A24: =IF(C24="","",17) | B24: =IF('دليل العملاء'!$B$20="","",'دليل العملاء'!$A$20) | C24: =IF('دليل العملاء'!$B$20="","",'دليل العملاء'!$B$20) | D24: =IF($C24="","",IF($B$4&$B$5="",COUNTIFS('المبيعات اليومية'!$B$9:$B$308,$C24),COUNTIFS('المبيعات اليومية'!$B$9:$B$308,$C24,'المبيعات اليومية'!$A$9:$A$308,">="&IF($B$4="",0,$B$4),'المبيعات اليومية'!$A$9:$A$308,"<="&IF($B$5="",2958465,$B$5)))) | E24: =IF($C24="","",IF($B$4&$B$5="",SUMIFS('المبيعات اليومية'!$E$9:$E$308,'المبيعات اليومية'!$B$9:$B$308,$C24),SUMIFS('المبيعات اليومية'!$E$9:$E$308,'المبيعات اليومية'!$B$9:$B$308,$C24,'المبيعات اليومية'!$A$9:$A$308,">="&IF($B$4="",0,$B$4),'المبيعات اليومية'!$A$9:$A$308,"<="&IF($B$5="",2958465,$B$5)))) | F24: =IF($C24="","",IF($B$4&$B$5="",SUMIFS('المبيعات اليومية'!$H$9:$H$308,'المبيعات اليومية'!$B$9:$B$308,$C24),SUMIFS('المبيعات اليومية'!$H$9:$H$308,'المبيعات اليومية'!$B$9:$B$308,$C24,'المبيعات اليومية'!$A$9:$A$308,">="&IF($B$4="",0,$B$4),'المبيعات اليومية'!$A$9:$A$308,"<="&IF($B$5="",2958465,$B$5)))) | G24: =IF($C24="","",IF($B$4&$B$5="",SUMIFS('المبيعات اليومية'!$I$9:$I$308,'المبيعات اليومية'!$B$9:$B$308,$C24),SUMIFS('المبيعات اليومية'!$I$9:$I$308,'المبيعات اليومية'!$B$9:$B$308,$C24,'المبيعات اليومية'!$A$9:$A$308,">="&IF($B$4="",0,$B$4),'المبيعات اليومية'!$A$9:$A$308,"<="&IF($B$5="",2958465,$B$5)))) | H24: =IF($C24="","",IF($B$4&$B$5="",SUMIFS('المبيعات اليومية'!$J$9:$J$308,'المبيعات اليومية'!$B$9:$B$308,$C24),SUMIFS('المبيعات اليومية'!$J$9:$J$308,'المبيعات اليومية'!$B$9:$B$308,$C24,'المبيعات اليومية'!$A$9:$A$308,">="&IF($B$4="",0,$B$4),'المبيعات اليومية'!$A$9:$A$308,"<="&IF($B$5="",2958465,$B$5)))) | I24: =IF(OR($C24="",$H$108=0),"",H24/$H$108) | J24: =IF(C24="","",IF(D24>0,"نشط","لا يوجد مبيعات"))
A25: =IF(C25="","",18) | B25: =IF('دليل العملاء'!$B$21="","",'دليل العملاء'!$A$21) | C25: =IF('دليل العملاء'!$B$21="","",'دليل العملاء'!$B$21) | D25: =IF($C25="","",IF($B$4&$B$5="",COUNTIFS('المبيعات اليومية'!$B$9:$B$308,$C25),COUNTIFS('المبيعات اليومية'!$B$9:$B$308,$C25,'المبيعات اليومية'!$A$9:$A$308,">="&IF($B$4="",0,$B$4),'المبيعات اليومية'!$A$9:$A$308,"<="&IF($B$5="",2958465,$B$5)))) | E25: =IF($C25="","",IF($B$4&$B$5="",SUMIFS('المبيعات اليومية'!$E$9:$E$308,'المبيعات اليومية'!$B$9:$B$308,$C25),SUMIFS('المبيعات اليومية'!$E$9:$E$308,'المبيعات اليومية'!$B$9:$B$308,$C25,'المبيعات اليومية'!$A$9:$A$308,">="&IF($B$4="",0,$B$4),'المبيعات اليومية'!$A$9:$A$308,"<="&IF($B$5="",2958465,$B$5)))) | F25: =IF($C25="","",IF($B$4&$B$5="",SUMIFS('المبيعات اليومية'!$H$9:$H$308,'المبيعات اليومية'!$B$9:$B$308,$C25),SUMIFS('المبيعات اليومية'!$H$9:$H$308,'المبيعات اليومية'!$B$9:$B$308,$C25,'المبيعات اليومية'!$A$9:$A$308,">="&IF($B$4="",0,$B$4),'المبيعات اليومية'!$A$9:$A$308,"<="&IF($B$5="",2958465,$B$5)))) | G25: =IF($C25="","",IF($B$4&$B$5="",SUMIFS('المبيعات اليومية'!$I$9:$I$308,'المبيعات اليومية'!$B$9:$B$308,$C25),SUMIFS('المبيعات اليومية'!$I$9:$I$308,'المبيعات اليومية'!$B$9:$B$308,$C25,'المبيعات اليومية'!$A$9:$A$308,">="&IF($B$4="",0,$B$4),'المبيعات اليومية'!$A$9:$A$308,"<="&IF($B$5="",2958465,$B$5)))) | H25: =IF($C25="","",IF($B$4&$B$5="",SUMIFS('المبيعات اليومية'!$J$9:$J$308,'المبيعات اليومية'!$B$9:$B$308,$C25),SUMIFS('المبيعات اليومية'!$J$9:$J$308,'المبيعات اليومية'!$B$9:$B$308,$C25,'المبيعات اليومية'!$A$9:$A$308,">="&IF($B$4="",0,$B$4),'المبيعات اليومية'!$A$9:$A$308,"<="&IF($B$5="",2958465,$B$5)))) | I25: =IF(OR($C25="",$H$108=0),"",H25/$H$108) | J25: =IF(C25="","",IF(D25>0,"نشط","لا يوجد مبيعات"))
A26: =IF(C26="","",19) | B26: =IF('دليل العملاء'!$B$22="","",'دليل العملاء'!$A$22) | C26: =IF('دليل العملاء'!$B$22="","",'دليل العملاء'!$B$22) | D26: =IF($C26="","",IF($B$4&$B$5="",COUNTIFS('المبيعات اليومية'!$B$9:$B$308,$C26),COUNTIFS('المبيعات اليومية'!$B$9:$B$308,$C26,'المبيعات اليومية'!$A$9:$A$308,">="&IF($B$4="",0,$B$4),'المبيعات اليومية'!$A$9:$A$308,"<="&IF($B$5="",2958465,$B$5)))) | E26: =IF($C26="","",IF($B$4&$B$5="",SUMIFS('المبيعات اليومية'!$E$9:$E$308,'المبيعات اليومية'!$B$9:$B$308,$C26),SUMIFS('المبيعات اليومية'!$E$9:$E$308,'المبيعات اليومية'!$B$9:$B$308,$C26,'المبيعات اليومية'!$A$9:$A$308,">="&IF($B$4="",0,$B$4),'المبيعات اليومية'!$A$9:$A$308,"<="&IF($B$5="",2958465,$B$5)))) | F26: =IF($C26="","",IF($B$4&$B$5="",SUMIFS('المبيعات اليومية'!$H$9:$H$308,'المبيعات اليومية'!$B$9:$B$308,$C26),SUMIFS('المبيعات اليومية'!$H$9:$H$308,'المبيعات اليومية'!$B$9:$B$308,$C26,'المبيعات اليومية'!$A$9:$A$308,">="&IF($B$4="",0,$B$4),'المبيعات اليومية'!$A$9:$A$308,"<="&IF($B$5="",2958465,$B$5)))) | G26: =IF($C26="","",IF($B$4&$B$5="",SUMIFS('المبيعات اليومية'!$I$9:$I$308,'المبيعات اليومية'!$B$9:$B$308,$C26),SUMIFS('المبيعات اليومية'!$I$9:$I$308,'المبيعات اليومية'!$B$9:$B$308,$C26,'المبيعات اليومية'!$A$9:$A$308,">="&IF($B$4="",0,$B$4),'المبيعات اليومية'!$A$9:$A$308,"<="&IF($B$5="",2958465,$B$5)))) | H26: =IF($C26="","",IF($B$4&$B$5="",SUMIFS('المبيعات اليومية'!$J$9:$J$308,'المبيعات اليومية'!$B$9:$B$308,$C26),SUMIFS('المبيعات اليومية'!$J$9:$J$308,'المبيعات اليومية'!$B$9:$B$308,$C26,'المبيعات اليومية'!$A$9:$A$308,">="&IF($B$4="",0,$B$4),'المبيعات اليومية'!$A$9:$A$308,"<="&IF($B$5="",2958465,$B$5)))) | I26: =IF(OR($C26="",$H$108=0),"",H26/$H$108) | J26: =IF(C26="","",IF(D26>0,"نشط","لا يوجد مبيعات"))
A27: =IF(C27="","",20) | B27: =IF('دليل العملاء'!$B$23="","",'دليل العملاء'!$A$23) | C27: =IF('دليل العملاء'!$B$23="","",'دليل العملاء'!$B$23) | D27: =IF($C27="","",IF($B$4&$B$5="",COUNTIFS('المبيعات اليومية'!$B$9:$B$308,$C27),COUNTIFS('المبيعات اليومية'!$B$9:$B$308,$C27,'المبيعات اليومية'!$A$9:$A$308,">="&IF($B$4="",0,$B$4),'المبيعات اليومية'!$A$9:$A$308,"<="&IF($B$5="",2958465,$B$5)))) | E27: =IF($C27="","",IF($B$4&$B$5="",SUMIFS('المبيعات اليومية'!$E$9:$E$308,'المبيعات اليومية'!$B$9:$B$308,$C27),SUMIFS('المبيعات اليومية'!$E$9:$E$308,'المبيعات اليومية'!$B$9:$B$308,$C27,'المبيعات اليومية'!$A$9:$A$308,">="&IF($B$4="",0,$B$4),'المبيعات اليومية'!$A$9:$A$308,"<="&IF($B$5="",2958465,$B$5)))) | F27: =IF($C27="","",IF($B$4&$B$5="",SUMIFS('المبيعات اليومية'!$H$9:$H$308,'المبيعات اليومية'!$B$9:$B$308,$C27),SUMIFS('المبيعات اليومية'!$H$9:$H$308,'المبيعات اليومية'!$B$9:$B$308,$C27,'المبيعات اليومية'!$A$9:$A$308,">="&IF($B$4="",0,$B$4),'المبيعات اليومية'!$A$9:$A$308,"<="&IF($B$5="",2958465,$B$5)))) | G27: =IF($C27="","",IF($B$4&$B$5="",SUMIFS('المبيعات اليومية'!$I$9:$I$308,'المبيعات اليومية'!$B$9:$B$308,$C27),SUMIFS('المبيعات اليومية'!$I$9:$I$308,'المبيعات اليومية'!$B$9:$B$308,$C27,'المبيعات اليومية'!$A$9:$A$308,">="&IF($B$4="",0,$B$4),'المبيعات اليومية'!$A$9:$A$308,"<="&IF($B$5="",2958465,$B$5)))) | H27: =IF($C27="","",IF($B$4&$B$5="",SUMIFS('المبيعات اليومية'!$J$9:$J$308,'المبيعات اليومية'!$B$9:$B$308,$C27),SUMIFS('المبيعات اليومية'!$J$9:$J$308,'المبيعات اليومية'!$B$9:$B$308,$C27,'المبيعات اليومية'!$A$9:$A$308,">="&IF($B$4="",0,$B$4),'المبيعات اليومية'!$A$9:$A$308,"<="&IF($B$5="",2958465,$B$5)))) | I27: =IF(OR($C27="",$H$108=0),"",H27/$H$108) | J27: =IF(C27="","",IF(D27>0,"نشط","لا يوجد مبيعات"))
A28: =IF(C28="","",21) | B28: =IF('دليل العملاء'!$B$24="","",'دليل العملاء'!$A$24) | C28: =IF('دليل العملاء'!$B$24="","",'دليل العملاء'!$B$24) | D28: =IF($C28="","",IF($B$4&$B$5="",COUNTIFS('المبيعات اليومية'!$B$9:$B$308,$C28),COUNTIFS('المبيعات اليومية'!$B$9:$B$308,$C28,'المبيعات اليومية'!$A$9:$A$308,">="&IF($B$4="",0,$B$4),'المبيعات اليومية'!$A$9:$A$308,"<="&IF($B$5="",2958465,$B$5)))) | E28: =IF($C28="","",IF($B$4&$B$5="",SUMIFS('المبيعات اليومية'!$E$9:$E$308,'المبيعات اليومية'!$B$9:$B$308,$C28),SUMIFS('المبيعات اليومية'!$E$9:$E$308,'المبيعات اليومية'!$B$9:$B$308,$C28,'المبيعات اليومية'!$A$9:$A$308,">="&IF($B$4="",0,$B$4),'المبيعات اليومية'!$A$9:$A$308,"<="&IF($B$5="",2958465,$B$5)))) | F28: =IF($C28="","",IF($B$4&$B$5="",SUMIFS('المبيعات اليومية'!$H$9:$H$308,'المبيعات اليومية'!$B$9:$B$308,$C28),SUMIFS('المبيعات اليومية'!$H$9:$H$308,'المبيعات اليومية'!$B$9:$B$308,$C28,'المبيعات اليومية'!$A$9:$A$308,">="&IF($B$4="",0,$B$4),'المبيعات اليومية'!$A$9:$A$308,"<="&IF($B$5="",2958465,$B$5)))) | G28: =IF($C28="","",IF($B$4&$B$5="",SUMIFS('المبيعات اليومية'!$I$9:$I$308,'المبيعات اليومية'!$B$9:$B$308,$C28),SUMIFS('المبيعات اليومية'!$I$9:$I$308,'المبيعات اليومية'!$B$9:$B$308,$C28,'المبيعات اليومية'!$A$9:$A$308,">="&IF($B$4="",0,$B$4),'المبيعات اليومية'!$A$9:$A$308,"<="&IF($B$5="",2958465,$B$5)))) | H28: =IF($C28="","",IF($B$4&$B$5="",SUMIFS('المبيعات اليومية'!$J$9:$J$308,'المبيعات اليومية'!$B$9:$B$308,$C28),SUMIFS('المبيعات اليومية'!$J$9:$J$308,'المبيعات اليومية'!$B$9:$B$308,$C28,'المبيعات اليومية'!$A$9:$A$308,">="&IF($B$4="",0,$B$4),'المبيعات اليومية'!$A$9:$A$308,"<="&IF($B$5="",2958465,$B$5)))) | I28: =IF(OR($C28="",$H$108=0),"",H28/$H$108) | J28: =IF(C28="","",IF(D28>0,"نشط","لا يوجد مبيعات"))
A29: =IF(C29="","",22) | B29: =IF('دليل العملاء'!$B$25="","",'دليل العملاء'!$A$25) | C29: =IF('دليل العملاء'!$B$25="","",'دليل العملاء'!$B$25) | D29: =IF($C29="","",IF($B$4&$B$5="",COUNTIFS('المبيعات اليومية'!$B$9:$B$308,$C29),COUNTIFS('المبيعات اليومية'!$B$9:$B$308,$C29,'المبيعات اليومية'!$A$9:$A$308,">="&IF($B$4="",0,$B$4),'المبيعات اليومية'!$A$9:$A$308,"<="&IF($B$5="",2958465,$B$5)))) | E29: =IF($C29="","",IF($B$4&$B$5="",SUMIFS('المبيعات اليومية'!$E$9:$E$308,'المبيعات اليومية'!$B$9:$B$308,$C29),SUMIFS('المبيعات اليومية'!$E$9:$E$308,'المبيعات اليومية'!$B$9:$B$308,$C29,'المبيعات اليومية'!$A$9:$A$308,">="&IF($B$4="",0,$B$4),'المبيعات اليومية'!$A$9:$A$308,"<="&IF($B$5="",2958465,$B$5)))) | F29: =IF($C29="","",IF($B$4&$B$5="",SUMIFS('المبيعات اليومية'!$H$9:$H$308,'المبيعات اليومية'!$B$9:$B$308,$C29),SUMIFS('المبيعات اليومية'!$H$9:$H$308,'المبيعات اليومية'!$B$9:$B$308,$C29,'المبيعات اليومية'!$A$9:$A$308,">="&IF($B$4="",0,$B$4),'المبيعات اليومية'!$A$9:$A$308,"<="&IF($B$5="",2958465,$B$5)))) | G29: =IF($C29="","",IF($B$4&$B$5="",SUMIFS('المبيعات اليومية'!$I$9:$I$308,'المبيعات اليومية'!$B$9:$B$308,$C29),SUMIFS('المبيعات اليومية'!$I$9:$I$308,'المبيعات اليومية'!$B$9:$B$308,$C29,'المبيعات اليومية'!$A$9:$A$308,">="&IF($B$4="",0,$B$4),'المبيعات اليومية'!$A$9:$A$308,"<="&IF($B$5="",2958465,$B$5)))) | H29: =IF($C29="","",IF($B$4&$B$5="",SUMIFS('المبيعات اليومية'!$J$9:$J$308,'المبيعات اليومية'!$B$9:$B$308,$C29),SUMIFS('المبيعات اليومية'!$J$9:$J$308,'المبيعات اليومية'!$B$9:$B$308,$C29,'المبيعات اليومية'!$A$9:$A$308,">="&IF($B$4="",0,$B$4),'المبيعات اليومية'!$A$9:$A$308,"<="&IF($B$5="",2958465,$B$5)))) | I29: =IF(OR($C29="",$H$108=0),"",H29/$H$108) | J29: =IF(C29="","",IF(D29>0,"نشط","لا يوجد مبيعات"))
A30: =IF(C30="","",23) | B30: =IF('دليل العملاء'!$B$26="","",'دليل العملاء'!$A$26) | C30: =IF('دليل العملاء'!$B$26="","",'دليل العملاء'!$B$26) | D30: =IF($C30="","",IF($B$4&$B$5="",COUNTIFS('المبيعات اليومية'!$B$9:$B$308,$C30),COUNTIFS('المبيعات اليومية'!$B$9:$B$308,$C30,'المبيعات اليومية'!$A$9:$A$308,">="&IF($B$4="",0,$B$4),'المبيعات اليومية'!$A$9:$A$308,"<="&IF($B$5="",2958465,$B$5)))) | E30: =IF($C30="","",IF($B$4&$B$5="",SUMIFS('المبيعات اليومية'!$E$9:$E$308,'المبيعات اليومية'!$B$9:$B$308,$C30),SUMIFS('المبيعات اليومية'!$E$9:$E$308,'المبيعات اليومية'!$B$9:$B$308,$C30,'المبيعات اليومية'!$A$9:$A$308,">="&IF($B$4="",0,$B$4),'المبيعات اليومية'!$A$9:$A$308,"<="&IF($B$5="",2958465,$B$5)))) | F30: =IF($C30="","",IF($B$4&$B$5="",SUMIFS('المبيعات اليومية'!$H$9:$H$308,'المبيعات اليومية'!$B$9:$B$308,$C30),SUMIFS('المبيعات اليومية'!$H$9:$H$308,'المبيعات اليومية'!$B$9:$B$308,$C30,'المبيعات اليومية'!$A$9:$A$308,">="&IF($B$4="",0,$B$4),'المبيعات اليومية'!$A$9:$A$308,"<="&IF($B$5="",2958465,$B$5)))) | G30: =IF($C30="","",IF($B$4&$B$5="",SUMIFS('المبيعات اليومية'!$I$9:$I$308,'المبيعات اليومية'!$B$9:$B$308,$C30),SUMIFS('المبيعات اليومية'!$I$9:$I$308,'المبيعات اليومية'!$B$9:$B$308,$C30,'المبيعات اليومية'!$A$9:$A$308,">="&IF($B$4="",0,$B$4),'المبيعات اليومية'!$A$9:$A$308,"<="&IF($B$5="",2958465,$B$5)))) | H30: =IF($C30="","",IF($B$4&$B$5="",SUMIFS('المبيعات اليومية'!$J$9:$J$308,'المبيعات اليومية'!$B$9:$B$308,$C30),SUMIFS('المبيعات اليومية'!$J$9:$J$308,'المبيعات اليومية'!$B$9:$B$308,$C30,'المبيعات اليومية'!$A$9:$A$308,">="&IF($B$4="",0,$B$4),'المبيعات اليومية'!$A$9:$A$308,"<="&IF($B$5="",2958465,$B$5)))) | I30: =IF(OR($C30="",$H$108=0),"",H30/$H$108) | J30: =IF(C30="","",IF(D30>0,"نشط","لا يوجد مبيعات"))
